213.21 208.40348714884007 904
213.36 208.5034871488401 904
214.04 208.9568204821734 904
213.28 208.45015381550675 904
213.15 208.3634871488401 904
212.79 208.1234871488401 904
212.88 208.18348714884007 904
213.22 208.41015381550673 904
213.41 208.53682048217343 904
218.66 215.23671793850224 905
218.57 215.17671793850226 905
217.55 214.49671793850226 905
217.83 214.68338460516892 905
221.62 217.2100512718356 905
221.6 217.19671793850225 905
220.21 219.5900170906119 906
220.39 219.71001709061184 906
225.65 223.2166837572785 906
225.11 222.85668375727855 906
224.39 222.37668375727853 906
224.65 222.55001709061185 906
226.27 223.63001709061186 906
226.3 223.65001709061187 906
225.17 222.8966837572785 906
225.36 223.0233504239452 906
Traceback (most recent call last):
  File "/Library/Frameworks/Python.framework/Versions/3.8/lib/python3.8/site-packages/urllib3/connection.py", line 156, in _new_conn
    conn = connection.create_connection(
  File "/Library/Frameworks/Python.framework/Versions/3.8/lib/python3.8/site-packages/urllib3/util/connection.py", line 61, in create_connection
    for res in socket.getaddrinfo(host, port, family, socket.SOCK_STREAM):
  File "/Library/Frameworks/Python.framework/Versions/3.8/lib/python3.8/socket.py", line 914, in getaddrinfo
    for res in _socket.getaddrinfo(host, port, family, type, proto, flags):
socket.gaierror: [Errno 8] nodename nor servname provided, or not known

During handling of the above exception, another exception occurred:

Traceback (most recent call last):
  File "/Library/Frameworks/Python.framework/Versions/3.8/lib/python3.8/site-packages/urllib3/connectionpool.py", line 665, in urlopen
    httplib_response = self._make_request(
  File "/Library/Frameworks/Python.framework/Versions/3.8/lib/python3.8/site-packages/urllib3/connectionpool.py", line 376, in _make_request
    self._validate_conn(conn)
  File "/Library/Frameworks/Python.framework/Versions/3.8/lib/python3.8/site-packages/urllib3/connectionpool.py", line 994, in _validate_conn
    conn.connect()
  File "/Library/Frameworks/Python.framework/Versions/3.8/lib/python3.8/site-packages/urllib3/connection.py", line 334, in connect
    conn = self._new_conn()
  File "/Library/Frameworks/Python.framework/Versions/3.8/lib/python3.8/site-packages/urllib3/connection.py", line 168, in _new_conn
    raise NewConnectionError(
urllib3.exceptions.NewConnectionError: <urllib3.connection.VerifiedHTTPSConnection object at 0x11197c370>: Failed to establish a new connection: [Errno 8] nodename nor servname provided, or not known

During handling of the above exception, another exception occurred:

Traceback (most recent call last):
  File "/Library/Frameworks/Python.framework/Versions/3.8/lib/python3.8/site-packages/requests/adapters.py", line 439, in send
    resp = conn.urlopen(
  File "/Library/Frameworks/Python.framework/Versions/3.8/lib/python3.8/site-packages/urllib3/connectionpool.py", line 719, in urlopen
    retries = retries.increment(
  File "/Library/Frameworks/Python.framework/Versions/3.8/lib/python3.8/site-packages/urllib3/util/retry.py", line 436, in increment
    raise MaxRetryError(_pool, url, error or ResponseError(cause))
urllib3.exceptions.MaxRetryError: HTTPSConnectionPool(host='api.binance.com', port=443): Max retries exceeded with url: /api/v1/ping (Caused by NewConnectionError('<urllib3.connection.VerifiedHTTPSConnection object at 0x11197c370>: Failed to establish a new connection: [Errno 8] nodename nor servname provided, or not known'))

During handling of the above exception, another exception occurred:

Traceback (most recent call last):
  File "binance1.py", line 20, in <module>
    client = Client(api_key, api_secret)
  File "/Library/Frameworks/Python.framework/Versions/3.8/lib/python3.8/site-packages/binance/client.py", line 97, in __init__
    self.ping()
  File "/Library/Frameworks/Python.framework/Versions/3.8/lib/python3.8/site-packages/binance/client.py", line 378, in ping
    return self._get('ping')
  File "/Library/Frameworks/Python.framework/Versions/3.8/lib/python3.8/site-packages/binance/client.py", line 222, in _get
    return self._request_api('get', path, signed, version, **kwargs)
  File "/Library/Frameworks/Python.framework/Versions/3.8/lib/python3.8/site-packages/binance/client.py", line 191, in _request_api
    return self._request(method, uri, signed, **kwargs)
  File "/Library/Frameworks/Python.framework/Versions/3.8/lib/python3.8/site-packages/binance/client.py", line 185, in _request
    self.response = getattr(self.session, method)(uri, **kwargs)
  File "/Library/Frameworks/Python.framework/Versions/3.8/lib/python3.8/site-packages/requests/sessions.py", line 546, in get
    return self.request('GET', url, **kwargs)
  File "/Library/Frameworks/Python.framework/Versions/3.8/lib/python3.8/site-packages/requests/sessions.py", line 533, in request
    resp = self.send(prep, **send_kwargs)
  File "/Library/Frameworks/Python.framework/Versions/3.8/lib/python3.8/site-packages/requests/sessions.py", line 646, in send
    r = adapter.send(request, **kwargs)
  File "/Library/Frameworks/Python.framework/Versions/3.8/lib/python3.8/site-packages/requests/adapters.py", line 516, in send
    raise ConnectionError(e, request=request)
requests.exceptions.ConnectionError: HTTPSConnectionPool(host='api.binance.com', port=443): Max retries exceeded with url: /api/v1/ping (Caused by NewConnectionError('<urllib3.connection.VerifiedHTTPSConnection object at 0x11197c370>: Failed to establish a new connection: [Errno 8] nodename nor servname provided, or not known'))
Traceback (most recent call last):
  File "email_price_notify.py", line 77, in <module>
    server = smtplib.SMTP('smtp.gmail.com', 587) 
  File "/Library/Frameworks/Python.framework/Versions/3.8/lib/python3.8/smtplib.py", line 253, in __init__
    (code, msg) = self.connect(host, port)
  File "/Library/Frameworks/Python.framework/Versions/3.8/lib/python3.8/smtplib.py", line 339, in connect
    self.sock = self._get_socket(host, port, self.timeout)
  File "/Library/Frameworks/Python.framework/Versions/3.8/lib/python3.8/smtplib.py", line 308, in _get_socket
    return socket.create_connection((host, port), timeout,
  File "/Library/Frameworks/Python.framework/Versions/3.8/lib/python3.8/socket.py", line 787, in create_connection
    for res in getaddrinfo(host, port, 0, SOCK_STREAM):
  File "/Library/Frameworks/Python.framework/Versions/3.8/lib/python3.8/socket.py", line 914, in getaddrinfo
    for res in _socket.getaddrinfo(host, port, family, type, proto, flags):
socket.gaierror: [Errno 8] nodename nor servname provided, or not known
Traceback (most recent call last):
  File "/Library/Frameworks/Python.framework/Versions/3.8/lib/python3.8/site-packages/urllib3/connection.py", line 156, in _new_conn
    conn = connection.create_connection(
  File "/Library/Frameworks/Python.framework/Versions/3.8/lib/python3.8/site-packages/urllib3/util/connection.py", line 61, in create_connection
    for res in socket.getaddrinfo(host, port, family, socket.SOCK_STREAM):
  File "/Library/Frameworks/Python.framework/Versions/3.8/lib/python3.8/socket.py", line 914, in getaddrinfo
    for res in _socket.getaddrinfo(host, port, family, type, proto, flags):
socket.gaierror: [Errno 8] nodename nor servname provided, or not known

During handling of the above exception, another exception occurred:

Traceback (most recent call last):
  File "/Library/Frameworks/Python.framework/Versions/3.8/lib/python3.8/site-packages/urllib3/connectionpool.py", line 665, in urlopen
    httplib_response = self._make_request(
  File "/Library/Frameworks/Python.framework/Versions/3.8/lib/python3.8/site-packages/urllib3/connectionpool.py", line 376, in _make_request
    self._validate_conn(conn)
  File "/Library/Frameworks/Python.framework/Versions/3.8/lib/python3.8/site-packages/urllib3/connectionpool.py", line 994, in _validate_conn
    conn.connect()
  File "/Library/Frameworks/Python.framework/Versions/3.8/lib/python3.8/site-packages/urllib3/connection.py", line 334, in connect
    conn = self._new_conn()
  File "/Library/Frameworks/Python.framework/Versions/3.8/lib/python3.8/site-packages/urllib3/connection.py", line 168, in _new_conn
    raise NewConnectionError(
urllib3.exceptions.NewConnectionError: <urllib3.connection.VerifiedHTTPSConnection object at 0x1116723d0>: Failed to establish a new connection: [Errno 8] nodename nor servname provided, or not known

During handling of the above exception, another exception occurred:

Traceback (most recent call last):
  File "/Library/Frameworks/Python.framework/Versions/3.8/lib/python3.8/site-packages/requests/adapters.py", line 439, in send
    resp = conn.urlopen(
  File "/Library/Frameworks/Python.framework/Versions/3.8/lib/python3.8/site-packages/urllib3/connectionpool.py", line 719, in urlopen
    retries = retries.increment(
  File "/Library/Frameworks/Python.framework/Versions/3.8/lib/python3.8/site-packages/urllib3/util/retry.py", line 436, in increment
    raise MaxRetryError(_pool, url, error or ResponseError(cause))
urllib3.exceptions.MaxRetryError: HTTPSConnectionPool(host='api.binance.com', port=443): Max retries exceeded with url: /api/v1/ping (Caused by NewConnectionError('<urllib3.connection.VerifiedHTTPSConnection object at 0x1116723d0>: Failed to establish a new connection: [Errno 8] nodename nor servname provided, or not known'))

During handling of the above exception, another exception occurred:

Traceback (most recent call last):
  File "binance1.py", line 20, in <module>
    client = Client(api_key, api_secret)
  File "/Library/Frameworks/Python.framework/Versions/3.8/lib/python3.8/site-packages/binance/client.py", line 97, in __init__
    self.ping()
  File "/Library/Frameworks/Python.framework/Versions/3.8/lib/python3.8/site-packages/binance/client.py", line 378, in ping
    return self._get('ping')
  File "/Library/Frameworks/Python.framework/Versions/3.8/lib/python3.8/site-packages/binance/client.py", line 222, in _get
    return self._request_api('get', path, signed, version, **kwargs)
  File "/Library/Frameworks/Python.framework/Versions/3.8/lib/python3.8/site-packages/binance/client.py", line 191, in _request_api
    return self._request(method, uri, signed, **kwargs)
  File "/Library/Frameworks/Python.framework/Versions/3.8/lib/python3.8/site-packages/binance/client.py", line 185, in _request
    self.response = getattr(self.session, method)(uri, **kwargs)
  File "/Library/Frameworks/Python.framework/Versions/3.8/lib/python3.8/site-packages/requests/sessions.py", line 546, in get
    return self.request('GET', url, **kwargs)
  File "/Library/Frameworks/Python.framework/Versions/3.8/lib/python3.8/site-packages/requests/sessions.py", line 533, in request
    resp = self.send(prep, **send_kwargs)
  File "/Library/Frameworks/Python.framework/Versions/3.8/lib/python3.8/site-packages/requests/sessions.py", line 646, in send
    r = adapter.send(request, **kwargs)
  File "/Library/Frameworks/Python.framework/Versions/3.8/lib/python3.8/site-packages/requests/adapters.py", line 516, in send
    raise ConnectionError(e, request=request)
requests.exceptions.ConnectionError: HTTPSConnectionPool(host='api.binance.com', port=443): Max retries exceeded with url: /api/v1/ping (Caused by NewConnectionError('<urllib3.connection.VerifiedHTTPSConnection object at 0x1116723d0>: Failed to establish a new connection: [Errno 8] nodename nor servname provided, or not known'))
Traceback (most recent call last):
  File "email_price_notify.py", line 77, in <module>
    server = smtplib.SMTP('smtp.gmail.com', 587) 
  File "/Library/Frameworks/Python.framework/Versions/3.8/lib/python3.8/smtplib.py", line 253, in __init__
    (code, msg) = self.connect(host, port)
  File "/Library/Frameworks/Python.framework/Versions/3.8/lib/python3.8/smtplib.py", line 339, in connect
    self.sock = self._get_socket(host, port, self.timeout)
  File "/Library/Frameworks/Python.framework/Versions/3.8/lib/python3.8/smtplib.py", line 308, in _get_socket
    return socket.create_connection((host, port), timeout,
  File "/Library/Frameworks/Python.framework/Versions/3.8/lib/python3.8/socket.py", line 787, in create_connection
    for res in getaddrinfo(host, port, 0, SOCK_STREAM):
  File "/Library/Frameworks/Python.framework/Versions/3.8/lib/python3.8/socket.py", line 914, in getaddrinfo
    for res in _socket.getaddrinfo(host, port, family, type, proto, flags):
socket.gaierror: [Errno 8] nodename nor servname provided, or not known
Traceback (most recent call last):
  File "/Library/Frameworks/Python.framework/Versions/3.8/lib/python3.8/site-packages/urllib3/connection.py", line 156, in _new_conn
    conn = connection.create_connection(
  File "/Library/Frameworks/Python.framework/Versions/3.8/lib/python3.8/site-packages/urllib3/util/connection.py", line 61, in create_connection
    for res in socket.getaddrinfo(host, port, family, socket.SOCK_STREAM):
  File "/Library/Frameworks/Python.framework/Versions/3.8/lib/python3.8/socket.py", line 914, in getaddrinfo
    for res in _socket.getaddrinfo(host, port, family, type, proto, flags):
socket.gaierror: [Errno 8] nodename nor servname provided, or not known

During handling of the above exception, another exception occurred:

Traceback (most recent call last):
  File "/Library/Frameworks/Python.framework/Versions/3.8/lib/python3.8/site-packages/urllib3/connectionpool.py", line 665, in urlopen
    httplib_response = self._make_request(
  File "/Library/Frameworks/Python.framework/Versions/3.8/lib/python3.8/site-packages/urllib3/connectionpool.py", line 376, in _make_request
    self._validate_conn(conn)
  File "/Library/Frameworks/Python.framework/Versions/3.8/lib/python3.8/site-packages/urllib3/connectionpool.py", line 994, in _validate_conn
    conn.connect()
  File "/Library/Frameworks/Python.framework/Versions/3.8/lib/python3.8/site-packages/urllib3/connection.py", line 334, in connect
    conn = self._new_conn()
  File "/Library/Frameworks/Python.framework/Versions/3.8/lib/python3.8/site-packages/urllib3/connection.py", line 168, in _new_conn
    raise NewConnectionError(
urllib3.exceptions.NewConnectionError: <urllib3.connection.VerifiedHTTPSConnection object at 0x115ffe3d0>: Failed to establish a new connection: [Errno 8] nodename nor servname provided, or not known

During handling of the above exception, another exception occurred:

Traceback (most recent call last):
  File "/Library/Frameworks/Python.framework/Versions/3.8/lib/python3.8/site-packages/requests/adapters.py", line 439, in send
    resp = conn.urlopen(
  File "/Library/Frameworks/Python.framework/Versions/3.8/lib/python3.8/site-packages/urllib3/connectionpool.py", line 719, in urlopen
    retries = retries.increment(
  File "/Library/Frameworks/Python.framework/Versions/3.8/lib/python3.8/site-packages/urllib3/util/retry.py", line 436, in increment
    raise MaxRetryError(_pool, url, error or ResponseError(cause))
urllib3.exceptions.MaxRetryError: HTTPSConnectionPool(host='api.binance.com', port=443): Max retries exceeded with url: /api/v1/ping (Caused by NewConnectionError('<urllib3.connection.VerifiedHTTPSConnection object at 0x115ffe3d0>: Failed to establish a new connection: [Errno 8] nodename nor servname provided, or not known'))

During handling of the above exception, another exception occurred:

Traceback (most recent call last):
  File "binance1.py", line 20, in <module>
    client = Client(api_key, api_secret)
  File "/Library/Frameworks/Python.framework/Versions/3.8/lib/python3.8/site-packages/binance/client.py", line 97, in __init__
    self.ping()
  File "/Library/Frameworks/Python.framework/Versions/3.8/lib/python3.8/site-packages/binance/client.py", line 378, in ping
    return self._get('ping')
  File "/Library/Frameworks/Python.framework/Versions/3.8/lib/python3.8/site-packages/binance/client.py", line 222, in _get
    return self._request_api('get', path, signed, version, **kwargs)
  File "/Library/Frameworks/Python.framework/Versions/3.8/lib/python3.8/site-packages/binance/client.py", line 191, in _request_api
    return self._request(method, uri, signed, **kwargs)
  File "/Library/Frameworks/Python.framework/Versions/3.8/lib/python3.8/site-packages/binance/client.py", line 185, in _request
    self.response = getattr(self.session, method)(uri, **kwargs)
  File "/Library/Frameworks/Python.framework/Versions/3.8/lib/python3.8/site-packages/requests/sessions.py", line 546, in get
    return self.request('GET', url, **kwargs)
  File "/Library/Frameworks/Python.framework/Versions/3.8/lib/python3.8/site-packages/requests/sessions.py", line 533, in request
    resp = self.send(prep, **send_kwargs)
  File "/Library/Frameworks/Python.framework/Versions/3.8/lib/python3.8/site-packages/requests/sessions.py", line 646, in send
    r = adapter.send(request, **kwargs)
  File "/Library/Frameworks/Python.framework/Versions/3.8/lib/python3.8/site-packages/requests/adapters.py", line 516, in send
    raise ConnectionError(e, request=request)
requests.exceptions.ConnectionError: HTTPSConnectionPool(host='api.binance.com', port=443): Max retries exceeded with url: /api/v1/ping (Caused by NewConnectionError('<urllib3.connection.VerifiedHTTPSConnection object at 0x115ffe3d0>: Failed to establish a new connection: [Errno 8] nodename nor servname provided, or not known'))
Traceback (most recent call last):
  File "email_price_notify.py", line 77, in <module>
    server = smtplib.SMTP('smtp.gmail.com', 587) 
  File "/Library/Frameworks/Python.framework/Versions/3.8/lib/python3.8/smtplib.py", line 253, in __init__
    (code, msg) = self.connect(host, port)
  File "/Library/Frameworks/Python.framework/Versions/3.8/lib/python3.8/smtplib.py", line 339, in connect
    self.sock = self._get_socket(host, port, self.timeout)
  File "/Library/Frameworks/Python.framework/Versions/3.8/lib/python3.8/smtplib.py", line 308, in _get_socket
    return socket.create_connection((host, port), timeout,
  File "/Library/Frameworks/Python.framework/Versions/3.8/lib/python3.8/socket.py", line 787, in create_connection
    for res in getaddrinfo(host, port, 0, SOCK_STREAM):
  File "/Library/Frameworks/Python.framework/Versions/3.8/lib/python3.8/socket.py", line 914, in getaddrinfo
    for res in _socket.getaddrinfo(host, port, family, type, proto, flags):
socket.gaierror: [Errno 8] nodename nor servname provided, or not known
Traceback (most recent call last):
  File "/Library/Frameworks/Python.framework/Versions/3.8/lib/python3.8/site-packages/urllib3/connection.py", line 156, in _new_conn
    conn = connection.create_connection(
  File "/Library/Frameworks/Python.framework/Versions/3.8/lib/python3.8/site-packages/urllib3/util/connection.py", line 61, in create_connection
    for res in socket.getaddrinfo(host, port, family, socket.SOCK_STREAM):
  File "/Library/Frameworks/Python.framework/Versions/3.8/lib/python3.8/socket.py", line 914, in getaddrinfo
    for res in _socket.getaddrinfo(host, port, family, type, proto, flags):
socket.gaierror: [Errno 8] nodename nor servname provided, or not known

During handling of the above exception, another exception occurred:

Traceback (most recent call last):
  File "/Library/Frameworks/Python.framework/Versions/3.8/lib/python3.8/site-packages/urllib3/connectionpool.py", line 665, in urlopen
    httplib_response = self._make_request(
  File "/Library/Frameworks/Python.framework/Versions/3.8/lib/python3.8/site-packages/urllib3/connectionpool.py", line 376, in _make_request
    self._validate_conn(conn)
  File "/Library/Frameworks/Python.framework/Versions/3.8/lib/python3.8/site-packages/urllib3/connectionpool.py", line 994, in _validate_conn
    conn.connect()
  File "/Library/Frameworks/Python.framework/Versions/3.8/lib/python3.8/site-packages/urllib3/connection.py", line 334, in connect
    conn = self._new_conn()
  File "/Library/Frameworks/Python.framework/Versions/3.8/lib/python3.8/site-packages/urllib3/connection.py", line 168, in _new_conn
    raise NewConnectionError(
urllib3.exceptions.NewConnectionError: <urllib3.connection.VerifiedHTTPSConnection object at 0x118fe9400>: Failed to establish a new connection: [Errno 8] nodename nor servname provided, or not known

During handling of the above exception, another exception occurred:

Traceback (most recent call last):
  File "/Library/Frameworks/Python.framework/Versions/3.8/lib/python3.8/site-packages/requests/adapters.py", line 439, in send
    resp = conn.urlopen(
  File "/Library/Frameworks/Python.framework/Versions/3.8/lib/python3.8/site-packages/urllib3/connectionpool.py", line 719, in urlopen
    retries = retries.increment(
  File "/Library/Frameworks/Python.framework/Versions/3.8/lib/python3.8/site-packages/urllib3/util/retry.py", line 436, in increment
    raise MaxRetryError(_pool, url, error or ResponseError(cause))
urllib3.exceptions.MaxRetryError: HTTPSConnectionPool(host='api.binance.com', port=443): Max retries exceeded with url: /api/v1/ping (Caused by NewConnectionError('<urllib3.connection.VerifiedHTTPSConnection object at 0x118fe9400>: Failed to establish a new connection: [Errno 8] nodename nor servname provided, or not known'))

During handling of the above exception, another exception occurred:

Traceback (most recent call last):
  File "binance1.py", line 20, in <module>
    client = Client(api_key, api_secret)
  File "/Library/Frameworks/Python.framework/Versions/3.8/lib/python3.8/site-packages/binance/client.py", line 97, in __init__
    self.ping()
  File "/Library/Frameworks/Python.framework/Versions/3.8/lib/python3.8/site-packages/binance/client.py", line 378, in ping
    return self._get('ping')
  File "/Library/Frameworks/Python.framework/Versions/3.8/lib/python3.8/site-packages/binance/client.py", line 222, in _get
    return self._request_api('get', path, signed, version, **kwargs)
  File "/Library/Frameworks/Python.framework/Versions/3.8/lib/python3.8/site-packages/binance/client.py", line 191, in _request_api
    return self._request(method, uri, signed, **kwargs)
  File "/Library/Frameworks/Python.framework/Versions/3.8/lib/python3.8/site-packages/binance/client.py", line 185, in _request
    self.response = getattr(self.session, method)(uri, **kwargs)
  File "/Library/Frameworks/Python.framework/Versions/3.8/lib/python3.8/site-packages/requests/sessions.py", line 546, in get
    return self.request('GET', url, **kwargs)
  File "/Library/Frameworks/Python.framework/Versions/3.8/lib/python3.8/site-packages/requests/sessions.py", line 533, in request
    resp = self.send(prep, **send_kwargs)
  File "/Library/Frameworks/Python.framework/Versions/3.8/lib/python3.8/site-packages/requests/sessions.py", line 646, in send
    r = adapter.send(request, **kwargs)
  File "/Library/Frameworks/Python.framework/Versions/3.8/lib/python3.8/site-packages/requests/adapters.py", line 516, in send
    raise ConnectionError(e, request=request)
requests.exceptions.ConnectionError: HTTPSConnectionPool(host='api.binance.com', port=443): Max retries exceeded with url: /api/v1/ping (Caused by NewConnectionError('<urllib3.connection.VerifiedHTTPSConnection object at 0x118fe9400>: Failed to establish a new connection: [Errno 8] nodename nor servname provided, or not known'))
Traceback (most recent call last):
  File "email_price_notify.py", line 77, in <module>
    server = smtplib.SMTP('smtp.gmail.com', 587) 
  File "/Library/Frameworks/Python.framework/Versions/3.8/lib/python3.8/smtplib.py", line 253, in __init__
    (code, msg) = self.connect(host, port)
  File "/Library/Frameworks/Python.framework/Versions/3.8/lib/python3.8/smtplib.py", line 339, in connect
    self.sock = self._get_socket(host, port, self.timeout)
  File "/Library/Frameworks/Python.framework/Versions/3.8/lib/python3.8/smtplib.py", line 308, in _get_socket
    return socket.create_connection((host, port), timeout,
  File "/Library/Frameworks/Python.framework/Versions/3.8/lib/python3.8/socket.py", line 787, in create_connection
    for res in getaddrinfo(host, port, 0, SOCK_STREAM):
  File "/Library/Frameworks/Python.framework/Versions/3.8/lib/python3.8/socket.py", line 914, in getaddrinfo
    for res in _socket.getaddrinfo(host, port, family, type, proto, flags):
socket.gaierror: [Errno 8] nodename nor servname provided, or not known
Traceback (most recent call last):
  File "/Library/Frameworks/Python.framework/Versions/3.8/lib/python3.8/site-packages/urllib3/connection.py", line 156, in _new_conn
    conn = connection.create_connection(
  File "/Library/Frameworks/Python.framework/Versions/3.8/lib/python3.8/site-packages/urllib3/util/connection.py", line 61, in create_connection
    for res in socket.getaddrinfo(host, port, family, socket.SOCK_STREAM):
  File "/Library/Frameworks/Python.framework/Versions/3.8/lib/python3.8/socket.py", line 914, in getaddrinfo
    for res in _socket.getaddrinfo(host, port, family, type, proto, flags):
socket.gaierror: [Errno 8] nodename nor servname provided, or not known

During handling of the above exception, another exception occurred:

Traceback (most recent call last):
  File "/Library/Frameworks/Python.framework/Versions/3.8/lib/python3.8/site-packages/urllib3/connectionpool.py", line 665, in urlopen
    httplib_response = self._make_request(
  File "/Library/Frameworks/Python.framework/Versions/3.8/lib/python3.8/site-packages/urllib3/connectionpool.py", line 376, in _make_request
    self._validate_conn(conn)
  File "/Library/Frameworks/Python.framework/Versions/3.8/lib/python3.8/site-packages/urllib3/connectionpool.py", line 994, in _validate_conn
    conn.connect()
  File "/Library/Frameworks/Python.framework/Versions/3.8/lib/python3.8/site-packages/urllib3/connection.py", line 334, in connect
    conn = self._new_conn()
  File "/Library/Frameworks/Python.framework/Versions/3.8/lib/python3.8/site-packages/urllib3/connection.py", line 168, in _new_conn
    raise NewConnectionError(
urllib3.exceptions.NewConnectionError: <urllib3.connection.VerifiedHTTPSConnection object at 0x113a4b370>: Failed to establish a new connection: [Errno 8] nodename nor servname provided, or not known

During handling of the above exception, another exception occurred:

Traceback (most recent call last):
  File "/Library/Frameworks/Python.framework/Versions/3.8/lib/python3.8/site-packages/requests/adapters.py", line 439, in send
    resp = conn.urlopen(
  File "/Library/Frameworks/Python.framework/Versions/3.8/lib/python3.8/site-packages/urllib3/connectionpool.py", line 719, in urlopen
    retries = retries.increment(
  File "/Library/Frameworks/Python.framework/Versions/3.8/lib/python3.8/site-packages/urllib3/util/retry.py", line 436, in increment
    raise MaxRetryError(_pool, url, error or ResponseError(cause))
urllib3.exceptions.MaxRetryError: HTTPSConnectionPool(host='api.binance.com', port=443): Max retries exceeded with url: /api/v1/ping (Caused by NewConnectionError('<urllib3.connection.VerifiedHTTPSConnection object at 0x113a4b370>: Failed to establish a new connection: [Errno 8] nodename nor servname provided, or not known'))

During handling of the above exception, another exception occurred:

Traceback (most recent call last):
  File "binance1.py", line 20, in <module>
    client = Client(api_key, api_secret)
  File "/Library/Frameworks/Python.framework/Versions/3.8/lib/python3.8/site-packages/binance/client.py", line 97, in __init__
    self.ping()
  File "/Library/Frameworks/Python.framework/Versions/3.8/lib/python3.8/site-packages/binance/client.py", line 378, in ping
    return self._get('ping')
  File "/Library/Frameworks/Python.framework/Versions/3.8/lib/python3.8/site-packages/binance/client.py", line 222, in _get
    return self._request_api('get', path, signed, version, **kwargs)
  File "/Library/Frameworks/Python.framework/Versions/3.8/lib/python3.8/site-packages/binance/client.py", line 191, in _request_api
    return self._request(method, uri, signed, **kwargs)
  File "/Library/Frameworks/Python.framework/Versions/3.8/lib/python3.8/site-packages/binance/client.py", line 185, in _request
    self.response = getattr(self.session, method)(uri, **kwargs)
  File "/Library/Frameworks/Python.framework/Versions/3.8/lib/python3.8/site-packages/requests/sessions.py", line 546, in get
    return self.request('GET', url, **kwargs)
  File "/Library/Frameworks/Python.framework/Versions/3.8/lib/python3.8/site-packages/requests/sessions.py", line 533, in request
    resp = self.send(prep, **send_kwargs)
  File "/Library/Frameworks/Python.framework/Versions/3.8/lib/python3.8/site-packages/requests/sessions.py", line 646, in send
    r = adapter.send(request, **kwargs)
  File "/Library/Frameworks/Python.framework/Versions/3.8/lib/python3.8/site-packages/requests/adapters.py", line 516, in send
    raise ConnectionError(e, request=request)
requests.exceptions.ConnectionError: HTTPSConnectionPool(host='api.binance.com', port=443): Max retries exceeded with url: /api/v1/ping (Caused by NewConnectionError('<urllib3.connection.VerifiedHTTPSConnection object at 0x113a4b370>: Failed to establish a new connection: [Errno 8] nodename nor servname provided, or not known'))
Traceback (most recent call last):
  File "email_price_notify.py", line 77, in <module>
    server = smtplib.SMTP('smtp.gmail.com', 587) 
  File "/Library/Frameworks/Python.framework/Versions/3.8/lib/python3.8/smtplib.py", line 253, in __init__
    (code, msg) = self.connect(host, port)
  File "/Library/Frameworks/Python.framework/Versions/3.8/lib/python3.8/smtplib.py", line 339, in connect
    self.sock = self._get_socket(host, port, self.timeout)
  File "/Library/Frameworks/Python.framework/Versions/3.8/lib/python3.8/smtplib.py", line 308, in _get_socket
    return socket.create_connection((host, port), timeout,
  File "/Library/Frameworks/Python.framework/Versions/3.8/lib/python3.8/socket.py", line 787, in create_connection
    for res in getaddrinfo(host, port, 0, SOCK_STREAM):
  File "/Library/Frameworks/Python.framework/Versions/3.8/lib/python3.8/socket.py", line 914, in getaddrinfo
    for res in _socket.getaddrinfo(host, port, family, type, proto, flags):
socket.gaierror: [Errno 8] nodename nor servname provided, or not known
Traceback (most recent call last):
  File "/Library/Frameworks/Python.framework/Versions/3.8/lib/python3.8/site-packages/urllib3/connection.py", line 156, in _new_conn
    conn = connection.create_connection(
  File "/Library/Frameworks/Python.framework/Versions/3.8/lib/python3.8/site-packages/urllib3/util/connection.py", line 61, in create_connection
    for res in socket.getaddrinfo(host, port, family, socket.SOCK_STREAM):
  File "/Library/Frameworks/Python.framework/Versions/3.8/lib/python3.8/socket.py", line 914, in getaddrinfo
    for res in _socket.getaddrinfo(host, port, family, type, proto, flags):
socket.gaierror: [Errno 8] nodename nor servname provided, or not known

During handling of the above exception, another exception occurred:

Traceback (most recent call last):
  File "/Library/Frameworks/Python.framework/Versions/3.8/lib/python3.8/site-packages/urllib3/connectionpool.py", line 665, in urlopen
    httplib_response = self._make_request(
  File "/Library/Frameworks/Python.framework/Versions/3.8/lib/python3.8/site-packages/urllib3/connectionpool.py", line 376, in _make_request
    self._validate_conn(conn)
  File "/Library/Frameworks/Python.framework/Versions/3.8/lib/python3.8/site-packages/urllib3/connectionpool.py", line 994, in _validate_conn
    conn.connect()
  File "/Library/Frameworks/Python.framework/Versions/3.8/lib/python3.8/site-packages/urllib3/connection.py", line 334, in connect
    conn = self._new_conn()
  File "/Library/Frameworks/Python.framework/Versions/3.8/lib/python3.8/site-packages/urllib3/connection.py", line 168, in _new_conn
    raise NewConnectionError(
urllib3.exceptions.NewConnectionError: <urllib3.connection.VerifiedHTTPSConnection object at 0x117338400>: Failed to establish a new connection: [Errno 8] nodename nor servname provided, or not known

During handling of the above exception, another exception occurred:

Traceback (most recent call last):
  File "/Library/Frameworks/Python.framework/Versions/3.8/lib/python3.8/site-packages/requests/adapters.py", line 439, in send
    resp = conn.urlopen(
  File "/Library/Frameworks/Python.framework/Versions/3.8/lib/python3.8/site-packages/urllib3/connectionpool.py", line 719, in urlopen
    retries = retries.increment(
  File "/Library/Frameworks/Python.framework/Versions/3.8/lib/python3.8/site-packages/urllib3/util/retry.py", line 436, in increment
    raise MaxRetryError(_pool, url, error or ResponseError(cause))
urllib3.exceptions.MaxRetryError: HTTPSConnectionPool(host='api.binance.com', port=443): Max retries exceeded with url: /api/v1/ping (Caused by NewConnectionError('<urllib3.connection.VerifiedHTTPSConnection object at 0x117338400>: Failed to establish a new connection: [Errno 8] nodename nor servname provided, or not known'))

During handling of the above exception, another exception occurred:

Traceback (most recent call last):
  File "binance1.py", line 20, in <module>
    client = Client(api_key, api_secret)
  File "/Library/Frameworks/Python.framework/Versions/3.8/lib/python3.8/site-packages/binance/client.py", line 97, in __init__
    self.ping()
  File "/Library/Frameworks/Python.framework/Versions/3.8/lib/python3.8/site-packages/binance/client.py", line 378, in ping
    return self._get('ping')
  File "/Library/Frameworks/Python.framework/Versions/3.8/lib/python3.8/site-packages/binance/client.py", line 222, in _get
    return self._request_api('get', path, signed, version, **kwargs)
  File "/Library/Frameworks/Python.framework/Versions/3.8/lib/python3.8/site-packages/binance/client.py", line 191, in _request_api
    return self._request(method, uri, signed, **kwargs)
  File "/Library/Frameworks/Python.framework/Versions/3.8/lib/python3.8/site-packages/binance/client.py", line 185, in _request
    self.response = getattr(self.session, method)(uri, **kwargs)
  File "/Library/Frameworks/Python.framework/Versions/3.8/lib/python3.8/site-packages/requests/sessions.py", line 546, in get
    return self.request('GET', url, **kwargs)
  File "/Library/Frameworks/Python.framework/Versions/3.8/lib/python3.8/site-packages/requests/sessions.py", line 533, in request
    resp = self.send(prep, **send_kwargs)
  File "/Library/Frameworks/Python.framework/Versions/3.8/lib/python3.8/site-packages/requests/sessions.py", line 646, in send
    r = adapter.send(request, **kwargs)
  File "/Library/Frameworks/Python.framework/Versions/3.8/lib/python3.8/site-packages/requests/adapters.py", line 516, in send
    raise ConnectionError(e, request=request)
requests.exceptions.ConnectionError: HTTPSConnectionPool(host='api.binance.com', port=443): Max retries exceeded with url: /api/v1/ping (Caused by NewConnectionError('<urllib3.connection.VerifiedHTTPSConnection object at 0x117338400>: Failed to establish a new connection: [Errno 8] nodename nor servname provided, or not known'))
Traceback (most recent call last):
  File "email_price_notify.py", line 77, in <module>
    server = smtplib.SMTP('smtp.gmail.com', 587) 
  File "/Library/Frameworks/Python.framework/Versions/3.8/lib/python3.8/smtplib.py", line 253, in __init__
    (code, msg) = self.connect(host, port)
  File "/Library/Frameworks/Python.framework/Versions/3.8/lib/python3.8/smtplib.py", line 339, in connect
    self.sock = self._get_socket(host, port, self.timeout)
  File "/Library/Frameworks/Python.framework/Versions/3.8/lib/python3.8/smtplib.py", line 308, in _get_socket
    return socket.create_connection((host, port), timeout,
  File "/Library/Frameworks/Python.framework/Versions/3.8/lib/python3.8/socket.py", line 787, in create_connection
    for res in getaddrinfo(host, port, 0, SOCK_STREAM):
  File "/Library/Frameworks/Python.framework/Versions/3.8/lib/python3.8/socket.py", line 914, in getaddrinfo
    for res in _socket.getaddrinfo(host, port, family, type, proto, flags):
socket.gaierror: [Errno 8] nodename nor servname provided, or not known
Traceback (most recent call last):
  File "/Library/Frameworks/Python.framework/Versions/3.8/lib/python3.8/site-packages/urllib3/connection.py", line 156, in _new_conn
    conn = connection.create_connection(
  File "/Library/Frameworks/Python.framework/Versions/3.8/lib/python3.8/site-packages/urllib3/util/connection.py", line 61, in create_connection
    for res in socket.getaddrinfo(host, port, family, socket.SOCK_STREAM):
  File "/Library/Frameworks/Python.framework/Versions/3.8/lib/python3.8/socket.py", line 914, in getaddrinfo
    for res in _socket.getaddrinfo(host, port, family, type, proto, flags):
socket.gaierror: [Errno 8] nodename nor servname provided, or not known

During handling of the above exception, another exception occurred:

Traceback (most recent call last):
  File "/Library/Frameworks/Python.framework/Versions/3.8/lib/python3.8/site-packages/urllib3/connectionpool.py", line 665, in urlopen
    httplib_response = self._make_request(
  File "/Library/Frameworks/Python.framework/Versions/3.8/lib/python3.8/site-packages/urllib3/connectionpool.py", line 376, in _make_request
    self._validate_conn(conn)
  File "/Library/Frameworks/Python.framework/Versions/3.8/lib/python3.8/site-packages/urllib3/connectionpool.py", line 994, in _validate_conn
    conn.connect()
  File "/Library/Frameworks/Python.framework/Versions/3.8/lib/python3.8/site-packages/urllib3/connection.py", line 334, in connect
    conn = self._new_conn()
  File "/Library/Frameworks/Python.framework/Versions/3.8/lib/python3.8/site-packages/urllib3/connection.py", line 168, in _new_conn
    raise NewConnectionError(
urllib3.exceptions.NewConnectionError: <urllib3.connection.VerifiedHTTPSConnection object at 0x11aaf83d0>: Failed to establish a new connection: [Errno 8] nodename nor servname provided, or not known

During handling of the above exception, another exception occurred:

Traceback (most recent call last):
  File "/Library/Frameworks/Python.framework/Versions/3.8/lib/python3.8/site-packages/requests/adapters.py", line 439, in send
    resp = conn.urlopen(
  File "/Library/Frameworks/Python.framework/Versions/3.8/lib/python3.8/site-packages/urllib3/connectionpool.py", line 719, in urlopen
    retries = retries.increment(
  File "/Library/Frameworks/Python.framework/Versions/3.8/lib/python3.8/site-packages/urllib3/util/retry.py", line 436, in increment
    raise MaxRetryError(_pool, url, error or ResponseError(cause))
urllib3.exceptions.MaxRetryError: HTTPSConnectionPool(host='api.binance.com', port=443): Max retries exceeded with url: /api/v1/ping (Caused by NewConnectionError('<urllib3.connection.VerifiedHTTPSConnection object at 0x11aaf83d0>: Failed to establish a new connection: [Errno 8] nodename nor servname provided, or not known'))

During handling of the above exception, another exception occurred:

Traceback (most recent call last):
  File "binance1.py", line 20, in <module>
    client = Client(api_key, api_secret)
  File "/Library/Frameworks/Python.framework/Versions/3.8/lib/python3.8/site-packages/binance/client.py", line 97, in __init__
    self.ping()
  File "/Library/Frameworks/Python.framework/Versions/3.8/lib/python3.8/site-packages/binance/client.py", line 378, in ping
    return self._get('ping')
  File "/Library/Frameworks/Python.framework/Versions/3.8/lib/python3.8/site-packages/binance/client.py", line 222, in _get
    return self._request_api('get', path, signed, version, **kwargs)
  File "/Library/Frameworks/Python.framework/Versions/3.8/lib/python3.8/site-packages/binance/client.py", line 191, in _request_api
    return self._request(method, uri, signed, **kwargs)
  File "/Library/Frameworks/Python.framework/Versions/3.8/lib/python3.8/site-packages/binance/client.py", line 185, in _request
    self.response = getattr(self.session, method)(uri, **kwargs)
  File "/Library/Frameworks/Python.framework/Versions/3.8/lib/python3.8/site-packages/requests/sessions.py", line 546, in get
    return self.request('GET', url, **kwargs)
  File "/Library/Frameworks/Python.framework/Versions/3.8/lib/python3.8/site-packages/requests/sessions.py", line 533, in request
    resp = self.send(prep, **send_kwargs)
  File "/Library/Frameworks/Python.framework/Versions/3.8/lib/python3.8/site-packages/requests/sessions.py", line 646, in send
    r = adapter.send(request, **kwargs)
  File "/Library/Frameworks/Python.framework/Versions/3.8/lib/python3.8/site-packages/requests/adapters.py", line 516, in send
    raise ConnectionError(e, request=request)
requests.exceptions.ConnectionError: HTTPSConnectionPool(host='api.binance.com', port=443): Max retries exceeded with url: /api/v1/ping (Caused by NewConnectionError('<urllib3.connection.VerifiedHTTPSConnection object at 0x11aaf83d0>: Failed to establish a new connection: [Errno 8] nodename nor servname provided, or not known'))
Traceback (most recent call last):
  File "email_price_notify.py", line 77, in <module>
    server = smtplib.SMTP('smtp.gmail.com', 587) 
  File "/Library/Frameworks/Python.framework/Versions/3.8/lib/python3.8/smtplib.py", line 253, in __init__
    (code, msg) = self.connect(host, port)
  File "/Library/Frameworks/Python.framework/Versions/3.8/lib/python3.8/smtplib.py", line 339, in connect
    self.sock = self._get_socket(host, port, self.timeout)
  File "/Library/Frameworks/Python.framework/Versions/3.8/lib/python3.8/smtplib.py", line 308, in _get_socket
    return socket.create_connection((host, port), timeout,
  File "/Library/Frameworks/Python.framework/Versions/3.8/lib/python3.8/socket.py", line 787, in create_connection
    for res in getaddrinfo(host, port, 0, SOCK_STREAM):
  File "/Library/Frameworks/Python.framework/Versions/3.8/lib/python3.8/socket.py", line 914, in getaddrinfo
    for res in _socket.getaddrinfo(host, port, family, type, proto, flags):
socket.gaierror: [Errno 8] nodename nor servname provided, or not known
Traceback (most recent call last):
  File "/Library/Frameworks/Python.framework/Versions/3.8/lib/python3.8/site-packages/urllib3/connection.py", line 156, in _new_conn
    conn = connection.create_connection(
  File "/Library/Frameworks/Python.framework/Versions/3.8/lib/python3.8/site-packages/urllib3/util/connection.py", line 61, in create_connection
    for res in socket.getaddrinfo(host, port, family, socket.SOCK_STREAM):
  File "/Library/Frameworks/Python.framework/Versions/3.8/lib/python3.8/socket.py", line 914, in getaddrinfo
    for res in _socket.getaddrinfo(host, port, family, type, proto, flags):
socket.gaierror: [Errno 8] nodename nor servname provided, or not known

During handling of the above exception, another exception occurred:

Traceback (most recent call last):
  File "/Library/Frameworks/Python.framework/Versions/3.8/lib/python3.8/site-packages/urllib3/connectionpool.py", line 665, in urlopen
    httplib_response = self._make_request(
  File "/Library/Frameworks/Python.framework/Versions/3.8/lib/python3.8/site-packages/urllib3/connectionpool.py", line 376, in _make_request
    self._validate_conn(conn)
  File "/Library/Frameworks/Python.framework/Versions/3.8/lib/python3.8/site-packages/urllib3/connectionpool.py", line 994, in _validate_conn
    conn.connect()
  File "/Library/Frameworks/Python.framework/Versions/3.8/lib/python3.8/site-packages/urllib3/connection.py", line 334, in connect
    conn = self._new_conn()
  File "/Library/Frameworks/Python.framework/Versions/3.8/lib/python3.8/site-packages/urllib3/connection.py", line 168, in _new_conn
    raise NewConnectionError(
urllib3.exceptions.NewConnectionError: <urllib3.connection.VerifiedHTTPSConnection object at 0x113ba3370>: Failed to establish a new connection: [Errno 8] nodename nor servname provided, or not known

During handling of the above exception, another exception occurred:

Traceback (most recent call last):
  File "/Library/Frameworks/Python.framework/Versions/3.8/lib/python3.8/site-packages/requests/adapters.py", line 439, in send
    resp = conn.urlopen(
  File "/Library/Frameworks/Python.framework/Versions/3.8/lib/python3.8/site-packages/urllib3/connectionpool.py", line 719, in urlopen
    retries = retries.increment(
  File "/Library/Frameworks/Python.framework/Versions/3.8/lib/python3.8/site-packages/urllib3/util/retry.py", line 436, in increment
    raise MaxRetryError(_pool, url, error or ResponseError(cause))
urllib3.exceptions.MaxRetryError: HTTPSConnectionPool(host='api.binance.com', port=443): Max retries exceeded with url: /api/v1/ping (Caused by NewConnectionError('<urllib3.connection.VerifiedHTTPSConnection object at 0x113ba3370>: Failed to establish a new connection: [Errno 8] nodename nor servname provided, or not known'))

During handling of the above exception, another exception occurred:

Traceback (most recent call last):
  File "binance1.py", line 20, in <module>
    client = Client(api_key, api_secret)
  File "/Library/Frameworks/Python.framework/Versions/3.8/lib/python3.8/site-packages/binance/client.py", line 97, in __init__
    self.ping()
  File "/Library/Frameworks/Python.framework/Versions/3.8/lib/python3.8/site-packages/binance/client.py", line 378, in ping
    return self._get('ping')
  File "/Library/Frameworks/Python.framework/Versions/3.8/lib/python3.8/site-packages/binance/client.py", line 222, in _get
    return self._request_api('get', path, signed, version, **kwargs)
  File "/Library/Frameworks/Python.framework/Versions/3.8/lib/python3.8/site-packages/binance/client.py", line 191, in _request_api
    return self._request(method, uri, signed, **kwargs)
  File "/Library/Frameworks/Python.framework/Versions/3.8/lib/python3.8/site-packages/binance/client.py", line 185, in _request
    self.response = getattr(self.session, method)(uri, **kwargs)
  File "/Library/Frameworks/Python.framework/Versions/3.8/lib/python3.8/site-packages/requests/sessions.py", line 546, in get
    return self.request('GET', url, **kwargs)
  File "/Library/Frameworks/Python.framework/Versions/3.8/lib/python3.8/site-packages/requests/sessions.py", line 533, in request
    resp = self.send(prep, **send_kwargs)
  File "/Library/Frameworks/Python.framework/Versions/3.8/lib/python3.8/site-packages/requests/sessions.py", line 646, in send
    r = adapter.send(request, **kwargs)
  File "/Library/Frameworks/Python.framework/Versions/3.8/lib/python3.8/site-packages/requests/adapters.py", line 516, in send
    raise ConnectionError(e, request=request)
requests.exceptions.ConnectionError: HTTPSConnectionPool(host='api.binance.com', port=443): Max retries exceeded with url: /api/v1/ping (Caused by NewConnectionError('<urllib3.connection.VerifiedHTTPSConnection object at 0x113ba3370>: Failed to establish a new connection: [Errno 8] nodename nor servname provided, or not known'))
Traceback (most recent call last):
  File "email_price_notify.py", line 77, in <module>
    server = smtplib.SMTP('smtp.gmail.com', 587) 
  File "/Library/Frameworks/Python.framework/Versions/3.8/lib/python3.8/smtplib.py", line 253, in __init__
    (code, msg) = self.connect(host, port)
  File "/Library/Frameworks/Python.framework/Versions/3.8/lib/python3.8/smtplib.py", line 339, in connect
    self.sock = self._get_socket(host, port, self.timeout)
  File "/Library/Frameworks/Python.framework/Versions/3.8/lib/python3.8/smtplib.py", line 308, in _get_socket
    return socket.create_connection((host, port), timeout,
  File "/Library/Frameworks/Python.framework/Versions/3.8/lib/python3.8/socket.py", line 787, in create_connection
    for res in getaddrinfo(host, port, 0, SOCK_STREAM):
  File "/Library/Frameworks/Python.framework/Versions/3.8/lib/python3.8/socket.py", line 914, in getaddrinfo
    for res in _socket.getaddrinfo(host, port, family, type, proto, flags):
socket.gaierror: [Errno 8] nodename nor servname provided, or not known
Traceback (most recent call last):
  File "/Library/Frameworks/Python.framework/Versions/3.8/lib/python3.8/site-packages/urllib3/connection.py", line 156, in _new_conn
    conn = connection.create_connection(
  File "/Library/Frameworks/Python.framework/Versions/3.8/lib/python3.8/site-packages/urllib3/util/connection.py", line 61, in create_connection
    for res in socket.getaddrinfo(host, port, family, socket.SOCK_STREAM):
  File "/Library/Frameworks/Python.framework/Versions/3.8/lib/python3.8/socket.py", line 914, in getaddrinfo
    for res in _socket.getaddrinfo(host, port, family, type, proto, flags):
socket.gaierror: [Errno 8] nodename nor servname provided, or not known

During handling of the above exception, another exception occurred:

Traceback (most recent call last):
  File "/Library/Frameworks/Python.framework/Versions/3.8/lib/python3.8/site-packages/urllib3/connectionpool.py", line 665, in urlopen
    httplib_response = self._make_request(
  File "/Library/Frameworks/Python.framework/Versions/3.8/lib/python3.8/site-packages/urllib3/connectionpool.py", line 376, in _make_request
    self._validate_conn(conn)
  File "/Library/Frameworks/Python.framework/Versions/3.8/lib/python3.8/site-packages/urllib3/connectionpool.py", line 994, in _validate_conn
    conn.connect()
  File "/Library/Frameworks/Python.framework/Versions/3.8/lib/python3.8/site-packages/urllib3/connection.py", line 334, in connect
    conn = self._new_conn()
  File "/Library/Frameworks/Python.framework/Versions/3.8/lib/python3.8/site-packages/urllib3/connection.py", line 168, in _new_conn
    raise NewConnectionError(
urllib3.exceptions.NewConnectionError: <urllib3.connection.VerifiedHTTPSConnection object at 0x1108773d0>: Failed to establish a new connection: [Errno 8] nodename nor servname provided, or not known

During handling of the above exception, another exception occurred:

Traceback (most recent call last):
  File "/Library/Frameworks/Python.framework/Versions/3.8/lib/python3.8/site-packages/requests/adapters.py", line 439, in send
    resp = conn.urlopen(
  File "/Library/Frameworks/Python.framework/Versions/3.8/lib/python3.8/site-packages/urllib3/connectionpool.py", line 719, in urlopen
    retries = retries.increment(
  File "/Library/Frameworks/Python.framework/Versions/3.8/lib/python3.8/site-packages/urllib3/util/retry.py", line 436, in increment
    raise MaxRetryError(_pool, url, error or ResponseError(cause))
urllib3.exceptions.MaxRetryError: HTTPSConnectionPool(host='api.binance.com', port=443): Max retries exceeded with url: /api/v1/ping (Caused by NewConnectionError('<urllib3.connection.VerifiedHTTPSConnection object at 0x1108773d0>: Failed to establish a new connection: [Errno 8] nodename nor servname provided, or not known'))

During handling of the above exception, another exception occurred:

Traceback (most recent call last):
  File "binance1.py", line 20, in <module>
    client = Client(api_key, api_secret)
  File "/Library/Frameworks/Python.framework/Versions/3.8/lib/python3.8/site-packages/binance/client.py", line 97, in __init__
    self.ping()
  File "/Library/Frameworks/Python.framework/Versions/3.8/lib/python3.8/site-packages/binance/client.py", line 378, in ping
    return self._get('ping')
  File "/Library/Frameworks/Python.framework/Versions/3.8/lib/python3.8/site-packages/binance/client.py", line 222, in _get
    return self._request_api('get', path, signed, version, **kwargs)
  File "/Library/Frameworks/Python.framework/Versions/3.8/lib/python3.8/site-packages/binance/client.py", line 191, in _request_api
    return self._request(method, uri, signed, **kwargs)
  File "/Library/Frameworks/Python.framework/Versions/3.8/lib/python3.8/site-packages/binance/client.py", line 185, in _request
    self.response = getattr(self.session, method)(uri, **kwargs)
  File "/Library/Frameworks/Python.framework/Versions/3.8/lib/python3.8/site-packages/requests/sessions.py", line 546, in get
    return self.request('GET', url, **kwargs)
  File "/Library/Frameworks/Python.framework/Versions/3.8/lib/python3.8/site-packages/requests/sessions.py", line 533, in request
    resp = self.send(prep, **send_kwargs)
  File "/Library/Frameworks/Python.framework/Versions/3.8/lib/python3.8/site-packages/requests/sessions.py", line 646, in send
    r = adapter.send(request, **kwargs)
  File "/Library/Frameworks/Python.framework/Versions/3.8/lib/python3.8/site-packages/requests/adapters.py", line 516, in send
    raise ConnectionError(e, request=request)
requests.exceptions.ConnectionError: HTTPSConnectionPool(host='api.binance.com', port=443): Max retries exceeded with url: /api/v1/ping (Caused by NewConnectionError('<urllib3.connection.VerifiedHTTPSConnection object at 0x1108773d0>: Failed to establish a new connection: [Errno 8] nodename nor servname provided, or not known'))
Traceback (most recent call last):
  File "email_price_notify.py", line 77, in <module>
    server = smtplib.SMTP('smtp.gmail.com', 587) 
  File "/Library/Frameworks/Python.framework/Versions/3.8/lib/python3.8/smtplib.py", line 253, in __init__
    (code, msg) = self.connect(host, port)
  File "/Library/Frameworks/Python.framework/Versions/3.8/lib/python3.8/smtplib.py", line 339, in connect
    self.sock = self._get_socket(host, port, self.timeout)
  File "/Library/Frameworks/Python.framework/Versions/3.8/lib/python3.8/smtplib.py", line 308, in _get_socket
    return socket.create_connection((host, port), timeout,
  File "/Library/Frameworks/Python.framework/Versions/3.8/lib/python3.8/socket.py", line 787, in create_connection
    for res in getaddrinfo(host, port, 0, SOCK_STREAM):
  File "/Library/Frameworks/Python.framework/Versions/3.8/lib/python3.8/socket.py", line 914, in getaddrinfo
    for res in _socket.getaddrinfo(host, port, family, type, proto, flags):
socket.gaierror: [Errno 8] nodename nor servname provided, or not known
Traceback (most recent call last):
  File "/Library/Frameworks/Python.framework/Versions/3.8/lib/python3.8/site-packages/urllib3/connection.py", line 156, in _new_conn
    conn = connection.create_connection(
  File "/Library/Frameworks/Python.framework/Versions/3.8/lib/python3.8/site-packages/urllib3/util/connection.py", line 61, in create_connection
    for res in socket.getaddrinfo(host, port, family, socket.SOCK_STREAM):
  File "/Library/Frameworks/Python.framework/Versions/3.8/lib/python3.8/socket.py", line 914, in getaddrinfo
    for res in _socket.getaddrinfo(host, port, family, type, proto, flags):
socket.gaierror: [Errno 8] nodename nor servname provided, or not known

During handling of the above exception, another exception occurred:

Traceback (most recent call last):
  File "/Library/Frameworks/Python.framework/Versions/3.8/lib/python3.8/site-packages/urllib3/connectionpool.py", line 665, in urlopen
    httplib_response = self._make_request(
  File "/Library/Frameworks/Python.framework/Versions/3.8/lib/python3.8/site-packages/urllib3/connectionpool.py", line 376, in _make_request
    self._validate_conn(conn)
  File "/Library/Frameworks/Python.framework/Versions/3.8/lib/python3.8/site-packages/urllib3/connectionpool.py", line 994, in _validate_conn
    conn.connect()
  File "/Library/Frameworks/Python.framework/Versions/3.8/lib/python3.8/site-packages/urllib3/connection.py", line 334, in connect
    conn = self._new_conn()
  File "/Library/Frameworks/Python.framework/Versions/3.8/lib/python3.8/site-packages/urllib3/connection.py", line 168, in _new_conn
    raise NewConnectionError(
urllib3.exceptions.NewConnectionError: <urllib3.connection.VerifiedHTTPSConnection object at 0x116d18400>: Failed to establish a new connection: [Errno 8] nodename nor servname provided, or not known

During handling of the above exception, another exception occurred:

Traceback (most recent call last):
  File "/Library/Frameworks/Python.framework/Versions/3.8/lib/python3.8/site-packages/requests/adapters.py", line 439, in send
    resp = conn.urlopen(
  File "/Library/Frameworks/Python.framework/Versions/3.8/lib/python3.8/site-packages/urllib3/connectionpool.py", line 719, in urlopen
    retries = retries.increment(
  File "/Library/Frameworks/Python.framework/Versions/3.8/lib/python3.8/site-packages/urllib3/util/retry.py", line 436, in increment
    raise MaxRetryError(_pool, url, error or ResponseError(cause))
urllib3.exceptions.MaxRetryError: HTTPSConnectionPool(host='api.binance.com', port=443): Max retries exceeded with url: /api/v1/ping (Caused by NewConnectionError('<urllib3.connection.VerifiedHTTPSConnection object at 0x116d18400>: Failed to establish a new connection: [Errno 8] nodename nor servname provided, or not known'))

During handling of the above exception, another exception occurred:

Traceback (most recent call last):
  File "binance1.py", line 20, in <module>
    client = Client(api_key, api_secret)
  File "/Library/Frameworks/Python.framework/Versions/3.8/lib/python3.8/site-packages/binance/client.py", line 97, in __init__
    self.ping()
  File "/Library/Frameworks/Python.framework/Versions/3.8/lib/python3.8/site-packages/binance/client.py", line 378, in ping
    return self._get('ping')
  File "/Library/Frameworks/Python.framework/Versions/3.8/lib/python3.8/site-packages/binance/client.py", line 222, in _get
    return self._request_api('get', path, signed, version, **kwargs)
  File "/Library/Frameworks/Python.framework/Versions/3.8/lib/python3.8/site-packages/binance/client.py", line 191, in _request_api
    return self._request(method, uri, signed, **kwargs)
  File "/Library/Frameworks/Python.framework/Versions/3.8/lib/python3.8/site-packages/binance/client.py", line 185, in _request
    self.response = getattr(self.session, method)(uri, **kwargs)
  File "/Library/Frameworks/Python.framework/Versions/3.8/lib/python3.8/site-packages/requests/sessions.py", line 546, in get
    return self.request('GET', url, **kwargs)
  File "/Library/Frameworks/Python.framework/Versions/3.8/lib/python3.8/site-packages/requests/sessions.py", line 533, in request
    resp = self.send(prep, **send_kwargs)
  File "/Library/Frameworks/Python.framework/Versions/3.8/lib/python3.8/site-packages/requests/sessions.py", line 646, in send
    r = adapter.send(request, **kwargs)
  File "/Library/Frameworks/Python.framework/Versions/3.8/lib/python3.8/site-packages/requests/adapters.py", line 516, in send
    raise ConnectionError(e, request=request)
requests.exceptions.ConnectionError: HTTPSConnectionPool(host='api.binance.com', port=443): Max retries exceeded with url: /api/v1/ping (Caused by NewConnectionError('<urllib3.connection.VerifiedHTTPSConnection object at 0x116d18400>: Failed to establish a new connection: [Errno 8] nodename nor servname provided, or not known'))
Traceback (most recent call last):
  File "email_price_notify.py", line 77, in <module>
    server = smtplib.SMTP('smtp.gmail.com', 587) 
  File "/Library/Frameworks/Python.framework/Versions/3.8/lib/python3.8/smtplib.py", line 253, in __init__
    (code, msg) = self.connect(host, port)
  File "/Library/Frameworks/Python.framework/Versions/3.8/lib/python3.8/smtplib.py", line 339, in connect
    self.sock = self._get_socket(host, port, self.timeout)
  File "/Library/Frameworks/Python.framework/Versions/3.8/lib/python3.8/smtplib.py", line 308, in _get_socket
    return socket.create_connection((host, port), timeout,
  File "/Library/Frameworks/Python.framework/Versions/3.8/lib/python3.8/socket.py", line 787, in create_connection
    for res in getaddrinfo(host, port, 0, SOCK_STREAM):
  File "/Library/Frameworks/Python.framework/Versions/3.8/lib/python3.8/socket.py", line 914, in getaddrinfo
    for res in _socket.getaddrinfo(host, port, family, type, proto, flags):
socket.gaierror: [Errno 8] nodename nor servname provided, or not known
Traceback (most recent call last):
  File "/Library/Frameworks/Python.framework/Versions/3.8/lib/python3.8/site-packages/urllib3/connection.py", line 156, in _new_conn
    conn = connection.create_connection(
  File "/Library/Frameworks/Python.framework/Versions/3.8/lib/python3.8/site-packages/urllib3/util/connection.py", line 61, in create_connection
    for res in socket.getaddrinfo(host, port, family, socket.SOCK_STREAM):
  File "/Library/Frameworks/Python.framework/Versions/3.8/lib/python3.8/socket.py", line 914, in getaddrinfo
    for res in _socket.getaddrinfo(host, port, family, type, proto, flags):
socket.gaierror: [Errno 8] nodename nor servname provided, or not known

During handling of the above exception, another exception occurred:

Traceback (most recent call last):
  File "/Library/Frameworks/Python.framework/Versions/3.8/lib/python3.8/site-packages/urllib3/connectionpool.py", line 665, in urlopen
    httplib_response = self._make_request(
  File "/Library/Frameworks/Python.framework/Versions/3.8/lib/python3.8/site-packages/urllib3/connectionpool.py", line 376, in _make_request
    self._validate_conn(conn)
  File "/Library/Frameworks/Python.framework/Versions/3.8/lib/python3.8/site-packages/urllib3/connectionpool.py", line 994, in _validate_conn
    conn.connect()
  File "/Library/Frameworks/Python.framework/Versions/3.8/lib/python3.8/site-packages/urllib3/connection.py", line 334, in connect
    conn = self._new_conn()
  File "/Library/Frameworks/Python.framework/Versions/3.8/lib/python3.8/site-packages/urllib3/connection.py", line 168, in _new_conn
    raise NewConnectionError(
urllib3.exceptions.NewConnectionError: <urllib3.connection.VerifiedHTTPSConnection object at 0x112cf23a0>: Failed to establish a new connection: [Errno 8] nodename nor servname provided, or not known

During handling of the above exception, another exception occurred:

Traceback (most recent call last):
  File "/Library/Frameworks/Python.framework/Versions/3.8/lib/python3.8/site-packages/requests/adapters.py", line 439, in send
    resp = conn.urlopen(
  File "/Library/Frameworks/Python.framework/Versions/3.8/lib/python3.8/site-packages/urllib3/connectionpool.py", line 719, in urlopen
    retries = retries.increment(
  File "/Library/Frameworks/Python.framework/Versions/3.8/lib/python3.8/site-packages/urllib3/util/retry.py", line 436, in increment
    raise MaxRetryError(_pool, url, error or ResponseError(cause))
urllib3.exceptions.MaxRetryError: HTTPSConnectionPool(host='api.binance.com', port=443): Max retries exceeded with url: /api/v1/ping (Caused by NewConnectionError('<urllib3.connection.VerifiedHTTPSConnection object at 0x112cf23a0>: Failed to establish a new connection: [Errno 8] nodename nor servname provided, or not known'))

During handling of the above exception, another exception occurred:

Traceback (most recent call last):
  File "binance1.py", line 20, in <module>
    client = Client(api_key, api_secret)
  File "/Library/Frameworks/Python.framework/Versions/3.8/lib/python3.8/site-packages/binance/client.py", line 97, in __init__
    self.ping()
  File "/Library/Frameworks/Python.framework/Versions/3.8/lib/python3.8/site-packages/binance/client.py", line 378, in ping
    return self._get('ping')
  File "/Library/Frameworks/Python.framework/Versions/3.8/lib/python3.8/site-packages/binance/client.py", line 222, in _get
    return self._request_api('get', path, signed, version, **kwargs)
  File "/Library/Frameworks/Python.framework/Versions/3.8/lib/python3.8/site-packages/binance/client.py", line 191, in _request_api
    return self._request(method, uri, signed, **kwargs)
  File "/Library/Frameworks/Python.framework/Versions/3.8/lib/python3.8/site-packages/binance/client.py", line 185, in _request
    self.response = getattr(self.session, method)(uri, **kwargs)
  File "/Library/Frameworks/Python.framework/Versions/3.8/lib/python3.8/site-packages/requests/sessions.py", line 546, in get
    return self.request('GET', url, **kwargs)
  File "/Library/Frameworks/Python.framework/Versions/3.8/lib/python3.8/site-packages/requests/sessions.py", line 533, in request
    resp = self.send(prep, **send_kwargs)
  File "/Library/Frameworks/Python.framework/Versions/3.8/lib/python3.8/site-packages/requests/sessions.py", line 646, in send
    r = adapter.send(request, **kwargs)
  File "/Library/Frameworks/Python.framework/Versions/3.8/lib/python3.8/site-packages/requests/adapters.py", line 516, in send
    raise ConnectionError(e, request=request)
requests.exceptions.ConnectionError: HTTPSConnectionPool(host='api.binance.com', port=443): Max retries exceeded with url: /api/v1/ping (Caused by NewConnectionError('<urllib3.connection.VerifiedHTTPSConnection object at 0x112cf23a0>: Failed to establish a new connection: [Errno 8] nodename nor servname provided, or not known'))
Traceback (most recent call last):
  File "email_price_notify.py", line 77, in <module>
    server = smtplib.SMTP('smtp.gmail.com', 587) 
  File "/Library/Frameworks/Python.framework/Versions/3.8/lib/python3.8/smtplib.py", line 253, in __init__
    (code, msg) = self.connect(host, port)
  File "/Library/Frameworks/Python.framework/Versions/3.8/lib/python3.8/smtplib.py", line 339, in connect
    self.sock = self._get_socket(host, port, self.timeout)
  File "/Library/Frameworks/Python.framework/Versions/3.8/lib/python3.8/smtplib.py", line 308, in _get_socket
    return socket.create_connection((host, port), timeout,
  File "/Library/Frameworks/Python.framework/Versions/3.8/lib/python3.8/socket.py", line 787, in create_connection
    for res in getaddrinfo(host, port, 0, SOCK_STREAM):
  File "/Library/Frameworks/Python.framework/Versions/3.8/lib/python3.8/socket.py", line 914, in getaddrinfo
    for res in _socket.getaddrinfo(host, port, family, type, proto, flags):
socket.gaierror: [Errno 8] nodename nor servname provided, or not known
Traceback (most recent call last):
  File "/Library/Frameworks/Python.framework/Versions/3.8/lib/python3.8/site-packages/urllib3/connection.py", line 156, in _new_conn
    conn = connection.create_connection(
  File "/Library/Frameworks/Python.framework/Versions/3.8/lib/python3.8/site-packages/urllib3/util/connection.py", line 61, in create_connection
    for res in socket.getaddrinfo(host, port, family, socket.SOCK_STREAM):
  File "/Library/Frameworks/Python.framework/Versions/3.8/lib/python3.8/socket.py", line 914, in getaddrinfo
    for res in _socket.getaddrinfo(host, port, family, type, proto, flags):
socket.gaierror: [Errno 8] nodename nor servname provided, or not known

During handling of the above exception, another exception occurred:

Traceback (most recent call last):
  File "/Library/Frameworks/Python.framework/Versions/3.8/lib/python3.8/site-packages/urllib3/connectionpool.py", line 665, in urlopen
    httplib_response = self._make_request(
  File "/Library/Frameworks/Python.framework/Versions/3.8/lib/python3.8/site-packages/urllib3/connectionpool.py", line 376, in _make_request
    self._validate_conn(conn)
  File "/Library/Frameworks/Python.framework/Versions/3.8/lib/python3.8/site-packages/urllib3/connectionpool.py", line 994, in _validate_conn
    conn.connect()
  File "/Library/Frameworks/Python.framework/Versions/3.8/lib/python3.8/site-packages/urllib3/connection.py", line 334, in connect
    conn = self._new_conn()
  File "/Library/Frameworks/Python.framework/Versions/3.8/lib/python3.8/site-packages/urllib3/connection.py", line 168, in _new_conn
    raise NewConnectionError(
urllib3.exceptions.NewConnectionError: <urllib3.connection.VerifiedHTTPSConnection object at 0x1171f3370>: Failed to establish a new connection: [Errno 8] nodename nor servname provided, or not known

During handling of the above exception, another exception occurred:

Traceback (most recent call last):
  File "/Library/Frameworks/Python.framework/Versions/3.8/lib/python3.8/site-packages/requests/adapters.py", line 439, in send
    resp = conn.urlopen(
  File "/Library/Frameworks/Python.framework/Versions/3.8/lib/python3.8/site-packages/urllib3/connectionpool.py", line 719, in urlopen
    retries = retries.increment(
  File "/Library/Frameworks/Python.framework/Versions/3.8/lib/python3.8/site-packages/urllib3/util/retry.py", line 436, in increment
    raise MaxRetryError(_pool, url, error or ResponseError(cause))
urllib3.exceptions.MaxRetryError: HTTPSConnectionPool(host='api.binance.com', port=443): Max retries exceeded with url: /api/v1/ping (Caused by NewConnectionError('<urllib3.connection.VerifiedHTTPSConnection object at 0x1171f3370>: Failed to establish a new connection: [Errno 8] nodename nor servname provided, or not known'))

During handling of the above exception, another exception occurred:

Traceback (most recent call last):
  File "binance1.py", line 20, in <module>
    client = Client(api_key, api_secret)
  File "/Library/Frameworks/Python.framework/Versions/3.8/lib/python3.8/site-packages/binance/client.py", line 97, in __init__
    self.ping()
  File "/Library/Frameworks/Python.framework/Versions/3.8/lib/python3.8/site-packages/binance/client.py", line 378, in ping
    return self._get('ping')
  File "/Library/Frameworks/Python.framework/Versions/3.8/lib/python3.8/site-packages/binance/client.py", line 222, in _get
    return self._request_api('get', path, signed, version, **kwargs)
  File "/Library/Frameworks/Python.framework/Versions/3.8/lib/python3.8/site-packages/binance/client.py", line 191, in _request_api
    return self._request(method, uri, signed, **kwargs)
  File "/Library/Frameworks/Python.framework/Versions/3.8/lib/python3.8/site-packages/binance/client.py", line 185, in _request
    self.response = getattr(self.session, method)(uri, **kwargs)
  File "/Library/Frameworks/Python.framework/Versions/3.8/lib/python3.8/site-packages/requests/sessions.py", line 546, in get
    return self.request('GET', url, **kwargs)
  File "/Library/Frameworks/Python.framework/Versions/3.8/lib/python3.8/site-packages/requests/sessions.py", line 533, in request
    resp = self.send(prep, **send_kwargs)
  File "/Library/Frameworks/Python.framework/Versions/3.8/lib/python3.8/site-packages/requests/sessions.py", line 646, in send
    r = adapter.send(request, **kwargs)
  File "/Library/Frameworks/Python.framework/Versions/3.8/lib/python3.8/site-packages/requests/adapters.py", line 516, in send
    raise ConnectionError(e, request=request)
requests.exceptions.ConnectionError: HTTPSConnectionPool(host='api.binance.com', port=443): Max retries exceeded with url: /api/v1/ping (Caused by NewConnectionError('<urllib3.connection.VerifiedHTTPSConnection object at 0x1171f3370>: Failed to establish a new connection: [Errno 8] nodename nor servname provided, or not known'))
Traceback (most recent call last):
  File "email_price_notify.py", line 77, in <module>
    server = smtplib.SMTP('smtp.gmail.com', 587) 
  File "/Library/Frameworks/Python.framework/Versions/3.8/lib/python3.8/smtplib.py", line 253, in __init__
    (code, msg) = self.connect(host, port)
  File "/Library/Frameworks/Python.framework/Versions/3.8/lib/python3.8/smtplib.py", line 339, in connect
    self.sock = self._get_socket(host, port, self.timeout)
  File "/Library/Frameworks/Python.framework/Versions/3.8/lib/python3.8/smtplib.py", line 308, in _get_socket
    return socket.create_connection((host, port), timeout,
  File "/Library/Frameworks/Python.framework/Versions/3.8/lib/python3.8/socket.py", line 787, in create_connection
    for res in getaddrinfo(host, port, 0, SOCK_STREAM):
  File "/Library/Frameworks/Python.framework/Versions/3.8/lib/python3.8/socket.py", line 914, in getaddrinfo
    for res in _socket.getaddrinfo(host, port, family, type, proto, flags):
socket.gaierror: [Errno 8] nodename nor servname provided, or not known
Traceback (most recent call last):
  File "/Library/Frameworks/Python.framework/Versions/3.8/lib/python3.8/site-packages/urllib3/connection.py", line 156, in _new_conn
    conn = connection.create_connection(
  File "/Library/Frameworks/Python.framework/Versions/3.8/lib/python3.8/site-packages/urllib3/util/connection.py", line 61, in create_connection
    for res in socket.getaddrinfo(host, port, family, socket.SOCK_STREAM):
  File "/Library/Frameworks/Python.framework/Versions/3.8/lib/python3.8/socket.py", line 914, in getaddrinfo
    for res in _socket.getaddrinfo(host, port, family, type, proto, flags):
socket.gaierror: [Errno 8] nodename nor servname provided, or not known

During handling of the above exception, another exception occurred:

Traceback (most recent call last):
  File "/Library/Frameworks/Python.framework/Versions/3.8/lib/python3.8/site-packages/urllib3/connectionpool.py", line 665, in urlopen
    httplib_response = self._make_request(
  File "/Library/Frameworks/Python.framework/Versions/3.8/lib/python3.8/site-packages/urllib3/connectionpool.py", line 376, in _make_request
    self._validate_conn(conn)
  File "/Library/Frameworks/Python.framework/Versions/3.8/lib/python3.8/site-packages/urllib3/connectionpool.py", line 994, in _validate_conn
    conn.connect()
  File "/Library/Frameworks/Python.framework/Versions/3.8/lib/python3.8/site-packages/urllib3/connection.py", line 334, in connect
    conn = self._new_conn()
  File "/Library/Frameworks/Python.framework/Versions/3.8/lib/python3.8/site-packages/urllib3/connection.py", line 168, in _new_conn
    raise NewConnectionError(
urllib3.exceptions.NewConnectionError: <urllib3.connection.VerifiedHTTPSConnection object at 0x11097f370>: Failed to establish a new connection: [Errno 8] nodename nor servname provided, or not known

During handling of the above exception, another exception occurred:

Traceback (most recent call last):
  File "/Library/Frameworks/Python.framework/Versions/3.8/lib/python3.8/site-packages/requests/adapters.py", line 439, in send
    resp = conn.urlopen(
  File "/Library/Frameworks/Python.framework/Versions/3.8/lib/python3.8/site-packages/urllib3/connectionpool.py", line 719, in urlopen
    retries = retries.increment(
  File "/Library/Frameworks/Python.framework/Versions/3.8/lib/python3.8/site-packages/urllib3/util/retry.py", line 436, in increment
    raise MaxRetryError(_pool, url, error or ResponseError(cause))
urllib3.exceptions.MaxRetryError: HTTPSConnectionPool(host='api.binance.com', port=443): Max retries exceeded with url: /api/v1/ping (Caused by NewConnectionError('<urllib3.connection.VerifiedHTTPSConnection object at 0x11097f370>: Failed to establish a new connection: [Errno 8] nodename nor servname provided, or not known'))

During handling of the above exception, another exception occurred:

Traceback (most recent call last):
  File "binance1.py", line 20, in <module>
    client = Client(api_key, api_secret)
  File "/Library/Frameworks/Python.framework/Versions/3.8/lib/python3.8/site-packages/binance/client.py", line 97, in __init__
    self.ping()
  File "/Library/Frameworks/Python.framework/Versions/3.8/lib/python3.8/site-packages/binance/client.py", line 378, in ping
    return self._get('ping')
  File "/Library/Frameworks/Python.framework/Versions/3.8/lib/python3.8/site-packages/binance/client.py", line 222, in _get
    return self._request_api('get', path, signed, version, **kwargs)
  File "/Library/Frameworks/Python.framework/Versions/3.8/lib/python3.8/site-packages/binance/client.py", line 191, in _request_api
    return self._request(method, uri, signed, **kwargs)
  File "/Library/Frameworks/Python.framework/Versions/3.8/lib/python3.8/site-packages/binance/client.py", line 185, in _request
    self.response = getattr(self.session, method)(uri, **kwargs)
  File "/Library/Frameworks/Python.framework/Versions/3.8/lib/python3.8/site-packages/requests/sessions.py", line 546, in get
    return self.request('GET', url, **kwargs)
  File "/Library/Frameworks/Python.framework/Versions/3.8/lib/python3.8/site-packages/requests/sessions.py", line 533, in request
    resp = self.send(prep, **send_kwargs)
  File "/Library/Frameworks/Python.framework/Versions/3.8/lib/python3.8/site-packages/requests/sessions.py", line 646, in send
    r = adapter.send(request, **kwargs)
  File "/Library/Frameworks/Python.framework/Versions/3.8/lib/python3.8/site-packages/requests/adapters.py", line 516, in send
    raise ConnectionError(e, request=request)
requests.exceptions.ConnectionError: HTTPSConnectionPool(host='api.binance.com', port=443): Max retries exceeded with url: /api/v1/ping (Caused by NewConnectionError('<urllib3.connection.VerifiedHTTPSConnection object at 0x11097f370>: Failed to establish a new connection: [Errno 8] nodename nor servname provided, or not known'))
Traceback (most recent call last):
  File "email_price_notify.py", line 77, in <module>
    server = smtplib.SMTP('smtp.gmail.com', 587) 
  File "/Library/Frameworks/Python.framework/Versions/3.8/lib/python3.8/smtplib.py", line 253, in __init__
    (code, msg) = self.connect(host, port)
  File "/Library/Frameworks/Python.framework/Versions/3.8/lib/python3.8/smtplib.py", line 339, in connect
    self.sock = self._get_socket(host, port, self.timeout)
  File "/Library/Frameworks/Python.framework/Versions/3.8/lib/python3.8/smtplib.py", line 308, in _get_socket
    return socket.create_connection((host, port), timeout,
  File "/Library/Frameworks/Python.framework/Versions/3.8/lib/python3.8/socket.py", line 787, in create_connection
    for res in getaddrinfo(host, port, 0, SOCK_STREAM):
  File "/Library/Frameworks/Python.framework/Versions/3.8/lib/python3.8/socket.py", line 914, in getaddrinfo
    for res in _socket.getaddrinfo(host, port, family, type, proto, flags):
socket.gaierror: [Errno 8] nodename nor servname provided, or not known
Traceback (most recent call last):
  File "/Library/Frameworks/Python.framework/Versions/3.8/lib/python3.8/site-packages/urllib3/connection.py", line 156, in _new_conn
    conn = connection.create_connection(
  File "/Library/Frameworks/Python.framework/Versions/3.8/lib/python3.8/site-packages/urllib3/util/connection.py", line 61, in create_connection
    for res in socket.getaddrinfo(host, port, family, socket.SOCK_STREAM):
  File "/Library/Frameworks/Python.framework/Versions/3.8/lib/python3.8/socket.py", line 914, in getaddrinfo
    for res in _socket.getaddrinfo(host, port, family, type, proto, flags):
socket.gaierror: [Errno 8] nodename nor servname provided, or not known

During handling of the above exception, another exception occurred:

Traceback (most recent call last):
  File "/Library/Frameworks/Python.framework/Versions/3.8/lib/python3.8/site-packages/urllib3/connectionpool.py", line 665, in urlopen
    httplib_response = self._make_request(
  File "/Library/Frameworks/Python.framework/Versions/3.8/lib/python3.8/site-packages/urllib3/connectionpool.py", line 376, in _make_request
    self._validate_conn(conn)
  File "/Library/Frameworks/Python.framework/Versions/3.8/lib/python3.8/site-packages/urllib3/connectionpool.py", line 994, in _validate_conn
    conn.connect()
  File "/Library/Frameworks/Python.framework/Versions/3.8/lib/python3.8/site-packages/urllib3/connection.py", line 334, in connect
    conn = self._new_conn()
  File "/Library/Frameworks/Python.framework/Versions/3.8/lib/python3.8/site-packages/urllib3/connection.py", line 168, in _new_conn
    raise NewConnectionError(
urllib3.exceptions.NewConnectionError: <urllib3.connection.VerifiedHTTPSConnection object at 0x10d569340>: Failed to establish a new connection: [Errno 8] nodename nor servname provided, or not known

During handling of the above exception, another exception occurred:

Traceback (most recent call last):
  File "/Library/Frameworks/Python.framework/Versions/3.8/lib/python3.8/site-packages/requests/adapters.py", line 439, in send
    resp = conn.urlopen(
  File "/Library/Frameworks/Python.framework/Versions/3.8/lib/python3.8/site-packages/urllib3/connectionpool.py", line 719, in urlopen
    retries = retries.increment(
  File "/Library/Frameworks/Python.framework/Versions/3.8/lib/python3.8/site-packages/urllib3/util/retry.py", line 436, in increment
    raise MaxRetryError(_pool, url, error or ResponseError(cause))
urllib3.exceptions.MaxRetryError: HTTPSConnectionPool(host='api.binance.com', port=443): Max retries exceeded with url: /api/v1/ping (Caused by NewConnectionError('<urllib3.connection.VerifiedHTTPSConnection object at 0x10d569340>: Failed to establish a new connection: [Errno 8] nodename nor servname provided, or not known'))

During handling of the above exception, another exception occurred:

Traceback (most recent call last):
  File "binance1.py", line 20, in <module>
    client = Client(api_key, api_secret)
  File "/Library/Frameworks/Python.framework/Versions/3.8/lib/python3.8/site-packages/binance/client.py", line 97, in __init__
    self.ping()
  File "/Library/Frameworks/Python.framework/Versions/3.8/lib/python3.8/site-packages/binance/client.py", line 378, in ping
    return self._get('ping')
  File "/Library/Frameworks/Python.framework/Versions/3.8/lib/python3.8/site-packages/binance/client.py", line 222, in _get
    return self._request_api('get', path, signed, version, **kwargs)
  File "/Library/Frameworks/Python.framework/Versions/3.8/lib/python3.8/site-packages/binance/client.py", line 191, in _request_api
    return self._request(method, uri, signed, **kwargs)
  File "/Library/Frameworks/Python.framework/Versions/3.8/lib/python3.8/site-packages/binance/client.py", line 185, in _request
    self.response = getattr(self.session, method)(uri, **kwargs)
  File "/Library/Frameworks/Python.framework/Versions/3.8/lib/python3.8/site-packages/requests/sessions.py", line 546, in get
    return self.request('GET', url, **kwargs)
  File "/Library/Frameworks/Python.framework/Versions/3.8/lib/python3.8/site-packages/requests/sessions.py", line 533, in request
    resp = self.send(prep, **send_kwargs)
  File "/Library/Frameworks/Python.framework/Versions/3.8/lib/python3.8/site-packages/requests/sessions.py", line 646, in send
    r = adapter.send(request, **kwargs)
  File "/Library/Frameworks/Python.framework/Versions/3.8/lib/python3.8/site-packages/requests/adapters.py", line 516, in send
    raise ConnectionError(e, request=request)
requests.exceptions.ConnectionError: HTTPSConnectionPool(host='api.binance.com', port=443): Max retries exceeded with url: /api/v1/ping (Caused by NewConnectionError('<urllib3.connection.VerifiedHTTPSConnection object at 0x10d569340>: Failed to establish a new connection: [Errno 8] nodename nor servname provided, or not known'))
Traceback (most recent call last):
  File "email_price_notify.py", line 77, in <module>
    server = smtplib.SMTP('smtp.gmail.com', 587) 
  File "/Library/Frameworks/Python.framework/Versions/3.8/lib/python3.8/smtplib.py", line 253, in __init__
    (code, msg) = self.connect(host, port)
  File "/Library/Frameworks/Python.framework/Versions/3.8/lib/python3.8/smtplib.py", line 339, in connect
    self.sock = self._get_socket(host, port, self.timeout)
  File "/Library/Frameworks/Python.framework/Versions/3.8/lib/python3.8/smtplib.py", line 308, in _get_socket
    return socket.create_connection((host, port), timeout,
  File "/Library/Frameworks/Python.framework/Versions/3.8/lib/python3.8/socket.py", line 787, in create_connection
    for res in getaddrinfo(host, port, 0, SOCK_STREAM):
  File "/Library/Frameworks/Python.framework/Versions/3.8/lib/python3.8/socket.py", line 914, in getaddrinfo
    for res in _socket.getaddrinfo(host, port, family, type, proto, flags):
socket.gaierror: [Errno 8] nodename nor servname provided, or not known
Traceback (most recent call last):
  File "/Library/Frameworks/Python.framework/Versions/3.8/lib/python3.8/site-packages/urllib3/connection.py", line 156, in _new_conn
    conn = connection.create_connection(
  File "/Library/Frameworks/Python.framework/Versions/3.8/lib/python3.8/site-packages/urllib3/util/connection.py", line 61, in create_connection
    for res in socket.getaddrinfo(host, port, family, socket.SOCK_STREAM):
  File "/Library/Frameworks/Python.framework/Versions/3.8/lib/python3.8/socket.py", line 914, in getaddrinfo
    for res in _socket.getaddrinfo(host, port, family, type, proto, flags):
socket.gaierror: [Errno 8] nodename nor servname provided, or not known

During handling of the above exception, another exception occurred:

Traceback (most recent call last):
  File "/Library/Frameworks/Python.framework/Versions/3.8/lib/python3.8/site-packages/urllib3/connectionpool.py", line 665, in urlopen
    httplib_response = self._make_request(
  File "/Library/Frameworks/Python.framework/Versions/3.8/lib/python3.8/site-packages/urllib3/connectionpool.py", line 376, in _make_request
    self._validate_conn(conn)
  File "/Library/Frameworks/Python.framework/Versions/3.8/lib/python3.8/site-packages/urllib3/connectionpool.py", line 994, in _validate_conn
    conn.connect()
  File "/Library/Frameworks/Python.framework/Versions/3.8/lib/python3.8/site-packages/urllib3/connection.py", line 334, in connect
    conn = self._new_conn()
  File "/Library/Frameworks/Python.framework/Versions/3.8/lib/python3.8/site-packages/urllib3/connection.py", line 168, in _new_conn
    raise NewConnectionError(
urllib3.exceptions.NewConnectionError: <urllib3.connection.VerifiedHTTPSConnection object at 0x115a913a0>: Failed to establish a new connection: [Errno 8] nodename nor servname provided, or not known

During handling of the above exception, another exception occurred:

Traceback (most recent call last):
  File "/Library/Frameworks/Python.framework/Versions/3.8/lib/python3.8/site-packages/requests/adapters.py", line 439, in send
    resp = conn.urlopen(
  File "/Library/Frameworks/Python.framework/Versions/3.8/lib/python3.8/site-packages/urllib3/connectionpool.py", line 719, in urlopen
    retries = retries.increment(
  File "/Library/Frameworks/Python.framework/Versions/3.8/lib/python3.8/site-packages/urllib3/util/retry.py", line 436, in increment
    raise MaxRetryError(_pool, url, error or ResponseError(cause))
urllib3.exceptions.MaxRetryError: HTTPSConnectionPool(host='api.binance.com', port=443): Max retries exceeded with url: /api/v1/ping (Caused by NewConnectionError('<urllib3.connection.VerifiedHTTPSConnection object at 0x115a913a0>: Failed to establish a new connection: [Errno 8] nodename nor servname provided, or not known'))

During handling of the above exception, another exception occurred:

Traceback (most recent call last):
  File "binance1.py", line 20, in <module>
    client = Client(api_key, api_secret)
  File "/Library/Frameworks/Python.framework/Versions/3.8/lib/python3.8/site-packages/binance/client.py", line 97, in __init__
    self.ping()
  File "/Library/Frameworks/Python.framework/Versions/3.8/lib/python3.8/site-packages/binance/client.py", line 378, in ping
    return self._get('ping')
  File "/Library/Frameworks/Python.framework/Versions/3.8/lib/python3.8/site-packages/binance/client.py", line 222, in _get
    return self._request_api('get', path, signed, version, **kwargs)
  File "/Library/Frameworks/Python.framework/Versions/3.8/lib/python3.8/site-packages/binance/client.py", line 191, in _request_api
    return self._request(method, uri, signed, **kwargs)
  File "/Library/Frameworks/Python.framework/Versions/3.8/lib/python3.8/site-packages/binance/client.py", line 185, in _request
    self.response = getattr(self.session, method)(uri, **kwargs)
  File "/Library/Frameworks/Python.framework/Versions/3.8/lib/python3.8/site-packages/requests/sessions.py", line 546, in get
    return self.request('GET', url, **kwargs)
  File "/Library/Frameworks/Python.framework/Versions/3.8/lib/python3.8/site-packages/requests/sessions.py", line 533, in request
    resp = self.send(prep, **send_kwargs)
  File "/Library/Frameworks/Python.framework/Versions/3.8/lib/python3.8/site-packages/requests/sessions.py", line 646, in send
    r = adapter.send(request, **kwargs)
  File "/Library/Frameworks/Python.framework/Versions/3.8/lib/python3.8/site-packages/requests/adapters.py", line 516, in send
    raise ConnectionError(e, request=request)
requests.exceptions.ConnectionError: HTTPSConnectionPool(host='api.binance.com', port=443): Max retries exceeded with url: /api/v1/ping (Caused by NewConnectionError('<urllib3.connection.VerifiedHTTPSConnection object at 0x115a913a0>: Failed to establish a new connection: [Errno 8] nodename nor servname provided, or not known'))
Traceback (most recent call last):
  File "email_price_notify.py", line 77, in <module>
    server = smtplib.SMTP('smtp.gmail.com', 587) 
  File "/Library/Frameworks/Python.framework/Versions/3.8/lib/python3.8/smtplib.py", line 253, in __init__
    (code, msg) = self.connect(host, port)
  File "/Library/Frameworks/Python.framework/Versions/3.8/lib/python3.8/smtplib.py", line 339, in connect
    self.sock = self._get_socket(host, port, self.timeout)
  File "/Library/Frameworks/Python.framework/Versions/3.8/lib/python3.8/smtplib.py", line 308, in _get_socket
    return socket.create_connection((host, port), timeout,
  File "/Library/Frameworks/Python.framework/Versions/3.8/lib/python3.8/socket.py", line 787, in create_connection
    for res in getaddrinfo(host, port, 0, SOCK_STREAM):
  File "/Library/Frameworks/Python.framework/Versions/3.8/lib/python3.8/socket.py", line 914, in getaddrinfo
    for res in _socket.getaddrinfo(host, port, family, type, proto, flags):
socket.gaierror: [Errno 8] nodename nor servname provided, or not known
Traceback (most recent call last):
  File "/Library/Frameworks/Python.framework/Versions/3.8/lib/python3.8/site-packages/urllib3/connection.py", line 156, in _new_conn
    conn = connection.create_connection(
  File "/Library/Frameworks/Python.framework/Versions/3.8/lib/python3.8/site-packages/urllib3/util/connection.py", line 61, in create_connection
    for res in socket.getaddrinfo(host, port, family, socket.SOCK_STREAM):
  File "/Library/Frameworks/Python.framework/Versions/3.8/lib/python3.8/socket.py", line 914, in getaddrinfo
    for res in _socket.getaddrinfo(host, port, family, type, proto, flags):
socket.gaierror: [Errno 8] nodename nor servname provided, or not known

During handling of the above exception, another exception occurred:

Traceback (most recent call last):
  File "/Library/Frameworks/Python.framework/Versions/3.8/lib/python3.8/site-packages/urllib3/connectionpool.py", line 665, in urlopen
    httplib_response = self._make_request(
  File "/Library/Frameworks/Python.framework/Versions/3.8/lib/python3.8/site-packages/urllib3/connectionpool.py", line 376, in _make_request
    self._validate_conn(conn)
  File "/Library/Frameworks/Python.framework/Versions/3.8/lib/python3.8/site-packages/urllib3/connectionpool.py", line 994, in _validate_conn
    conn.connect()
  File "/Library/Frameworks/Python.framework/Versions/3.8/lib/python3.8/site-packages/urllib3/connection.py", line 334, in connect
    conn = self._new_conn()
  File "/Library/Frameworks/Python.framework/Versions/3.8/lib/python3.8/site-packages/urllib3/connection.py", line 168, in _new_conn
    raise NewConnectionError(
urllib3.exceptions.NewConnectionError: <urllib3.connection.VerifiedHTTPSConnection object at 0x1193333d0>: Failed to establish a new connection: [Errno 8] nodename nor servname provided, or not known

During handling of the above exception, another exception occurred:

Traceback (most recent call last):
  File "/Library/Frameworks/Python.framework/Versions/3.8/lib/python3.8/site-packages/requests/adapters.py", line 439, in send
    resp = conn.urlopen(
  File "/Library/Frameworks/Python.framework/Versions/3.8/lib/python3.8/site-packages/urllib3/connectionpool.py", line 719, in urlopen
    retries = retries.increment(
  File "/Library/Frameworks/Python.framework/Versions/3.8/lib/python3.8/site-packages/urllib3/util/retry.py", line 436, in increment
    raise MaxRetryError(_pool, url, error or ResponseError(cause))
urllib3.exceptions.MaxRetryError: HTTPSConnectionPool(host='api.binance.com', port=443): Max retries exceeded with url: /api/v1/ping (Caused by NewConnectionError('<urllib3.connection.VerifiedHTTPSConnection object at 0x1193333d0>: Failed to establish a new connection: [Errno 8] nodename nor servname provided, or not known'))

During handling of the above exception, another exception occurred:

Traceback (most recent call last):
  File "binance1.py", line 20, in <module>
    client = Client(api_key, api_secret)
  File "/Library/Frameworks/Python.framework/Versions/3.8/lib/python3.8/site-packages/binance/client.py", line 97, in __init__
    self.ping()
  File "/Library/Frameworks/Python.framework/Versions/3.8/lib/python3.8/site-packages/binance/client.py", line 378, in ping
    return self._get('ping')
  File "/Library/Frameworks/Python.framework/Versions/3.8/lib/python3.8/site-packages/binance/client.py", line 222, in _get
    return self._request_api('get', path, signed, version, **kwargs)
  File "/Library/Frameworks/Python.framework/Versions/3.8/lib/python3.8/site-packages/binance/client.py", line 191, in _request_api
    return self._request(method, uri, signed, **kwargs)
  File "/Library/Frameworks/Python.framework/Versions/3.8/lib/python3.8/site-packages/binance/client.py", line 185, in _request
    self.response = getattr(self.session, method)(uri, **kwargs)
  File "/Library/Frameworks/Python.framework/Versions/3.8/lib/python3.8/site-packages/requests/sessions.py", line 546, in get
    return self.request('GET', url, **kwargs)
  File "/Library/Frameworks/Python.framework/Versions/3.8/lib/python3.8/site-packages/requests/sessions.py", line 533, in request
    resp = self.send(prep, **send_kwargs)
  File "/Library/Frameworks/Python.framework/Versions/3.8/lib/python3.8/site-packages/requests/sessions.py", line 646, in send
    r = adapter.send(request, **kwargs)
  File "/Library/Frameworks/Python.framework/Versions/3.8/lib/python3.8/site-packages/requests/adapters.py", line 516, in send
    raise ConnectionError(e, request=request)
requests.exceptions.ConnectionError: HTTPSConnectionPool(host='api.binance.com', port=443): Max retries exceeded with url: /api/v1/ping (Caused by NewConnectionError('<urllib3.connection.VerifiedHTTPSConnection object at 0x1193333d0>: Failed to establish a new connection: [Errno 8] nodename nor servname provided, or not known'))
Traceback (most recent call last):
  File "email_price_notify.py", line 77, in <module>
    server = smtplib.SMTP('smtp.gmail.com', 587) 
  File "/Library/Frameworks/Python.framework/Versions/3.8/lib/python3.8/smtplib.py", line 253, in __init__
    (code, msg) = self.connect(host, port)
  File "/Library/Frameworks/Python.framework/Versions/3.8/lib/python3.8/smtplib.py", line 339, in connect
    self.sock = self._get_socket(host, port, self.timeout)
  File "/Library/Frameworks/Python.framework/Versions/3.8/lib/python3.8/smtplib.py", line 308, in _get_socket
    return socket.create_connection((host, port), timeout,
  File "/Library/Frameworks/Python.framework/Versions/3.8/lib/python3.8/socket.py", line 787, in create_connection
    for res in getaddrinfo(host, port, 0, SOCK_STREAM):
  File "/Library/Frameworks/Python.framework/Versions/3.8/lib/python3.8/socket.py", line 914, in getaddrinfo
    for res in _socket.getaddrinfo(host, port, family, type, proto, flags):
socket.gaierror: [Errno 8] nodename nor servname provided, or not known
Traceback (most recent call last):
  File "/Library/Frameworks/Python.framework/Versions/3.8/lib/python3.8/site-packages/urllib3/connection.py", line 156, in _new_conn
    conn = connection.create_connection(
  File "/Library/Frameworks/Python.framework/Versions/3.8/lib/python3.8/site-packages/urllib3/util/connection.py", line 61, in create_connection
    for res in socket.getaddrinfo(host, port, family, socket.SOCK_STREAM):
  File "/Library/Frameworks/Python.framework/Versions/3.8/lib/python3.8/socket.py", line 914, in getaddrinfo
    for res in _socket.getaddrinfo(host, port, family, type, proto, flags):
socket.gaierror: [Errno 8] nodename nor servname provided, or not known

During handling of the above exception, another exception occurred:

Traceback (most recent call last):
  File "/Library/Frameworks/Python.framework/Versions/3.8/lib/python3.8/site-packages/urllib3/connectionpool.py", line 665, in urlopen
    httplib_response = self._make_request(
  File "/Library/Frameworks/Python.framework/Versions/3.8/lib/python3.8/site-packages/urllib3/connectionpool.py", line 376, in _make_request
    self._validate_conn(conn)
  File "/Library/Frameworks/Python.framework/Versions/3.8/lib/python3.8/site-packages/urllib3/connectionpool.py", line 994, in _validate_conn
    conn.connect()
  File "/Library/Frameworks/Python.framework/Versions/3.8/lib/python3.8/site-packages/urllib3/connection.py", line 334, in connect
    conn = self._new_conn()
  File "/Library/Frameworks/Python.framework/Versions/3.8/lib/python3.8/site-packages/urllib3/connection.py", line 168, in _new_conn
    raise NewConnectionError(
urllib3.exceptions.NewConnectionError: <urllib3.connection.VerifiedHTTPSConnection object at 0x117aeb370>: Failed to establish a new connection: [Errno 8] nodename nor servname provided, or not known

During handling of the above exception, another exception occurred:

Traceback (most recent call last):
  File "/Library/Frameworks/Python.framework/Versions/3.8/lib/python3.8/site-packages/requests/adapters.py", line 439, in send
    resp = conn.urlopen(
  File "/Library/Frameworks/Python.framework/Versions/3.8/lib/python3.8/site-packages/urllib3/connectionpool.py", line 719, in urlopen
    retries = retries.increment(
  File "/Library/Frameworks/Python.framework/Versions/3.8/lib/python3.8/site-packages/urllib3/util/retry.py", line 436, in increment
    raise MaxRetryError(_pool, url, error or ResponseError(cause))
urllib3.exceptions.MaxRetryError: HTTPSConnectionPool(host='api.binance.com', port=443): Max retries exceeded with url: /api/v1/ping (Caused by NewConnectionError('<urllib3.connection.VerifiedHTTPSConnection object at 0x117aeb370>: Failed to establish a new connection: [Errno 8] nodename nor servname provided, or not known'))

During handling of the above exception, another exception occurred:

Traceback (most recent call last):
  File "binance1.py", line 20, in <module>
    client = Client(api_key, api_secret)
  File "/Library/Frameworks/Python.framework/Versions/3.8/lib/python3.8/site-packages/binance/client.py", line 97, in __init__
    self.ping()
  File "/Library/Frameworks/Python.framework/Versions/3.8/lib/python3.8/site-packages/binance/client.py", line 378, in ping
    return self._get('ping')
  File "/Library/Frameworks/Python.framework/Versions/3.8/lib/python3.8/site-packages/binance/client.py", line 222, in _get
    return self._request_api('get', path, signed, version, **kwargs)
  File "/Library/Frameworks/Python.framework/Versions/3.8/lib/python3.8/site-packages/binance/client.py", line 191, in _request_api
    return self._request(method, uri, signed, **kwargs)
  File "/Library/Frameworks/Python.framework/Versions/3.8/lib/python3.8/site-packages/binance/client.py", line 185, in _request
    self.response = getattr(self.session, method)(uri, **kwargs)
  File "/Library/Frameworks/Python.framework/Versions/3.8/lib/python3.8/site-packages/requests/sessions.py", line 546, in get
    return self.request('GET', url, **kwargs)
  File "/Library/Frameworks/Python.framework/Versions/3.8/lib/python3.8/site-packages/requests/sessions.py", line 533, in request
    resp = self.send(prep, **send_kwargs)
  File "/Library/Frameworks/Python.framework/Versions/3.8/lib/python3.8/site-packages/requests/sessions.py", line 646, in send
    r = adapter.send(request, **kwargs)
  File "/Library/Frameworks/Python.framework/Versions/3.8/lib/python3.8/site-packages/requests/adapters.py", line 516, in send
    raise ConnectionError(e, request=request)
requests.exceptions.ConnectionError: HTTPSConnectionPool(host='api.binance.com', port=443): Max retries exceeded with url: /api/v1/ping (Caused by NewConnectionError('<urllib3.connection.VerifiedHTTPSConnection object at 0x117aeb370>: Failed to establish a new connection: [Errno 8] nodename nor servname provided, or not known'))
Traceback (most recent call last):
  File "email_price_notify.py", line 77, in <module>
    server = smtplib.SMTP('smtp.gmail.com', 587) 
  File "/Library/Frameworks/Python.framework/Versions/3.8/lib/python3.8/smtplib.py", line 253, in __init__
    (code, msg) = self.connect(host, port)
  File "/Library/Frameworks/Python.framework/Versions/3.8/lib/python3.8/smtplib.py", line 339, in connect
    self.sock = self._get_socket(host, port, self.timeout)
  File "/Library/Frameworks/Python.framework/Versions/3.8/lib/python3.8/smtplib.py", line 308, in _get_socket
    return socket.create_connection((host, port), timeout,
  File "/Library/Frameworks/Python.framework/Versions/3.8/lib/python3.8/socket.py", line 787, in create_connection
    for res in getaddrinfo(host, port, 0, SOCK_STREAM):
  File "/Library/Frameworks/Python.framework/Versions/3.8/lib/python3.8/socket.py", line 914, in getaddrinfo
    for res in _socket.getaddrinfo(host, port, family, type, proto, flags):
socket.gaierror: [Errno 8] nodename nor servname provided, or not known
Traceback (most recent call last):
  File "/Library/Frameworks/Python.framework/Versions/3.8/lib/python3.8/site-packages/urllib3/connection.py", line 156, in _new_conn
    conn = connection.create_connection(
  File "/Library/Frameworks/Python.framework/Versions/3.8/lib/python3.8/site-packages/urllib3/util/connection.py", line 61, in create_connection
    for res in socket.getaddrinfo(host, port, family, socket.SOCK_STREAM):
  File "/Library/Frameworks/Python.framework/Versions/3.8/lib/python3.8/socket.py", line 914, in getaddrinfo
    for res in _socket.getaddrinfo(host, port, family, type, proto, flags):
socket.gaierror: [Errno 8] nodename nor servname provided, or not known

During handling of the above exception, another exception occurred:

Traceback (most recent call last):
  File "/Library/Frameworks/Python.framework/Versions/3.8/lib/python3.8/site-packages/urllib3/connectionpool.py", line 665, in urlopen
    httplib_response = self._make_request(
  File "/Library/Frameworks/Python.framework/Versions/3.8/lib/python3.8/site-packages/urllib3/connectionpool.py", line 376, in _make_request
    self._validate_conn(conn)
  File "/Library/Frameworks/Python.framework/Versions/3.8/lib/python3.8/site-packages/urllib3/connectionpool.py", line 994, in _validate_conn
    conn.connect()
  File "/Library/Frameworks/Python.framework/Versions/3.8/lib/python3.8/site-packages/urllib3/connection.py", line 334, in connect
    conn = self._new_conn()
  File "/Library/Frameworks/Python.framework/Versions/3.8/lib/python3.8/site-packages/urllib3/connection.py", line 168, in _new_conn
    raise NewConnectionError(
urllib3.exceptions.NewConnectionError: <urllib3.connection.VerifiedHTTPSConnection object at 0x116278370>: Failed to establish a new connection: [Errno 8] nodename nor servname provided, or not known

During handling of the above exception, another exception occurred:

Traceback (most recent call last):
  File "/Library/Frameworks/Python.framework/Versions/3.8/lib/python3.8/site-packages/requests/adapters.py", line 439, in send
    resp = conn.urlopen(
  File "/Library/Frameworks/Python.framework/Versions/3.8/lib/python3.8/site-packages/urllib3/connectionpool.py", line 719, in urlopen
    retries = retries.increment(
  File "/Library/Frameworks/Python.framework/Versions/3.8/lib/python3.8/site-packages/urllib3/util/retry.py", line 436, in increment
    raise MaxRetryError(_pool, url, error or ResponseError(cause))
urllib3.exceptions.MaxRetryError: HTTPSConnectionPool(host='api.binance.com', port=443): Max retries exceeded with url: /api/v1/ping (Caused by NewConnectionError('<urllib3.connection.VerifiedHTTPSConnection object at 0x116278370>: Failed to establish a new connection: [Errno 8] nodename nor servname provided, or not known'))

During handling of the above exception, another exception occurred:

Traceback (most recent call last):
  File "binance1.py", line 20, in <module>
    client = Client(api_key, api_secret)
  File "/Library/Frameworks/Python.framework/Versions/3.8/lib/python3.8/site-packages/binance/client.py", line 97, in __init__
    self.ping()
  File "/Library/Frameworks/Python.framework/Versions/3.8/lib/python3.8/site-packages/binance/client.py", line 378, in ping
    return self._get('ping')
  File "/Library/Frameworks/Python.framework/Versions/3.8/lib/python3.8/site-packages/binance/client.py", line 222, in _get
    return self._request_api('get', path, signed, version, **kwargs)
  File "/Library/Frameworks/Python.framework/Versions/3.8/lib/python3.8/site-packages/binance/client.py", line 191, in _request_api
    return self._request(method, uri, signed, **kwargs)
  File "/Library/Frameworks/Python.framework/Versions/3.8/lib/python3.8/site-packages/binance/client.py", line 185, in _request
    self.response = getattr(self.session, method)(uri, **kwargs)
  File "/Library/Frameworks/Python.framework/Versions/3.8/lib/python3.8/site-packages/requests/sessions.py", line 546, in get
    return self.request('GET', url, **kwargs)
  File "/Library/Frameworks/Python.framework/Versions/3.8/lib/python3.8/site-packages/requests/sessions.py", line 533, in request
    resp = self.send(prep, **send_kwargs)
  File "/Library/Frameworks/Python.framework/Versions/3.8/lib/python3.8/site-packages/requests/sessions.py", line 646, in send
    r = adapter.send(request, **kwargs)
  File "/Library/Frameworks/Python.framework/Versions/3.8/lib/python3.8/site-packages/requests/adapters.py", line 516, in send
    raise ConnectionError(e, request=request)
requests.exceptions.ConnectionError: HTTPSConnectionPool(host='api.binance.com', port=443): Max retries exceeded with url: /api/v1/ping (Caused by NewConnectionError('<urllib3.connection.VerifiedHTTPSConnection object at 0x116278370>: Failed to establish a new connection: [Errno 8] nodename nor servname provided, or not known'))
Traceback (most recent call last):
  File "email_price_notify.py", line 77, in <module>
    server = smtplib.SMTP('smtp.gmail.com', 587) 
  File "/Library/Frameworks/Python.framework/Versions/3.8/lib/python3.8/smtplib.py", line 253, in __init__
    (code, msg) = self.connect(host, port)
  File "/Library/Frameworks/Python.framework/Versions/3.8/lib/python3.8/smtplib.py", line 339, in connect
    self.sock = self._get_socket(host, port, self.timeout)
  File "/Library/Frameworks/Python.framework/Versions/3.8/lib/python3.8/smtplib.py", line 308, in _get_socket
    return socket.create_connection((host, port), timeout,
  File "/Library/Frameworks/Python.framework/Versions/3.8/lib/python3.8/socket.py", line 787, in create_connection
    for res in getaddrinfo(host, port, 0, SOCK_STREAM):
  File "/Library/Frameworks/Python.framework/Versions/3.8/lib/python3.8/socket.py", line 914, in getaddrinfo
    for res in _socket.getaddrinfo(host, port, family, type, proto, flags):
socket.gaierror: [Errno 8] nodename nor servname provided, or not known
Traceback (most recent call last):
  File "/Library/Frameworks/Python.framework/Versions/3.8/lib/python3.8/site-packages/urllib3/connection.py", line 156, in _new_conn
    conn = connection.create_connection(
  File "/Library/Frameworks/Python.framework/Versions/3.8/lib/python3.8/site-packages/urllib3/util/connection.py", line 61, in create_connection
    for res in socket.getaddrinfo(host, port, family, socket.SOCK_STREAM):
  File "/Library/Frameworks/Python.framework/Versions/3.8/lib/python3.8/socket.py", line 914, in getaddrinfo
    for res in _socket.getaddrinfo(host, port, family, type, proto, flags):
socket.gaierror: [Errno 8] nodename nor servname provided, or not known

During handling of the above exception, another exception occurred:

Traceback (most recent call last):
  File "/Library/Frameworks/Python.framework/Versions/3.8/lib/python3.8/site-packages/urllib3/connectionpool.py", line 665, in urlopen
    httplib_response = self._make_request(
  File "/Library/Frameworks/Python.framework/Versions/3.8/lib/python3.8/site-packages/urllib3/connectionpool.py", line 376, in _make_request
    self._validate_conn(conn)
  File "/Library/Frameworks/Python.framework/Versions/3.8/lib/python3.8/site-packages/urllib3/connectionpool.py", line 994, in _validate_conn
    conn.connect()
  File "/Library/Frameworks/Python.framework/Versions/3.8/lib/python3.8/site-packages/urllib3/connection.py", line 334, in connect
    conn = self._new_conn()
  File "/Library/Frameworks/Python.framework/Versions/3.8/lib/python3.8/site-packages/urllib3/connection.py", line 168, in _new_conn
    raise NewConnectionError(
urllib3.exceptions.NewConnectionError: <urllib3.connection.VerifiedHTTPSConnection object at 0x11268a370>: Failed to establish a new connection: [Errno 8] nodename nor servname provided, or not known

During handling of the above exception, another exception occurred:

Traceback (most recent call last):
  File "/Library/Frameworks/Python.framework/Versions/3.8/lib/python3.8/site-packages/requests/adapters.py", line 439, in send
    resp = conn.urlopen(
  File "/Library/Frameworks/Python.framework/Versions/3.8/lib/python3.8/site-packages/urllib3/connectionpool.py", line 719, in urlopen
    retries = retries.increment(
  File "/Library/Frameworks/Python.framework/Versions/3.8/lib/python3.8/site-packages/urllib3/util/retry.py", line 436, in increment
    raise MaxRetryError(_pool, url, error or ResponseError(cause))
urllib3.exceptions.MaxRetryError: HTTPSConnectionPool(host='api.binance.com', port=443): Max retries exceeded with url: /api/v1/ping (Caused by NewConnectionError('<urllib3.connection.VerifiedHTTPSConnection object at 0x11268a370>: Failed to establish a new connection: [Errno 8] nodename nor servname provided, or not known'))

During handling of the above exception, another exception occurred:

Traceback (most recent call last):
  File "binance1.py", line 20, in <module>
    client = Client(api_key, api_secret)
  File "/Library/Frameworks/Python.framework/Versions/3.8/lib/python3.8/site-packages/binance/client.py", line 97, in __init__
    self.ping()
  File "/Library/Frameworks/Python.framework/Versions/3.8/lib/python3.8/site-packages/binance/client.py", line 378, in ping
    return self._get('ping')
  File "/Library/Frameworks/Python.framework/Versions/3.8/lib/python3.8/site-packages/binance/client.py", line 222, in _get
    return self._request_api('get', path, signed, version, **kwargs)
  File "/Library/Frameworks/Python.framework/Versions/3.8/lib/python3.8/site-packages/binance/client.py", line 191, in _request_api
    return self._request(method, uri, signed, **kwargs)
  File "/Library/Frameworks/Python.framework/Versions/3.8/lib/python3.8/site-packages/binance/client.py", line 185, in _request
    self.response = getattr(self.session, method)(uri, **kwargs)
  File "/Library/Frameworks/Python.framework/Versions/3.8/lib/python3.8/site-packages/requests/sessions.py", line 546, in get
    return self.request('GET', url, **kwargs)
  File "/Library/Frameworks/Python.framework/Versions/3.8/lib/python3.8/site-packages/requests/sessions.py", line 533, in request
    resp = self.send(prep, **send_kwargs)
  File "/Library/Frameworks/Python.framework/Versions/3.8/lib/python3.8/site-packages/requests/sessions.py", line 646, in send
    r = adapter.send(request, **kwargs)
  File "/Library/Frameworks/Python.framework/Versions/3.8/lib/python3.8/site-packages/requests/adapters.py", line 516, in send
    raise ConnectionError(e, request=request)
requests.exceptions.ConnectionError: HTTPSConnectionPool(host='api.binance.com', port=443): Max retries exceeded with url: /api/v1/ping (Caused by NewConnectionError('<urllib3.connection.VerifiedHTTPSConnection object at 0x11268a370>: Failed to establish a new connection: [Errno 8] nodename nor servname provided, or not known'))
Traceback (most recent call last):
  File "email_price_notify.py", line 77, in <module>
    server = smtplib.SMTP('smtp.gmail.com', 587) 
  File "/Library/Frameworks/Python.framework/Versions/3.8/lib/python3.8/smtplib.py", line 253, in __init__
    (code, msg) = self.connect(host, port)
  File "/Library/Frameworks/Python.framework/Versions/3.8/lib/python3.8/smtplib.py", line 339, in connect
    self.sock = self._get_socket(host, port, self.timeout)
  File "/Library/Frameworks/Python.framework/Versions/3.8/lib/python3.8/smtplib.py", line 308, in _get_socket
    return socket.create_connection((host, port), timeout,
  File "/Library/Frameworks/Python.framework/Versions/3.8/lib/python3.8/socket.py", line 787, in create_connection
    for res in getaddrinfo(host, port, 0, SOCK_STREAM):
  File "/Library/Frameworks/Python.framework/Versions/3.8/lib/python3.8/socket.py", line 914, in getaddrinfo
    for res in _socket.getaddrinfo(host, port, family, type, proto, flags):
socket.gaierror: [Errno 8] nodename nor servname provided, or not known
Traceback (most recent call last):
  File "/Library/Frameworks/Python.framework/Versions/3.8/lib/python3.8/site-packages/urllib3/connection.py", line 156, in _new_conn
    conn = connection.create_connection(
  File "/Library/Frameworks/Python.framework/Versions/3.8/lib/python3.8/site-packages/urllib3/util/connection.py", line 61, in create_connection
    for res in socket.getaddrinfo(host, port, family, socket.SOCK_STREAM):
  File "/Library/Frameworks/Python.framework/Versions/3.8/lib/python3.8/socket.py", line 914, in getaddrinfo
    for res in _socket.getaddrinfo(host, port, family, type, proto, flags):
socket.gaierror: [Errno 8] nodename nor servname provided, or not known

During handling of the above exception, another exception occurred:

Traceback (most recent call last):
  File "/Library/Frameworks/Python.framework/Versions/3.8/lib/python3.8/site-packages/urllib3/connectionpool.py", line 665, in urlopen
    httplib_response = self._make_request(
  File "/Library/Frameworks/Python.framework/Versions/3.8/lib/python3.8/site-packages/urllib3/connectionpool.py", line 376, in _make_request
    self._validate_conn(conn)
  File "/Library/Frameworks/Python.framework/Versions/3.8/lib/python3.8/site-packages/urllib3/connectionpool.py", line 994, in _validate_conn
    conn.connect()
  File "/Library/Frameworks/Python.framework/Versions/3.8/lib/python3.8/site-packages/urllib3/connection.py", line 334, in connect
    conn = self._new_conn()
  File "/Library/Frameworks/Python.framework/Versions/3.8/lib/python3.8/site-packages/urllib3/connection.py", line 168, in _new_conn
    raise NewConnectionError(
urllib3.exceptions.NewConnectionError: <urllib3.connection.VerifiedHTTPSConnection object at 0x10e3bf370>: Failed to establish a new connection: [Errno 8] nodename nor servname provided, or not known

During handling of the above exception, another exception occurred:

Traceback (most recent call last):
  File "/Library/Frameworks/Python.framework/Versions/3.8/lib/python3.8/site-packages/requests/adapters.py", line 439, in send
    resp = conn.urlopen(
  File "/Library/Frameworks/Python.framework/Versions/3.8/lib/python3.8/site-packages/urllib3/connectionpool.py", line 719, in urlopen
    retries = retries.increment(
  File "/Library/Frameworks/Python.framework/Versions/3.8/lib/python3.8/site-packages/urllib3/util/retry.py", line 436, in increment
    raise MaxRetryError(_pool, url, error or ResponseError(cause))
urllib3.exceptions.MaxRetryError: HTTPSConnectionPool(host='api.binance.com', port=443): Max retries exceeded with url: /api/v1/ping (Caused by NewConnectionError('<urllib3.connection.VerifiedHTTPSConnection object at 0x10e3bf370>: Failed to establish a new connection: [Errno 8] nodename nor servname provided, or not known'))

During handling of the above exception, another exception occurred:

Traceback (most recent call last):
  File "binance1.py", line 20, in <module>
    client = Client(api_key, api_secret)
  File "/Library/Frameworks/Python.framework/Versions/3.8/lib/python3.8/site-packages/binance/client.py", line 97, in __init__
    self.ping()
  File "/Library/Frameworks/Python.framework/Versions/3.8/lib/python3.8/site-packages/binance/client.py", line 378, in ping
    return self._get('ping')
  File "/Library/Frameworks/Python.framework/Versions/3.8/lib/python3.8/site-packages/binance/client.py", line 222, in _get
    return self._request_api('get', path, signed, version, **kwargs)
  File "/Library/Frameworks/Python.framework/Versions/3.8/lib/python3.8/site-packages/binance/client.py", line 191, in _request_api
    return self._request(method, uri, signed, **kwargs)
  File "/Library/Frameworks/Python.framework/Versions/3.8/lib/python3.8/site-packages/binance/client.py", line 185, in _request
    self.response = getattr(self.session, method)(uri, **kwargs)
  File "/Library/Frameworks/Python.framework/Versions/3.8/lib/python3.8/site-packages/requests/sessions.py", line 546, in get
    return self.request('GET', url, **kwargs)
  File "/Library/Frameworks/Python.framework/Versions/3.8/lib/python3.8/site-packages/requests/sessions.py", line 533, in request
    resp = self.send(prep, **send_kwargs)
  File "/Library/Frameworks/Python.framework/Versions/3.8/lib/python3.8/site-packages/requests/sessions.py", line 646, in send
    r = adapter.send(request, **kwargs)
  File "/Library/Frameworks/Python.framework/Versions/3.8/lib/python3.8/site-packages/requests/adapters.py", line 516, in send
    raise ConnectionError(e, request=request)
requests.exceptions.ConnectionError: HTTPSConnectionPool(host='api.binance.com', port=443): Max retries exceeded with url: /api/v1/ping (Caused by NewConnectionError('<urllib3.connection.VerifiedHTTPSConnection object at 0x10e3bf370>: Failed to establish a new connection: [Errno 8] nodename nor servname provided, or not known'))
Traceback (most recent call last):
  File "email_price_notify.py", line 77, in <module>
    server = smtplib.SMTP('smtp.gmail.com', 587) 
  File "/Library/Frameworks/Python.framework/Versions/3.8/lib/python3.8/smtplib.py", line 253, in __init__
    (code, msg) = self.connect(host, port)
  File "/Library/Frameworks/Python.framework/Versions/3.8/lib/python3.8/smtplib.py", line 339, in connect
    self.sock = self._get_socket(host, port, self.timeout)
  File "/Library/Frameworks/Python.framework/Versions/3.8/lib/python3.8/smtplib.py", line 308, in _get_socket
    return socket.create_connection((host, port), timeout,
  File "/Library/Frameworks/Python.framework/Versions/3.8/lib/python3.8/socket.py", line 787, in create_connection
    for res in getaddrinfo(host, port, 0, SOCK_STREAM):
  File "/Library/Frameworks/Python.framework/Versions/3.8/lib/python3.8/socket.py", line 914, in getaddrinfo
    for res in _socket.getaddrinfo(host, port, family, type, proto, flags):
socket.gaierror: [Errno 8] nodename nor servname provided, or not known
228.41 226.10111680798173 907
228.34 226.05445014131507 907
227.8 225.6944501413151 907
227.88 225.7477834746484 907
Traceback (most recent call last):
  File "/Library/Frameworks/Python.framework/Versions/3.8/lib/python3.8/site-packages/urllib3/connection.py", line 156, in _new_conn
    conn = connection.create_connection(
  File "/Library/Frameworks/Python.framework/Versions/3.8/lib/python3.8/site-packages/urllib3/util/connection.py", line 61, in create_connection
    for res in socket.getaddrinfo(host, port, family, socket.SOCK_STREAM):
  File "/Library/Frameworks/Python.framework/Versions/3.8/lib/python3.8/socket.py", line 914, in getaddrinfo
    for res in _socket.getaddrinfo(host, port, family, type, proto, flags):
socket.gaierror: [Errno 8] nodename nor servname provided, or not known

During handling of the above exception, another exception occurred:

Traceback (most recent call last):
  File "/Library/Frameworks/Python.framework/Versions/3.8/lib/python3.8/site-packages/urllib3/connectionpool.py", line 665, in urlopen
    httplib_response = self._make_request(
  File "/Library/Frameworks/Python.framework/Versions/3.8/lib/python3.8/site-packages/urllib3/connectionpool.py", line 376, in _make_request
    self._validate_conn(conn)
  File "/Library/Frameworks/Python.framework/Versions/3.8/lib/python3.8/site-packages/urllib3/connectionpool.py", line 994, in _validate_conn
    conn.connect()
  File "/Library/Frameworks/Python.framework/Versions/3.8/lib/python3.8/site-packages/urllib3/connection.py", line 334, in connect
    conn = self._new_conn()
  File "/Library/Frameworks/Python.framework/Versions/3.8/lib/python3.8/site-packages/urllib3/connection.py", line 168, in _new_conn
    raise NewConnectionError(
urllib3.exceptions.NewConnectionError: <urllib3.connection.VerifiedHTTPSConnection object at 0x1125809a0>: Failed to establish a new connection: [Errno 8] nodename nor servname provided, or not known

During handling of the above exception, another exception occurred:

Traceback (most recent call last):
  File "/Library/Frameworks/Python.framework/Versions/3.8/lib/python3.8/site-packages/requests/adapters.py", line 439, in send
    resp = conn.urlopen(
  File "/Library/Frameworks/Python.framework/Versions/3.8/lib/python3.8/site-packages/urllib3/connectionpool.py", line 719, in urlopen
    retries = retries.increment(
  File "/Library/Frameworks/Python.framework/Versions/3.8/lib/python3.8/site-packages/urllib3/util/retry.py", line 436, in increment
    raise MaxRetryError(_pool, url, error or ResponseError(cause))
urllib3.exceptions.MaxRetryError: HTTPSConnectionPool(host='api.binance.com', port=443): Max retries exceeded with url: /api/v1/ping (Caused by NewConnectionError('<urllib3.connection.VerifiedHTTPSConnection object at 0x1125809a0>: Failed to establish a new connection: [Errno 8] nodename nor servname provided, or not known'))

During handling of the above exception, another exception occurred:

Traceback (most recent call last):
  File "binance1.py", line 20, in <module>
    client = Client(api_key, api_secret)
  File "/Library/Frameworks/Python.framework/Versions/3.8/lib/python3.8/site-packages/binance/client.py", line 97, in __init__
    self.ping()
  File "/Library/Frameworks/Python.framework/Versions/3.8/lib/python3.8/site-packages/binance/client.py", line 378, in ping
    return self._get('ping')
  File "/Library/Frameworks/Python.framework/Versions/3.8/lib/python3.8/site-packages/binance/client.py", line 222, in _get
    return self._request_api('get', path, signed, version, **kwargs)
  File "/Library/Frameworks/Python.framework/Versions/3.8/lib/python3.8/site-packages/binance/client.py", line 191, in _request_api
    return self._request(method, uri, signed, **kwargs)
  File "/Library/Frameworks/Python.framework/Versions/3.8/lib/python3.8/site-packages/binance/client.py", line 185, in _request
    self.response = getattr(self.session, method)(uri, **kwargs)
  File "/Library/Frameworks/Python.framework/Versions/3.8/lib/python3.8/site-packages/requests/sessions.py", line 546, in get
    return self.request('GET', url, **kwargs)
  File "/Library/Frameworks/Python.framework/Versions/3.8/lib/python3.8/site-packages/requests/sessions.py", line 533, in request
    resp = self.send(prep, **send_kwargs)
  File "/Library/Frameworks/Python.framework/Versions/3.8/lib/python3.8/site-packages/requests/sessions.py", line 646, in send
    r = adapter.send(request, **kwargs)
  File "/Library/Frameworks/Python.framework/Versions/3.8/lib/python3.8/site-packages/requests/adapters.py", line 516, in send
    raise ConnectionError(e, request=request)
requests.exceptions.ConnectionError: HTTPSConnectionPool(host='api.binance.com', port=443): Max retries exceeded with url: /api/v1/ping (Caused by NewConnectionError('<urllib3.connection.VerifiedHTTPSConnection object at 0x1125809a0>: Failed to establish a new connection: [Errno 8] nodename nor servname provided, or not known'))
Traceback (most recent call last):
  File "/Library/Frameworks/Python.framework/Versions/3.8/lib/python3.8/site-packages/urllib3/connection.py", line 156, in _new_conn
    conn = connection.create_connection(
  File "/Library/Frameworks/Python.framework/Versions/3.8/lib/python3.8/site-packages/urllib3/util/connection.py", line 61, in create_connection
    for res in socket.getaddrinfo(host, port, family, socket.SOCK_STREAM):
  File "/Library/Frameworks/Python.framework/Versions/3.8/lib/python3.8/socket.py", line 914, in getaddrinfo
    for res in _socket.getaddrinfo(host, port, family, type, proto, flags):
socket.gaierror: [Errno 8] nodename nor servname provided, or not known

During handling of the above exception, another exception occurred:

Traceback (most recent call last):
  File "/Library/Frameworks/Python.framework/Versions/3.8/lib/python3.8/site-packages/urllib3/connectionpool.py", line 665, in urlopen
    httplib_response = self._make_request(
  File "/Library/Frameworks/Python.framework/Versions/3.8/lib/python3.8/site-packages/urllib3/connectionpool.py", line 376, in _make_request
    self._validate_conn(conn)
  File "/Library/Frameworks/Python.framework/Versions/3.8/lib/python3.8/site-packages/urllib3/connectionpool.py", line 994, in _validate_conn
    conn.connect()
  File "/Library/Frameworks/Python.framework/Versions/3.8/lib/python3.8/site-packages/urllib3/connection.py", line 334, in connect
    conn = self._new_conn()
  File "/Library/Frameworks/Python.framework/Versions/3.8/lib/python3.8/site-packages/urllib3/connection.py", line 168, in _new_conn
    raise NewConnectionError(
urllib3.exceptions.NewConnectionError: <urllib3.connection.VerifiedHTTPSConnection object at 0x114426a00>: Failed to establish a new connection: [Errno 8] nodename nor servname provided, or not known

During handling of the above exception, another exception occurred:

Traceback (most recent call last):
  File "/Library/Frameworks/Python.framework/Versions/3.8/lib/python3.8/site-packages/requests/adapters.py", line 439, in send
    resp = conn.urlopen(
  File "/Library/Frameworks/Python.framework/Versions/3.8/lib/python3.8/site-packages/urllib3/connectionpool.py", line 719, in urlopen
    retries = retries.increment(
  File "/Library/Frameworks/Python.framework/Versions/3.8/lib/python3.8/site-packages/urllib3/util/retry.py", line 436, in increment
    raise MaxRetryError(_pool, url, error or ResponseError(cause))
urllib3.exceptions.MaxRetryError: HTTPSConnectionPool(host='api.binance.com', port=443): Max retries exceeded with url: /api/v1/ping (Caused by NewConnectionError('<urllib3.connection.VerifiedHTTPSConnection object at 0x114426a00>: Failed to establish a new connection: [Errno 8] nodename nor servname provided, or not known'))

During handling of the above exception, another exception occurred:

Traceback (most recent call last):
  File "binance1.py", line 20, in <module>
    client = Client(api_key, api_secret)
  File "/Library/Frameworks/Python.framework/Versions/3.8/lib/python3.8/site-packages/binance/client.py", line 97, in __init__
    self.ping()
  File "/Library/Frameworks/Python.framework/Versions/3.8/lib/python3.8/site-packages/binance/client.py", line 378, in ping
    return self._get('ping')
  File "/Library/Frameworks/Python.framework/Versions/3.8/lib/python3.8/site-packages/binance/client.py", line 222, in _get
    return self._request_api('get', path, signed, version, **kwargs)
  File "/Library/Frameworks/Python.framework/Versions/3.8/lib/python3.8/site-packages/binance/client.py", line 191, in _request_api
    return self._request(method, uri, signed, **kwargs)
  File "/Library/Frameworks/Python.framework/Versions/3.8/lib/python3.8/site-packages/binance/client.py", line 185, in _request
    self.response = getattr(self.session, method)(uri, **kwargs)
  File "/Library/Frameworks/Python.framework/Versions/3.8/lib/python3.8/site-packages/requests/sessions.py", line 546, in get
    return self.request('GET', url, **kwargs)
  File "/Library/Frameworks/Python.framework/Versions/3.8/lib/python3.8/site-packages/requests/sessions.py", line 533, in request
    resp = self.send(prep, **send_kwargs)
  File "/Library/Frameworks/Python.framework/Versions/3.8/lib/python3.8/site-packages/requests/sessions.py", line 646, in send
    r = adapter.send(request, **kwargs)
  File "/Library/Frameworks/Python.framework/Versions/3.8/lib/python3.8/site-packages/requests/adapters.py", line 516, in send
    raise ConnectionError(e, request=request)
requests.exceptions.ConnectionError: HTTPSConnectionPool(host='api.binance.com', port=443): Max retries exceeded with url: /api/v1/ping (Caused by NewConnectionError('<urllib3.connection.VerifiedHTTPSConnection object at 0x114426a00>: Failed to establish a new connection: [Errno 8] nodename nor servname provided, or not known'))
Traceback (most recent call last):
  File "email_price_notify.py", line 77, in <module>
    server = smtplib.SMTP('smtp.gmail.com', 587) 
  File "/Library/Frameworks/Python.framework/Versions/3.8/lib/python3.8/smtplib.py", line 253, in __init__
    (code, msg) = self.connect(host, port)
  File "/Library/Frameworks/Python.framework/Versions/3.8/lib/python3.8/smtplib.py", line 339, in connect
    self.sock = self._get_socket(host, port, self.timeout)
  File "/Library/Frameworks/Python.framework/Versions/3.8/lib/python3.8/smtplib.py", line 308, in _get_socket
    return socket.create_connection((host, port), timeout,
  File "/Library/Frameworks/Python.framework/Versions/3.8/lib/python3.8/socket.py", line 787, in create_connection
    for res in getaddrinfo(host, port, 0, SOCK_STREAM):
  File "/Library/Frameworks/Python.framework/Versions/3.8/lib/python3.8/socket.py", line 914, in getaddrinfo
    for res in _socket.getaddrinfo(host, port, family, type, proto, flags):
socket.gaierror: [Errno 8] nodename nor servname provided, or not known
Traceback (most recent call last):
  File "/Library/Frameworks/Python.framework/Versions/3.8/lib/python3.8/site-packages/urllib3/connection.py", line 156, in _new_conn
    conn = connection.create_connection(
  File "/Library/Frameworks/Python.framework/Versions/3.8/lib/python3.8/site-packages/urllib3/util/connection.py", line 61, in create_connection
    for res in socket.getaddrinfo(host, port, family, socket.SOCK_STREAM):
  File "/Library/Frameworks/Python.framework/Versions/3.8/lib/python3.8/socket.py", line 914, in getaddrinfo
    for res in _socket.getaddrinfo(host, port, family, type, proto, flags):
socket.gaierror: [Errno 8] nodename nor servname provided, or not known

During handling of the above exception, another exception occurred:

Traceback (most recent call last):
  File "/Library/Frameworks/Python.framework/Versions/3.8/lib/python3.8/site-packages/urllib3/connectionpool.py", line 665, in urlopen
    httplib_response = self._make_request(
  File "/Library/Frameworks/Python.framework/Versions/3.8/lib/python3.8/site-packages/urllib3/connectionpool.py", line 376, in _make_request
    self._validate_conn(conn)
  File "/Library/Frameworks/Python.framework/Versions/3.8/lib/python3.8/site-packages/urllib3/connectionpool.py", line 994, in _validate_conn
    conn.connect()
  File "/Library/Frameworks/Python.framework/Versions/3.8/lib/python3.8/site-packages/urllib3/connection.py", line 334, in connect
    conn = self._new_conn()
  File "/Library/Frameworks/Python.framework/Versions/3.8/lib/python3.8/site-packages/urllib3/connection.py", line 168, in _new_conn
    raise NewConnectionError(
urllib3.exceptions.NewConnectionError: <urllib3.connection.VerifiedHTTPSConnection object at 0x11b6bea30>: Failed to establish a new connection: [Errno 8] nodename nor servname provided, or not known

During handling of the above exception, another exception occurred:

Traceback (most recent call last):
  File "/Library/Frameworks/Python.framework/Versions/3.8/lib/python3.8/site-packages/requests/adapters.py", line 439, in send
    resp = conn.urlopen(
  File "/Library/Frameworks/Python.framework/Versions/3.8/lib/python3.8/site-packages/urllib3/connectionpool.py", line 719, in urlopen
    retries = retries.increment(
  File "/Library/Frameworks/Python.framework/Versions/3.8/lib/python3.8/site-packages/urllib3/util/retry.py", line 436, in increment
    raise MaxRetryError(_pool, url, error or ResponseError(cause))
urllib3.exceptions.MaxRetryError: HTTPSConnectionPool(host='api.binance.com', port=443): Max retries exceeded with url: /api/v1/ping (Caused by NewConnectionError('<urllib3.connection.VerifiedHTTPSConnection object at 0x11b6bea30>: Failed to establish a new connection: [Errno 8] nodename nor servname provided, or not known'))

During handling of the above exception, another exception occurred:

Traceback (most recent call last):
  File "binance1.py", line 20, in <module>
    client = Client(api_key, api_secret)
  File "/Library/Frameworks/Python.framework/Versions/3.8/lib/python3.8/site-packages/binance/client.py", line 97, in __init__
    self.ping()
  File "/Library/Frameworks/Python.framework/Versions/3.8/lib/python3.8/site-packages/binance/client.py", line 378, in ping
    return self._get('ping')
  File "/Library/Frameworks/Python.framework/Versions/3.8/lib/python3.8/site-packages/binance/client.py", line 222, in _get
    return self._request_api('get', path, signed, version, **kwargs)
  File "/Library/Frameworks/Python.framework/Versions/3.8/lib/python3.8/site-packages/binance/client.py", line 191, in _request_api
    return self._request(method, uri, signed, **kwargs)
  File "/Library/Frameworks/Python.framework/Versions/3.8/lib/python3.8/site-packages/binance/client.py", line 185, in _request
    self.response = getattr(self.session, method)(uri, **kwargs)
  File "/Library/Frameworks/Python.framework/Versions/3.8/lib/python3.8/site-packages/requests/sessions.py", line 546, in get
    return self.request('GET', url, **kwargs)
  File "/Library/Frameworks/Python.framework/Versions/3.8/lib/python3.8/site-packages/requests/sessions.py", line 533, in request
    resp = self.send(prep, **send_kwargs)
  File "/Library/Frameworks/Python.framework/Versions/3.8/lib/python3.8/site-packages/requests/sessions.py", line 646, in send
    r = adapter.send(request, **kwargs)
  File "/Library/Frameworks/Python.framework/Versions/3.8/lib/python3.8/site-packages/requests/adapters.py", line 516, in send
    raise ConnectionError(e, request=request)
requests.exceptions.ConnectionError: HTTPSConnectionPool(host='api.binance.com', port=443): Max retries exceeded with url: /api/v1/ping (Caused by NewConnectionError('<urllib3.connection.VerifiedHTTPSConnection object at 0x11b6bea30>: Failed to establish a new connection: [Errno 8] nodename nor servname provided, or not known'))
228.45 226.1277834746484 907
228.63 226.2477834746484 907
227.3 225.36111680798174 907
227.25 225.3277834746484 907
226.05 224.52778347464843 907
226.1 224.56111680798173 907
Sun Feb  9 23:23:00 CST 2020
225.16 223.93445014131507 907
Sun Feb  9 23:24:00 CST 2020
224.38 223.4144501413151 907
Sun Feb  9 23:25:00 CST 2020
224.58 223.5477834746484 907
Sun Feb  9 23:26:00 CST 2020
224.13 223.2477834746484 907
Sun Feb  9 23:27:00 CST 2020
224.35 223.39445014131505 907
Sun Feb  9 23:59:00 CST 2020
226.93 225.11445014131507 907
Mon Feb 10 00:00:00 CST 2020
226.88 225.08111680798174 907
Mon Feb 10 08:59:00 CST 2020
228.9 227.9848167137717 908
Mon Feb 10 09:00:00 CST 2020
228.86 227.95815004710505 908
Mon Feb 10 09:59:01 CST 2020
226.8 226.58481671377172 908
Mon Feb 10 10:00:01 CST 2020
226.92 226.66481671377167 908
Mon Feb 10 10:59:00 CST 2020
226.66 226.49148338043835 908
Mon Feb 10 11:00:00 CST 2020
226.71 226.52481671377168 908
Mon Feb 10 11:59:00 CST 2020
225.46 225.69148338043837 908
Mon Feb 10 12:00:00 CST 2020
225.42 225.66481671377167 908
Mon Feb 10 12:59:00 CST 2020
224.69 225.17815004710505 908
Mon Feb 10 13:00:00 CST 2020
224.44 225.01148338043836 908
Mon Feb 10 13:59:00 CST 2020
220.2 222.1848167137717 908
Mon Feb 10 14:00:01 CST 2020
220.64 222.47815004710503 908
Mon Feb 10 14:59:00 CST 2020
222.78 223.90481671377168 908
Mon Feb 10 15:00:01 CST 2020
223.22 224.19815004710503 908
Mon Feb 10 15:59:01 CST 2020
223.84 224.61148338043836 908
Mon Feb 10 16:00:00 CST 2020
223.64 224.47815004710503 908
Mon Feb 10 16:59:01 CST 2020
221.21 222.85815004710503 908
Mon Feb 10 17:00:00 CST 2020
220.9 222.65148338043835 908
Mon Feb 10 17:59:00 CST 2020
218.98 221.37148338043835 908
Mon Feb 10 18:00:00 CST 2020
219.17 221.498150047105 908
Mon Feb 10 18:59:00 CST 2020
219.95 222.01815004710502 908
Mon Feb 10 19:00:00 CST 2020
220.16 222.158150047105 908
Mon Feb 10 19:59:00 CST 2020
218.34 220.9448167137717 908
Mon Feb 10 20:00:00 CST 2020
218.58 221.1048167137717 908
Mon Feb 10 20:59:00 CST 2020
220.08 222.1048167137717 908
Mon Feb 10 21:00:00 CST 2020
220.01 222.05815004710504 908
Mon Feb 10 21:59:00 CST 2020
219.55 221.75148338043837 908
Mon Feb 10 22:00:00 CST 2020
219.57 221.7648167137717 908
Mon Feb 10 22:59:00 CST 2020
223.19 224.17815004710505 908
Mon Feb 10 23:00:00 CST 2020
223.39 224.31148338043837 908
Mon Feb 10 23:59:01 CST 2020
223.41 224.3248167137717 908
Tue Feb 11 00:00:00 CST 2020
223.28 224.23815004710502 908
Tue Feb 11 00:59:00 CST 2020
221.52 223.0648167137717 908
Tue Feb 11 01:00:00 CST 2020
221.98 223.37148338043835 908
Tue Feb 11 20:59:00 CST 2020
223.36 223.56605001570168 909
Tue Feb 11 21:00:00 CST 2020
223.26 223.499383349035 909
Tue Feb 11 21:59:00 CST 2020
223.52 223.67271668236836 909
Tue Feb 11 22:00:01 CST 2020
223.42 223.6060500157017 909
Tue Feb 11 22:59:00 CST 2020
222.29 222.85271668236837 909
Tue Feb 11 23:00:01 CST 2020
222.52 223.0060500157017 909
Tue Feb 11 23:59:00 CST 2020
228.9 227.25938334903503 909
Wed Feb 12 00:00:00 CST 2020
228.88 227.24605001570168 909
Wed Feb 12 00:59:01 CST 2020
231.55 229.02605001570168 909
Wed Feb 12 01:00:00 CST 2020
231.53 229.01271668236836 909
Wed Feb 12 12:59:00 CST 2020
244.96 240.79090556078947 910
Wed Feb 12 13:00:00 CST 2020
244.91 240.7575722274561 910
Wed Feb 12 14:59:00 CST 2020
248.46 243.12423889412278 910
Wed Feb 12 15:00:00 CST 2020
248.91 243.4242388941228 910
Wed Feb 12 15:59:00 CST 2020
253.3 246.35090556078944 910
Wed Feb 12 16:00:00 CST 2020
253.34 246.3775722274561 910
Wed Feb 12 17:59:00 CST 2020
253.14 246.24423889412276 910
Wed Feb 12 18:00:00 CST 2020
253.07 246.1975722274561 910
Wed Feb 12 18:59:00 CST 2020
254.42 247.0975722274561 910
Wed Feb 12 19:00:01 CST 2020
254.34 247.0442388941228 910
Wed Feb 12 19:59:00 CST 2020
255.54 247.84423889412278 910
Wed Feb 12 20:00:00 CST 2020
255.56 247.8575722274561 910
Wed Feb 12 20:59:00 CST 2020
255.88 248.07090556078944 910
Wed Feb 12 21:00:00 CST 2020
255.56 247.8575722274561 910
Wed Feb 12 21:59:00 CST 2020
256.09 248.21090556078943 910
Wed Feb 12 22:00:00 CST 2020
256.21 248.2909055607894 910
Wed Feb 12 22:59:00 CST 2020
255.77 247.99757222745612 910
Wed Feb 12 23:00:00 CST 2020
255.9 248.0842388941228 910
Wed Feb 12 23:59:01 CST 2020
254.6 247.21757222745612 910
Thu Feb 13 00:00:00 CST 2020
254.23 246.97090556078945 910
Thu Feb 13 00:59:04 CST 2020
262.0 252.15090556078943 910
Thu Feb 13 01:00:00 CST 2020
261.81 252.02423889412276 910
Thu Feb 13 01:59:01 CST 2020
264.63 253.90423889412276 910
Thu Feb 13 02:00:00 CST 2020
264.64 253.91090556078942 910
Thu Feb 13 19:59:00 CST 2020
262.48 259.86807963137426 911
Thu Feb 13 20:00:00 CST 2020
262.79 260.0747462980409 911
Thu Feb 13 20:59:00 CST 2020
268.16 263.65474629804095 911
Thu Feb 13 21:00:01 CST 2020
268.45 263.8480796313742 911
Thu Feb 13 21:59:00 CST 2020
273.86 267.4547462980409 911
Thu Feb 13 22:00:01 CST 2020
269.05 264.24807963137425 911
Thu Feb 13 22:59:00 CST 2020
269.53 264.56807963137425 911
Thu Feb 13 23:00:00 CST 2020
269.94 264.84141296470756 911
Thu Feb 13 23:59:02 CST 2020
271.09 265.6080796313742 911
Fri Feb 14 00:00:00 CST 2020
270.73 265.36807963137426 911
Fri Feb 14 08:59:00 CST 2020
268.29 266.7804709882359 912
Fri Feb 14 09:00:00 CST 2020
268.17 266.70047098823585 912
Fri Feb 14 09:59:00 CST 2020
267.66 266.3604709882359 912
Fri Feb 14 10:00:00 CST 2020
267.31 266.1271376549025 912
Fri Feb 14 10:59:00 CST 2020
267.86 266.4938043215692 912
Fri Feb 14 11:00:00 CST 2020
267.97 266.5671376549025 912
Fri Feb 14 11:59:00 CST 2020
266.15 265.35380432156916 912
Fri Feb 14 12:00:00 CST 2020
266.63 265.6738043215692 912
Fri Feb 14 12:59:01 CST 2020
266.66 265.6938043215692 912
Fri Feb 14 13:00:00 CST 2020
266.72 265.7338043215692 912
Fri Feb 14 13:59:00 CST 2020
264.37 264.16713765490255 912
Fri Feb 14 14:00:00 CST 2020
264.35 264.1538043215692 912
Fri Feb 14 14:59:00 CST 2020
264.37 264.16713765490255 912
Fri Feb 14 15:00:00 CST 2020
264.42 264.20047098823585 912
Fri Feb 14 15:59:00 CST 2020
262.01 262.59380432156917 912
Fri Feb 14 16:00:00 CST 2020
262.71 263.06047098823586 912
Fri Feb 14 16:59:00 CST 2020
265.34 264.8138043215692 912
Fri Feb 14 17:00:00 CST 2020
265.76 265.09380432156917 912
Fri Feb 14 17:59:00 CST 2020
268.25 266.7538043215692 912
Fri Feb 14 18:00:00 CST 2020
268.3 266.78713765490255 912
Fri Feb 14 18:59:00 CST 2020
270.56 268.2938043215692 912
Fri Feb 14 19:00:00 CST 2020
270.3 268.12047098823587 912
Fri Feb 14 19:59:00 CST 2020
270.33 268.14047098823585 912
Fri Feb 14 20:00:00 CST 2020
270.92 268.5338043215692 912
Fri Feb 14 20:59:00 CST 2020
271.0 268.5871376549025 912
Fri Feb 14 21:00:00 CST 2020
270.69 268.38047098823586 912
Fri Feb 14 21:59:00 CST 2020
270.32 268.1338043215692 912
Fri Feb 14 22:00:00 CST 2020
270.22 268.0671376549025 912
Sat Feb 15 00:59:00 CST 2020
277.39 272.8471376549025 912
Sat Feb 15 01:00:00 CST 2020
277.88 273.1738043215692 912
Sat Feb 15 20:59:00 CST 2020
Traceback (most recent call last):
  File "/Library/Frameworks/Python.framework/Versions/3.8/lib/python3.8/site-packages/urllib3/connection.py", line 156, in _new_conn
    conn = connection.create_connection(
  File "/Library/Frameworks/Python.framework/Versions/3.8/lib/python3.8/site-packages/urllib3/util/connection.py", line 61, in create_connection
    for res in socket.getaddrinfo(host, port, family, socket.SOCK_STREAM):
  File "/Library/Frameworks/Python.framework/Versions/3.8/lib/python3.8/socket.py", line 914, in getaddrinfo
    for res in _socket.getaddrinfo(host, port, family, type, proto, flags):
socket.gaierror: [Errno 8] nodename nor servname provided, or not known

During handling of the above exception, another exception occurred:

Traceback (most recent call last):
  File "/Library/Frameworks/Python.framework/Versions/3.8/lib/python3.8/site-packages/urllib3/connectionpool.py", line 665, in urlopen
    httplib_response = self._make_request(
  File "/Library/Frameworks/Python.framework/Versions/3.8/lib/python3.8/site-packages/urllib3/connectionpool.py", line 376, in _make_request
    self._validate_conn(conn)
  File "/Library/Frameworks/Python.framework/Versions/3.8/lib/python3.8/site-packages/urllib3/connectionpool.py", line 994, in _validate_conn
    conn.connect()
  File "/Library/Frameworks/Python.framework/Versions/3.8/lib/python3.8/site-packages/urllib3/connection.py", line 334, in connect
    conn = self._new_conn()
  File "/Library/Frameworks/Python.framework/Versions/3.8/lib/python3.8/site-packages/urllib3/connection.py", line 168, in _new_conn
    raise NewConnectionError(
urllib3.exceptions.NewConnectionError: <urllib3.connection.VerifiedHTTPSConnection object at 0x1167a03a0>: Failed to establish a new connection: [Errno 8] nodename nor servname provided, or not known

During handling of the above exception, another exception occurred:

Traceback (most recent call last):
  File "/Library/Frameworks/Python.framework/Versions/3.8/lib/python3.8/site-packages/requests/adapters.py", line 439, in send
    resp = conn.urlopen(
  File "/Library/Frameworks/Python.framework/Versions/3.8/lib/python3.8/site-packages/urllib3/connectionpool.py", line 719, in urlopen
    retries = retries.increment(
  File "/Library/Frameworks/Python.framework/Versions/3.8/lib/python3.8/site-packages/urllib3/util/retry.py", line 436, in increment
    raise MaxRetryError(_pool, url, error or ResponseError(cause))
urllib3.exceptions.MaxRetryError: HTTPSConnectionPool(host='api.binance.com', port=443): Max retries exceeded with url: /api/v1/ping (Caused by NewConnectionError('<urllib3.connection.VerifiedHTTPSConnection object at 0x1167a03a0>: Failed to establish a new connection: [Errno 8] nodename nor servname provided, or not known'))

During handling of the above exception, another exception occurred:

Traceback (most recent call last):
  File "binance1.py", line 20, in <module>
    client = Client(api_key, api_secret)
  File "/Library/Frameworks/Python.framework/Versions/3.8/lib/python3.8/site-packages/binance/client.py", line 97, in __init__
    self.ping()
  File "/Library/Frameworks/Python.framework/Versions/3.8/lib/python3.8/site-packages/binance/client.py", line 378, in ping
    return self._get('ping')
  File "/Library/Frameworks/Python.framework/Versions/3.8/lib/python3.8/site-packages/binance/client.py", line 222, in _get
    return self._request_api('get', path, signed, version, **kwargs)
  File "/Library/Frameworks/Python.framework/Versions/3.8/lib/python3.8/site-packages/binance/client.py", line 191, in _request_api
    return self._request(method, uri, signed, **kwargs)
  File "/Library/Frameworks/Python.framework/Versions/3.8/lib/python3.8/site-packages/binance/client.py", line 185, in _request
    self.response = getattr(self.session, method)(uri, **kwargs)
  File "/Library/Frameworks/Python.framework/Versions/3.8/lib/python3.8/site-packages/requests/sessions.py", line 546, in get
    return self.request('GET', url, **kwargs)
  File "/Library/Frameworks/Python.framework/Versions/3.8/lib/python3.8/site-packages/requests/sessions.py", line 533, in request
    resp = self.send(prep, **send_kwargs)
  File "/Library/Frameworks/Python.framework/Versions/3.8/lib/python3.8/site-packages/requests/sessions.py", line 646, in send
    r = adapter.send(request, **kwargs)
  File "/Library/Frameworks/Python.framework/Versions/3.8/lib/python3.8/site-packages/requests/adapters.py", line 516, in send
    raise ConnectionError(e, request=request)
requests.exceptions.ConnectionError: HTTPSConnectionPool(host='api.binance.com', port=443): Max retries exceeded with url: /api/v1/ping (Caused by NewConnectionError('<urllib3.connection.VerifiedHTTPSConnection object at 0x1167a03a0>: Failed to establish a new connection: [Errno 8] nodename nor servname provided, or not known'))
Traceback (most recent call last):
  File "email_price_notify.py", line 77, in <module>
    server = smtplib.SMTP('smtp.gmail.com', 587) 
  File "/Library/Frameworks/Python.framework/Versions/3.8/lib/python3.8/smtplib.py", line 253, in __init__
    (code, msg) = self.connect(host, port)
  File "/Library/Frameworks/Python.framework/Versions/3.8/lib/python3.8/smtplib.py", line 339, in connect
    self.sock = self._get_socket(host, port, self.timeout)
  File "/Library/Frameworks/Python.framework/Versions/3.8/lib/python3.8/smtplib.py", line 308, in _get_socket
    return socket.create_connection((host, port), timeout,
  File "/Library/Frameworks/Python.framework/Versions/3.8/lib/python3.8/socket.py", line 787, in create_connection
    for res in getaddrinfo(host, port, 0, SOCK_STREAM):
  File "/Library/Frameworks/Python.framework/Versions/3.8/lib/python3.8/socket.py", line 914, in getaddrinfo
    for res in _socket.getaddrinfo(host, port, family, type, proto, flags):
socket.gaierror: [Errno 8] nodename nor servname provided, or not known
Sat Feb 15 21:00:00 CST 2020
Traceback (most recent call last):
  File "/Library/Frameworks/Python.framework/Versions/3.8/lib/python3.8/site-packages/urllib3/connection.py", line 156, in _new_conn
    conn = connection.create_connection(
  File "/Library/Frameworks/Python.framework/Versions/3.8/lib/python3.8/site-packages/urllib3/util/connection.py", line 61, in create_connection
    for res in socket.getaddrinfo(host, port, family, socket.SOCK_STREAM):
  File "/Library/Frameworks/Python.framework/Versions/3.8/lib/python3.8/socket.py", line 914, in getaddrinfo
    for res in _socket.getaddrinfo(host, port, family, type, proto, flags):
socket.gaierror: [Errno 8] nodename nor servname provided, or not known

During handling of the above exception, another exception occurred:

Traceback (most recent call last):
  File "/Library/Frameworks/Python.framework/Versions/3.8/lib/python3.8/site-packages/urllib3/connectionpool.py", line 665, in urlopen
    httplib_response = self._make_request(
  File "/Library/Frameworks/Python.framework/Versions/3.8/lib/python3.8/site-packages/urllib3/connectionpool.py", line 376, in _make_request
    self._validate_conn(conn)
  File "/Library/Frameworks/Python.framework/Versions/3.8/lib/python3.8/site-packages/urllib3/connectionpool.py", line 994, in _validate_conn
    conn.connect()
  File "/Library/Frameworks/Python.framework/Versions/3.8/lib/python3.8/site-packages/urllib3/connection.py", line 334, in connect
    conn = self._new_conn()
  File "/Library/Frameworks/Python.framework/Versions/3.8/lib/python3.8/site-packages/urllib3/connection.py", line 168, in _new_conn
    raise NewConnectionError(
urllib3.exceptions.NewConnectionError: <urllib3.connection.VerifiedHTTPSConnection object at 0x115434370>: Failed to establish a new connection: [Errno 8] nodename nor servname provided, or not known

During handling of the above exception, another exception occurred:

Traceback (most recent call last):
  File "/Library/Frameworks/Python.framework/Versions/3.8/lib/python3.8/site-packages/requests/adapters.py", line 439, in send
    resp = conn.urlopen(
  File "/Library/Frameworks/Python.framework/Versions/3.8/lib/python3.8/site-packages/urllib3/connectionpool.py", line 719, in urlopen
    retries = retries.increment(
  File "/Library/Frameworks/Python.framework/Versions/3.8/lib/python3.8/site-packages/urllib3/util/retry.py", line 436, in increment
    raise MaxRetryError(_pool, url, error or ResponseError(cause))
urllib3.exceptions.MaxRetryError: HTTPSConnectionPool(host='api.binance.com', port=443): Max retries exceeded with url: /api/v1/ping (Caused by NewConnectionError('<urllib3.connection.VerifiedHTTPSConnection object at 0x115434370>: Failed to establish a new connection: [Errno 8] nodename nor servname provided, or not known'))

During handling of the above exception, another exception occurred:

Traceback (most recent call last):
  File "binance1.py", line 20, in <module>
    client = Client(api_key, api_secret)
  File "/Library/Frameworks/Python.framework/Versions/3.8/lib/python3.8/site-packages/binance/client.py", line 97, in __init__
    self.ping()
  File "/Library/Frameworks/Python.framework/Versions/3.8/lib/python3.8/site-packages/binance/client.py", line 378, in ping
    return self._get('ping')
  File "/Library/Frameworks/Python.framework/Versions/3.8/lib/python3.8/site-packages/binance/client.py", line 222, in _get
    return self._request_api('get', path, signed, version, **kwargs)
  File "/Library/Frameworks/Python.framework/Versions/3.8/lib/python3.8/site-packages/binance/client.py", line 191, in _request_api
    return self._request(method, uri, signed, **kwargs)
  File "/Library/Frameworks/Python.framework/Versions/3.8/lib/python3.8/site-packages/binance/client.py", line 185, in _request
    self.response = getattr(self.session, method)(uri, **kwargs)
  File "/Library/Frameworks/Python.framework/Versions/3.8/lib/python3.8/site-packages/requests/sessions.py", line 546, in get
    return self.request('GET', url, **kwargs)
  File "/Library/Frameworks/Python.framework/Versions/3.8/lib/python3.8/site-packages/requests/sessions.py", line 533, in request
    resp = self.send(prep, **send_kwargs)
  File "/Library/Frameworks/Python.framework/Versions/3.8/lib/python3.8/site-packages/requests/sessions.py", line 646, in send
    r = adapter.send(request, **kwargs)
  File "/Library/Frameworks/Python.framework/Versions/3.8/lib/python3.8/site-packages/requests/adapters.py", line 516, in send
    raise ConnectionError(e, request=request)
requests.exceptions.ConnectionError: HTTPSConnectionPool(host='api.binance.com', port=443): Max retries exceeded with url: /api/v1/ping (Caused by NewConnectionError('<urllib3.connection.VerifiedHTTPSConnection object at 0x115434370>: Failed to establish a new connection: [Errno 8] nodename nor servname provided, or not known'))
Traceback (most recent call last):
  File "email_price_notify.py", line 77, in <module>
    server = smtplib.SMTP('smtp.gmail.com', 587) 
  File "/Library/Frameworks/Python.framework/Versions/3.8/lib/python3.8/smtplib.py", line 253, in __init__
    (code, msg) = self.connect(host, port)
  File "/Library/Frameworks/Python.framework/Versions/3.8/lib/python3.8/smtplib.py", line 339, in connect
    self.sock = self._get_socket(host, port, self.timeout)
  File "/Library/Frameworks/Python.framework/Versions/3.8/lib/python3.8/smtplib.py", line 308, in _get_socket
    return socket.create_connection((host, port), timeout,
  File "/Library/Frameworks/Python.framework/Versions/3.8/lib/python3.8/socket.py", line 787, in create_connection
    for res in getaddrinfo(host, port, 0, SOCK_STREAM):
  File "/Library/Frameworks/Python.framework/Versions/3.8/lib/python3.8/socket.py", line 914, in getaddrinfo
    for res in _socket.getaddrinfo(host, port, family, type, proto, flags):
socket.gaierror: [Errno 8] nodename nor servname provided, or not known
Sun Feb 16 00:59:00 CST 2020
266.34 270.23349032941195 913
Sun Feb 16 01:00:00 CST 2020
267.03 270.69349032941193 913
Sun Feb 16 01:59:00 CST 2020
263.33 268.2268236627453 913
Sun Feb 16 02:00:00 CST 2020
262.92 267.953490329412 913
Sun Feb 16 02:59:00 CST 2020
268.6 271.7401569960786 913
Sun Feb 16 03:00:00 CST 2020
268.67 271.7868236627453 913
Sun Feb 16 08:59:00 CST 2020
265.66 266.8600523320262 914
Sun Feb 16 09:00:00 CST 2020
265.88 267.00671899869286 914
Sun Feb 16 09:59:00 CST 2020
267.41 268.02671899869284 914
Sun Feb 16 10:00:00 CST 2020
267.94 268.3800523320262 914
Sun Feb 16 10:59:00 CST 2020
273.21 271.8933856653595 914
Sun Feb 16 11:00:00 CST 2020
273.42 272.0333856653595 914
Sun Feb 16 11:59:00 CST 2020
271.48 270.7400523320262 914
Sun Feb 16 12:00:00 CST 2020
271.38 270.67338566535955 914
Sun Feb 16 12:59:00 CST 2020
272.48 271.4067189986929 914
Sun Feb 16 13:00:00 CST 2020
272.94 271.7133856653595 914
Sun Feb 16 13:59:00 CST 2020
270.83 270.3067189986928 914
Sun Feb 16 14:00:01 CST 2020
270.94 270.3800523320262 914
Sun Feb 16 15:59:01 CST 2020
270.14 269.8467189986929 914
Sun Feb 16 16:00:01 CST 2020
270.24 269.91338566535956 914
Sun Feb 16 16:59:00 CST 2020
270.41 270.02671899869284 914
Sun Feb 16 17:00:00 CST 2020
271.06 270.4600523320262 914
Sun Feb 16 17:59:00 CST 2020
269.7 269.5533856653595 914
Sun Feb 16 18:00:00 CST 2020
269.9 269.68671899869287 914
Sun Feb 16 20:59:00 CST 2020
265.85 266.9867189986929 914
Sun Feb 16 21:00:00 CST 2020
265.65 266.85338566535955 914
Sun Feb 16 21:59:00 CST 2020
266.77 267.6000523320262 914
Sun Feb 16 22:00:00 CST 2020
266.63 267.50671899869286 914
Sun Feb 16 22:59:00 CST 2020
262.94 265.0467189986928 914
Sun Feb 16 23:00:00 CST 2020
262.59 264.8133856653595 914
Mon Feb 17 14:59:00 CST 2020
248.93 253.39335077734208 915
Mon Feb 17 15:00:00 CST 2020
248.92 253.38668411067542 915
Mon Feb 17 20:59:00 CST 2020
247.79 252.6333507773421 915
Mon Feb 17 21:00:01 CST 2020
248.22 252.92001744400875 915
Mon Feb 17 21:59:00 CST 2020
245.37 251.02001744400877 915
Mon Feb 17 22:00:00 CST 2020
244.93 250.7266841106754 915
Mon Feb 17 22:59:00 CST 2020
252.54 255.80001744400874 915
Mon Feb 17 23:00:00 CST 2020
252.29 255.6333507773421 915
Mon Feb 17 23:59:01 CST 2020
256.43 258.39335077734205 915
Tue Feb 18 00:00:00 CST 2020
256.22 258.2533507773421 915
Tue Feb 18 19:59:00 CST 2020
267.77 267.1822280368918 916
Tue Feb 18 20:00:00 CST 2020
267.5 267.00222803689184 916
Tue Feb 18 20:59:01 CST 2020
263.08 264.0555613702251 916
Tue Feb 18 21:00:01 CST 2020
263.85 264.5688947035585 916
Tue Feb 18 21:59:00 CST 2020
263.07 264.04889470355846 916
Tue Feb 18 22:00:01 CST 2020
263.44 264.29556137022513 916
Tue Feb 18 22:59:00 CST 2020
265.88 265.9222280368918 916
Tue Feb 18 23:00:00 CST 2020
265.82 265.88222803689183 916
Tue Feb 18 23:59:00 CST 2020
274.03 271.35556137022513 916
Wed Feb 19 00:00:00 CST 2020
273.73 271.15556137022514 916
Wed Feb 19 00:59:00 CST 2020
281.01 276.0088947035585 916
Wed Feb 19 01:00:00 CST 2020
280.84 275.89556137022515 916
Wed Feb 19 08:59:01 CST 2020
278.12 277.77185379007506 917
Wed Feb 19 09:00:00 CST 2020
277.92 277.63852045674173 917
Wed Feb 19 09:59:00 CST 2020
278.05 277.7251871234084 917
Wed Feb 19 10:00:00 CST 2020
278.4 277.9585204567417 917
Wed Feb 19 10:59:00 CST 2020
281.0 279.6918537900751 917
Wed Feb 19 11:00:00 CST 2020
281.17 279.8051871234084 917
Wed Feb 19 11:59:00 CST 2020
279.87 278.93852045674174 917
Wed Feb 19 12:00:00 CST 2020
280.15 279.12518712340835 917
Wed Feb 19 12:59:00 CST 2020
278.59 278.0851871234084 917
Wed Feb 19 13:00:00 CST 2020
278.63 278.11185379007503 917
Wed Feb 19 13:59:01 CST 2020
280.11 279.0985204567417 917
Wed Feb 19 14:00:01 CST 2020
280.5 279.3585204567417 917
Wed Feb 19 14:59:00 CST 2020
276.69 276.81852045674174 917
Wed Feb 19 15:00:00 CST 2020
277.41 277.29852045674176 917
Wed Feb 19 15:59:00 CST 2020
276.46 276.6651871234084 917
Wed Feb 19 16:00:00 CST 2020
276.65 276.79185379007504 917
Wed Feb 19 16:59:00 CST 2020
282.2 280.491853790075 917
Wed Feb 19 17:00:00 CST 2020
282.67 280.8051871234084 917
Wed Feb 19 17:59:00 CST 2020
279.31 278.5651871234084 917
Wed Feb 19 18:00:00 CST 2020
278.59 278.0851871234084 917
Wed Feb 19 18:59:00 CST 2020
280.13 279.11185379007503 917
Wed Feb 19 19:00:00 CST 2020
280.04 279.0518537900751 917
Wed Feb 19 19:59:00 CST 2020
280.6 279.4251871234084 917
Wed Feb 19 20:00:00 CST 2020
280.6 279.4251871234084 917
Wed Feb 19 20:59:00 CST 2020
280.6 279.4251871234084 917
Wed Feb 19 21:00:00 CST 2020
280.6 279.4251871234084 917
Wed Feb 19 21:59:00 CST 2020
280.6 279.4251871234084 917
Wed Feb 19 22:00:00 CST 2020
280.6 279.4251871234084 917
Wed Feb 19 22:59:00 CST 2020
280.6 279.4251871234084 917
Wed Feb 19 23:00:00 CST 2020
280.6 279.4251871234084 917
Wed Feb 19 23:59:03 CST 2020
280.6 279.4251871234084 917
Thu Feb 20 00:00:01 CST 2020
280.6 279.4251871234084 917
Thu Feb 20 00:59:00 CST 2020
279.51 278.69852045674173 917
Thu Feb 20 01:00:00 CST 2020
280.95 279.6585204567417 917
Thu Feb 20 08:59:00 CST 2020
262.63 263.3061734855806 918
Thu Feb 20 09:00:00 CST 2020
262.58 263.2728401522472 918
Thu Feb 20 09:59:00 CST 2020
261.59 262.6128401522472 918
Thu Feb 20 10:00:00 CST 2020
261.56 262.5928401522472 918
Thu Feb 20 10:59:00 CST 2020
261.0 262.2195068189139 918
Thu Feb 20 11:00:01 CST 2020
261.63 262.6395068189139 918
Thu Feb 20 11:59:00 CST 2020
260.94 262.1795068189139 918
Thu Feb 20 12:00:01 CST 2020
260.88 262.1395068189139 918
Thu Feb 20 12:59:00 CST 2020
260.6 261.95284015224723 918
Thu Feb 20 13:00:00 CST 2020
260.59 261.9461734855806 918
Thu Feb 20 13:59:01 CST 2020
259.52 261.2328401522472 918
Thu Feb 20 14:00:00 CST 2020
259.3 261.08617348558056 918
Thu Feb 20 14:59:00 CST 2020
261.75 262.7195068189139 918
Thu Feb 20 15:00:00 CST 2020
261.97 262.8661734855806 918
Thu Feb 20 15:59:00 CST 2020
260.8 262.08617348558056 918
Thu Feb 20 16:00:01 CST 2020
261.0 262.2195068189139 918
Thu Feb 20 16:59:00 CST 2020
256.58 259.2728401522472 918
Thu Feb 20 17:00:00 CST 2020
256.95 259.5195068189139 918
Thu Feb 20 17:59:00 CST 2020
258.49 260.5461734855806 918
Thu Feb 20 18:00:00 CST 2020
258.51 260.5595068189139 918
Thu Feb 20 18:59:00 CST 2020
257.8 260.08617348558056 918
Thu Feb 20 19:00:00 CST 2020
257.82 260.0995068189139 918
Thu Feb 20 19:59:00 CST 2020
253.86 257.4595068189139 918
Thu Feb 20 20:00:00 CST 2020
253.43 257.17284015224726 918
Thu Feb 20 20:59:00 CST 2020
250.57 255.26617348558057 918
Thu Feb 20 21:00:00 CST 2020
250.43 255.17284015224723 918
Thu Feb 20 21:59:00 CST 2020
256.15 258.98617348558054 918
Thu Feb 20 22:00:00 CST 2020
256.04 258.91284015224727 918
Thu Feb 20 22:59:00 CST 2020
256.94 259.51284015224724 918
Thu Feb 20 23:00:00 CST 2020
257.25 259.7195068189139 918
Thu Feb 20 23:59:00 CST 2020
254.46 257.85950681891387 918
Fri Feb 21 00:00:00 CST 2020
254.92 258.1661734855806 918
Fri Feb 21 07:59:00 CST 2020
256.93 259.5061734855806 918
Fri Feb 21 08:00:00 CST 2020
256.93 257.7953911618602 919
Fri Feb 21 08:59:00 CST 2020
256.36 257.4153911618602 919
Fri Feb 21 09:00:00 CST 2020
256.05 257.2087244951935 919
Fri Feb 21 09:59:00 CST 2020
260.17 259.9553911618602 919
Fri Feb 21 10:00:00 CST 2020
260.37 260.0887244951935 919
Fri Feb 21 10:59:00 CST 2020
259.14 259.2687244951935 919
Fri Feb 21 11:00:00 CST 2020
259.15 259.27539116186017 919
Fri Feb 21 11:59:01 CST 2020
262.04 261.20205782852685 919
Fri Feb 21 12:00:00 CST 2020
262.06 261.21539116186017 919
Fri Feb 21 12:59:00 CST 2020
260.48 260.1620578285269 919
Fri Feb 21 13:00:00 CST 2020
260.77 260.35539116186015 919
Fri Feb 21 13:59:00 CST 2020
261.07 260.5553911618602 919
Fri Feb 21 14:00:00 CST 2020
260.94 260.4687244951935 919
Fri Feb 21 14:59:00 CST 2020
260.6 260.24205782852687 919
Fri Feb 21 15:00:00 CST 2020
260.64 260.2687244951935 919
Fri Feb 21 15:59:00 CST 2020
260.46 260.1487244951935 919
Fri Feb 21 16:00:00 CST 2020
260.16 259.9487244951935 919
Fri Feb 21 16:59:01 CST 2020
259.24 259.3353911618602 919
Fri Feb 21 17:00:00 CST 2020
258.77 259.02205782852684 919
Fri Feb 21 17:59:00 CST 2020
260.86 260.4153911618602 919
Fri Feb 21 18:00:01 CST 2020
260.64 260.2687244951935 919
Fri Feb 21 18:59:00 CST 2020
260.96 260.4820578285268 919
Fri Feb 21 19:00:00 CST 2020
260.65 260.27539116186017 919
Fri Feb 21 19:59:00 CST 2020
262.33 261.3953911618602 919
Fri Feb 21 20:00:00 CST 2020
261.81 261.04872449519354 919
Fri Feb 21 20:59:01 CST 2020
265.98 263.8287244951935 919
Fri Feb 21 21:00:00 CST 2020
265.78 263.6953911618602 919
Fri Feb 21 21:59:00 CST 2020
264.85 263.0753911618602 919
Fri Feb 21 22:00:01 CST 2020
264.93 263.1287244951935 919
Fri Feb 21 22:59:00 CST 2020
262.83 261.7287244951935 919
Fri Feb 21 23:00:00 CST 2020
262.6 261.5753911618602 919
Fri Feb 21 23:59:00 CST 2020
264.7 262.97539116186016 919
Sat Feb 22 00:00:00 CST 2020
265.2 263.30872449519353 919
Sat Feb 22 12:59:00 CST 2020
260.92 261.7317970539534 920
Sat Feb 22 13:00:00 CST 2020
260.79 261.64513038728677 920
Sat Feb 22 13:59:00 CST 2020
260.5 261.4517970539534 920
Sat Feb 22 14:00:00 CST 2020
260.53 261.47179705395337 920
Sat Feb 22 14:59:01 CST 2020
258.22 259.9317970539534 920
Sat Feb 22 15:00:00 CST 2020
257.98 259.7717970539534 920
Sat Feb 22 15:59:00 CST 2020
258.71 260.25846372062006 920
Sat Feb 22 16:00:00 CST 2020
258.2 259.9184637206201 920
Sat Feb 22 16:59:00 CST 2020
260.1 261.18513038728673 920
Sat Feb 22 17:00:00 CST 2020
260.5 261.4517970539534 920
Sat Feb 22 17:59:00 CST 2020
258.5 260.11846372062 920
Sat Feb 22 18:00:00 CST 2020
258.79 260.3117970539534 920
Sat Feb 22 19:59:01 CST 2020
261.88 262.37179705395334 920
Sat Feb 22 20:00:00 CST 2020
261.86 262.35846372062 920
Sat Feb 22 20:59:00 CST 2020
262.55 262.81846372062006 920
Sat Feb 22 21:00:01 CST 2020
262.43 262.7384637206201 920
Sat Feb 22 23:59:00 CST 2020
Traceback (most recent call last):
  File "/Library/Frameworks/Python.framework/Versions/3.8/lib/python3.8/site-packages/urllib3/connection.py", line 156, in _new_conn
    conn = connection.create_connection(
  File "/Library/Frameworks/Python.framework/Versions/3.8/lib/python3.8/site-packages/urllib3/util/connection.py", line 61, in create_connection
    for res in socket.getaddrinfo(host, port, family, socket.SOCK_STREAM):
  File "/Library/Frameworks/Python.framework/Versions/3.8/lib/python3.8/socket.py", line 914, in getaddrinfo
    for res in _socket.getaddrinfo(host, port, family, type, proto, flags):
socket.gaierror: [Errno 8] nodename nor servname provided, or not known

During handling of the above exception, another exception occurred:

Traceback (most recent call last):
  File "/Library/Frameworks/Python.framework/Versions/3.8/lib/python3.8/site-packages/urllib3/connectionpool.py", line 665, in urlopen
    httplib_response = self._make_request(
  File "/Library/Frameworks/Python.framework/Versions/3.8/lib/python3.8/site-packages/urllib3/connectionpool.py", line 376, in _make_request
    self._validate_conn(conn)
  File "/Library/Frameworks/Python.framework/Versions/3.8/lib/python3.8/site-packages/urllib3/connectionpool.py", line 994, in _validate_conn
    conn.connect()
  File "/Library/Frameworks/Python.framework/Versions/3.8/lib/python3.8/site-packages/urllib3/connection.py", line 334, in connect
    conn = self._new_conn()
  File "/Library/Frameworks/Python.framework/Versions/3.8/lib/python3.8/site-packages/urllib3/connection.py", line 168, in _new_conn
    raise NewConnectionError(
urllib3.exceptions.NewConnectionError: <urllib3.connection.VerifiedHTTPSConnection object at 0x1185073d0>: Failed to establish a new connection: [Errno 8] nodename nor servname provided, or not known

During handling of the above exception, another exception occurred:

Traceback (most recent call last):
  File "/Library/Frameworks/Python.framework/Versions/3.8/lib/python3.8/site-packages/requests/adapters.py", line 439, in send
    resp = conn.urlopen(
  File "/Library/Frameworks/Python.framework/Versions/3.8/lib/python3.8/site-packages/urllib3/connectionpool.py", line 719, in urlopen
    retries = retries.increment(
  File "/Library/Frameworks/Python.framework/Versions/3.8/lib/python3.8/site-packages/urllib3/util/retry.py", line 436, in increment
    raise MaxRetryError(_pool, url, error or ResponseError(cause))
urllib3.exceptions.MaxRetryError: HTTPSConnectionPool(host='api.binance.com', port=443): Max retries exceeded with url: /api/v1/ping (Caused by NewConnectionError('<urllib3.connection.VerifiedHTTPSConnection object at 0x1185073d0>: Failed to establish a new connection: [Errno 8] nodename nor servname provided, or not known'))

During handling of the above exception, another exception occurred:

Traceback (most recent call last):
  File "binance1.py", line 20, in <module>
    client = Client(api_key, api_secret)
  File "/Library/Frameworks/Python.framework/Versions/3.8/lib/python3.8/site-packages/binance/client.py", line 97, in __init__
    self.ping()
  File "/Library/Frameworks/Python.framework/Versions/3.8/lib/python3.8/site-packages/binance/client.py", line 378, in ping
    return self._get('ping')
  File "/Library/Frameworks/Python.framework/Versions/3.8/lib/python3.8/site-packages/binance/client.py", line 222, in _get
    return self._request_api('get', path, signed, version, **kwargs)
  File "/Library/Frameworks/Python.framework/Versions/3.8/lib/python3.8/site-packages/binance/client.py", line 191, in _request_api
    return self._request(method, uri, signed, **kwargs)
  File "/Library/Frameworks/Python.framework/Versions/3.8/lib/python3.8/site-packages/binance/client.py", line 185, in _request
    self.response = getattr(self.session, method)(uri, **kwargs)
  File "/Library/Frameworks/Python.framework/Versions/3.8/lib/python3.8/site-packages/requests/sessions.py", line 546, in get
    return self.request('GET', url, **kwargs)
  File "/Library/Frameworks/Python.framework/Versions/3.8/lib/python3.8/site-packages/requests/sessions.py", line 533, in request
    resp = self.send(prep, **send_kwargs)
  File "/Library/Frameworks/Python.framework/Versions/3.8/lib/python3.8/site-packages/requests/sessions.py", line 646, in send
    r = adapter.send(request, **kwargs)
  File "/Library/Frameworks/Python.framework/Versions/3.8/lib/python3.8/site-packages/requests/adapters.py", line 516, in send
    raise ConnectionError(e, request=request)
requests.exceptions.ConnectionError: HTTPSConnectionPool(host='api.binance.com', port=443): Max retries exceeded with url: /api/v1/ping (Caused by NewConnectionError('<urllib3.connection.VerifiedHTTPSConnection object at 0x1185073d0>: Failed to establish a new connection: [Errno 8] nodename nor servname provided, or not known'))
Traceback (most recent call last):
  File "email_price_notify.py", line 77, in <module>
    server = smtplib.SMTP('smtp.gmail.com', 587) 
  File "/Library/Frameworks/Python.framework/Versions/3.8/lib/python3.8/smtplib.py", line 253, in __init__
    (code, msg) = self.connect(host, port)
  File "/Library/Frameworks/Python.framework/Versions/3.8/lib/python3.8/smtplib.py", line 339, in connect
    self.sock = self._get_socket(host, port, self.timeout)
  File "/Library/Frameworks/Python.framework/Versions/3.8/lib/python3.8/smtplib.py", line 308, in _get_socket
    return socket.create_connection((host, port), timeout,
  File "/Library/Frameworks/Python.framework/Versions/3.8/lib/python3.8/socket.py", line 787, in create_connection
    for res in getaddrinfo(host, port, 0, SOCK_STREAM):
  File "/Library/Frameworks/Python.framework/Versions/3.8/lib/python3.8/socket.py", line 914, in getaddrinfo
    for res in _socket.getaddrinfo(host, port, family, type, proto, flags):
socket.gaierror: [Errno 8] nodename nor servname provided, or not known
Sun Feb 23 00:00:00 CST 2020
Traceback (most recent call last):
  File "/Library/Frameworks/Python.framework/Versions/3.8/lib/python3.8/site-packages/urllib3/connection.py", line 156, in _new_conn
    conn = connection.create_connection(
  File "/Library/Frameworks/Python.framework/Versions/3.8/lib/python3.8/site-packages/urllib3/util/connection.py", line 61, in create_connection
    for res in socket.getaddrinfo(host, port, family, socket.SOCK_STREAM):
  File "/Library/Frameworks/Python.framework/Versions/3.8/lib/python3.8/socket.py", line 914, in getaddrinfo
    for res in _socket.getaddrinfo(host, port, family, type, proto, flags):
socket.gaierror: [Errno 8] nodename nor servname provided, or not known

During handling of the above exception, another exception occurred:

Traceback (most recent call last):
  File "/Library/Frameworks/Python.framework/Versions/3.8/lib/python3.8/site-packages/urllib3/connectionpool.py", line 665, in urlopen
    httplib_response = self._make_request(
  File "/Library/Frameworks/Python.framework/Versions/3.8/lib/python3.8/site-packages/urllib3/connectionpool.py", line 376, in _make_request
    self._validate_conn(conn)
  File "/Library/Frameworks/Python.framework/Versions/3.8/lib/python3.8/site-packages/urllib3/connectionpool.py", line 994, in _validate_conn
    conn.connect()
  File "/Library/Frameworks/Python.framework/Versions/3.8/lib/python3.8/site-packages/urllib3/connection.py", line 334, in connect
    conn = self._new_conn()
  File "/Library/Frameworks/Python.framework/Versions/3.8/lib/python3.8/site-packages/urllib3/connection.py", line 168, in _new_conn
    raise NewConnectionError(
urllib3.exceptions.NewConnectionError: <urllib3.connection.VerifiedHTTPSConnection object at 0x1142a5340>: Failed to establish a new connection: [Errno 8] nodename nor servname provided, or not known

During handling of the above exception, another exception occurred:

Traceback (most recent call last):
  File "/Library/Frameworks/Python.framework/Versions/3.8/lib/python3.8/site-packages/requests/adapters.py", line 439, in send
    resp = conn.urlopen(
  File "/Library/Frameworks/Python.framework/Versions/3.8/lib/python3.8/site-packages/urllib3/connectionpool.py", line 719, in urlopen
    retries = retries.increment(
  File "/Library/Frameworks/Python.framework/Versions/3.8/lib/python3.8/site-packages/urllib3/util/retry.py", line 436, in increment
    raise MaxRetryError(_pool, url, error or ResponseError(cause))
urllib3.exceptions.MaxRetryError: HTTPSConnectionPool(host='api.binance.com', port=443): Max retries exceeded with url: /api/v1/ping (Caused by NewConnectionError('<urllib3.connection.VerifiedHTTPSConnection object at 0x1142a5340>: Failed to establish a new connection: [Errno 8] nodename nor servname provided, or not known'))

During handling of the above exception, another exception occurred:

Traceback (most recent call last):
  File "binance1.py", line 20, in <module>
    client = Client(api_key, api_secret)
  File "/Library/Frameworks/Python.framework/Versions/3.8/lib/python3.8/site-packages/binance/client.py", line 97, in __init__
    self.ping()
  File "/Library/Frameworks/Python.framework/Versions/3.8/lib/python3.8/site-packages/binance/client.py", line 378, in ping
    return self._get('ping')
  File "/Library/Frameworks/Python.framework/Versions/3.8/lib/python3.8/site-packages/binance/client.py", line 222, in _get
    return self._request_api('get', path, signed, version, **kwargs)
  File "/Library/Frameworks/Python.framework/Versions/3.8/lib/python3.8/site-packages/binance/client.py", line 191, in _request_api
    return self._request(method, uri, signed, **kwargs)
  File "/Library/Frameworks/Python.framework/Versions/3.8/lib/python3.8/site-packages/binance/client.py", line 185, in _request
    self.response = getattr(self.session, method)(uri, **kwargs)
  File "/Library/Frameworks/Python.framework/Versions/3.8/lib/python3.8/site-packages/requests/sessions.py", line 546, in get
    return self.request('GET', url, **kwargs)
  File "/Library/Frameworks/Python.framework/Versions/3.8/lib/python3.8/site-packages/requests/sessions.py", line 533, in request
    resp = self.send(prep, **send_kwargs)
  File "/Library/Frameworks/Python.framework/Versions/3.8/lib/python3.8/site-packages/requests/sessions.py", line 646, in send
    r = adapter.send(request, **kwargs)
  File "/Library/Frameworks/Python.framework/Versions/3.8/lib/python3.8/site-packages/requests/adapters.py", line 516, in send
    raise ConnectionError(e, request=request)
requests.exceptions.ConnectionError: HTTPSConnectionPool(host='api.binance.com', port=443): Max retries exceeded with url: /api/v1/ping (Caused by NewConnectionError('<urllib3.connection.VerifiedHTTPSConnection object at 0x1142a5340>: Failed to establish a new connection: [Errno 8] nodename nor servname provided, or not known'))
Traceback (most recent call last):
  File "email_price_notify.py", line 77, in <module>
    server = smtplib.SMTP('smtp.gmail.com', 587) 
  File "/Library/Frameworks/Python.framework/Versions/3.8/lib/python3.8/smtplib.py", line 253, in __init__
    (code, msg) = self.connect(host, port)
  File "/Library/Frameworks/Python.framework/Versions/3.8/lib/python3.8/smtplib.py", line 339, in connect
    self.sock = self._get_socket(host, port, self.timeout)
  File "/Library/Frameworks/Python.framework/Versions/3.8/lib/python3.8/smtplib.py", line 308, in _get_socket
    return socket.create_connection((host, port), timeout,
  File "/Library/Frameworks/Python.framework/Versions/3.8/lib/python3.8/socket.py", line 787, in create_connection
    for res in getaddrinfo(host, port, 0, SOCK_STREAM):
  File "/Library/Frameworks/Python.framework/Versions/3.8/lib/python3.8/socket.py", line 914, in getaddrinfo
    for res in _socket.getaddrinfo(host, port, family, type, proto, flags):
socket.gaierror: [Errno 8] nodename nor servname provided, or not known
Sun Feb 23 00:59:00 CST 2020
Traceback (most recent call last):
  File "/Library/Frameworks/Python.framework/Versions/3.8/lib/python3.8/site-packages/urllib3/connection.py", line 156, in _new_conn
    conn = connection.create_connection(
  File "/Library/Frameworks/Python.framework/Versions/3.8/lib/python3.8/site-packages/urllib3/util/connection.py", line 61, in create_connection
    for res in socket.getaddrinfo(host, port, family, socket.SOCK_STREAM):
  File "/Library/Frameworks/Python.framework/Versions/3.8/lib/python3.8/socket.py", line 914, in getaddrinfo
    for res in _socket.getaddrinfo(host, port, family, type, proto, flags):
socket.gaierror: [Errno 8] nodename nor servname provided, or not known

During handling of the above exception, another exception occurred:

Traceback (most recent call last):
  File "/Library/Frameworks/Python.framework/Versions/3.8/lib/python3.8/site-packages/urllib3/connectionpool.py", line 665, in urlopen
    httplib_response = self._make_request(
  File "/Library/Frameworks/Python.framework/Versions/3.8/lib/python3.8/site-packages/urllib3/connectionpool.py", line 376, in _make_request
    self._validate_conn(conn)
  File "/Library/Frameworks/Python.framework/Versions/3.8/lib/python3.8/site-packages/urllib3/connectionpool.py", line 994, in _validate_conn
    conn.connect()
  File "/Library/Frameworks/Python.framework/Versions/3.8/lib/python3.8/site-packages/urllib3/connection.py", line 334, in connect
    conn = self._new_conn()
  File "/Library/Frameworks/Python.framework/Versions/3.8/lib/python3.8/site-packages/urllib3/connection.py", line 168, in _new_conn
    raise NewConnectionError(
urllib3.exceptions.NewConnectionError: <urllib3.connection.VerifiedHTTPSConnection object at 0x111fef3d0>: Failed to establish a new connection: [Errno 8] nodename nor servname provided, or not known

During handling of the above exception, another exception occurred:

Traceback (most recent call last):
  File "/Library/Frameworks/Python.framework/Versions/3.8/lib/python3.8/site-packages/requests/adapters.py", line 439, in send
    resp = conn.urlopen(
  File "/Library/Frameworks/Python.framework/Versions/3.8/lib/python3.8/site-packages/urllib3/connectionpool.py", line 719, in urlopen
    retries = retries.increment(
  File "/Library/Frameworks/Python.framework/Versions/3.8/lib/python3.8/site-packages/urllib3/util/retry.py", line 436, in increment
    raise MaxRetryError(_pool, url, error or ResponseError(cause))
urllib3.exceptions.MaxRetryError: HTTPSConnectionPool(host='api.binance.com', port=443): Max retries exceeded with url: /api/v1/ping (Caused by NewConnectionError('<urllib3.connection.VerifiedHTTPSConnection object at 0x111fef3d0>: Failed to establish a new connection: [Errno 8] nodename nor servname provided, or not known'))

During handling of the above exception, another exception occurred:

Traceback (most recent call last):
  File "binance1.py", line 20, in <module>
    client = Client(api_key, api_secret)
  File "/Library/Frameworks/Python.framework/Versions/3.8/lib/python3.8/site-packages/binance/client.py", line 97, in __init__
    self.ping()
  File "/Library/Frameworks/Python.framework/Versions/3.8/lib/python3.8/site-packages/binance/client.py", line 378, in ping
    return self._get('ping')
  File "/Library/Frameworks/Python.framework/Versions/3.8/lib/python3.8/site-packages/binance/client.py", line 222, in _get
    return self._request_api('get', path, signed, version, **kwargs)
  File "/Library/Frameworks/Python.framework/Versions/3.8/lib/python3.8/site-packages/binance/client.py", line 191, in _request_api
    return self._request(method, uri, signed, **kwargs)
  File "/Library/Frameworks/Python.framework/Versions/3.8/lib/python3.8/site-packages/binance/client.py", line 185, in _request
    self.response = getattr(self.session, method)(uri, **kwargs)
  File "/Library/Frameworks/Python.framework/Versions/3.8/lib/python3.8/site-packages/requests/sessions.py", line 546, in get
    return self.request('GET', url, **kwargs)
  File "/Library/Frameworks/Python.framework/Versions/3.8/lib/python3.8/site-packages/requests/sessions.py", line 533, in request
    resp = self.send(prep, **send_kwargs)
  File "/Library/Frameworks/Python.framework/Versions/3.8/lib/python3.8/site-packages/requests/sessions.py", line 646, in send
    r = adapter.send(request, **kwargs)
  File "/Library/Frameworks/Python.framework/Versions/3.8/lib/python3.8/site-packages/requests/adapters.py", line 516, in send
    raise ConnectionError(e, request=request)
requests.exceptions.ConnectionError: HTTPSConnectionPool(host='api.binance.com', port=443): Max retries exceeded with url: /api/v1/ping (Caused by NewConnectionError('<urllib3.connection.VerifiedHTTPSConnection object at 0x111fef3d0>: Failed to establish a new connection: [Errno 8] nodename nor servname provided, or not known'))
Traceback (most recent call last):
  File "email_price_notify.py", line 77, in <module>
    server = smtplib.SMTP('smtp.gmail.com', 587) 
  File "/Library/Frameworks/Python.framework/Versions/3.8/lib/python3.8/smtplib.py", line 253, in __init__
    (code, msg) = self.connect(host, port)
  File "/Library/Frameworks/Python.framework/Versions/3.8/lib/python3.8/smtplib.py", line 339, in connect
    self.sock = self._get_socket(host, port, self.timeout)
  File "/Library/Frameworks/Python.framework/Versions/3.8/lib/python3.8/smtplib.py", line 308, in _get_socket
    return socket.create_connection((host, port), timeout,
  File "/Library/Frameworks/Python.framework/Versions/3.8/lib/python3.8/socket.py", line 787, in create_connection
    for res in getaddrinfo(host, port, 0, SOCK_STREAM):
  File "/Library/Frameworks/Python.framework/Versions/3.8/lib/python3.8/socket.py", line 914, in getaddrinfo
    for res in _socket.getaddrinfo(host, port, family, type, proto, flags):
socket.gaierror: [Errno 8] nodename nor servname provided, or not known
Sun Feb 23 01:00:01 CST 2020
Traceback (most recent call last):
  File "/Library/Frameworks/Python.framework/Versions/3.8/lib/python3.8/site-packages/urllib3/connection.py", line 156, in _new_conn
    conn = connection.create_connection(
  File "/Library/Frameworks/Python.framework/Versions/3.8/lib/python3.8/site-packages/urllib3/util/connection.py", line 61, in create_connection
    for res in socket.getaddrinfo(host, port, family, socket.SOCK_STREAM):
  File "/Library/Frameworks/Python.framework/Versions/3.8/lib/python3.8/socket.py", line 914, in getaddrinfo
    for res in _socket.getaddrinfo(host, port, family, type, proto, flags):
socket.gaierror: [Errno 8] nodename nor servname provided, or not known

During handling of the above exception, another exception occurred:

Traceback (most recent call last):
  File "/Library/Frameworks/Python.framework/Versions/3.8/lib/python3.8/site-packages/urllib3/connectionpool.py", line 665, in urlopen
    httplib_response = self._make_request(
  File "/Library/Frameworks/Python.framework/Versions/3.8/lib/python3.8/site-packages/urllib3/connectionpool.py", line 376, in _make_request
    self._validate_conn(conn)
  File "/Library/Frameworks/Python.framework/Versions/3.8/lib/python3.8/site-packages/urllib3/connectionpool.py", line 994, in _validate_conn
    conn.connect()
  File "/Library/Frameworks/Python.framework/Versions/3.8/lib/python3.8/site-packages/urllib3/connection.py", line 334, in connect
    conn = self._new_conn()
  File "/Library/Frameworks/Python.framework/Versions/3.8/lib/python3.8/site-packages/urllib3/connection.py", line 168, in _new_conn
    raise NewConnectionError(
urllib3.exceptions.NewConnectionError: <urllib3.connection.VerifiedHTTPSConnection object at 0x115b993d0>: Failed to establish a new connection: [Errno 8] nodename nor servname provided, or not known

During handling of the above exception, another exception occurred:

Traceback (most recent call last):
  File "/Library/Frameworks/Python.framework/Versions/3.8/lib/python3.8/site-packages/requests/adapters.py", line 439, in send
    resp = conn.urlopen(
  File "/Library/Frameworks/Python.framework/Versions/3.8/lib/python3.8/site-packages/urllib3/connectionpool.py", line 719, in urlopen
    retries = retries.increment(
  File "/Library/Frameworks/Python.framework/Versions/3.8/lib/python3.8/site-packages/urllib3/util/retry.py", line 436, in increment
    raise MaxRetryError(_pool, url, error or ResponseError(cause))
urllib3.exceptions.MaxRetryError: HTTPSConnectionPool(host='api.binance.com', port=443): Max retries exceeded with url: /api/v1/ping (Caused by NewConnectionError('<urllib3.connection.VerifiedHTTPSConnection object at 0x115b993d0>: Failed to establish a new connection: [Errno 8] nodename nor servname provided, or not known'))

During handling of the above exception, another exception occurred:

Traceback (most recent call last):
  File "binance1.py", line 20, in <module>
    client = Client(api_key, api_secret)
  File "/Library/Frameworks/Python.framework/Versions/3.8/lib/python3.8/site-packages/binance/client.py", line 97, in __init__
    self.ping()
  File "/Library/Frameworks/Python.framework/Versions/3.8/lib/python3.8/site-packages/binance/client.py", line 378, in ping
    return self._get('ping')
  File "/Library/Frameworks/Python.framework/Versions/3.8/lib/python3.8/site-packages/binance/client.py", line 222, in _get
    return self._request_api('get', path, signed, version, **kwargs)
  File "/Library/Frameworks/Python.framework/Versions/3.8/lib/python3.8/site-packages/binance/client.py", line 191, in _request_api
    return self._request(method, uri, signed, **kwargs)
  File "/Library/Frameworks/Python.framework/Versions/3.8/lib/python3.8/site-packages/binance/client.py", line 185, in _request
    self.response = getattr(self.session, method)(uri, **kwargs)
  File "/Library/Frameworks/Python.framework/Versions/3.8/lib/python3.8/site-packages/requests/sessions.py", line 546, in get
    return self.request('GET', url, **kwargs)
  File "/Library/Frameworks/Python.framework/Versions/3.8/lib/python3.8/site-packages/requests/sessions.py", line 533, in request
    resp = self.send(prep, **send_kwargs)
  File "/Library/Frameworks/Python.framework/Versions/3.8/lib/python3.8/site-packages/requests/sessions.py", line 646, in send
    r = adapter.send(request, **kwargs)
  File "/Library/Frameworks/Python.framework/Versions/3.8/lib/python3.8/site-packages/requests/adapters.py", line 516, in send
    raise ConnectionError(e, request=request)
requests.exceptions.ConnectionError: HTTPSConnectionPool(host='api.binance.com', port=443): Max retries exceeded with url: /api/v1/ping (Caused by NewConnectionError('<urllib3.connection.VerifiedHTTPSConnection object at 0x115b993d0>: Failed to establish a new connection: [Errno 8] nodename nor servname provided, or not known'))
Traceback (most recent call last):
  File "email_price_notify.py", line 77, in <module>
    server = smtplib.SMTP('smtp.gmail.com', 587) 
  File "/Library/Frameworks/Python.framework/Versions/3.8/lib/python3.8/smtplib.py", line 253, in __init__
    (code, msg) = self.connect(host, port)
  File "/Library/Frameworks/Python.framework/Versions/3.8/lib/python3.8/smtplib.py", line 339, in connect
    self.sock = self._get_socket(host, port, self.timeout)
  File "/Library/Frameworks/Python.framework/Versions/3.8/lib/python3.8/smtplib.py", line 308, in _get_socket
    return socket.create_connection((host, port), timeout,
  File "/Library/Frameworks/Python.framework/Versions/3.8/lib/python3.8/socket.py", line 787, in create_connection
    for res in getaddrinfo(host, port, 0, SOCK_STREAM):
  File "/Library/Frameworks/Python.framework/Versions/3.8/lib/python3.8/socket.py", line 914, in getaddrinfo
    for res in _socket.getaddrinfo(host, port, family, type, proto, flags):
socket.gaierror: [Errno 8] nodename nor servname provided, or not known
Sun Feb 23 04:59:00 CST 2020
261.51 262.1251303872867 920
Sun Feb 23 05:00:00 CST 2020
261.51 262.1251303872867 920
Sun Feb 23 05:59:00 CST 2020
262.29 262.64513038728677 920
Sun Feb 23 06:00:00 CST 2020
262.93 263.0717970539534 920
Sun Feb 23 06:59:00 CST 2020
261.98 262.43846372062006 920
Sun Feb 23 07:00:00 CST 2020
261.88 262.37179705395334 920
Sun Feb 23 07:59:00 CST 2020
261.62 262.19846372062005 920
Sun Feb 23 08:00:00 CST 2020
261.55 261.7550434624289 921
Sun Feb 23 08:59:00 CST 2020
263.14 262.81504346242895 921
Sun Feb 23 09:00:00 CST 2020
263.47 263.035043462429 921
Sun Feb 23 09:59:00 CST 2020
261.73 261.87504346242895 921
Sun Feb 23 10:00:00 CST 2020
262.0 262.05504346242896 921
Sun Feb 23 12:59:00 CST 2020
266.29 264.9150434624289 921
Sun Feb 23 13:00:00 CST 2020
266.25 264.88837679576227 921
Sun Feb 23 13:59:00 CST 2020
268.74 266.5483767957623 921
Sun Feb 23 14:00:00 CST 2020
268.76 266.5617101290956 921
Sun Feb 23 14:59:00 CST 2020
271.26 268.22837679576224 921
Sun Feb 23 15:00:00 CST 2020
271.13 268.1417101290956 921
Sun Feb 23 15:59:00 CST 2020
270.04 267.4150434624289 921
Sun Feb 23 16:00:00 CST 2020
270.28 267.57504346242894 921
Sun Feb 23 16:59:00 CST 2020
270.77 267.9017101290956 921
Sun Feb 23 17:00:00 CST 2020
270.89 267.9817101290956 921
Sun Feb 23 22:59:00 CST 2020
272.13 268.8083767957623 921
Sun Feb 23 23:00:00 CST 2020
272.06 268.76171012909555 921
Sun Feb 23 23:59:01 CST 2020
269.6 267.1217101290956 921
Mon Feb 24 00:00:00 CST 2020
269.99 267.3817101290956 921
Mon Feb 24 08:59:00 CST 2020
275.37 273.7050144874763 922
Mon Feb 24 09:00:01 CST 2020
275.91 274.06501448747633 922
Mon Feb 24 09:59:00 CST 2020
272.56 271.831681154143 922
Mon Feb 24 10:00:00 CST 2020
272.19 271.5850144874763 922
Mon Feb 24 10:59:00 CST 2020
268.54 269.151681154143 922
Mon Feb 24 11:00:00 CST 2020
268.15 268.891681154143 922
Mon Feb 24 11:59:00 CST 2020
268.04 268.81834782080966 922
Mon Feb 24 12:00:00 CST 2020
267.94 268.751681154143 922
Mon Feb 24 12:59:00 CST 2020
267.67 268.571681154143 922
Mon Feb 24 13:00:00 CST 2020
267.62 268.53834782080963 922
Mon Feb 24 13:59:00 CST 2020
268.51 269.131681154143 922
Mon Feb 24 14:00:00 CST 2020
268.62 269.2050144874763 922
Mon Feb 24 14:59:00 CST 2020
266.78 267.97834782080963 922
Mon Feb 24 15:00:00 CST 2020
266.81 267.99834782080967 922
Mon Feb 24 15:59:00 CST 2020
267.46 268.43168115414295 922
Mon Feb 24 16:00:00 CST 2020
267.6 268.5250144874763 922
Mon Feb 24 16:59:00 CST 2020
268.05 268.8250144874763 922
Mon Feb 24 17:00:01 CST 2020
267.72 268.60501448747635 922
Mon Feb 24 17:59:01 CST 2020
266.1 267.5250144874763 922
Mon Feb 24 18:00:00 CST 2020
266.3 267.65834782080964 922
Mon Feb 24 18:59:00 CST 2020
267.46 268.43168115414295 922
Mon Feb 24 19:00:00 CST 2020
267.29 268.31834782080966 922
Mon Feb 24 19:59:00 CST 2020
271.44 271.0850144874763 922
Mon Feb 24 20:00:01 CST 2020
271.87 271.371681154143 922
Mon Feb 24 20:59:00 CST 2020
270.74 270.6183478208097 922
Mon Feb 24 21:00:00 CST 2020
270.73 270.611681154143 922
Mon Feb 24 21:59:00 CST 2020
269.3 269.65834782080964 922
Mon Feb 24 22:00:00 CST 2020
268.93 269.41168115414297 922
Mon Feb 24 22:59:01 CST 2020
268.89 269.3850144874763 922
Mon Feb 24 23:00:00 CST 2020
268.75 269.29168115414296 922
Mon Feb 24 23:59:00 CST 2020
267.37 268.371681154143 922
Tue Feb 25 00:00:00 CST 2020
267.55 268.491681154143 922
Tue Feb 25 21:59:00 CST 2020
258.95 261.6794492736032 923
Tue Feb 25 22:00:00 CST 2020
259.0 261.71278260693657 923
Wed Feb 26 08:59:00 CST 2020
246.81 249.0375942023122 924
Wed Feb 26 09:00:00 CST 2020
246.86 249.07092753564552 924
Wed Feb 26 09:59:01 CST 2020
240.62 244.91092753564553 924
Wed Feb 26 10:00:01 CST 2020
239.8 244.36426086897885 924
Wed Feb 26 10:59:00 CST 2020
240.02 244.5109275356455 924
Wed Feb 26 11:00:00 CST 2020
240.12 244.57759420231218 924
Wed Feb 26 11:59:00 CST 2020
239.15 243.9309275356455 924
Wed Feb 26 12:00:00 CST 2020
238.9 243.76426086897882 924
Wed Feb 26 12:59:01 CST 2020
240.72 244.9775942023122 924
Wed Feb 26 13:00:00 CST 2020
240.61 244.90426086897887 924
Wed Feb 26 13:59:00 CST 2020
240.81 245.0375942023122 924
Wed Feb 26 14:00:01 CST 2020
240.84 245.0575942023122 924
Wed Feb 26 14:59:00 CST 2020
242.14 245.92426086897885 924
Wed Feb 26 15:00:00 CST 2020
241.78 245.68426086897884 924
Wed Feb 26 15:59:00 CST 2020
238.11 243.23759420231218 924
Wed Feb 26 16:00:00 CST 2020
237.95 243.1309275356455 924
Wed Feb 26 16:59:00 CST 2020
238.61 243.57092753564552 924
Wed Feb 26 17:00:01 CST 2020
238.66 243.60426086897883 924
Wed Feb 26 17:59:00 CST 2020
236.15 241.9309275356455 924
Wed Feb 26 18:00:00 CST 2020
235.37 241.41092753564553 924
Wed Feb 26 18:59:00 CST 2020
237.89 243.0909275356455 924
Wed Feb 26 19:00:01 CST 2020
237.69 242.95759420231218 924
Wed Feb 26 19:59:00 CST 2020
235.62 241.57759420231218 924
Wed Feb 26 20:00:00 CST 2020
235.64 241.5909275356455 924
Wed Feb 26 20:59:00 CST 2020
240.43 244.78426086897886 924
Wed Feb 26 21:00:00 CST 2020
240.98 245.15092753564554 924
Wed Feb 26 21:59:00 CST 2020
234.01 240.50426086897883 924
Wed Feb 26 22:00:01 CST 2020
234.32 240.7109275356455 924
Wed Feb 26 22:59:00 CST 2020
231.23 238.65092753564554 924
Wed Feb 26 23:00:00 CST 2020
231.52 238.84426086897884 924
Wed Feb 26 23:59:00 CST 2020
226.7 235.6309275356455 924
Thu Feb 27 00:00:00 CST 2020
226.53 235.51759420231215 924
Thu Feb 27 20:59:00 CST 2020
226.46 228.90142028965963 925
Thu Feb 27 21:00:00 CST 2020
226.96 229.23475362299294 925
Thu Feb 27 21:59:00 CST 2020
229.01 230.60142028965961 925
Thu Feb 27 22:00:00 CST 2020
228.95 230.56142028965962 925
Thu Feb 27 22:59:01 CST 2020
230.21 231.40142028965963 925
Thu Feb 27 23:00:00 CST 2020
229.9 231.19475362299295 925
Thu Feb 27 23:59:00 CST 2020
230.76 231.7680869563263 925
Fri Feb 28 00:00:00 CST 2020
231.05 231.96142028965963 925
Fri Feb 28 00:59:00 CST 2020
236.32 235.47475362299295 925
Fri Feb 28 01:00:00 CST 2020
236.35 235.49475362299293 925
Fri Feb 28 01:59:00 CST 2020
236.1 235.32808695632627 925
Fri Feb 28 02:00:00 CST 2020
235.8 235.1280869563263 925
Fri Feb 28 12:59:00 CST 2020
229.51 229.60269565210876 926
Fri Feb 28 13:00:00 CST 2020
228.95 229.22936231877543 926
Fri Feb 28 15:59:00 CST 2020
223.77 225.77602898544208 926
Fri Feb 28 16:00:00 CST 2020
224.04 225.9560289854421 926
