213.21 208.40348714884007 904
213.36 208.5034871488401 904
214.04 208.9568204821734 904
213.28 208.45015381550675 904
213.15 208.3634871488401 904
212.79 208.1234871488401 904
212.88 208.18348714884007 904
213.22 208.41015381550673 904
213.41 208.53682048217343 904
218.66 215.23671793850224 905
218.57 215.17671793850226 905
217.55 214.49671793850226 905
217.83 214.68338460516892 905
221.62 217.2100512718356 905
221.6 217.19671793850225 905
220.21 219.5900170906119 906
220.39 219.71001709061184 906
225.65 223.2166837572785 906
225.11 222.85668375727855 906
224.39 222.37668375727853 906
224.65 222.55001709061185 906
226.27 223.63001709061186 906
226.3 223.65001709061187 906
225.17 222.8966837572785 906
225.36 223.0233504239452 906
Traceback (most recent call last):
  File "/Library/Frameworks/Python.framework/Versions/3.8/lib/python3.8/site-packages/urllib3/connection.py", line 156, in _new_conn
    conn = connection.create_connection(
  File "/Library/Frameworks/Python.framework/Versions/3.8/lib/python3.8/site-packages/urllib3/util/connection.py", line 61, in create_connection
    for res in socket.getaddrinfo(host, port, family, socket.SOCK_STREAM):
  File "/Library/Frameworks/Python.framework/Versions/3.8/lib/python3.8/socket.py", line 914, in getaddrinfo
    for res in _socket.getaddrinfo(host, port, family, type, proto, flags):
socket.gaierror: [Errno 8] nodename nor servname provided, or not known

During handling of the above exception, another exception occurred:

Traceback (most recent call last):
  File "/Library/Frameworks/Python.framework/Versions/3.8/lib/python3.8/site-packages/urllib3/connectionpool.py", line 665, in urlopen
    httplib_response = self._make_request(
  File "/Library/Frameworks/Python.framework/Versions/3.8/lib/python3.8/site-packages/urllib3/connectionpool.py", line 376, in _make_request
    self._validate_conn(conn)
  File "/Library/Frameworks/Python.framework/Versions/3.8/lib/python3.8/site-packages/urllib3/connectionpool.py", line 994, in _validate_conn
    conn.connect()
  File "/Library/Frameworks/Python.framework/Versions/3.8/lib/python3.8/site-packages/urllib3/connection.py", line 334, in connect
    conn = self._new_conn()
  File "/Library/Frameworks/Python.framework/Versions/3.8/lib/python3.8/site-packages/urllib3/connection.py", line 168, in _new_conn
    raise NewConnectionError(
urllib3.exceptions.NewConnectionError: <urllib3.connection.VerifiedHTTPSConnection object at 0x11197c370>: Failed to establish a new connection: [Errno 8] nodename nor servname provided, or not known

During handling of the above exception, another exception occurred:

Traceback (most recent call last):
  File "/Library/Frameworks/Python.framework/Versions/3.8/lib/python3.8/site-packages/requests/adapters.py", line 439, in send
    resp = conn.urlopen(
  File "/Library/Frameworks/Python.framework/Versions/3.8/lib/python3.8/site-packages/urllib3/connectionpool.py", line 719, in urlopen
    retries = retries.increment(
  File "/Library/Frameworks/Python.framework/Versions/3.8/lib/python3.8/site-packages/urllib3/util/retry.py", line 436, in increment
    raise MaxRetryError(_pool, url, error or ResponseError(cause))
urllib3.exceptions.MaxRetryError: HTTPSConnectionPool(host='api.binance.com', port=443): Max retries exceeded with url: /api/v1/ping (Caused by NewConnectionError('<urllib3.connection.VerifiedHTTPSConnection object at 0x11197c370>: Failed to establish a new connection: [Errno 8] nodename nor servname provided, or not known'))

During handling of the above exception, another exception occurred:

Traceback (most recent call last):
  File "binance1.py", line 20, in <module>
    client = Client(api_key, api_secret)
  File "/Library/Frameworks/Python.framework/Versions/3.8/lib/python3.8/site-packages/binance/client.py", line 97, in __init__
    self.ping()
  File "/Library/Frameworks/Python.framework/Versions/3.8/lib/python3.8/site-packages/binance/client.py", line 378, in ping
    return self._get('ping')
  File "/Library/Frameworks/Python.framework/Versions/3.8/lib/python3.8/site-packages/binance/client.py", line 222, in _get
    return self._request_api('get', path, signed, version, **kwargs)
  File "/Library/Frameworks/Python.framework/Versions/3.8/lib/python3.8/site-packages/binance/client.py", line 191, in _request_api
    return self._request(method, uri, signed, **kwargs)
  File "/Library/Frameworks/Python.framework/Versions/3.8/lib/python3.8/site-packages/binance/client.py", line 185, in _request
    self.response = getattr(self.session, method)(uri, **kwargs)
  File "/Library/Frameworks/Python.framework/Versions/3.8/lib/python3.8/site-packages/requests/sessions.py", line 546, in get
    return self.request('GET', url, **kwargs)
  File "/Library/Frameworks/Python.framework/Versions/3.8/lib/python3.8/site-packages/requests/sessions.py", line 533, in request
    resp = self.send(prep, **send_kwargs)
  File "/Library/Frameworks/Python.framework/Versions/3.8/lib/python3.8/site-packages/requests/sessions.py", line 646, in send
    r = adapter.send(request, **kwargs)
  File "/Library/Frameworks/Python.framework/Versions/3.8/lib/python3.8/site-packages/requests/adapters.py", line 516, in send
    raise ConnectionError(e, request=request)
requests.exceptions.ConnectionError: HTTPSConnectionPool(host='api.binance.com', port=443): Max retries exceeded with url: /api/v1/ping (Caused by NewConnectionError('<urllib3.connection.VerifiedHTTPSConnection object at 0x11197c370>: Failed to establish a new connection: [Errno 8] nodename nor servname provided, or not known'))
Traceback (most recent call last):
  File "email_price_notify.py", line 77, in <module>
    server = smtplib.SMTP('smtp.gmail.com', 587) 
  File "/Library/Frameworks/Python.framework/Versions/3.8/lib/python3.8/smtplib.py", line 253, in __init__
    (code, msg) = self.connect(host, port)
  File "/Library/Frameworks/Python.framework/Versions/3.8/lib/python3.8/smtplib.py", line 339, in connect
    self.sock = self._get_socket(host, port, self.timeout)
  File "/Library/Frameworks/Python.framework/Versions/3.8/lib/python3.8/smtplib.py", line 308, in _get_socket
    return socket.create_connection((host, port), timeout,
  File "/Library/Frameworks/Python.framework/Versions/3.8/lib/python3.8/socket.py", line 787, in create_connection
    for res in getaddrinfo(host, port, 0, SOCK_STREAM):
  File "/Library/Frameworks/Python.framework/Versions/3.8/lib/python3.8/socket.py", line 914, in getaddrinfo
    for res in _socket.getaddrinfo(host, port, family, type, proto, flags):
socket.gaierror: [Errno 8] nodename nor servname provided, or not known
Traceback (most recent call last):
  File "/Library/Frameworks/Python.framework/Versions/3.8/lib/python3.8/site-packages/urllib3/connection.py", line 156, in _new_conn
    conn = connection.create_connection(
  File "/Library/Frameworks/Python.framework/Versions/3.8/lib/python3.8/site-packages/urllib3/util/connection.py", line 61, in create_connection
    for res in socket.getaddrinfo(host, port, family, socket.SOCK_STREAM):
  File "/Library/Frameworks/Python.framework/Versions/3.8/lib/python3.8/socket.py", line 914, in getaddrinfo
    for res in _socket.getaddrinfo(host, port, family, type, proto, flags):
socket.gaierror: [Errno 8] nodename nor servname provided, or not known

During handling of the above exception, another exception occurred:

Traceback (most recent call last):
  File "/Library/Frameworks/Python.framework/Versions/3.8/lib/python3.8/site-packages/urllib3/connectionpool.py", line 665, in urlopen
    httplib_response = self._make_request(
  File "/Library/Frameworks/Python.framework/Versions/3.8/lib/python3.8/site-packages/urllib3/connectionpool.py", line 376, in _make_request
    self._validate_conn(conn)
  File "/Library/Frameworks/Python.framework/Versions/3.8/lib/python3.8/site-packages/urllib3/connectionpool.py", line 994, in _validate_conn
    conn.connect()
  File "/Library/Frameworks/Python.framework/Versions/3.8/lib/python3.8/site-packages/urllib3/connection.py", line 334, in connect
    conn = self._new_conn()
  File "/Library/Frameworks/Python.framework/Versions/3.8/lib/python3.8/site-packages/urllib3/connection.py", line 168, in _new_conn
    raise NewConnectionError(
urllib3.exceptions.NewConnectionError: <urllib3.connection.VerifiedHTTPSConnection object at 0x1116723d0>: Failed to establish a new connection: [Errno 8] nodename nor servname provided, or not known

During handling of the above exception, another exception occurred:

Traceback (most recent call last):
  File "/Library/Frameworks/Python.framework/Versions/3.8/lib/python3.8/site-packages/requests/adapters.py", line 439, in send
    resp = conn.urlopen(
  File "/Library/Frameworks/Python.framework/Versions/3.8/lib/python3.8/site-packages/urllib3/connectionpool.py", line 719, in urlopen
    retries = retries.increment(
  File "/Library/Frameworks/Python.framework/Versions/3.8/lib/python3.8/site-packages/urllib3/util/retry.py", line 436, in increment
    raise MaxRetryError(_pool, url, error or ResponseError(cause))
urllib3.exceptions.MaxRetryError: HTTPSConnectionPool(host='api.binance.com', port=443): Max retries exceeded with url: /api/v1/ping (Caused by NewConnectionError('<urllib3.connection.VerifiedHTTPSConnection object at 0x1116723d0>: Failed to establish a new connection: [Errno 8] nodename nor servname provided, or not known'))

During handling of the above exception, another exception occurred:

Traceback (most recent call last):
  File "binance1.py", line 20, in <module>
    client = Client(api_key, api_secret)
  File "/Library/Frameworks/Python.framework/Versions/3.8/lib/python3.8/site-packages/binance/client.py", line 97, in __init__
    self.ping()
  File "/Library/Frameworks/Python.framework/Versions/3.8/lib/python3.8/site-packages/binance/client.py", line 378, in ping
    return self._get('ping')
  File "/Library/Frameworks/Python.framework/Versions/3.8/lib/python3.8/site-packages/binance/client.py", line 222, in _get
    return self._request_api('get', path, signed, version, **kwargs)
  File "/Library/Frameworks/Python.framework/Versions/3.8/lib/python3.8/site-packages/binance/client.py", line 191, in _request_api
    return self._request(method, uri, signed, **kwargs)
  File "/Library/Frameworks/Python.framework/Versions/3.8/lib/python3.8/site-packages/binance/client.py", line 185, in _request
    self.response = getattr(self.session, method)(uri, **kwargs)
  File "/Library/Frameworks/Python.framework/Versions/3.8/lib/python3.8/site-packages/requests/sessions.py", line 546, in get
    return self.request('GET', url, **kwargs)
  File "/Library/Frameworks/Python.framework/Versions/3.8/lib/python3.8/site-packages/requests/sessions.py", line 533, in request
    resp = self.send(prep, **send_kwargs)
  File "/Library/Frameworks/Python.framework/Versions/3.8/lib/python3.8/site-packages/requests/sessions.py", line 646, in send
    r = adapter.send(request, **kwargs)
  File "/Library/Frameworks/Python.framework/Versions/3.8/lib/python3.8/site-packages/requests/adapters.py", line 516, in send
    raise ConnectionError(e, request=request)
requests.exceptions.ConnectionError: HTTPSConnectionPool(host='api.binance.com', port=443): Max retries exceeded with url: /api/v1/ping (Caused by NewConnectionError('<urllib3.connection.VerifiedHTTPSConnection object at 0x1116723d0>: Failed to establish a new connection: [Errno 8] nodename nor servname provided, or not known'))
Traceback (most recent call last):
  File "email_price_notify.py", line 77, in <module>
    server = smtplib.SMTP('smtp.gmail.com', 587) 
  File "/Library/Frameworks/Python.framework/Versions/3.8/lib/python3.8/smtplib.py", line 253, in __init__
    (code, msg) = self.connect(host, port)
  File "/Library/Frameworks/Python.framework/Versions/3.8/lib/python3.8/smtplib.py", line 339, in connect
    self.sock = self._get_socket(host, port, self.timeout)
  File "/Library/Frameworks/Python.framework/Versions/3.8/lib/python3.8/smtplib.py", line 308, in _get_socket
    return socket.create_connection((host, port), timeout,
  File "/Library/Frameworks/Python.framework/Versions/3.8/lib/python3.8/socket.py", line 787, in create_connection
    for res in getaddrinfo(host, port, 0, SOCK_STREAM):
  File "/Library/Frameworks/Python.framework/Versions/3.8/lib/python3.8/socket.py", line 914, in getaddrinfo
    for res in _socket.getaddrinfo(host, port, family, type, proto, flags):
socket.gaierror: [Errno 8] nodename nor servname provided, or not known
Traceback (most recent call last):
  File "/Library/Frameworks/Python.framework/Versions/3.8/lib/python3.8/site-packages/urllib3/connection.py", line 156, in _new_conn
    conn = connection.create_connection(
  File "/Library/Frameworks/Python.framework/Versions/3.8/lib/python3.8/site-packages/urllib3/util/connection.py", line 61, in create_connection
    for res in socket.getaddrinfo(host, port, family, socket.SOCK_STREAM):
  File "/Library/Frameworks/Python.framework/Versions/3.8/lib/python3.8/socket.py", line 914, in getaddrinfo
    for res in _socket.getaddrinfo(host, port, family, type, proto, flags):
socket.gaierror: [Errno 8] nodename nor servname provided, or not known

During handling of the above exception, another exception occurred:

Traceback (most recent call last):
  File "/Library/Frameworks/Python.framework/Versions/3.8/lib/python3.8/site-packages/urllib3/connectionpool.py", line 665, in urlopen
    httplib_response = self._make_request(
  File "/Library/Frameworks/Python.framework/Versions/3.8/lib/python3.8/site-packages/urllib3/connectionpool.py", line 376, in _make_request
    self._validate_conn(conn)
  File "/Library/Frameworks/Python.framework/Versions/3.8/lib/python3.8/site-packages/urllib3/connectionpool.py", line 994, in _validate_conn
    conn.connect()
  File "/Library/Frameworks/Python.framework/Versions/3.8/lib/python3.8/site-packages/urllib3/connection.py", line 334, in connect
    conn = self._new_conn()
  File "/Library/Frameworks/Python.framework/Versions/3.8/lib/python3.8/site-packages/urllib3/connection.py", line 168, in _new_conn
    raise NewConnectionError(
urllib3.exceptions.NewConnectionError: <urllib3.connection.VerifiedHTTPSConnection object at 0x115ffe3d0>: Failed to establish a new connection: [Errno 8] nodename nor servname provided, or not known

During handling of the above exception, another exception occurred:

Traceback (most recent call last):
  File "/Library/Frameworks/Python.framework/Versions/3.8/lib/python3.8/site-packages/requests/adapters.py", line 439, in send
    resp = conn.urlopen(
  File "/Library/Frameworks/Python.framework/Versions/3.8/lib/python3.8/site-packages/urllib3/connectionpool.py", line 719, in urlopen
    retries = retries.increment(
  File "/Library/Frameworks/Python.framework/Versions/3.8/lib/python3.8/site-packages/urllib3/util/retry.py", line 436, in increment
    raise MaxRetryError(_pool, url, error or ResponseError(cause))
urllib3.exceptions.MaxRetryError: HTTPSConnectionPool(host='api.binance.com', port=443): Max retries exceeded with url: /api/v1/ping (Caused by NewConnectionError('<urllib3.connection.VerifiedHTTPSConnection object at 0x115ffe3d0>: Failed to establish a new connection: [Errno 8] nodename nor servname provided, or not known'))

During handling of the above exception, another exception occurred:

Traceback (most recent call last):
  File "binance1.py", line 20, in <module>
    client = Client(api_key, api_secret)
  File "/Library/Frameworks/Python.framework/Versions/3.8/lib/python3.8/site-packages/binance/client.py", line 97, in __init__
    self.ping()
  File "/Library/Frameworks/Python.framework/Versions/3.8/lib/python3.8/site-packages/binance/client.py", line 378, in ping
    return self._get('ping')
  File "/Library/Frameworks/Python.framework/Versions/3.8/lib/python3.8/site-packages/binance/client.py", line 222, in _get
    return self._request_api('get', path, signed, version, **kwargs)
  File "/Library/Frameworks/Python.framework/Versions/3.8/lib/python3.8/site-packages/binance/client.py", line 191, in _request_api
    return self._request(method, uri, signed, **kwargs)
  File "/Library/Frameworks/Python.framework/Versions/3.8/lib/python3.8/site-packages/binance/client.py", line 185, in _request
    self.response = getattr(self.session, method)(uri, **kwargs)
  File "/Library/Frameworks/Python.framework/Versions/3.8/lib/python3.8/site-packages/requests/sessions.py", line 546, in get
    return self.request('GET', url, **kwargs)
  File "/Library/Frameworks/Python.framework/Versions/3.8/lib/python3.8/site-packages/requests/sessions.py", line 533, in request
    resp = self.send(prep, **send_kwargs)
  File "/Library/Frameworks/Python.framework/Versions/3.8/lib/python3.8/site-packages/requests/sessions.py", line 646, in send
    r = adapter.send(request, **kwargs)
  File "/Library/Frameworks/Python.framework/Versions/3.8/lib/python3.8/site-packages/requests/adapters.py", line 516, in send
    raise ConnectionError(e, request=request)
requests.exceptions.ConnectionError: HTTPSConnectionPool(host='api.binance.com', port=443): Max retries exceeded with url: /api/v1/ping (Caused by NewConnectionError('<urllib3.connection.VerifiedHTTPSConnection object at 0x115ffe3d0>: Failed to establish a new connection: [Errno 8] nodename nor servname provided, or not known'))
Traceback (most recent call last):
  File "email_price_notify.py", line 77, in <module>
    server = smtplib.SMTP('smtp.gmail.com', 587) 
  File "/Library/Frameworks/Python.framework/Versions/3.8/lib/python3.8/smtplib.py", line 253, in __init__
    (code, msg) = self.connect(host, port)
  File "/Library/Frameworks/Python.framework/Versions/3.8/lib/python3.8/smtplib.py", line 339, in connect
    self.sock = self._get_socket(host, port, self.timeout)
  File "/Library/Frameworks/Python.framework/Versions/3.8/lib/python3.8/smtplib.py", line 308, in _get_socket
    return socket.create_connection((host, port), timeout,
  File "/Library/Frameworks/Python.framework/Versions/3.8/lib/python3.8/socket.py", line 787, in create_connection
    for res in getaddrinfo(host, port, 0, SOCK_STREAM):
  File "/Library/Frameworks/Python.framework/Versions/3.8/lib/python3.8/socket.py", line 914, in getaddrinfo
    for res in _socket.getaddrinfo(host, port, family, type, proto, flags):
socket.gaierror: [Errno 8] nodename nor servname provided, or not known
Traceback (most recent call last):
  File "/Library/Frameworks/Python.framework/Versions/3.8/lib/python3.8/site-packages/urllib3/connection.py", line 156, in _new_conn
    conn = connection.create_connection(
  File "/Library/Frameworks/Python.framework/Versions/3.8/lib/python3.8/site-packages/urllib3/util/connection.py", line 61, in create_connection
    for res in socket.getaddrinfo(host, port, family, socket.SOCK_STREAM):
  File "/Library/Frameworks/Python.framework/Versions/3.8/lib/python3.8/socket.py", line 914, in getaddrinfo
    for res in _socket.getaddrinfo(host, port, family, type, proto, flags):
socket.gaierror: [Errno 8] nodename nor servname provided, or not known

During handling of the above exception, another exception occurred:

Traceback (most recent call last):
  File "/Library/Frameworks/Python.framework/Versions/3.8/lib/python3.8/site-packages/urllib3/connectionpool.py", line 665, in urlopen
    httplib_response = self._make_request(
  File "/Library/Frameworks/Python.framework/Versions/3.8/lib/python3.8/site-packages/urllib3/connectionpool.py", line 376, in _make_request
    self._validate_conn(conn)
  File "/Library/Frameworks/Python.framework/Versions/3.8/lib/python3.8/site-packages/urllib3/connectionpool.py", line 994, in _validate_conn
    conn.connect()
  File "/Library/Frameworks/Python.framework/Versions/3.8/lib/python3.8/site-packages/urllib3/connection.py", line 334, in connect
    conn = self._new_conn()
  File "/Library/Frameworks/Python.framework/Versions/3.8/lib/python3.8/site-packages/urllib3/connection.py", line 168, in _new_conn
    raise NewConnectionError(
urllib3.exceptions.NewConnectionError: <urllib3.connection.VerifiedHTTPSConnection object at 0x118fe9400>: Failed to establish a new connection: [Errno 8] nodename nor servname provided, or not known

During handling of the above exception, another exception occurred:

Traceback (most recent call last):
  File "/Library/Frameworks/Python.framework/Versions/3.8/lib/python3.8/site-packages/requests/adapters.py", line 439, in send
    resp = conn.urlopen(
  File "/Library/Frameworks/Python.framework/Versions/3.8/lib/python3.8/site-packages/urllib3/connectionpool.py", line 719, in urlopen
    retries = retries.increment(
  File "/Library/Frameworks/Python.framework/Versions/3.8/lib/python3.8/site-packages/urllib3/util/retry.py", line 436, in increment
    raise MaxRetryError(_pool, url, error or ResponseError(cause))
urllib3.exceptions.MaxRetryError: HTTPSConnectionPool(host='api.binance.com', port=443): Max retries exceeded with url: /api/v1/ping (Caused by NewConnectionError('<urllib3.connection.VerifiedHTTPSConnection object at 0x118fe9400>: Failed to establish a new connection: [Errno 8] nodename nor servname provided, or not known'))

During handling of the above exception, another exception occurred:

Traceback (most recent call last):
  File "binance1.py", line 20, in <module>
    client = Client(api_key, api_secret)
  File "/Library/Frameworks/Python.framework/Versions/3.8/lib/python3.8/site-packages/binance/client.py", line 97, in __init__
    self.ping()
  File "/Library/Frameworks/Python.framework/Versions/3.8/lib/python3.8/site-packages/binance/client.py", line 378, in ping
    return self._get('ping')
  File "/Library/Frameworks/Python.framework/Versions/3.8/lib/python3.8/site-packages/binance/client.py", line 222, in _get
    return self._request_api('get', path, signed, version, **kwargs)
  File "/Library/Frameworks/Python.framework/Versions/3.8/lib/python3.8/site-packages/binance/client.py", line 191, in _request_api
    return self._request(method, uri, signed, **kwargs)
  File "/Library/Frameworks/Python.framework/Versions/3.8/lib/python3.8/site-packages/binance/client.py", line 185, in _request
    self.response = getattr(self.session, method)(uri, **kwargs)
  File "/Library/Frameworks/Python.framework/Versions/3.8/lib/python3.8/site-packages/requests/sessions.py", line 546, in get
    return self.request('GET', url, **kwargs)
  File "/Library/Frameworks/Python.framework/Versions/3.8/lib/python3.8/site-packages/requests/sessions.py", line 533, in request
    resp = self.send(prep, **send_kwargs)
  File "/Library/Frameworks/Python.framework/Versions/3.8/lib/python3.8/site-packages/requests/sessions.py", line 646, in send
    r = adapter.send(request, **kwargs)
  File "/Library/Frameworks/Python.framework/Versions/3.8/lib/python3.8/site-packages/requests/adapters.py", line 516, in send
    raise ConnectionError(e, request=request)
requests.exceptions.ConnectionError: HTTPSConnectionPool(host='api.binance.com', port=443): Max retries exceeded with url: /api/v1/ping (Caused by NewConnectionError('<urllib3.connection.VerifiedHTTPSConnection object at 0x118fe9400>: Failed to establish a new connection: [Errno 8] nodename nor servname provided, or not known'))
Traceback (most recent call last):
  File "email_price_notify.py", line 77, in <module>
    server = smtplib.SMTP('smtp.gmail.com', 587) 
  File "/Library/Frameworks/Python.framework/Versions/3.8/lib/python3.8/smtplib.py", line 253, in __init__
    (code, msg) = self.connect(host, port)
  File "/Library/Frameworks/Python.framework/Versions/3.8/lib/python3.8/smtplib.py", line 339, in connect
    self.sock = self._get_socket(host, port, self.timeout)
  File "/Library/Frameworks/Python.framework/Versions/3.8/lib/python3.8/smtplib.py", line 308, in _get_socket
    return socket.create_connection((host, port), timeout,
  File "/Library/Frameworks/Python.framework/Versions/3.8/lib/python3.8/socket.py", line 787, in create_connection
    for res in getaddrinfo(host, port, 0, SOCK_STREAM):
  File "/Library/Frameworks/Python.framework/Versions/3.8/lib/python3.8/socket.py", line 914, in getaddrinfo
    for res in _socket.getaddrinfo(host, port, family, type, proto, flags):
socket.gaierror: [Errno 8] nodename nor servname provided, or not known
Traceback (most recent call last):
  File "/Library/Frameworks/Python.framework/Versions/3.8/lib/python3.8/site-packages/urllib3/connection.py", line 156, in _new_conn
    conn = connection.create_connection(
  File "/Library/Frameworks/Python.framework/Versions/3.8/lib/python3.8/site-packages/urllib3/util/connection.py", line 61, in create_connection
    for res in socket.getaddrinfo(host, port, family, socket.SOCK_STREAM):
  File "/Library/Frameworks/Python.framework/Versions/3.8/lib/python3.8/socket.py", line 914, in getaddrinfo
    for res in _socket.getaddrinfo(host, port, family, type, proto, flags):
socket.gaierror: [Errno 8] nodename nor servname provided, or not known

During handling of the above exception, another exception occurred:

Traceback (most recent call last):
  File "/Library/Frameworks/Python.framework/Versions/3.8/lib/python3.8/site-packages/urllib3/connectionpool.py", line 665, in urlopen
    httplib_response = self._make_request(
  File "/Library/Frameworks/Python.framework/Versions/3.8/lib/python3.8/site-packages/urllib3/connectionpool.py", line 376, in _make_request
    self._validate_conn(conn)
  File "/Library/Frameworks/Python.framework/Versions/3.8/lib/python3.8/site-packages/urllib3/connectionpool.py", line 994, in _validate_conn
    conn.connect()
  File "/Library/Frameworks/Python.framework/Versions/3.8/lib/python3.8/site-packages/urllib3/connection.py", line 334, in connect
    conn = self._new_conn()
  File "/Library/Frameworks/Python.framework/Versions/3.8/lib/python3.8/site-packages/urllib3/connection.py", line 168, in _new_conn
    raise NewConnectionError(
urllib3.exceptions.NewConnectionError: <urllib3.connection.VerifiedHTTPSConnection object at 0x113a4b370>: Failed to establish a new connection: [Errno 8] nodename nor servname provided, or not known

During handling of the above exception, another exception occurred:

Traceback (most recent call last):
  File "/Library/Frameworks/Python.framework/Versions/3.8/lib/python3.8/site-packages/requests/adapters.py", line 439, in send
    resp = conn.urlopen(
  File "/Library/Frameworks/Python.framework/Versions/3.8/lib/python3.8/site-packages/urllib3/connectionpool.py", line 719, in urlopen
    retries = retries.increment(
  File "/Library/Frameworks/Python.framework/Versions/3.8/lib/python3.8/site-packages/urllib3/util/retry.py", line 436, in increment
    raise MaxRetryError(_pool, url, error or ResponseError(cause))
urllib3.exceptions.MaxRetryError: HTTPSConnectionPool(host='api.binance.com', port=443): Max retries exceeded with url: /api/v1/ping (Caused by NewConnectionError('<urllib3.connection.VerifiedHTTPSConnection object at 0x113a4b370>: Failed to establish a new connection: [Errno 8] nodename nor servname provided, or not known'))

During handling of the above exception, another exception occurred:

Traceback (most recent call last):
  File "binance1.py", line 20, in <module>
    client = Client(api_key, api_secret)
  File "/Library/Frameworks/Python.framework/Versions/3.8/lib/python3.8/site-packages/binance/client.py", line 97, in __init__
    self.ping()
  File "/Library/Frameworks/Python.framework/Versions/3.8/lib/python3.8/site-packages/binance/client.py", line 378, in ping
    return self._get('ping')
  File "/Library/Frameworks/Python.framework/Versions/3.8/lib/python3.8/site-packages/binance/client.py", line 222, in _get
    return self._request_api('get', path, signed, version, **kwargs)
  File "/Library/Frameworks/Python.framework/Versions/3.8/lib/python3.8/site-packages/binance/client.py", line 191, in _request_api
    return self._request(method, uri, signed, **kwargs)
  File "/Library/Frameworks/Python.framework/Versions/3.8/lib/python3.8/site-packages/binance/client.py", line 185, in _request
    self.response = getattr(self.session, method)(uri, **kwargs)
  File "/Library/Frameworks/Python.framework/Versions/3.8/lib/python3.8/site-packages/requests/sessions.py", line 546, in get
    return self.request('GET', url, **kwargs)
  File "/Library/Frameworks/Python.framework/Versions/3.8/lib/python3.8/site-packages/requests/sessions.py", line 533, in request
    resp = self.send(prep, **send_kwargs)
  File "/Library/Frameworks/Python.framework/Versions/3.8/lib/python3.8/site-packages/requests/sessions.py", line 646, in send
    r = adapter.send(request, **kwargs)
  File "/Library/Frameworks/Python.framework/Versions/3.8/lib/python3.8/site-packages/requests/adapters.py", line 516, in send
    raise ConnectionError(e, request=request)
requests.exceptions.ConnectionError: HTTPSConnectionPool(host='api.binance.com', port=443): Max retries exceeded with url: /api/v1/ping (Caused by NewConnectionError('<urllib3.connection.VerifiedHTTPSConnection object at 0x113a4b370>: Failed to establish a new connection: [Errno 8] nodename nor servname provided, or not known'))
Traceback (most recent call last):
  File "email_price_notify.py", line 77, in <module>
    server = smtplib.SMTP('smtp.gmail.com', 587) 
  File "/Library/Frameworks/Python.framework/Versions/3.8/lib/python3.8/smtplib.py", line 253, in __init__
    (code, msg) = self.connect(host, port)
  File "/Library/Frameworks/Python.framework/Versions/3.8/lib/python3.8/smtplib.py", line 339, in connect
    self.sock = self._get_socket(host, port, self.timeout)
  File "/Library/Frameworks/Python.framework/Versions/3.8/lib/python3.8/smtplib.py", line 308, in _get_socket
    return socket.create_connection((host, port), timeout,
  File "/Library/Frameworks/Python.framework/Versions/3.8/lib/python3.8/socket.py", line 787, in create_connection
    for res in getaddrinfo(host, port, 0, SOCK_STREAM):
  File "/Library/Frameworks/Python.framework/Versions/3.8/lib/python3.8/socket.py", line 914, in getaddrinfo
    for res in _socket.getaddrinfo(host, port, family, type, proto, flags):
socket.gaierror: [Errno 8] nodename nor servname provided, or not known
Traceback (most recent call last):
  File "/Library/Frameworks/Python.framework/Versions/3.8/lib/python3.8/site-packages/urllib3/connection.py", line 156, in _new_conn
    conn = connection.create_connection(
  File "/Library/Frameworks/Python.framework/Versions/3.8/lib/python3.8/site-packages/urllib3/util/connection.py", line 61, in create_connection
    for res in socket.getaddrinfo(host, port, family, socket.SOCK_STREAM):
  File "/Library/Frameworks/Python.framework/Versions/3.8/lib/python3.8/socket.py", line 914, in getaddrinfo
    for res in _socket.getaddrinfo(host, port, family, type, proto, flags):
socket.gaierror: [Errno 8] nodename nor servname provided, or not known

During handling of the above exception, another exception occurred:

Traceback (most recent call last):
  File "/Library/Frameworks/Python.framework/Versions/3.8/lib/python3.8/site-packages/urllib3/connectionpool.py", line 665, in urlopen
    httplib_response = self._make_request(
  File "/Library/Frameworks/Python.framework/Versions/3.8/lib/python3.8/site-packages/urllib3/connectionpool.py", line 376, in _make_request
    self._validate_conn(conn)
  File "/Library/Frameworks/Python.framework/Versions/3.8/lib/python3.8/site-packages/urllib3/connectionpool.py", line 994, in _validate_conn
    conn.connect()
  File "/Library/Frameworks/Python.framework/Versions/3.8/lib/python3.8/site-packages/urllib3/connection.py", line 334, in connect
    conn = self._new_conn()
  File "/Library/Frameworks/Python.framework/Versions/3.8/lib/python3.8/site-packages/urllib3/connection.py", line 168, in _new_conn
    raise NewConnectionError(
urllib3.exceptions.NewConnectionError: <urllib3.connection.VerifiedHTTPSConnection object at 0x117338400>: Failed to establish a new connection: [Errno 8] nodename nor servname provided, or not known

During handling of the above exception, another exception occurred:

Traceback (most recent call last):
  File "/Library/Frameworks/Python.framework/Versions/3.8/lib/python3.8/site-packages/requests/adapters.py", line 439, in send
    resp = conn.urlopen(
  File "/Library/Frameworks/Python.framework/Versions/3.8/lib/python3.8/site-packages/urllib3/connectionpool.py", line 719, in urlopen
    retries = retries.increment(
  File "/Library/Frameworks/Python.framework/Versions/3.8/lib/python3.8/site-packages/urllib3/util/retry.py", line 436, in increment
    raise MaxRetryError(_pool, url, error or ResponseError(cause))
urllib3.exceptions.MaxRetryError: HTTPSConnectionPool(host='api.binance.com', port=443): Max retries exceeded with url: /api/v1/ping (Caused by NewConnectionError('<urllib3.connection.VerifiedHTTPSConnection object at 0x117338400>: Failed to establish a new connection: [Errno 8] nodename nor servname provided, or not known'))

During handling of the above exception, another exception occurred:

Traceback (most recent call last):
  File "binance1.py", line 20, in <module>
    client = Client(api_key, api_secret)
  File "/Library/Frameworks/Python.framework/Versions/3.8/lib/python3.8/site-packages/binance/client.py", line 97, in __init__
    self.ping()
  File "/Library/Frameworks/Python.framework/Versions/3.8/lib/python3.8/site-packages/binance/client.py", line 378, in ping
    return self._get('ping')
  File "/Library/Frameworks/Python.framework/Versions/3.8/lib/python3.8/site-packages/binance/client.py", line 222, in _get
    return self._request_api('get', path, signed, version, **kwargs)
  File "/Library/Frameworks/Python.framework/Versions/3.8/lib/python3.8/site-packages/binance/client.py", line 191, in _request_api
    return self._request(method, uri, signed, **kwargs)
  File "/Library/Frameworks/Python.framework/Versions/3.8/lib/python3.8/site-packages/binance/client.py", line 185, in _request
    self.response = getattr(self.session, method)(uri, **kwargs)
  File "/Library/Frameworks/Python.framework/Versions/3.8/lib/python3.8/site-packages/requests/sessions.py", line 546, in get
    return self.request('GET', url, **kwargs)
  File "/Library/Frameworks/Python.framework/Versions/3.8/lib/python3.8/site-packages/requests/sessions.py", line 533, in request
    resp = self.send(prep, **send_kwargs)
  File "/Library/Frameworks/Python.framework/Versions/3.8/lib/python3.8/site-packages/requests/sessions.py", line 646, in send
    r = adapter.send(request, **kwargs)
  File "/Library/Frameworks/Python.framework/Versions/3.8/lib/python3.8/site-packages/requests/adapters.py", line 516, in send
    raise ConnectionError(e, request=request)
requests.exceptions.ConnectionError: HTTPSConnectionPool(host='api.binance.com', port=443): Max retries exceeded with url: /api/v1/ping (Caused by NewConnectionError('<urllib3.connection.VerifiedHTTPSConnection object at 0x117338400>: Failed to establish a new connection: [Errno 8] nodename nor servname provided, or not known'))
Traceback (most recent call last):
  File "email_price_notify.py", line 77, in <module>
    server = smtplib.SMTP('smtp.gmail.com', 587) 
  File "/Library/Frameworks/Python.framework/Versions/3.8/lib/python3.8/smtplib.py", line 253, in __init__
    (code, msg) = self.connect(host, port)
  File "/Library/Frameworks/Python.framework/Versions/3.8/lib/python3.8/smtplib.py", line 339, in connect
    self.sock = self._get_socket(host, port, self.timeout)
  File "/Library/Frameworks/Python.framework/Versions/3.8/lib/python3.8/smtplib.py", line 308, in _get_socket
    return socket.create_connection((host, port), timeout,
  File "/Library/Frameworks/Python.framework/Versions/3.8/lib/python3.8/socket.py", line 787, in create_connection
    for res in getaddrinfo(host, port, 0, SOCK_STREAM):
  File "/Library/Frameworks/Python.framework/Versions/3.8/lib/python3.8/socket.py", line 914, in getaddrinfo
    for res in _socket.getaddrinfo(host, port, family, type, proto, flags):
socket.gaierror: [Errno 8] nodename nor servname provided, or not known
Traceback (most recent call last):
  File "/Library/Frameworks/Python.framework/Versions/3.8/lib/python3.8/site-packages/urllib3/connection.py", line 156, in _new_conn
    conn = connection.create_connection(
  File "/Library/Frameworks/Python.framework/Versions/3.8/lib/python3.8/site-packages/urllib3/util/connection.py", line 61, in create_connection
    for res in socket.getaddrinfo(host, port, family, socket.SOCK_STREAM):
  File "/Library/Frameworks/Python.framework/Versions/3.8/lib/python3.8/socket.py", line 914, in getaddrinfo
    for res in _socket.getaddrinfo(host, port, family, type, proto, flags):
socket.gaierror: [Errno 8] nodename nor servname provided, or not known

During handling of the above exception, another exception occurred:

Traceback (most recent call last):
  File "/Library/Frameworks/Python.framework/Versions/3.8/lib/python3.8/site-packages/urllib3/connectionpool.py", line 665, in urlopen
    httplib_response = self._make_request(
  File "/Library/Frameworks/Python.framework/Versions/3.8/lib/python3.8/site-packages/urllib3/connectionpool.py", line 376, in _make_request
    self._validate_conn(conn)
  File "/Library/Frameworks/Python.framework/Versions/3.8/lib/python3.8/site-packages/urllib3/connectionpool.py", line 994, in _validate_conn
    conn.connect()
  File "/Library/Frameworks/Python.framework/Versions/3.8/lib/python3.8/site-packages/urllib3/connection.py", line 334, in connect
    conn = self._new_conn()
  File "/Library/Frameworks/Python.framework/Versions/3.8/lib/python3.8/site-packages/urllib3/connection.py", line 168, in _new_conn
    raise NewConnectionError(
urllib3.exceptions.NewConnectionError: <urllib3.connection.VerifiedHTTPSConnection object at 0x11aaf83d0>: Failed to establish a new connection: [Errno 8] nodename nor servname provided, or not known

During handling of the above exception, another exception occurred:

Traceback (most recent call last):
  File "/Library/Frameworks/Python.framework/Versions/3.8/lib/python3.8/site-packages/requests/adapters.py", line 439, in send
    resp = conn.urlopen(
  File "/Library/Frameworks/Python.framework/Versions/3.8/lib/python3.8/site-packages/urllib3/connectionpool.py", line 719, in urlopen
    retries = retries.increment(
  File "/Library/Frameworks/Python.framework/Versions/3.8/lib/python3.8/site-packages/urllib3/util/retry.py", line 436, in increment
    raise MaxRetryError(_pool, url, error or ResponseError(cause))
urllib3.exceptions.MaxRetryError: HTTPSConnectionPool(host='api.binance.com', port=443): Max retries exceeded with url: /api/v1/ping (Caused by NewConnectionError('<urllib3.connection.VerifiedHTTPSConnection object at 0x11aaf83d0>: Failed to establish a new connection: [Errno 8] nodename nor servname provided, or not known'))

During handling of the above exception, another exception occurred:

Traceback (most recent call last):
  File "binance1.py", line 20, in <module>
    client = Client(api_key, api_secret)
  File "/Library/Frameworks/Python.framework/Versions/3.8/lib/python3.8/site-packages/binance/client.py", line 97, in __init__
    self.ping()
  File "/Library/Frameworks/Python.framework/Versions/3.8/lib/python3.8/site-packages/binance/client.py", line 378, in ping
    return self._get('ping')
  File "/Library/Frameworks/Python.framework/Versions/3.8/lib/python3.8/site-packages/binance/client.py", line 222, in _get
    return self._request_api('get', path, signed, version, **kwargs)
  File "/Library/Frameworks/Python.framework/Versions/3.8/lib/python3.8/site-packages/binance/client.py", line 191, in _request_api
    return self._request(method, uri, signed, **kwargs)
  File "/Library/Frameworks/Python.framework/Versions/3.8/lib/python3.8/site-packages/binance/client.py", line 185, in _request
    self.response = getattr(self.session, method)(uri, **kwargs)
  File "/Library/Frameworks/Python.framework/Versions/3.8/lib/python3.8/site-packages/requests/sessions.py", line 546, in get
    return self.request('GET', url, **kwargs)
  File "/Library/Frameworks/Python.framework/Versions/3.8/lib/python3.8/site-packages/requests/sessions.py", line 533, in request
    resp = self.send(prep, **send_kwargs)
  File "/Library/Frameworks/Python.framework/Versions/3.8/lib/python3.8/site-packages/requests/sessions.py", line 646, in send
    r = adapter.send(request, **kwargs)
  File "/Library/Frameworks/Python.framework/Versions/3.8/lib/python3.8/site-packages/requests/adapters.py", line 516, in send
    raise ConnectionError(e, request=request)
requests.exceptions.ConnectionError: HTTPSConnectionPool(host='api.binance.com', port=443): Max retries exceeded with url: /api/v1/ping (Caused by NewConnectionError('<urllib3.connection.VerifiedHTTPSConnection object at 0x11aaf83d0>: Failed to establish a new connection: [Errno 8] nodename nor servname provided, or not known'))
Traceback (most recent call last):
  File "email_price_notify.py", line 77, in <module>
    server = smtplib.SMTP('smtp.gmail.com', 587) 
  File "/Library/Frameworks/Python.framework/Versions/3.8/lib/python3.8/smtplib.py", line 253, in __init__
    (code, msg) = self.connect(host, port)
  File "/Library/Frameworks/Python.framework/Versions/3.8/lib/python3.8/smtplib.py", line 339, in connect
    self.sock = self._get_socket(host, port, self.timeout)
  File "/Library/Frameworks/Python.framework/Versions/3.8/lib/python3.8/smtplib.py", line 308, in _get_socket
    return socket.create_connection((host, port), timeout,
  File "/Library/Frameworks/Python.framework/Versions/3.8/lib/python3.8/socket.py", line 787, in create_connection
    for res in getaddrinfo(host, port, 0, SOCK_STREAM):
  File "/Library/Frameworks/Python.framework/Versions/3.8/lib/python3.8/socket.py", line 914, in getaddrinfo
    for res in _socket.getaddrinfo(host, port, family, type, proto, flags):
socket.gaierror: [Errno 8] nodename nor servname provided, or not known
Traceback (most recent call last):
  File "/Library/Frameworks/Python.framework/Versions/3.8/lib/python3.8/site-packages/urllib3/connection.py", line 156, in _new_conn
    conn = connection.create_connection(
  File "/Library/Frameworks/Python.framework/Versions/3.8/lib/python3.8/site-packages/urllib3/util/connection.py", line 61, in create_connection
    for res in socket.getaddrinfo(host, port, family, socket.SOCK_STREAM):
  File "/Library/Frameworks/Python.framework/Versions/3.8/lib/python3.8/socket.py", line 914, in getaddrinfo
    for res in _socket.getaddrinfo(host, port, family, type, proto, flags):
socket.gaierror: [Errno 8] nodename nor servname provided, or not known

During handling of the above exception, another exception occurred:

Traceback (most recent call last):
  File "/Library/Frameworks/Python.framework/Versions/3.8/lib/python3.8/site-packages/urllib3/connectionpool.py", line 665, in urlopen
    httplib_response = self._make_request(
  File "/Library/Frameworks/Python.framework/Versions/3.8/lib/python3.8/site-packages/urllib3/connectionpool.py", line 376, in _make_request
    self._validate_conn(conn)
  File "/Library/Frameworks/Python.framework/Versions/3.8/lib/python3.8/site-packages/urllib3/connectionpool.py", line 994, in _validate_conn
    conn.connect()
  File "/Library/Frameworks/Python.framework/Versions/3.8/lib/python3.8/site-packages/urllib3/connection.py", line 334, in connect
    conn = self._new_conn()
  File "/Library/Frameworks/Python.framework/Versions/3.8/lib/python3.8/site-packages/urllib3/connection.py", line 168, in _new_conn
    raise NewConnectionError(
urllib3.exceptions.NewConnectionError: <urllib3.connection.VerifiedHTTPSConnection object at 0x113ba3370>: Failed to establish a new connection: [Errno 8] nodename nor servname provided, or not known

During handling of the above exception, another exception occurred:

Traceback (most recent call last):
  File "/Library/Frameworks/Python.framework/Versions/3.8/lib/python3.8/site-packages/requests/adapters.py", line 439, in send
    resp = conn.urlopen(
  File "/Library/Frameworks/Python.framework/Versions/3.8/lib/python3.8/site-packages/urllib3/connectionpool.py", line 719, in urlopen
    retries = retries.increment(
  File "/Library/Frameworks/Python.framework/Versions/3.8/lib/python3.8/site-packages/urllib3/util/retry.py", line 436, in increment
    raise MaxRetryError(_pool, url, error or ResponseError(cause))
urllib3.exceptions.MaxRetryError: HTTPSConnectionPool(host='api.binance.com', port=443): Max retries exceeded with url: /api/v1/ping (Caused by NewConnectionError('<urllib3.connection.VerifiedHTTPSConnection object at 0x113ba3370>: Failed to establish a new connection: [Errno 8] nodename nor servname provided, or not known'))

During handling of the above exception, another exception occurred:

Traceback (most recent call last):
  File "binance1.py", line 20, in <module>
    client = Client(api_key, api_secret)
  File "/Library/Frameworks/Python.framework/Versions/3.8/lib/python3.8/site-packages/binance/client.py", line 97, in __init__
    self.ping()
  File "/Library/Frameworks/Python.framework/Versions/3.8/lib/python3.8/site-packages/binance/client.py", line 378, in ping
    return self._get('ping')
  File "/Library/Frameworks/Python.framework/Versions/3.8/lib/python3.8/site-packages/binance/client.py", line 222, in _get
    return self._request_api('get', path, signed, version, **kwargs)
  File "/Library/Frameworks/Python.framework/Versions/3.8/lib/python3.8/site-packages/binance/client.py", line 191, in _request_api
    return self._request(method, uri, signed, **kwargs)
  File "/Library/Frameworks/Python.framework/Versions/3.8/lib/python3.8/site-packages/binance/client.py", line 185, in _request
    self.response = getattr(self.session, method)(uri, **kwargs)
  File "/Library/Frameworks/Python.framework/Versions/3.8/lib/python3.8/site-packages/requests/sessions.py", line 546, in get
    return self.request('GET', url, **kwargs)
  File "/Library/Frameworks/Python.framework/Versions/3.8/lib/python3.8/site-packages/requests/sessions.py", line 533, in request
    resp = self.send(prep, **send_kwargs)
  File "/Library/Frameworks/Python.framework/Versions/3.8/lib/python3.8/site-packages/requests/sessions.py", line 646, in send
    r = adapter.send(request, **kwargs)
  File "/Library/Frameworks/Python.framework/Versions/3.8/lib/python3.8/site-packages/requests/adapters.py", line 516, in send
    raise ConnectionError(e, request=request)
requests.exceptions.ConnectionError: HTTPSConnectionPool(host='api.binance.com', port=443): Max retries exceeded with url: /api/v1/ping (Caused by NewConnectionError('<urllib3.connection.VerifiedHTTPSConnection object at 0x113ba3370>: Failed to establish a new connection: [Errno 8] nodename nor servname provided, or not known'))
Traceback (most recent call last):
  File "email_price_notify.py", line 77, in <module>
    server = smtplib.SMTP('smtp.gmail.com', 587) 
  File "/Library/Frameworks/Python.framework/Versions/3.8/lib/python3.8/smtplib.py", line 253, in __init__
    (code, msg) = self.connect(host, port)
  File "/Library/Frameworks/Python.framework/Versions/3.8/lib/python3.8/smtplib.py", line 339, in connect
    self.sock = self._get_socket(host, port, self.timeout)
  File "/Library/Frameworks/Python.framework/Versions/3.8/lib/python3.8/smtplib.py", line 308, in _get_socket
    return socket.create_connection((host, port), timeout,
  File "/Library/Frameworks/Python.framework/Versions/3.8/lib/python3.8/socket.py", line 787, in create_connection
    for res in getaddrinfo(host, port, 0, SOCK_STREAM):
  File "/Library/Frameworks/Python.framework/Versions/3.8/lib/python3.8/socket.py", line 914, in getaddrinfo
    for res in _socket.getaddrinfo(host, port, family, type, proto, flags):
socket.gaierror: [Errno 8] nodename nor servname provided, or not known
Traceback (most recent call last):
  File "/Library/Frameworks/Python.framework/Versions/3.8/lib/python3.8/site-packages/urllib3/connection.py", line 156, in _new_conn
    conn = connection.create_connection(
  File "/Library/Frameworks/Python.framework/Versions/3.8/lib/python3.8/site-packages/urllib3/util/connection.py", line 61, in create_connection
    for res in socket.getaddrinfo(host, port, family, socket.SOCK_STREAM):
  File "/Library/Frameworks/Python.framework/Versions/3.8/lib/python3.8/socket.py", line 914, in getaddrinfo
    for res in _socket.getaddrinfo(host, port, family, type, proto, flags):
socket.gaierror: [Errno 8] nodename nor servname provided, or not known

During handling of the above exception, another exception occurred:

Traceback (most recent call last):
  File "/Library/Frameworks/Python.framework/Versions/3.8/lib/python3.8/site-packages/urllib3/connectionpool.py", line 665, in urlopen
    httplib_response = self._make_request(
  File "/Library/Frameworks/Python.framework/Versions/3.8/lib/python3.8/site-packages/urllib3/connectionpool.py", line 376, in _make_request
    self._validate_conn(conn)
  File "/Library/Frameworks/Python.framework/Versions/3.8/lib/python3.8/site-packages/urllib3/connectionpool.py", line 994, in _validate_conn
    conn.connect()
  File "/Library/Frameworks/Python.framework/Versions/3.8/lib/python3.8/site-packages/urllib3/connection.py", line 334, in connect
    conn = self._new_conn()
  File "/Library/Frameworks/Python.framework/Versions/3.8/lib/python3.8/site-packages/urllib3/connection.py", line 168, in _new_conn
    raise NewConnectionError(
urllib3.exceptions.NewConnectionError: <urllib3.connection.VerifiedHTTPSConnection object at 0x1108773d0>: Failed to establish a new connection: [Errno 8] nodename nor servname provided, or not known

During handling of the above exception, another exception occurred:

Traceback (most recent call last):
  File "/Library/Frameworks/Python.framework/Versions/3.8/lib/python3.8/site-packages/requests/adapters.py", line 439, in send
    resp = conn.urlopen(
  File "/Library/Frameworks/Python.framework/Versions/3.8/lib/python3.8/site-packages/urllib3/connectionpool.py", line 719, in urlopen
    retries = retries.increment(
  File "/Library/Frameworks/Python.framework/Versions/3.8/lib/python3.8/site-packages/urllib3/util/retry.py", line 436, in increment
    raise MaxRetryError(_pool, url, error or ResponseError(cause))
urllib3.exceptions.MaxRetryError: HTTPSConnectionPool(host='api.binance.com', port=443): Max retries exceeded with url: /api/v1/ping (Caused by NewConnectionError('<urllib3.connection.VerifiedHTTPSConnection object at 0x1108773d0>: Failed to establish a new connection: [Errno 8] nodename nor servname provided, or not known'))

During handling of the above exception, another exception occurred:

Traceback (most recent call last):
  File "binance1.py", line 20, in <module>
    client = Client(api_key, api_secret)
  File "/Library/Frameworks/Python.framework/Versions/3.8/lib/python3.8/site-packages/binance/client.py", line 97, in __init__
    self.ping()
  File "/Library/Frameworks/Python.framework/Versions/3.8/lib/python3.8/site-packages/binance/client.py", line 378, in ping
    return self._get('ping')
  File "/Library/Frameworks/Python.framework/Versions/3.8/lib/python3.8/site-packages/binance/client.py", line 222, in _get
    return self._request_api('get', path, signed, version, **kwargs)
  File "/Library/Frameworks/Python.framework/Versions/3.8/lib/python3.8/site-packages/binance/client.py", line 191, in _request_api
    return self._request(method, uri, signed, **kwargs)
  File "/Library/Frameworks/Python.framework/Versions/3.8/lib/python3.8/site-packages/binance/client.py", line 185, in _request
    self.response = getattr(self.session, method)(uri, **kwargs)
  File "/Library/Frameworks/Python.framework/Versions/3.8/lib/python3.8/site-packages/requests/sessions.py", line 546, in get
    return self.request('GET', url, **kwargs)
  File "/Library/Frameworks/Python.framework/Versions/3.8/lib/python3.8/site-packages/requests/sessions.py", line 533, in request
    resp = self.send(prep, **send_kwargs)
  File "/Library/Frameworks/Python.framework/Versions/3.8/lib/python3.8/site-packages/requests/sessions.py", line 646, in send
    r = adapter.send(request, **kwargs)
  File "/Library/Frameworks/Python.framework/Versions/3.8/lib/python3.8/site-packages/requests/adapters.py", line 516, in send
    raise ConnectionError(e, request=request)
requests.exceptions.ConnectionError: HTTPSConnectionPool(host='api.binance.com', port=443): Max retries exceeded with url: /api/v1/ping (Caused by NewConnectionError('<urllib3.connection.VerifiedHTTPSConnection object at 0x1108773d0>: Failed to establish a new connection: [Errno 8] nodename nor servname provided, or not known'))
Traceback (most recent call last):
  File "email_price_notify.py", line 77, in <module>
    server = smtplib.SMTP('smtp.gmail.com', 587) 
  File "/Library/Frameworks/Python.framework/Versions/3.8/lib/python3.8/smtplib.py", line 253, in __init__
    (code, msg) = self.connect(host, port)
  File "/Library/Frameworks/Python.framework/Versions/3.8/lib/python3.8/smtplib.py", line 339, in connect
    self.sock = self._get_socket(host, port, self.timeout)
  File "/Library/Frameworks/Python.framework/Versions/3.8/lib/python3.8/smtplib.py", line 308, in _get_socket
    return socket.create_connection((host, port), timeout,
  File "/Library/Frameworks/Python.framework/Versions/3.8/lib/python3.8/socket.py", line 787, in create_connection
    for res in getaddrinfo(host, port, 0, SOCK_STREAM):
  File "/Library/Frameworks/Python.framework/Versions/3.8/lib/python3.8/socket.py", line 914, in getaddrinfo
    for res in _socket.getaddrinfo(host, port, family, type, proto, flags):
socket.gaierror: [Errno 8] nodename nor servname provided, or not known
Traceback (most recent call last):
  File "/Library/Frameworks/Python.framework/Versions/3.8/lib/python3.8/site-packages/urllib3/connection.py", line 156, in _new_conn
    conn = connection.create_connection(
  File "/Library/Frameworks/Python.framework/Versions/3.8/lib/python3.8/site-packages/urllib3/util/connection.py", line 61, in create_connection
    for res in socket.getaddrinfo(host, port, family, socket.SOCK_STREAM):
  File "/Library/Frameworks/Python.framework/Versions/3.8/lib/python3.8/socket.py", line 914, in getaddrinfo
    for res in _socket.getaddrinfo(host, port, family, type, proto, flags):
socket.gaierror: [Errno 8] nodename nor servname provided, or not known

During handling of the above exception, another exception occurred:

Traceback (most recent call last):
  File "/Library/Frameworks/Python.framework/Versions/3.8/lib/python3.8/site-packages/urllib3/connectionpool.py", line 665, in urlopen
    httplib_response = self._make_request(
  File "/Library/Frameworks/Python.framework/Versions/3.8/lib/python3.8/site-packages/urllib3/connectionpool.py", line 376, in _make_request
    self._validate_conn(conn)
  File "/Library/Frameworks/Python.framework/Versions/3.8/lib/python3.8/site-packages/urllib3/connectionpool.py", line 994, in _validate_conn
    conn.connect()
  File "/Library/Frameworks/Python.framework/Versions/3.8/lib/python3.8/site-packages/urllib3/connection.py", line 334, in connect
    conn = self._new_conn()
  File "/Library/Frameworks/Python.framework/Versions/3.8/lib/python3.8/site-packages/urllib3/connection.py", line 168, in _new_conn
    raise NewConnectionError(
urllib3.exceptions.NewConnectionError: <urllib3.connection.VerifiedHTTPSConnection object at 0x116d18400>: Failed to establish a new connection: [Errno 8] nodename nor servname provided, or not known

During handling of the above exception, another exception occurred:

Traceback (most recent call last):
  File "/Library/Frameworks/Python.framework/Versions/3.8/lib/python3.8/site-packages/requests/adapters.py", line 439, in send
    resp = conn.urlopen(
  File "/Library/Frameworks/Python.framework/Versions/3.8/lib/python3.8/site-packages/urllib3/connectionpool.py", line 719, in urlopen
    retries = retries.increment(
  File "/Library/Frameworks/Python.framework/Versions/3.8/lib/python3.8/site-packages/urllib3/util/retry.py", line 436, in increment
    raise MaxRetryError(_pool, url, error or ResponseError(cause))
urllib3.exceptions.MaxRetryError: HTTPSConnectionPool(host='api.binance.com', port=443): Max retries exceeded with url: /api/v1/ping (Caused by NewConnectionError('<urllib3.connection.VerifiedHTTPSConnection object at 0x116d18400>: Failed to establish a new connection: [Errno 8] nodename nor servname provided, or not known'))

During handling of the above exception, another exception occurred:

Traceback (most recent call last):
  File "binance1.py", line 20, in <module>
    client = Client(api_key, api_secret)
  File "/Library/Frameworks/Python.framework/Versions/3.8/lib/python3.8/site-packages/binance/client.py", line 97, in __init__
    self.ping()
  File "/Library/Frameworks/Python.framework/Versions/3.8/lib/python3.8/site-packages/binance/client.py", line 378, in ping
    return self._get('ping')
  File "/Library/Frameworks/Python.framework/Versions/3.8/lib/python3.8/site-packages/binance/client.py", line 222, in _get
    return self._request_api('get', path, signed, version, **kwargs)
  File "/Library/Frameworks/Python.framework/Versions/3.8/lib/python3.8/site-packages/binance/client.py", line 191, in _request_api
    return self._request(method, uri, signed, **kwargs)
  File "/Library/Frameworks/Python.framework/Versions/3.8/lib/python3.8/site-packages/binance/client.py", line 185, in _request
    self.response = getattr(self.session, method)(uri, **kwargs)
  File "/Library/Frameworks/Python.framework/Versions/3.8/lib/python3.8/site-packages/requests/sessions.py", line 546, in get
    return self.request('GET', url, **kwargs)
  File "/Library/Frameworks/Python.framework/Versions/3.8/lib/python3.8/site-packages/requests/sessions.py", line 533, in request
    resp = self.send(prep, **send_kwargs)
  File "/Library/Frameworks/Python.framework/Versions/3.8/lib/python3.8/site-packages/requests/sessions.py", line 646, in send
    r = adapter.send(request, **kwargs)
  File "/Library/Frameworks/Python.framework/Versions/3.8/lib/python3.8/site-packages/requests/adapters.py", line 516, in send
    raise ConnectionError(e, request=request)
requests.exceptions.ConnectionError: HTTPSConnectionPool(host='api.binance.com', port=443): Max retries exceeded with url: /api/v1/ping (Caused by NewConnectionError('<urllib3.connection.VerifiedHTTPSConnection object at 0x116d18400>: Failed to establish a new connection: [Errno 8] nodename nor servname provided, or not known'))
Traceback (most recent call last):
  File "email_price_notify.py", line 77, in <module>
    server = smtplib.SMTP('smtp.gmail.com', 587) 
  File "/Library/Frameworks/Python.framework/Versions/3.8/lib/python3.8/smtplib.py", line 253, in __init__
    (code, msg) = self.connect(host, port)
  File "/Library/Frameworks/Python.framework/Versions/3.8/lib/python3.8/smtplib.py", line 339, in connect
    self.sock = self._get_socket(host, port, self.timeout)
  File "/Library/Frameworks/Python.framework/Versions/3.8/lib/python3.8/smtplib.py", line 308, in _get_socket
    return socket.create_connection((host, port), timeout,
  File "/Library/Frameworks/Python.framework/Versions/3.8/lib/python3.8/socket.py", line 787, in create_connection
    for res in getaddrinfo(host, port, 0, SOCK_STREAM):
  File "/Library/Frameworks/Python.framework/Versions/3.8/lib/python3.8/socket.py", line 914, in getaddrinfo
    for res in _socket.getaddrinfo(host, port, family, type, proto, flags):
socket.gaierror: [Errno 8] nodename nor servname provided, or not known
Traceback (most recent call last):
  File "/Library/Frameworks/Python.framework/Versions/3.8/lib/python3.8/site-packages/urllib3/connection.py", line 156, in _new_conn
    conn = connection.create_connection(
  File "/Library/Frameworks/Python.framework/Versions/3.8/lib/python3.8/site-packages/urllib3/util/connection.py", line 61, in create_connection
    for res in socket.getaddrinfo(host, port, family, socket.SOCK_STREAM):
  File "/Library/Frameworks/Python.framework/Versions/3.8/lib/python3.8/socket.py", line 914, in getaddrinfo
    for res in _socket.getaddrinfo(host, port, family, type, proto, flags):
socket.gaierror: [Errno 8] nodename nor servname provided, or not known

During handling of the above exception, another exception occurred:

Traceback (most recent call last):
  File "/Library/Frameworks/Python.framework/Versions/3.8/lib/python3.8/site-packages/urllib3/connectionpool.py", line 665, in urlopen
    httplib_response = self._make_request(
  File "/Library/Frameworks/Python.framework/Versions/3.8/lib/python3.8/site-packages/urllib3/connectionpool.py", line 376, in _make_request
    self._validate_conn(conn)
  File "/Library/Frameworks/Python.framework/Versions/3.8/lib/python3.8/site-packages/urllib3/connectionpool.py", line 994, in _validate_conn
    conn.connect()
  File "/Library/Frameworks/Python.framework/Versions/3.8/lib/python3.8/site-packages/urllib3/connection.py", line 334, in connect
    conn = self._new_conn()
  File "/Library/Frameworks/Python.framework/Versions/3.8/lib/python3.8/site-packages/urllib3/connection.py", line 168, in _new_conn
    raise NewConnectionError(
urllib3.exceptions.NewConnectionError: <urllib3.connection.VerifiedHTTPSConnection object at 0x112cf23a0>: Failed to establish a new connection: [Errno 8] nodename nor servname provided, or not known

During handling of the above exception, another exception occurred:

Traceback (most recent call last):
  File "/Library/Frameworks/Python.framework/Versions/3.8/lib/python3.8/site-packages/requests/adapters.py", line 439, in send
    resp = conn.urlopen(
  File "/Library/Frameworks/Python.framework/Versions/3.8/lib/python3.8/site-packages/urllib3/connectionpool.py", line 719, in urlopen
    retries = retries.increment(
  File "/Library/Frameworks/Python.framework/Versions/3.8/lib/python3.8/site-packages/urllib3/util/retry.py", line 436, in increment
    raise MaxRetryError(_pool, url, error or ResponseError(cause))
urllib3.exceptions.MaxRetryError: HTTPSConnectionPool(host='api.binance.com', port=443): Max retries exceeded with url: /api/v1/ping (Caused by NewConnectionError('<urllib3.connection.VerifiedHTTPSConnection object at 0x112cf23a0>: Failed to establish a new connection: [Errno 8] nodename nor servname provided, or not known'))

During handling of the above exception, another exception occurred:

Traceback (most recent call last):
  File "binance1.py", line 20, in <module>
    client = Client(api_key, api_secret)
  File "/Library/Frameworks/Python.framework/Versions/3.8/lib/python3.8/site-packages/binance/client.py", line 97, in __init__
    self.ping()
  File "/Library/Frameworks/Python.framework/Versions/3.8/lib/python3.8/site-packages/binance/client.py", line 378, in ping
    return self._get('ping')
  File "/Library/Frameworks/Python.framework/Versions/3.8/lib/python3.8/site-packages/binance/client.py", line 222, in _get
    return self._request_api('get', path, signed, version, **kwargs)
  File "/Library/Frameworks/Python.framework/Versions/3.8/lib/python3.8/site-packages/binance/client.py", line 191, in _request_api
    return self._request(method, uri, signed, **kwargs)
  File "/Library/Frameworks/Python.framework/Versions/3.8/lib/python3.8/site-packages/binance/client.py", line 185, in _request
    self.response = getattr(self.session, method)(uri, **kwargs)
  File "/Library/Frameworks/Python.framework/Versions/3.8/lib/python3.8/site-packages/requests/sessions.py", line 546, in get
    return self.request('GET', url, **kwargs)
  File "/Library/Frameworks/Python.framework/Versions/3.8/lib/python3.8/site-packages/requests/sessions.py", line 533, in request
    resp = self.send(prep, **send_kwargs)
  File "/Library/Frameworks/Python.framework/Versions/3.8/lib/python3.8/site-packages/requests/sessions.py", line 646, in send
    r = adapter.send(request, **kwargs)
  File "/Library/Frameworks/Python.framework/Versions/3.8/lib/python3.8/site-packages/requests/adapters.py", line 516, in send
    raise ConnectionError(e, request=request)
requests.exceptions.ConnectionError: HTTPSConnectionPool(host='api.binance.com', port=443): Max retries exceeded with url: /api/v1/ping (Caused by NewConnectionError('<urllib3.connection.VerifiedHTTPSConnection object at 0x112cf23a0>: Failed to establish a new connection: [Errno 8] nodename nor servname provided, or not known'))
Traceback (most recent call last):
  File "email_price_notify.py", line 77, in <module>
    server = smtplib.SMTP('smtp.gmail.com', 587) 
  File "/Library/Frameworks/Python.framework/Versions/3.8/lib/python3.8/smtplib.py", line 253, in __init__
    (code, msg) = self.connect(host, port)
  File "/Library/Frameworks/Python.framework/Versions/3.8/lib/python3.8/smtplib.py", line 339, in connect
    self.sock = self._get_socket(host, port, self.timeout)
  File "/Library/Frameworks/Python.framework/Versions/3.8/lib/python3.8/smtplib.py", line 308, in _get_socket
    return socket.create_connection((host, port), timeout,
  File "/Library/Frameworks/Python.framework/Versions/3.8/lib/python3.8/socket.py", line 787, in create_connection
    for res in getaddrinfo(host, port, 0, SOCK_STREAM):
  File "/Library/Frameworks/Python.framework/Versions/3.8/lib/python3.8/socket.py", line 914, in getaddrinfo
    for res in _socket.getaddrinfo(host, port, family, type, proto, flags):
socket.gaierror: [Errno 8] nodename nor servname provided, or not known
Traceback (most recent call last):
  File "/Library/Frameworks/Python.framework/Versions/3.8/lib/python3.8/site-packages/urllib3/connection.py", line 156, in _new_conn
    conn = connection.create_connection(
  File "/Library/Frameworks/Python.framework/Versions/3.8/lib/python3.8/site-packages/urllib3/util/connection.py", line 61, in create_connection
    for res in socket.getaddrinfo(host, port, family, socket.SOCK_STREAM):
  File "/Library/Frameworks/Python.framework/Versions/3.8/lib/python3.8/socket.py", line 914, in getaddrinfo
    for res in _socket.getaddrinfo(host, port, family, type, proto, flags):
socket.gaierror: [Errno 8] nodename nor servname provided, or not known

During handling of the above exception, another exception occurred:

Traceback (most recent call last):
  File "/Library/Frameworks/Python.framework/Versions/3.8/lib/python3.8/site-packages/urllib3/connectionpool.py", line 665, in urlopen
    httplib_response = self._make_request(
  File "/Library/Frameworks/Python.framework/Versions/3.8/lib/python3.8/site-packages/urllib3/connectionpool.py", line 376, in _make_request
    self._validate_conn(conn)
  File "/Library/Frameworks/Python.framework/Versions/3.8/lib/python3.8/site-packages/urllib3/connectionpool.py", line 994, in _validate_conn
    conn.connect()
  File "/Library/Frameworks/Python.framework/Versions/3.8/lib/python3.8/site-packages/urllib3/connection.py", line 334, in connect
    conn = self._new_conn()
  File "/Library/Frameworks/Python.framework/Versions/3.8/lib/python3.8/site-packages/urllib3/connection.py", line 168, in _new_conn
    raise NewConnectionError(
urllib3.exceptions.NewConnectionError: <urllib3.connection.VerifiedHTTPSConnection object at 0x1171f3370>: Failed to establish a new connection: [Errno 8] nodename nor servname provided, or not known

During handling of the above exception, another exception occurred:

Traceback (most recent call last):
  File "/Library/Frameworks/Python.framework/Versions/3.8/lib/python3.8/site-packages/requests/adapters.py", line 439, in send
    resp = conn.urlopen(
  File "/Library/Frameworks/Python.framework/Versions/3.8/lib/python3.8/site-packages/urllib3/connectionpool.py", line 719, in urlopen
    retries = retries.increment(
  File "/Library/Frameworks/Python.framework/Versions/3.8/lib/python3.8/site-packages/urllib3/util/retry.py", line 436, in increment
    raise MaxRetryError(_pool, url, error or ResponseError(cause))
urllib3.exceptions.MaxRetryError: HTTPSConnectionPool(host='api.binance.com', port=443): Max retries exceeded with url: /api/v1/ping (Caused by NewConnectionError('<urllib3.connection.VerifiedHTTPSConnection object at 0x1171f3370>: Failed to establish a new connection: [Errno 8] nodename nor servname provided, or not known'))

During handling of the above exception, another exception occurred:

Traceback (most recent call last):
  File "binance1.py", line 20, in <module>
    client = Client(api_key, api_secret)
  File "/Library/Frameworks/Python.framework/Versions/3.8/lib/python3.8/site-packages/binance/client.py", line 97, in __init__
    self.ping()
  File "/Library/Frameworks/Python.framework/Versions/3.8/lib/python3.8/site-packages/binance/client.py", line 378, in ping
    return self._get('ping')
  File "/Library/Frameworks/Python.framework/Versions/3.8/lib/python3.8/site-packages/binance/client.py", line 222, in _get
    return self._request_api('get', path, signed, version, **kwargs)
  File "/Library/Frameworks/Python.framework/Versions/3.8/lib/python3.8/site-packages/binance/client.py", line 191, in _request_api
    return self._request(method, uri, signed, **kwargs)
  File "/Library/Frameworks/Python.framework/Versions/3.8/lib/python3.8/site-packages/binance/client.py", line 185, in _request
    self.response = getattr(self.session, method)(uri, **kwargs)
  File "/Library/Frameworks/Python.framework/Versions/3.8/lib/python3.8/site-packages/requests/sessions.py", line 546, in get
    return self.request('GET', url, **kwargs)
  File "/Library/Frameworks/Python.framework/Versions/3.8/lib/python3.8/site-packages/requests/sessions.py", line 533, in request
    resp = self.send(prep, **send_kwargs)
  File "/Library/Frameworks/Python.framework/Versions/3.8/lib/python3.8/site-packages/requests/sessions.py", line 646, in send
    r = adapter.send(request, **kwargs)
  File "/Library/Frameworks/Python.framework/Versions/3.8/lib/python3.8/site-packages/requests/adapters.py", line 516, in send
    raise ConnectionError(e, request=request)
requests.exceptions.ConnectionError: HTTPSConnectionPool(host='api.binance.com', port=443): Max retries exceeded with url: /api/v1/ping (Caused by NewConnectionError('<urllib3.connection.VerifiedHTTPSConnection object at 0x1171f3370>: Failed to establish a new connection: [Errno 8] nodename nor servname provided, or not known'))
Traceback (most recent call last):
  File "email_price_notify.py", line 77, in <module>
    server = smtplib.SMTP('smtp.gmail.com', 587) 
  File "/Library/Frameworks/Python.framework/Versions/3.8/lib/python3.8/smtplib.py", line 253, in __init__
    (code, msg) = self.connect(host, port)
  File "/Library/Frameworks/Python.framework/Versions/3.8/lib/python3.8/smtplib.py", line 339, in connect
    self.sock = self._get_socket(host, port, self.timeout)
  File "/Library/Frameworks/Python.framework/Versions/3.8/lib/python3.8/smtplib.py", line 308, in _get_socket
    return socket.create_connection((host, port), timeout,
  File "/Library/Frameworks/Python.framework/Versions/3.8/lib/python3.8/socket.py", line 787, in create_connection
    for res in getaddrinfo(host, port, 0, SOCK_STREAM):
  File "/Library/Frameworks/Python.framework/Versions/3.8/lib/python3.8/socket.py", line 914, in getaddrinfo
    for res in _socket.getaddrinfo(host, port, family, type, proto, flags):
socket.gaierror: [Errno 8] nodename nor servname provided, or not known
Traceback (most recent call last):
  File "/Library/Frameworks/Python.framework/Versions/3.8/lib/python3.8/site-packages/urllib3/connection.py", line 156, in _new_conn
    conn = connection.create_connection(
  File "/Library/Frameworks/Python.framework/Versions/3.8/lib/python3.8/site-packages/urllib3/util/connection.py", line 61, in create_connection
    for res in socket.getaddrinfo(host, port, family, socket.SOCK_STREAM):
  File "/Library/Frameworks/Python.framework/Versions/3.8/lib/python3.8/socket.py", line 914, in getaddrinfo
    for res in _socket.getaddrinfo(host, port, family, type, proto, flags):
socket.gaierror: [Errno 8] nodename nor servname provided, or not known

During handling of the above exception, another exception occurred:

Traceback (most recent call last):
  File "/Library/Frameworks/Python.framework/Versions/3.8/lib/python3.8/site-packages/urllib3/connectionpool.py", line 665, in urlopen
    httplib_response = self._make_request(
  File "/Library/Frameworks/Python.framework/Versions/3.8/lib/python3.8/site-packages/urllib3/connectionpool.py", line 376, in _make_request
    self._validate_conn(conn)
  File "/Library/Frameworks/Python.framework/Versions/3.8/lib/python3.8/site-packages/urllib3/connectionpool.py", line 994, in _validate_conn
    conn.connect()
  File "/Library/Frameworks/Python.framework/Versions/3.8/lib/python3.8/site-packages/urllib3/connection.py", line 334, in connect
    conn = self._new_conn()
  File "/Library/Frameworks/Python.framework/Versions/3.8/lib/python3.8/site-packages/urllib3/connection.py", line 168, in _new_conn
    raise NewConnectionError(
urllib3.exceptions.NewConnectionError: <urllib3.connection.VerifiedHTTPSConnection object at 0x11097f370>: Failed to establish a new connection: [Errno 8] nodename nor servname provided, or not known

During handling of the above exception, another exception occurred:

Traceback (most recent call last):
  File "/Library/Frameworks/Python.framework/Versions/3.8/lib/python3.8/site-packages/requests/adapters.py", line 439, in send
    resp = conn.urlopen(
  File "/Library/Frameworks/Python.framework/Versions/3.8/lib/python3.8/site-packages/urllib3/connectionpool.py", line 719, in urlopen
    retries = retries.increment(
  File "/Library/Frameworks/Python.framework/Versions/3.8/lib/python3.8/site-packages/urllib3/util/retry.py", line 436, in increment
    raise MaxRetryError(_pool, url, error or ResponseError(cause))
urllib3.exceptions.MaxRetryError: HTTPSConnectionPool(host='api.binance.com', port=443): Max retries exceeded with url: /api/v1/ping (Caused by NewConnectionError('<urllib3.connection.VerifiedHTTPSConnection object at 0x11097f370>: Failed to establish a new connection: [Errno 8] nodename nor servname provided, or not known'))

During handling of the above exception, another exception occurred:

Traceback (most recent call last):
  File "binance1.py", line 20, in <module>
    client = Client(api_key, api_secret)
  File "/Library/Frameworks/Python.framework/Versions/3.8/lib/python3.8/site-packages/binance/client.py", line 97, in __init__
    self.ping()
  File "/Library/Frameworks/Python.framework/Versions/3.8/lib/python3.8/site-packages/binance/client.py", line 378, in ping
    return self._get('ping')
  File "/Library/Frameworks/Python.framework/Versions/3.8/lib/python3.8/site-packages/binance/client.py", line 222, in _get
    return self._request_api('get', path, signed, version, **kwargs)
  File "/Library/Frameworks/Python.framework/Versions/3.8/lib/python3.8/site-packages/binance/client.py", line 191, in _request_api
    return self._request(method, uri, signed, **kwargs)
  File "/Library/Frameworks/Python.framework/Versions/3.8/lib/python3.8/site-packages/binance/client.py", line 185, in _request
    self.response = getattr(self.session, method)(uri, **kwargs)
  File "/Library/Frameworks/Python.framework/Versions/3.8/lib/python3.8/site-packages/requests/sessions.py", line 546, in get
    return self.request('GET', url, **kwargs)
  File "/Library/Frameworks/Python.framework/Versions/3.8/lib/python3.8/site-packages/requests/sessions.py", line 533, in request
    resp = self.send(prep, **send_kwargs)
  File "/Library/Frameworks/Python.framework/Versions/3.8/lib/python3.8/site-packages/requests/sessions.py", line 646, in send
    r = adapter.send(request, **kwargs)
  File "/Library/Frameworks/Python.framework/Versions/3.8/lib/python3.8/site-packages/requests/adapters.py", line 516, in send
    raise ConnectionError(e, request=request)
requests.exceptions.ConnectionError: HTTPSConnectionPool(host='api.binance.com', port=443): Max retries exceeded with url: /api/v1/ping (Caused by NewConnectionError('<urllib3.connection.VerifiedHTTPSConnection object at 0x11097f370>: Failed to establish a new connection: [Errno 8] nodename nor servname provided, or not known'))
Traceback (most recent call last):
  File "email_price_notify.py", line 77, in <module>
    server = smtplib.SMTP('smtp.gmail.com', 587) 
  File "/Library/Frameworks/Python.framework/Versions/3.8/lib/python3.8/smtplib.py", line 253, in __init__
    (code, msg) = self.connect(host, port)
  File "/Library/Frameworks/Python.framework/Versions/3.8/lib/python3.8/smtplib.py", line 339, in connect
    self.sock = self._get_socket(host, port, self.timeout)
  File "/Library/Frameworks/Python.framework/Versions/3.8/lib/python3.8/smtplib.py", line 308, in _get_socket
    return socket.create_connection((host, port), timeout,
  File "/Library/Frameworks/Python.framework/Versions/3.8/lib/python3.8/socket.py", line 787, in create_connection
    for res in getaddrinfo(host, port, 0, SOCK_STREAM):
  File "/Library/Frameworks/Python.framework/Versions/3.8/lib/python3.8/socket.py", line 914, in getaddrinfo
    for res in _socket.getaddrinfo(host, port, family, type, proto, flags):
socket.gaierror: [Errno 8] nodename nor servname provided, or not known
Traceback (most recent call last):
  File "/Library/Frameworks/Python.framework/Versions/3.8/lib/python3.8/site-packages/urllib3/connection.py", line 156, in _new_conn
    conn = connection.create_connection(
  File "/Library/Frameworks/Python.framework/Versions/3.8/lib/python3.8/site-packages/urllib3/util/connection.py", line 61, in create_connection
    for res in socket.getaddrinfo(host, port, family, socket.SOCK_STREAM):
  File "/Library/Frameworks/Python.framework/Versions/3.8/lib/python3.8/socket.py", line 914, in getaddrinfo
    for res in _socket.getaddrinfo(host, port, family, type, proto, flags):
socket.gaierror: [Errno 8] nodename nor servname provided, or not known

During handling of the above exception, another exception occurred:

Traceback (most recent call last):
  File "/Library/Frameworks/Python.framework/Versions/3.8/lib/python3.8/site-packages/urllib3/connectionpool.py", line 665, in urlopen
    httplib_response = self._make_request(
  File "/Library/Frameworks/Python.framework/Versions/3.8/lib/python3.8/site-packages/urllib3/connectionpool.py", line 376, in _make_request
    self._validate_conn(conn)
  File "/Library/Frameworks/Python.framework/Versions/3.8/lib/python3.8/site-packages/urllib3/connectionpool.py", line 994, in _validate_conn
    conn.connect()
  File "/Library/Frameworks/Python.framework/Versions/3.8/lib/python3.8/site-packages/urllib3/connection.py", line 334, in connect
    conn = self._new_conn()
  File "/Library/Frameworks/Python.framework/Versions/3.8/lib/python3.8/site-packages/urllib3/connection.py", line 168, in _new_conn
    raise NewConnectionError(
urllib3.exceptions.NewConnectionError: <urllib3.connection.VerifiedHTTPSConnection object at 0x10d569340>: Failed to establish a new connection: [Errno 8] nodename nor servname provided, or not known

During handling of the above exception, another exception occurred:

Traceback (most recent call last):
  File "/Library/Frameworks/Python.framework/Versions/3.8/lib/python3.8/site-packages/requests/adapters.py", line 439, in send
    resp = conn.urlopen(
  File "/Library/Frameworks/Python.framework/Versions/3.8/lib/python3.8/site-packages/urllib3/connectionpool.py", line 719, in urlopen
    retries = retries.increment(
  File "/Library/Frameworks/Python.framework/Versions/3.8/lib/python3.8/site-packages/urllib3/util/retry.py", line 436, in increment
    raise MaxRetryError(_pool, url, error or ResponseError(cause))
urllib3.exceptions.MaxRetryError: HTTPSConnectionPool(host='api.binance.com', port=443): Max retries exceeded with url: /api/v1/ping (Caused by NewConnectionError('<urllib3.connection.VerifiedHTTPSConnection object at 0x10d569340>: Failed to establish a new connection: [Errno 8] nodename nor servname provided, or not known'))

During handling of the above exception, another exception occurred:

Traceback (most recent call last):
  File "binance1.py", line 20, in <module>
    client = Client(api_key, api_secret)
  File "/Library/Frameworks/Python.framework/Versions/3.8/lib/python3.8/site-packages/binance/client.py", line 97, in __init__
    self.ping()
  File "/Library/Frameworks/Python.framework/Versions/3.8/lib/python3.8/site-packages/binance/client.py", line 378, in ping
    return self._get('ping')
  File "/Library/Frameworks/Python.framework/Versions/3.8/lib/python3.8/site-packages/binance/client.py", line 222, in _get
    return self._request_api('get', path, signed, version, **kwargs)
  File "/Library/Frameworks/Python.framework/Versions/3.8/lib/python3.8/site-packages/binance/client.py", line 191, in _request_api
    return self._request(method, uri, signed, **kwargs)
  File "/Library/Frameworks/Python.framework/Versions/3.8/lib/python3.8/site-packages/binance/client.py", line 185, in _request
    self.response = getattr(self.session, method)(uri, **kwargs)
  File "/Library/Frameworks/Python.framework/Versions/3.8/lib/python3.8/site-packages/requests/sessions.py", line 546, in get
    return self.request('GET', url, **kwargs)
  File "/Library/Frameworks/Python.framework/Versions/3.8/lib/python3.8/site-packages/requests/sessions.py", line 533, in request
    resp = self.send(prep, **send_kwargs)
  File "/Library/Frameworks/Python.framework/Versions/3.8/lib/python3.8/site-packages/requests/sessions.py", line 646, in send
    r = adapter.send(request, **kwargs)
  File "/Library/Frameworks/Python.framework/Versions/3.8/lib/python3.8/site-packages/requests/adapters.py", line 516, in send
    raise ConnectionError(e, request=request)
requests.exceptions.ConnectionError: HTTPSConnectionPool(host='api.binance.com', port=443): Max retries exceeded with url: /api/v1/ping (Caused by NewConnectionError('<urllib3.connection.VerifiedHTTPSConnection object at 0x10d569340>: Failed to establish a new connection: [Errno 8] nodename nor servname provided, or not known'))
Traceback (most recent call last):
  File "email_price_notify.py", line 77, in <module>
    server = smtplib.SMTP('smtp.gmail.com', 587) 
  File "/Library/Frameworks/Python.framework/Versions/3.8/lib/python3.8/smtplib.py", line 253, in __init__
    (code, msg) = self.connect(host, port)
  File "/Library/Frameworks/Python.framework/Versions/3.8/lib/python3.8/smtplib.py", line 339, in connect
    self.sock = self._get_socket(host, port, self.timeout)
  File "/Library/Frameworks/Python.framework/Versions/3.8/lib/python3.8/smtplib.py", line 308, in _get_socket
    return socket.create_connection((host, port), timeout,
  File "/Library/Frameworks/Python.framework/Versions/3.8/lib/python3.8/socket.py", line 787, in create_connection
    for res in getaddrinfo(host, port, 0, SOCK_STREAM):
  File "/Library/Frameworks/Python.framework/Versions/3.8/lib/python3.8/socket.py", line 914, in getaddrinfo
    for res in _socket.getaddrinfo(host, port, family, type, proto, flags):
socket.gaierror: [Errno 8] nodename nor servname provided, or not known
Traceback (most recent call last):
  File "/Library/Frameworks/Python.framework/Versions/3.8/lib/python3.8/site-packages/urllib3/connection.py", line 156, in _new_conn
    conn = connection.create_connection(
  File "/Library/Frameworks/Python.framework/Versions/3.8/lib/python3.8/site-packages/urllib3/util/connection.py", line 61, in create_connection
    for res in socket.getaddrinfo(host, port, family, socket.SOCK_STREAM):
  File "/Library/Frameworks/Python.framework/Versions/3.8/lib/python3.8/socket.py", line 914, in getaddrinfo
    for res in _socket.getaddrinfo(host, port, family, type, proto, flags):
socket.gaierror: [Errno 8] nodename nor servname provided, or not known

During handling of the above exception, another exception occurred:

Traceback (most recent call last):
  File "/Library/Frameworks/Python.framework/Versions/3.8/lib/python3.8/site-packages/urllib3/connectionpool.py", line 665, in urlopen
    httplib_response = self._make_request(
  File "/Library/Frameworks/Python.framework/Versions/3.8/lib/python3.8/site-packages/urllib3/connectionpool.py", line 376, in _make_request
    self._validate_conn(conn)
  File "/Library/Frameworks/Python.framework/Versions/3.8/lib/python3.8/site-packages/urllib3/connectionpool.py", line 994, in _validate_conn
    conn.connect()
  File "/Library/Frameworks/Python.framework/Versions/3.8/lib/python3.8/site-packages/urllib3/connection.py", line 334, in connect
    conn = self._new_conn()
  File "/Library/Frameworks/Python.framework/Versions/3.8/lib/python3.8/site-packages/urllib3/connection.py", line 168, in _new_conn
    raise NewConnectionError(
urllib3.exceptions.NewConnectionError: <urllib3.connection.VerifiedHTTPSConnection object at 0x115a913a0>: Failed to establish a new connection: [Errno 8] nodename nor servname provided, or not known

During handling of the above exception, another exception occurred:

Traceback (most recent call last):
  File "/Library/Frameworks/Python.framework/Versions/3.8/lib/python3.8/site-packages/requests/adapters.py", line 439, in send
    resp = conn.urlopen(
  File "/Library/Frameworks/Python.framework/Versions/3.8/lib/python3.8/site-packages/urllib3/connectionpool.py", line 719, in urlopen
    retries = retries.increment(
  File "/Library/Frameworks/Python.framework/Versions/3.8/lib/python3.8/site-packages/urllib3/util/retry.py", line 436, in increment
    raise MaxRetryError(_pool, url, error or ResponseError(cause))
urllib3.exceptions.MaxRetryError: HTTPSConnectionPool(host='api.binance.com', port=443): Max retries exceeded with url: /api/v1/ping (Caused by NewConnectionError('<urllib3.connection.VerifiedHTTPSConnection object at 0x115a913a0>: Failed to establish a new connection: [Errno 8] nodename nor servname provided, or not known'))

During handling of the above exception, another exception occurred:

Traceback (most recent call last):
  File "binance1.py", line 20, in <module>
    client = Client(api_key, api_secret)
  File "/Library/Frameworks/Python.framework/Versions/3.8/lib/python3.8/site-packages/binance/client.py", line 97, in __init__
    self.ping()
  File "/Library/Frameworks/Python.framework/Versions/3.8/lib/python3.8/site-packages/binance/client.py", line 378, in ping
    return self._get('ping')
  File "/Library/Frameworks/Python.framework/Versions/3.8/lib/python3.8/site-packages/binance/client.py", line 222, in _get
    return self._request_api('get', path, signed, version, **kwargs)
  File "/Library/Frameworks/Python.framework/Versions/3.8/lib/python3.8/site-packages/binance/client.py", line 191, in _request_api
    return self._request(method, uri, signed, **kwargs)
  File "/Library/Frameworks/Python.framework/Versions/3.8/lib/python3.8/site-packages/binance/client.py", line 185, in _request
    self.response = getattr(self.session, method)(uri, **kwargs)
  File "/Library/Frameworks/Python.framework/Versions/3.8/lib/python3.8/site-packages/requests/sessions.py", line 546, in get
    return self.request('GET', url, **kwargs)
  File "/Library/Frameworks/Python.framework/Versions/3.8/lib/python3.8/site-packages/requests/sessions.py", line 533, in request
    resp = self.send(prep, **send_kwargs)
  File "/Library/Frameworks/Python.framework/Versions/3.8/lib/python3.8/site-packages/requests/sessions.py", line 646, in send
    r = adapter.send(request, **kwargs)
  File "/Library/Frameworks/Python.framework/Versions/3.8/lib/python3.8/site-packages/requests/adapters.py", line 516, in send
    raise ConnectionError(e, request=request)
requests.exceptions.ConnectionError: HTTPSConnectionPool(host='api.binance.com', port=443): Max retries exceeded with url: /api/v1/ping (Caused by NewConnectionError('<urllib3.connection.VerifiedHTTPSConnection object at 0x115a913a0>: Failed to establish a new connection: [Errno 8] nodename nor servname provided, or not known'))
Traceback (most recent call last):
  File "email_price_notify.py", line 77, in <module>
    server = smtplib.SMTP('smtp.gmail.com', 587) 
  File "/Library/Frameworks/Python.framework/Versions/3.8/lib/python3.8/smtplib.py", line 253, in __init__
    (code, msg) = self.connect(host, port)
  File "/Library/Frameworks/Python.framework/Versions/3.8/lib/python3.8/smtplib.py", line 339, in connect
    self.sock = self._get_socket(host, port, self.timeout)
  File "/Library/Frameworks/Python.framework/Versions/3.8/lib/python3.8/smtplib.py", line 308, in _get_socket
    return socket.create_connection((host, port), timeout,
  File "/Library/Frameworks/Python.framework/Versions/3.8/lib/python3.8/socket.py", line 787, in create_connection
    for res in getaddrinfo(host, port, 0, SOCK_STREAM):
  File "/Library/Frameworks/Python.framework/Versions/3.8/lib/python3.8/socket.py", line 914, in getaddrinfo
    for res in _socket.getaddrinfo(host, port, family, type, proto, flags):
socket.gaierror: [Errno 8] nodename nor servname provided, or not known
Traceback (most recent call last):
  File "/Library/Frameworks/Python.framework/Versions/3.8/lib/python3.8/site-packages/urllib3/connection.py", line 156, in _new_conn
    conn = connection.create_connection(
  File "/Library/Frameworks/Python.framework/Versions/3.8/lib/python3.8/site-packages/urllib3/util/connection.py", line 61, in create_connection
    for res in socket.getaddrinfo(host, port, family, socket.SOCK_STREAM):
  File "/Library/Frameworks/Python.framework/Versions/3.8/lib/python3.8/socket.py", line 914, in getaddrinfo
    for res in _socket.getaddrinfo(host, port, family, type, proto, flags):
socket.gaierror: [Errno 8] nodename nor servname provided, or not known

During handling of the above exception, another exception occurred:

Traceback (most recent call last):
  File "/Library/Frameworks/Python.framework/Versions/3.8/lib/python3.8/site-packages/urllib3/connectionpool.py", line 665, in urlopen
    httplib_response = self._make_request(
  File "/Library/Frameworks/Python.framework/Versions/3.8/lib/python3.8/site-packages/urllib3/connectionpool.py", line 376, in _make_request
    self._validate_conn(conn)
  File "/Library/Frameworks/Python.framework/Versions/3.8/lib/python3.8/site-packages/urllib3/connectionpool.py", line 994, in _validate_conn
    conn.connect()
  File "/Library/Frameworks/Python.framework/Versions/3.8/lib/python3.8/site-packages/urllib3/connection.py", line 334, in connect
    conn = self._new_conn()
  File "/Library/Frameworks/Python.framework/Versions/3.8/lib/python3.8/site-packages/urllib3/connection.py", line 168, in _new_conn
    raise NewConnectionError(
urllib3.exceptions.NewConnectionError: <urllib3.connection.VerifiedHTTPSConnection object at 0x1193333d0>: Failed to establish a new connection: [Errno 8] nodename nor servname provided, or not known

During handling of the above exception, another exception occurred:

Traceback (most recent call last):
  File "/Library/Frameworks/Python.framework/Versions/3.8/lib/python3.8/site-packages/requests/adapters.py", line 439, in send
    resp = conn.urlopen(
  File "/Library/Frameworks/Python.framework/Versions/3.8/lib/python3.8/site-packages/urllib3/connectionpool.py", line 719, in urlopen
    retries = retries.increment(
  File "/Library/Frameworks/Python.framework/Versions/3.8/lib/python3.8/site-packages/urllib3/util/retry.py", line 436, in increment
    raise MaxRetryError(_pool, url, error or ResponseError(cause))
urllib3.exceptions.MaxRetryError: HTTPSConnectionPool(host='api.binance.com', port=443): Max retries exceeded with url: /api/v1/ping (Caused by NewConnectionError('<urllib3.connection.VerifiedHTTPSConnection object at 0x1193333d0>: Failed to establish a new connection: [Errno 8] nodename nor servname provided, or not known'))

During handling of the above exception, another exception occurred:

Traceback (most recent call last):
  File "binance1.py", line 20, in <module>
    client = Client(api_key, api_secret)
  File "/Library/Frameworks/Python.framework/Versions/3.8/lib/python3.8/site-packages/binance/client.py", line 97, in __init__
    self.ping()
  File "/Library/Frameworks/Python.framework/Versions/3.8/lib/python3.8/site-packages/binance/client.py", line 378, in ping
    return self._get('ping')
  File "/Library/Frameworks/Python.framework/Versions/3.8/lib/python3.8/site-packages/binance/client.py", line 222, in _get
    return self._request_api('get', path, signed, version, **kwargs)
  File "/Library/Frameworks/Python.framework/Versions/3.8/lib/python3.8/site-packages/binance/client.py", line 191, in _request_api
    return self._request(method, uri, signed, **kwargs)
  File "/Library/Frameworks/Python.framework/Versions/3.8/lib/python3.8/site-packages/binance/client.py", line 185, in _request
    self.response = getattr(self.session, method)(uri, **kwargs)
  File "/Library/Frameworks/Python.framework/Versions/3.8/lib/python3.8/site-packages/requests/sessions.py", line 546, in get
    return self.request('GET', url, **kwargs)
  File "/Library/Frameworks/Python.framework/Versions/3.8/lib/python3.8/site-packages/requests/sessions.py", line 533, in request
    resp = self.send(prep, **send_kwargs)
  File "/Library/Frameworks/Python.framework/Versions/3.8/lib/python3.8/site-packages/requests/sessions.py", line 646, in send
    r = adapter.send(request, **kwargs)
  File "/Library/Frameworks/Python.framework/Versions/3.8/lib/python3.8/site-packages/requests/adapters.py", line 516, in send
    raise ConnectionError(e, request=request)
requests.exceptions.ConnectionError: HTTPSConnectionPool(host='api.binance.com', port=443): Max retries exceeded with url: /api/v1/ping (Caused by NewConnectionError('<urllib3.connection.VerifiedHTTPSConnection object at 0x1193333d0>: Failed to establish a new connection: [Errno 8] nodename nor servname provided, or not known'))
Traceback (most recent call last):
  File "email_price_notify.py", line 77, in <module>
    server = smtplib.SMTP('smtp.gmail.com', 587) 
  File "/Library/Frameworks/Python.framework/Versions/3.8/lib/python3.8/smtplib.py", line 253, in __init__
    (code, msg) = self.connect(host, port)
  File "/Library/Frameworks/Python.framework/Versions/3.8/lib/python3.8/smtplib.py", line 339, in connect
    self.sock = self._get_socket(host, port, self.timeout)
  File "/Library/Frameworks/Python.framework/Versions/3.8/lib/python3.8/smtplib.py", line 308, in _get_socket
    return socket.create_connection((host, port), timeout,
  File "/Library/Frameworks/Python.framework/Versions/3.8/lib/python3.8/socket.py", line 787, in create_connection
    for res in getaddrinfo(host, port, 0, SOCK_STREAM):
  File "/Library/Frameworks/Python.framework/Versions/3.8/lib/python3.8/socket.py", line 914, in getaddrinfo
    for res in _socket.getaddrinfo(host, port, family, type, proto, flags):
socket.gaierror: [Errno 8] nodename nor servname provided, or not known
Traceback (most recent call last):
  File "/Library/Frameworks/Python.framework/Versions/3.8/lib/python3.8/site-packages/urllib3/connection.py", line 156, in _new_conn
    conn = connection.create_connection(
  File "/Library/Frameworks/Python.framework/Versions/3.8/lib/python3.8/site-packages/urllib3/util/connection.py", line 61, in create_connection
    for res in socket.getaddrinfo(host, port, family, socket.SOCK_STREAM):
  File "/Library/Frameworks/Python.framework/Versions/3.8/lib/python3.8/socket.py", line 914, in getaddrinfo
    for res in _socket.getaddrinfo(host, port, family, type, proto, flags):
socket.gaierror: [Errno 8] nodename nor servname provided, or not known

During handling of the above exception, another exception occurred:

Traceback (most recent call last):
  File "/Library/Frameworks/Python.framework/Versions/3.8/lib/python3.8/site-packages/urllib3/connectionpool.py", line 665, in urlopen
    httplib_response = self._make_request(
  File "/Library/Frameworks/Python.framework/Versions/3.8/lib/python3.8/site-packages/urllib3/connectionpool.py", line 376, in _make_request
    self._validate_conn(conn)
  File "/Library/Frameworks/Python.framework/Versions/3.8/lib/python3.8/site-packages/urllib3/connectionpool.py", line 994, in _validate_conn
    conn.connect()
  File "/Library/Frameworks/Python.framework/Versions/3.8/lib/python3.8/site-packages/urllib3/connection.py", line 334, in connect
    conn = self._new_conn()
  File "/Library/Frameworks/Python.framework/Versions/3.8/lib/python3.8/site-packages/urllib3/connection.py", line 168, in _new_conn
    raise NewConnectionError(
urllib3.exceptions.NewConnectionError: <urllib3.connection.VerifiedHTTPSConnection object at 0x117aeb370>: Failed to establish a new connection: [Errno 8] nodename nor servname provided, or not known

During handling of the above exception, another exception occurred:

Traceback (most recent call last):
  File "/Library/Frameworks/Python.framework/Versions/3.8/lib/python3.8/site-packages/requests/adapters.py", line 439, in send
    resp = conn.urlopen(
  File "/Library/Frameworks/Python.framework/Versions/3.8/lib/python3.8/site-packages/urllib3/connectionpool.py", line 719, in urlopen
    retries = retries.increment(
  File "/Library/Frameworks/Python.framework/Versions/3.8/lib/python3.8/site-packages/urllib3/util/retry.py", line 436, in increment
    raise MaxRetryError(_pool, url, error or ResponseError(cause))
urllib3.exceptions.MaxRetryError: HTTPSConnectionPool(host='api.binance.com', port=443): Max retries exceeded with url: /api/v1/ping (Caused by NewConnectionError('<urllib3.connection.VerifiedHTTPSConnection object at 0x117aeb370>: Failed to establish a new connection: [Errno 8] nodename nor servname provided, or not known'))

During handling of the above exception, another exception occurred:

Traceback (most recent call last):
  File "binance1.py", line 20, in <module>
    client = Client(api_key, api_secret)
  File "/Library/Frameworks/Python.framework/Versions/3.8/lib/python3.8/site-packages/binance/client.py", line 97, in __init__
    self.ping()
  File "/Library/Frameworks/Python.framework/Versions/3.8/lib/python3.8/site-packages/binance/client.py", line 378, in ping
    return self._get('ping')
  File "/Library/Frameworks/Python.framework/Versions/3.8/lib/python3.8/site-packages/binance/client.py", line 222, in _get
    return self._request_api('get', path, signed, version, **kwargs)
  File "/Library/Frameworks/Python.framework/Versions/3.8/lib/python3.8/site-packages/binance/client.py", line 191, in _request_api
    return self._request(method, uri, signed, **kwargs)
  File "/Library/Frameworks/Python.framework/Versions/3.8/lib/python3.8/site-packages/binance/client.py", line 185, in _request
    self.response = getattr(self.session, method)(uri, **kwargs)
  File "/Library/Frameworks/Python.framework/Versions/3.8/lib/python3.8/site-packages/requests/sessions.py", line 546, in get
    return self.request('GET', url, **kwargs)
  File "/Library/Frameworks/Python.framework/Versions/3.8/lib/python3.8/site-packages/requests/sessions.py", line 533, in request
    resp = self.send(prep, **send_kwargs)
  File "/Library/Frameworks/Python.framework/Versions/3.8/lib/python3.8/site-packages/requests/sessions.py", line 646, in send
    r = adapter.send(request, **kwargs)
  File "/Library/Frameworks/Python.framework/Versions/3.8/lib/python3.8/site-packages/requests/adapters.py", line 516, in send
    raise ConnectionError(e, request=request)
requests.exceptions.ConnectionError: HTTPSConnectionPool(host='api.binance.com', port=443): Max retries exceeded with url: /api/v1/ping (Caused by NewConnectionError('<urllib3.connection.VerifiedHTTPSConnection object at 0x117aeb370>: Failed to establish a new connection: [Errno 8] nodename nor servname provided, or not known'))
Traceback (most recent call last):
  File "email_price_notify.py", line 77, in <module>
    server = smtplib.SMTP('smtp.gmail.com', 587) 
  File "/Library/Frameworks/Python.framework/Versions/3.8/lib/python3.8/smtplib.py", line 253, in __init__
    (code, msg) = self.connect(host, port)
  File "/Library/Frameworks/Python.framework/Versions/3.8/lib/python3.8/smtplib.py", line 339, in connect
    self.sock = self._get_socket(host, port, self.timeout)
  File "/Library/Frameworks/Python.framework/Versions/3.8/lib/python3.8/smtplib.py", line 308, in _get_socket
    return socket.create_connection((host, port), timeout,
  File "/Library/Frameworks/Python.framework/Versions/3.8/lib/python3.8/socket.py", line 787, in create_connection
    for res in getaddrinfo(host, port, 0, SOCK_STREAM):
  File "/Library/Frameworks/Python.framework/Versions/3.8/lib/python3.8/socket.py", line 914, in getaddrinfo
    for res in _socket.getaddrinfo(host, port, family, type, proto, flags):
socket.gaierror: [Errno 8] nodename nor servname provided, or not known
Traceback (most recent call last):
  File "/Library/Frameworks/Python.framework/Versions/3.8/lib/python3.8/site-packages/urllib3/connection.py", line 156, in _new_conn
    conn = connection.create_connection(
  File "/Library/Frameworks/Python.framework/Versions/3.8/lib/python3.8/site-packages/urllib3/util/connection.py", line 61, in create_connection
    for res in socket.getaddrinfo(host, port, family, socket.SOCK_STREAM):
  File "/Library/Frameworks/Python.framework/Versions/3.8/lib/python3.8/socket.py", line 914, in getaddrinfo
    for res in _socket.getaddrinfo(host, port, family, type, proto, flags):
socket.gaierror: [Errno 8] nodename nor servname provided, or not known

During handling of the above exception, another exception occurred:

Traceback (most recent call last):
  File "/Library/Frameworks/Python.framework/Versions/3.8/lib/python3.8/site-packages/urllib3/connectionpool.py", line 665, in urlopen
    httplib_response = self._make_request(
  File "/Library/Frameworks/Python.framework/Versions/3.8/lib/python3.8/site-packages/urllib3/connectionpool.py", line 376, in _make_request
    self._validate_conn(conn)
  File "/Library/Frameworks/Python.framework/Versions/3.8/lib/python3.8/site-packages/urllib3/connectionpool.py", line 994, in _validate_conn
    conn.connect()
  File "/Library/Frameworks/Python.framework/Versions/3.8/lib/python3.8/site-packages/urllib3/connection.py", line 334, in connect
    conn = self._new_conn()
  File "/Library/Frameworks/Python.framework/Versions/3.8/lib/python3.8/site-packages/urllib3/connection.py", line 168, in _new_conn
    raise NewConnectionError(
urllib3.exceptions.NewConnectionError: <urllib3.connection.VerifiedHTTPSConnection object at 0x116278370>: Failed to establish a new connection: [Errno 8] nodename nor servname provided, or not known

During handling of the above exception, another exception occurred:

Traceback (most recent call last):
  File "/Library/Frameworks/Python.framework/Versions/3.8/lib/python3.8/site-packages/requests/adapters.py", line 439, in send
    resp = conn.urlopen(
  File "/Library/Frameworks/Python.framework/Versions/3.8/lib/python3.8/site-packages/urllib3/connectionpool.py", line 719, in urlopen
    retries = retries.increment(
  File "/Library/Frameworks/Python.framework/Versions/3.8/lib/python3.8/site-packages/urllib3/util/retry.py", line 436, in increment
    raise MaxRetryError(_pool, url, error or ResponseError(cause))
urllib3.exceptions.MaxRetryError: HTTPSConnectionPool(host='api.binance.com', port=443): Max retries exceeded with url: /api/v1/ping (Caused by NewConnectionError('<urllib3.connection.VerifiedHTTPSConnection object at 0x116278370>: Failed to establish a new connection: [Errno 8] nodename nor servname provided, or not known'))

During handling of the above exception, another exception occurred:

Traceback (most recent call last):
  File "binance1.py", line 20, in <module>
    client = Client(api_key, api_secret)
  File "/Library/Frameworks/Python.framework/Versions/3.8/lib/python3.8/site-packages/binance/client.py", line 97, in __init__
    self.ping()
  File "/Library/Frameworks/Python.framework/Versions/3.8/lib/python3.8/site-packages/binance/client.py", line 378, in ping
    return self._get('ping')
  File "/Library/Frameworks/Python.framework/Versions/3.8/lib/python3.8/site-packages/binance/client.py", line 222, in _get
    return self._request_api('get', path, signed, version, **kwargs)
  File "/Library/Frameworks/Python.framework/Versions/3.8/lib/python3.8/site-packages/binance/client.py", line 191, in _request_api
    return self._request(method, uri, signed, **kwargs)
  File "/Library/Frameworks/Python.framework/Versions/3.8/lib/python3.8/site-packages/binance/client.py", line 185, in _request
    self.response = getattr(self.session, method)(uri, **kwargs)
  File "/Library/Frameworks/Python.framework/Versions/3.8/lib/python3.8/site-packages/requests/sessions.py", line 546, in get
    return self.request('GET', url, **kwargs)
  File "/Library/Frameworks/Python.framework/Versions/3.8/lib/python3.8/site-packages/requests/sessions.py", line 533, in request
    resp = self.send(prep, **send_kwargs)
  File "/Library/Frameworks/Python.framework/Versions/3.8/lib/python3.8/site-packages/requests/sessions.py", line 646, in send
    r = adapter.send(request, **kwargs)
  File "/Library/Frameworks/Python.framework/Versions/3.8/lib/python3.8/site-packages/requests/adapters.py", line 516, in send
    raise ConnectionError(e, request=request)
requests.exceptions.ConnectionError: HTTPSConnectionPool(host='api.binance.com', port=443): Max retries exceeded with url: /api/v1/ping (Caused by NewConnectionError('<urllib3.connection.VerifiedHTTPSConnection object at 0x116278370>: Failed to establish a new connection: [Errno 8] nodename nor servname provided, or not known'))
Traceback (most recent call last):
  File "email_price_notify.py", line 77, in <module>
    server = smtplib.SMTP('smtp.gmail.com', 587) 
  File "/Library/Frameworks/Python.framework/Versions/3.8/lib/python3.8/smtplib.py", line 253, in __init__
    (code, msg) = self.connect(host, port)
  File "/Library/Frameworks/Python.framework/Versions/3.8/lib/python3.8/smtplib.py", line 339, in connect
    self.sock = self._get_socket(host, port, self.timeout)
  File "/Library/Frameworks/Python.framework/Versions/3.8/lib/python3.8/smtplib.py", line 308, in _get_socket
    return socket.create_connection((host, port), timeout,
  File "/Library/Frameworks/Python.framework/Versions/3.8/lib/python3.8/socket.py", line 787, in create_connection
    for res in getaddrinfo(host, port, 0, SOCK_STREAM):
  File "/Library/Frameworks/Python.framework/Versions/3.8/lib/python3.8/socket.py", line 914, in getaddrinfo
    for res in _socket.getaddrinfo(host, port, family, type, proto, flags):
socket.gaierror: [Errno 8] nodename nor servname provided, or not known
Traceback (most recent call last):
  File "/Library/Frameworks/Python.framework/Versions/3.8/lib/python3.8/site-packages/urllib3/connection.py", line 156, in _new_conn
    conn = connection.create_connection(
  File "/Library/Frameworks/Python.framework/Versions/3.8/lib/python3.8/site-packages/urllib3/util/connection.py", line 61, in create_connection
    for res in socket.getaddrinfo(host, port, family, socket.SOCK_STREAM):
  File "/Library/Frameworks/Python.framework/Versions/3.8/lib/python3.8/socket.py", line 914, in getaddrinfo
    for res in _socket.getaddrinfo(host, port, family, type, proto, flags):
socket.gaierror: [Errno 8] nodename nor servname provided, or not known

During handling of the above exception, another exception occurred:

Traceback (most recent call last):
  File "/Library/Frameworks/Python.framework/Versions/3.8/lib/python3.8/site-packages/urllib3/connectionpool.py", line 665, in urlopen
    httplib_response = self._make_request(
  File "/Library/Frameworks/Python.framework/Versions/3.8/lib/python3.8/site-packages/urllib3/connectionpool.py", line 376, in _make_request
    self._validate_conn(conn)
  File "/Library/Frameworks/Python.framework/Versions/3.8/lib/python3.8/site-packages/urllib3/connectionpool.py", line 994, in _validate_conn
    conn.connect()
  File "/Library/Frameworks/Python.framework/Versions/3.8/lib/python3.8/site-packages/urllib3/connection.py", line 334, in connect
    conn = self._new_conn()
  File "/Library/Frameworks/Python.framework/Versions/3.8/lib/python3.8/site-packages/urllib3/connection.py", line 168, in _new_conn
    raise NewConnectionError(
urllib3.exceptions.NewConnectionError: <urllib3.connection.VerifiedHTTPSConnection object at 0x11268a370>: Failed to establish a new connection: [Errno 8] nodename nor servname provided, or not known

During handling of the above exception, another exception occurred:

Traceback (most recent call last):
  File "/Library/Frameworks/Python.framework/Versions/3.8/lib/python3.8/site-packages/requests/adapters.py", line 439, in send
    resp = conn.urlopen(
  File "/Library/Frameworks/Python.framework/Versions/3.8/lib/python3.8/site-packages/urllib3/connectionpool.py", line 719, in urlopen
    retries = retries.increment(
  File "/Library/Frameworks/Python.framework/Versions/3.8/lib/python3.8/site-packages/urllib3/util/retry.py", line 436, in increment
    raise MaxRetryError(_pool, url, error or ResponseError(cause))
urllib3.exceptions.MaxRetryError: HTTPSConnectionPool(host='api.binance.com', port=443): Max retries exceeded with url: /api/v1/ping (Caused by NewConnectionError('<urllib3.connection.VerifiedHTTPSConnection object at 0x11268a370>: Failed to establish a new connection: [Errno 8] nodename nor servname provided, or not known'))

During handling of the above exception, another exception occurred:

Traceback (most recent call last):
  File "binance1.py", line 20, in <module>
    client = Client(api_key, api_secret)
  File "/Library/Frameworks/Python.framework/Versions/3.8/lib/python3.8/site-packages/binance/client.py", line 97, in __init__
    self.ping()
  File "/Library/Frameworks/Python.framework/Versions/3.8/lib/python3.8/site-packages/binance/client.py", line 378, in ping
    return self._get('ping')
  File "/Library/Frameworks/Python.framework/Versions/3.8/lib/python3.8/site-packages/binance/client.py", line 222, in _get
    return self._request_api('get', path, signed, version, **kwargs)
  File "/Library/Frameworks/Python.framework/Versions/3.8/lib/python3.8/site-packages/binance/client.py", line 191, in _request_api
    return self._request(method, uri, signed, **kwargs)
  File "/Library/Frameworks/Python.framework/Versions/3.8/lib/python3.8/site-packages/binance/client.py", line 185, in _request
    self.response = getattr(self.session, method)(uri, **kwargs)
  File "/Library/Frameworks/Python.framework/Versions/3.8/lib/python3.8/site-packages/requests/sessions.py", line 546, in get
    return self.request('GET', url, **kwargs)
  File "/Library/Frameworks/Python.framework/Versions/3.8/lib/python3.8/site-packages/requests/sessions.py", line 533, in request
    resp = self.send(prep, **send_kwargs)
  File "/Library/Frameworks/Python.framework/Versions/3.8/lib/python3.8/site-packages/requests/sessions.py", line 646, in send
    r = adapter.send(request, **kwargs)
  File "/Library/Frameworks/Python.framework/Versions/3.8/lib/python3.8/site-packages/requests/adapters.py", line 516, in send
    raise ConnectionError(e, request=request)
requests.exceptions.ConnectionError: HTTPSConnectionPool(host='api.binance.com', port=443): Max retries exceeded with url: /api/v1/ping (Caused by NewConnectionError('<urllib3.connection.VerifiedHTTPSConnection object at 0x11268a370>: Failed to establish a new connection: [Errno 8] nodename nor servname provided, or not known'))
Traceback (most recent call last):
  File "email_price_notify.py", line 77, in <module>
    server = smtplib.SMTP('smtp.gmail.com', 587) 
  File "/Library/Frameworks/Python.framework/Versions/3.8/lib/python3.8/smtplib.py", line 253, in __init__
    (code, msg) = self.connect(host, port)
  File "/Library/Frameworks/Python.framework/Versions/3.8/lib/python3.8/smtplib.py", line 339, in connect
    self.sock = self._get_socket(host, port, self.timeout)
  File "/Library/Frameworks/Python.framework/Versions/3.8/lib/python3.8/smtplib.py", line 308, in _get_socket
    return socket.create_connection((host, port), timeout,
  File "/Library/Frameworks/Python.framework/Versions/3.8/lib/python3.8/socket.py", line 787, in create_connection
    for res in getaddrinfo(host, port, 0, SOCK_STREAM):
  File "/Library/Frameworks/Python.framework/Versions/3.8/lib/python3.8/socket.py", line 914, in getaddrinfo
    for res in _socket.getaddrinfo(host, port, family, type, proto, flags):
socket.gaierror: [Errno 8] nodename nor servname provided, or not known
Traceback (most recent call last):
  File "/Library/Frameworks/Python.framework/Versions/3.8/lib/python3.8/site-packages/urllib3/connection.py", line 156, in _new_conn
    conn = connection.create_connection(
  File "/Library/Frameworks/Python.framework/Versions/3.8/lib/python3.8/site-packages/urllib3/util/connection.py", line 61, in create_connection
    for res in socket.getaddrinfo(host, port, family, socket.SOCK_STREAM):
  File "/Library/Frameworks/Python.framework/Versions/3.8/lib/python3.8/socket.py", line 914, in getaddrinfo
    for res in _socket.getaddrinfo(host, port, family, type, proto, flags):
socket.gaierror: [Errno 8] nodename nor servname provided, or not known

During handling of the above exception, another exception occurred:

Traceback (most recent call last):
  File "/Library/Frameworks/Python.framework/Versions/3.8/lib/python3.8/site-packages/urllib3/connectionpool.py", line 665, in urlopen
    httplib_response = self._make_request(
  File "/Library/Frameworks/Python.framework/Versions/3.8/lib/python3.8/site-packages/urllib3/connectionpool.py", line 376, in _make_request
    self._validate_conn(conn)
  File "/Library/Frameworks/Python.framework/Versions/3.8/lib/python3.8/site-packages/urllib3/connectionpool.py", line 994, in _validate_conn
    conn.connect()
  File "/Library/Frameworks/Python.framework/Versions/3.8/lib/python3.8/site-packages/urllib3/connection.py", line 334, in connect
    conn = self._new_conn()
  File "/Library/Frameworks/Python.framework/Versions/3.8/lib/python3.8/site-packages/urllib3/connection.py", line 168, in _new_conn
    raise NewConnectionError(
urllib3.exceptions.NewConnectionError: <urllib3.connection.VerifiedHTTPSConnection object at 0x10e3bf370>: Failed to establish a new connection: [Errno 8] nodename nor servname provided, or not known

During handling of the above exception, another exception occurred:

Traceback (most recent call last):
  File "/Library/Frameworks/Python.framework/Versions/3.8/lib/python3.8/site-packages/requests/adapters.py", line 439, in send
    resp = conn.urlopen(
  File "/Library/Frameworks/Python.framework/Versions/3.8/lib/python3.8/site-packages/urllib3/connectionpool.py", line 719, in urlopen
    retries = retries.increment(
  File "/Library/Frameworks/Python.framework/Versions/3.8/lib/python3.8/site-packages/urllib3/util/retry.py", line 436, in increment
    raise MaxRetryError(_pool, url, error or ResponseError(cause))
urllib3.exceptions.MaxRetryError: HTTPSConnectionPool(host='api.binance.com', port=443): Max retries exceeded with url: /api/v1/ping (Caused by NewConnectionError('<urllib3.connection.VerifiedHTTPSConnection object at 0x10e3bf370>: Failed to establish a new connection: [Errno 8] nodename nor servname provided, or not known'))

During handling of the above exception, another exception occurred:

Traceback (most recent call last):
  File "binance1.py", line 20, in <module>
    client = Client(api_key, api_secret)
  File "/Library/Frameworks/Python.framework/Versions/3.8/lib/python3.8/site-packages/binance/client.py", line 97, in __init__
    self.ping()
  File "/Library/Frameworks/Python.framework/Versions/3.8/lib/python3.8/site-packages/binance/client.py", line 378, in ping
    return self._get('ping')
  File "/Library/Frameworks/Python.framework/Versions/3.8/lib/python3.8/site-packages/binance/client.py", line 222, in _get
    return self._request_api('get', path, signed, version, **kwargs)
  File "/Library/Frameworks/Python.framework/Versions/3.8/lib/python3.8/site-packages/binance/client.py", line 191, in _request_api
    return self._request(method, uri, signed, **kwargs)
  File "/Library/Frameworks/Python.framework/Versions/3.8/lib/python3.8/site-packages/binance/client.py", line 185, in _request
    self.response = getattr(self.session, method)(uri, **kwargs)
  File "/Library/Frameworks/Python.framework/Versions/3.8/lib/python3.8/site-packages/requests/sessions.py", line 546, in get
    return self.request('GET', url, **kwargs)
  File "/Library/Frameworks/Python.framework/Versions/3.8/lib/python3.8/site-packages/requests/sessions.py", line 533, in request
    resp = self.send(prep, **send_kwargs)
  File "/Library/Frameworks/Python.framework/Versions/3.8/lib/python3.8/site-packages/requests/sessions.py", line 646, in send
    r = adapter.send(request, **kwargs)
  File "/Library/Frameworks/Python.framework/Versions/3.8/lib/python3.8/site-packages/requests/adapters.py", line 516, in send
    raise ConnectionError(e, request=request)
requests.exceptions.ConnectionError: HTTPSConnectionPool(host='api.binance.com', port=443): Max retries exceeded with url: /api/v1/ping (Caused by NewConnectionError('<urllib3.connection.VerifiedHTTPSConnection object at 0x10e3bf370>: Failed to establish a new connection: [Errno 8] nodename nor servname provided, or not known'))
Traceback (most recent call last):
  File "email_price_notify.py", line 77, in <module>
    server = smtplib.SMTP('smtp.gmail.com', 587) 
  File "/Library/Frameworks/Python.framework/Versions/3.8/lib/python3.8/smtplib.py", line 253, in __init__
    (code, msg) = self.connect(host, port)
  File "/Library/Frameworks/Python.framework/Versions/3.8/lib/python3.8/smtplib.py", line 339, in connect
    self.sock = self._get_socket(host, port, self.timeout)
  File "/Library/Frameworks/Python.framework/Versions/3.8/lib/python3.8/smtplib.py", line 308, in _get_socket
    return socket.create_connection((host, port), timeout,
  File "/Library/Frameworks/Python.framework/Versions/3.8/lib/python3.8/socket.py", line 787, in create_connection
    for res in getaddrinfo(host, port, 0, SOCK_STREAM):
  File "/Library/Frameworks/Python.framework/Versions/3.8/lib/python3.8/socket.py", line 914, in getaddrinfo
    for res in _socket.getaddrinfo(host, port, family, type, proto, flags):
socket.gaierror: [Errno 8] nodename nor servname provided, or not known
228.41 226.10111680798173 907
228.34 226.05445014131507 907
227.8 225.6944501413151 907
227.88 225.7477834746484 907
Traceback (most recent call last):
  File "/Library/Frameworks/Python.framework/Versions/3.8/lib/python3.8/site-packages/urllib3/connection.py", line 156, in _new_conn
    conn = connection.create_connection(
  File "/Library/Frameworks/Python.framework/Versions/3.8/lib/python3.8/site-packages/urllib3/util/connection.py", line 61, in create_connection
    for res in socket.getaddrinfo(host, port, family, socket.SOCK_STREAM):
  File "/Library/Frameworks/Python.framework/Versions/3.8/lib/python3.8/socket.py", line 914, in getaddrinfo
    for res in _socket.getaddrinfo(host, port, family, type, proto, flags):
socket.gaierror: [Errno 8] nodename nor servname provided, or not known

During handling of the above exception, another exception occurred:

Traceback (most recent call last):
  File "/Library/Frameworks/Python.framework/Versions/3.8/lib/python3.8/site-packages/urllib3/connectionpool.py", line 665, in urlopen
    httplib_response = self._make_request(
  File "/Library/Frameworks/Python.framework/Versions/3.8/lib/python3.8/site-packages/urllib3/connectionpool.py", line 376, in _make_request
    self._validate_conn(conn)
  File "/Library/Frameworks/Python.framework/Versions/3.8/lib/python3.8/site-packages/urllib3/connectionpool.py", line 994, in _validate_conn
    conn.connect()
  File "/Library/Frameworks/Python.framework/Versions/3.8/lib/python3.8/site-packages/urllib3/connection.py", line 334, in connect
    conn = self._new_conn()
  File "/Library/Frameworks/Python.framework/Versions/3.8/lib/python3.8/site-packages/urllib3/connection.py", line 168, in _new_conn
    raise NewConnectionError(
urllib3.exceptions.NewConnectionError: <urllib3.connection.VerifiedHTTPSConnection object at 0x1125809a0>: Failed to establish a new connection: [Errno 8] nodename nor servname provided, or not known

During handling of the above exception, another exception occurred:

Traceback (most recent call last):
  File "/Library/Frameworks/Python.framework/Versions/3.8/lib/python3.8/site-packages/requests/adapters.py", line 439, in send
    resp = conn.urlopen(
  File "/Library/Frameworks/Python.framework/Versions/3.8/lib/python3.8/site-packages/urllib3/connectionpool.py", line 719, in urlopen
    retries = retries.increment(
  File "/Library/Frameworks/Python.framework/Versions/3.8/lib/python3.8/site-packages/urllib3/util/retry.py", line 436, in increment
    raise MaxRetryError(_pool, url, error or ResponseError(cause))
urllib3.exceptions.MaxRetryError: HTTPSConnectionPool(host='api.binance.com', port=443): Max retries exceeded with url: /api/v1/ping (Caused by NewConnectionError('<urllib3.connection.VerifiedHTTPSConnection object at 0x1125809a0>: Failed to establish a new connection: [Errno 8] nodename nor servname provided, or not known'))

During handling of the above exception, another exception occurred:

Traceback (most recent call last):
  File "binance1.py", line 20, in <module>
    client = Client(api_key, api_secret)
  File "/Library/Frameworks/Python.framework/Versions/3.8/lib/python3.8/site-packages/binance/client.py", line 97, in __init__
    self.ping()
  File "/Library/Frameworks/Python.framework/Versions/3.8/lib/python3.8/site-packages/binance/client.py", line 378, in ping
    return self._get('ping')
  File "/Library/Frameworks/Python.framework/Versions/3.8/lib/python3.8/site-packages/binance/client.py", line 222, in _get
    return self._request_api('get', path, signed, version, **kwargs)
  File "/Library/Frameworks/Python.framework/Versions/3.8/lib/python3.8/site-packages/binance/client.py", line 191, in _request_api
    return self._request(method, uri, signed, **kwargs)
  File "/Library/Frameworks/Python.framework/Versions/3.8/lib/python3.8/site-packages/binance/client.py", line 185, in _request
    self.response = getattr(self.session, method)(uri, **kwargs)
  File "/Library/Frameworks/Python.framework/Versions/3.8/lib/python3.8/site-packages/requests/sessions.py", line 546, in get
    return self.request('GET', url, **kwargs)
  File "/Library/Frameworks/Python.framework/Versions/3.8/lib/python3.8/site-packages/requests/sessions.py", line 533, in request
    resp = self.send(prep, **send_kwargs)
  File "/Library/Frameworks/Python.framework/Versions/3.8/lib/python3.8/site-packages/requests/sessions.py", line 646, in send
    r = adapter.send(request, **kwargs)
  File "/Library/Frameworks/Python.framework/Versions/3.8/lib/python3.8/site-packages/requests/adapters.py", line 516, in send
    raise ConnectionError(e, request=request)
requests.exceptions.ConnectionError: HTTPSConnectionPool(host='api.binance.com', port=443): Max retries exceeded with url: /api/v1/ping (Caused by NewConnectionError('<urllib3.connection.VerifiedHTTPSConnection object at 0x1125809a0>: Failed to establish a new connection: [Errno 8] nodename nor servname provided, or not known'))
Traceback (most recent call last):
  File "/Library/Frameworks/Python.framework/Versions/3.8/lib/python3.8/site-packages/urllib3/connection.py", line 156, in _new_conn
    conn = connection.create_connection(
  File "/Library/Frameworks/Python.framework/Versions/3.8/lib/python3.8/site-packages/urllib3/util/connection.py", line 61, in create_connection
    for res in socket.getaddrinfo(host, port, family, socket.SOCK_STREAM):
  File "/Library/Frameworks/Python.framework/Versions/3.8/lib/python3.8/socket.py", line 914, in getaddrinfo
    for res in _socket.getaddrinfo(host, port, family, type, proto, flags):
socket.gaierror: [Errno 8] nodename nor servname provided, or not known

During handling of the above exception, another exception occurred:

Traceback (most recent call last):
  File "/Library/Frameworks/Python.framework/Versions/3.8/lib/python3.8/site-packages/urllib3/connectionpool.py", line 665, in urlopen
    httplib_response = self._make_request(
  File "/Library/Frameworks/Python.framework/Versions/3.8/lib/python3.8/site-packages/urllib3/connectionpool.py", line 376, in _make_request
    self._validate_conn(conn)
  File "/Library/Frameworks/Python.framework/Versions/3.8/lib/python3.8/site-packages/urllib3/connectionpool.py", line 994, in _validate_conn
    conn.connect()
  File "/Library/Frameworks/Python.framework/Versions/3.8/lib/python3.8/site-packages/urllib3/connection.py", line 334, in connect
    conn = self._new_conn()
  File "/Library/Frameworks/Python.framework/Versions/3.8/lib/python3.8/site-packages/urllib3/connection.py", line 168, in _new_conn
    raise NewConnectionError(
urllib3.exceptions.NewConnectionError: <urllib3.connection.VerifiedHTTPSConnection object at 0x114426a00>: Failed to establish a new connection: [Errno 8] nodename nor servname provided, or not known

During handling of the above exception, another exception occurred:

Traceback (most recent call last):
  File "/Library/Frameworks/Python.framework/Versions/3.8/lib/python3.8/site-packages/requests/adapters.py", line 439, in send
    resp = conn.urlopen(
  File "/Library/Frameworks/Python.framework/Versions/3.8/lib/python3.8/site-packages/urllib3/connectionpool.py", line 719, in urlopen
    retries = retries.increment(
  File "/Library/Frameworks/Python.framework/Versions/3.8/lib/python3.8/site-packages/urllib3/util/retry.py", line 436, in increment
    raise MaxRetryError(_pool, url, error or ResponseError(cause))
urllib3.exceptions.MaxRetryError: HTTPSConnectionPool(host='api.binance.com', port=443): Max retries exceeded with url: /api/v1/ping (Caused by NewConnectionError('<urllib3.connection.VerifiedHTTPSConnection object at 0x114426a00>: Failed to establish a new connection: [Errno 8] nodename nor servname provided, or not known'))

During handling of the above exception, another exception occurred:

Traceback (most recent call last):
  File "binance1.py", line 20, in <module>
    client = Client(api_key, api_secret)
  File "/Library/Frameworks/Python.framework/Versions/3.8/lib/python3.8/site-packages/binance/client.py", line 97, in __init__
    self.ping()
  File "/Library/Frameworks/Python.framework/Versions/3.8/lib/python3.8/site-packages/binance/client.py", line 378, in ping
    return self._get('ping')
  File "/Library/Frameworks/Python.framework/Versions/3.8/lib/python3.8/site-packages/binance/client.py", line 222, in _get
    return self._request_api('get', path, signed, version, **kwargs)
  File "/Library/Frameworks/Python.framework/Versions/3.8/lib/python3.8/site-packages/binance/client.py", line 191, in _request_api
    return self._request(method, uri, signed, **kwargs)
  File "/Library/Frameworks/Python.framework/Versions/3.8/lib/python3.8/site-packages/binance/client.py", line 185, in _request
    self.response = getattr(self.session, method)(uri, **kwargs)
  File "/Library/Frameworks/Python.framework/Versions/3.8/lib/python3.8/site-packages/requests/sessions.py", line 546, in get
    return self.request('GET', url, **kwargs)
  File "/Library/Frameworks/Python.framework/Versions/3.8/lib/python3.8/site-packages/requests/sessions.py", line 533, in request
    resp = self.send(prep, **send_kwargs)
  File "/Library/Frameworks/Python.framework/Versions/3.8/lib/python3.8/site-packages/requests/sessions.py", line 646, in send
    r = adapter.send(request, **kwargs)
  File "/Library/Frameworks/Python.framework/Versions/3.8/lib/python3.8/site-packages/requests/adapters.py", line 516, in send
    raise ConnectionError(e, request=request)
requests.exceptions.ConnectionError: HTTPSConnectionPool(host='api.binance.com', port=443): Max retries exceeded with url: /api/v1/ping (Caused by NewConnectionError('<urllib3.connection.VerifiedHTTPSConnection object at 0x114426a00>: Failed to establish a new connection: [Errno 8] nodename nor servname provided, or not known'))
Traceback (most recent call last):
  File "email_price_notify.py", line 77, in <module>
    server = smtplib.SMTP('smtp.gmail.com', 587) 
  File "/Library/Frameworks/Python.framework/Versions/3.8/lib/python3.8/smtplib.py", line 253, in __init__
    (code, msg) = self.connect(host, port)
  File "/Library/Frameworks/Python.framework/Versions/3.8/lib/python3.8/smtplib.py", line 339, in connect
    self.sock = self._get_socket(host, port, self.timeout)
  File "/Library/Frameworks/Python.framework/Versions/3.8/lib/python3.8/smtplib.py", line 308, in _get_socket
    return socket.create_connection((host, port), timeout,
  File "/Library/Frameworks/Python.framework/Versions/3.8/lib/python3.8/socket.py", line 787, in create_connection
    for res in getaddrinfo(host, port, 0, SOCK_STREAM):
  File "/Library/Frameworks/Python.framework/Versions/3.8/lib/python3.8/socket.py", line 914, in getaddrinfo
    for res in _socket.getaddrinfo(host, port, family, type, proto, flags):
socket.gaierror: [Errno 8] nodename nor servname provided, or not known
Traceback (most recent call last):
  File "/Library/Frameworks/Python.framework/Versions/3.8/lib/python3.8/site-packages/urllib3/connection.py", line 156, in _new_conn
    conn = connection.create_connection(
  File "/Library/Frameworks/Python.framework/Versions/3.8/lib/python3.8/site-packages/urllib3/util/connection.py", line 61, in create_connection
    for res in socket.getaddrinfo(host, port, family, socket.SOCK_STREAM):
  File "/Library/Frameworks/Python.framework/Versions/3.8/lib/python3.8/socket.py", line 914, in getaddrinfo
    for res in _socket.getaddrinfo(host, port, family, type, proto, flags):
socket.gaierror: [Errno 8] nodename nor servname provided, or not known

During handling of the above exception, another exception occurred:

Traceback (most recent call last):
  File "/Library/Frameworks/Python.framework/Versions/3.8/lib/python3.8/site-packages/urllib3/connectionpool.py", line 665, in urlopen
    httplib_response = self._make_request(
  File "/Library/Frameworks/Python.framework/Versions/3.8/lib/python3.8/site-packages/urllib3/connectionpool.py", line 376, in _make_request
    self._validate_conn(conn)
  File "/Library/Frameworks/Python.framework/Versions/3.8/lib/python3.8/site-packages/urllib3/connectionpool.py", line 994, in _validate_conn
    conn.connect()
  File "/Library/Frameworks/Python.framework/Versions/3.8/lib/python3.8/site-packages/urllib3/connection.py", line 334, in connect
    conn = self._new_conn()
  File "/Library/Frameworks/Python.framework/Versions/3.8/lib/python3.8/site-packages/urllib3/connection.py", line 168, in _new_conn
    raise NewConnectionError(
urllib3.exceptions.NewConnectionError: <urllib3.connection.VerifiedHTTPSConnection object at 0x11b6bea30>: Failed to establish a new connection: [Errno 8] nodename nor servname provided, or not known

During handling of the above exception, another exception occurred:

Traceback (most recent call last):
  File "/Library/Frameworks/Python.framework/Versions/3.8/lib/python3.8/site-packages/requests/adapters.py", line 439, in send
    resp = conn.urlopen(
  File "/Library/Frameworks/Python.framework/Versions/3.8/lib/python3.8/site-packages/urllib3/connectionpool.py", line 719, in urlopen
    retries = retries.increment(
  File "/Library/Frameworks/Python.framework/Versions/3.8/lib/python3.8/site-packages/urllib3/util/retry.py", line 436, in increment
    raise MaxRetryError(_pool, url, error or ResponseError(cause))
urllib3.exceptions.MaxRetryError: HTTPSConnectionPool(host='api.binance.com', port=443): Max retries exceeded with url: /api/v1/ping (Caused by NewConnectionError('<urllib3.connection.VerifiedHTTPSConnection object at 0x11b6bea30>: Failed to establish a new connection: [Errno 8] nodename nor servname provided, or not known'))

During handling of the above exception, another exception occurred:

Traceback (most recent call last):
  File "binance1.py", line 20, in <module>
    client = Client(api_key, api_secret)
  File "/Library/Frameworks/Python.framework/Versions/3.8/lib/python3.8/site-packages/binance/client.py", line 97, in __init__
    self.ping()
  File "/Library/Frameworks/Python.framework/Versions/3.8/lib/python3.8/site-packages/binance/client.py", line 378, in ping
    return self._get('ping')
  File "/Library/Frameworks/Python.framework/Versions/3.8/lib/python3.8/site-packages/binance/client.py", line 222, in _get
    return self._request_api('get', path, signed, version, **kwargs)
  File "/Library/Frameworks/Python.framework/Versions/3.8/lib/python3.8/site-packages/binance/client.py", line 191, in _request_api
    return self._request(method, uri, signed, **kwargs)
  File "/Library/Frameworks/Python.framework/Versions/3.8/lib/python3.8/site-packages/binance/client.py", line 185, in _request
    self.response = getattr(self.session, method)(uri, **kwargs)
  File "/Library/Frameworks/Python.framework/Versions/3.8/lib/python3.8/site-packages/requests/sessions.py", line 546, in get
    return self.request('GET', url, **kwargs)
  File "/Library/Frameworks/Python.framework/Versions/3.8/lib/python3.8/site-packages/requests/sessions.py", line 533, in request
    resp = self.send(prep, **send_kwargs)
  File "/Library/Frameworks/Python.framework/Versions/3.8/lib/python3.8/site-packages/requests/sessions.py", line 646, in send
    r = adapter.send(request, **kwargs)
  File "/Library/Frameworks/Python.framework/Versions/3.8/lib/python3.8/site-packages/requests/adapters.py", line 516, in send
    raise ConnectionError(e, request=request)
requests.exceptions.ConnectionError: HTTPSConnectionPool(host='api.binance.com', port=443): Max retries exceeded with url: /api/v1/ping (Caused by NewConnectionError('<urllib3.connection.VerifiedHTTPSConnection object at 0x11b6bea30>: Failed to establish a new connection: [Errno 8] nodename nor servname provided, or not known'))
228.45 226.1277834746484 907
228.63 226.2477834746484 907
227.3 225.36111680798174 907
227.25 225.3277834746484 907
226.05 224.52778347464843 907
226.1 224.56111680798173 907
Sun Feb  9 23:23:00 CST 2020
225.16 223.93445014131507 907
Sun Feb  9 23:24:00 CST 2020
224.38 223.4144501413151 907
Sun Feb  9 23:25:00 CST 2020
224.58 223.5477834746484 907
Sun Feb  9 23:26:00 CST 2020
224.13 223.2477834746484 907
Sun Feb  9 23:27:00 CST 2020
224.35 223.39445014131505 907
Sun Feb  9 23:59:00 CST 2020
226.93 225.11445014131507 907
Mon Feb 10 00:00:00 CST 2020
226.88 225.08111680798174 907
Mon Feb 10 08:59:00 CST 2020
228.9 227.9848167137717 908
Mon Feb 10 09:00:00 CST 2020
228.86 227.95815004710505 908
Mon Feb 10 09:59:01 CST 2020
226.8 226.58481671377172 908
Mon Feb 10 10:00:01 CST 2020
226.92 226.66481671377167 908
Mon Feb 10 10:59:00 CST 2020
226.66 226.49148338043835 908
Mon Feb 10 11:00:00 CST 2020
226.71 226.52481671377168 908
Mon Feb 10 11:59:00 CST 2020
225.46 225.69148338043837 908
Mon Feb 10 12:00:00 CST 2020
225.42 225.66481671377167 908
Mon Feb 10 12:59:00 CST 2020
224.69 225.17815004710505 908
Mon Feb 10 13:00:00 CST 2020
224.44 225.01148338043836 908
Mon Feb 10 13:59:00 CST 2020
220.2 222.1848167137717 908
Mon Feb 10 14:00:01 CST 2020
220.64 222.47815004710503 908
Mon Feb 10 14:59:00 CST 2020
222.78 223.90481671377168 908
Mon Feb 10 15:00:01 CST 2020
223.22 224.19815004710503 908
Mon Feb 10 15:59:01 CST 2020
223.84 224.61148338043836 908
Mon Feb 10 16:00:00 CST 2020
223.64 224.47815004710503 908
Mon Feb 10 16:59:01 CST 2020
221.21 222.85815004710503 908
Mon Feb 10 17:00:00 CST 2020
220.9 222.65148338043835 908
Mon Feb 10 17:59:00 CST 2020
218.98 221.37148338043835 908
Mon Feb 10 18:00:00 CST 2020
219.17 221.498150047105 908
Mon Feb 10 18:59:00 CST 2020
219.95 222.01815004710502 908
Mon Feb 10 19:00:00 CST 2020
220.16 222.158150047105 908
Mon Feb 10 19:59:00 CST 2020
218.34 220.9448167137717 908
Mon Feb 10 20:00:00 CST 2020
218.58 221.1048167137717 908
Mon Feb 10 20:59:00 CST 2020
220.08 222.1048167137717 908
Mon Feb 10 21:00:00 CST 2020
220.01 222.05815004710504 908
Mon Feb 10 21:59:00 CST 2020
219.55 221.75148338043837 908
Mon Feb 10 22:00:00 CST 2020
219.57 221.7648167137717 908
Mon Feb 10 22:59:00 CST 2020
223.19 224.17815004710505 908
Mon Feb 10 23:00:00 CST 2020
223.39 224.31148338043837 908
Mon Feb 10 23:59:01 CST 2020
223.41 224.3248167137717 908
Tue Feb 11 00:00:00 CST 2020
223.28 224.23815004710502 908
Tue Feb 11 00:59:00 CST 2020
221.52 223.0648167137717 908
Tue Feb 11 01:00:00 CST 2020
221.98 223.37148338043835 908
Tue Feb 11 20:59:00 CST 2020
223.36 223.56605001570168 909
Tue Feb 11 21:00:00 CST 2020
223.26 223.499383349035 909
Tue Feb 11 21:59:00 CST 2020
223.52 223.67271668236836 909
Tue Feb 11 22:00:01 CST 2020
223.42 223.6060500157017 909
Tue Feb 11 22:59:00 CST 2020
222.29 222.85271668236837 909
Tue Feb 11 23:00:01 CST 2020
222.52 223.0060500157017 909
Tue Feb 11 23:59:00 CST 2020
228.9 227.25938334903503 909
Wed Feb 12 00:00:00 CST 2020
228.88 227.24605001570168 909
Wed Feb 12 00:59:01 CST 2020
231.55 229.02605001570168 909
Wed Feb 12 01:00:00 CST 2020
231.53 229.01271668236836 909
Wed Feb 12 12:59:00 CST 2020
244.96 240.79090556078947 910
Wed Feb 12 13:00:00 CST 2020
244.91 240.7575722274561 910
Wed Feb 12 14:59:00 CST 2020
248.46 243.12423889412278 910
Wed Feb 12 15:00:00 CST 2020
248.91 243.4242388941228 910
