Mon Nov  2 01:02:00 CST 2020
Predict_price 1.0175141512709653 389
Predict_Sell_price -1.0246510908942543 357
1.0436793934362454
Ready_toBuy: 958.6120488643646
Execute-Time: 1.6641829013824463
Mon Nov  2 01:04:00 CST 2020
Predict_price 1.0175141512709653 389
Predict_Sell_price -1.0246510908942543 357
1.0181523279091418
Ready_toBuy: 1081.0005640983582
Execute-Time: 1.62630295753479
Mon Nov  2 01:06:00 CST 2020
Predict_price 1.0175141512709653 389
Predict_Sell_price -1.0246510908942543 357
1.0009215586783777
Ready_toBuy: 1200.5677659511566
Execute-Time: 1.5934078693389893
Mon Nov  2 01:08:00 CST 2020
Predict_price 1.0175141512709653 389
Predict_Sell_price -1.0246510908942543 357
1.0104942082510244
Ready_toBuy: 1321.5893330574036
Execute-Time: 1.8759448528289795
Mon Nov  2 01:10:00 CST 2020
Predict_price 1.0175141512709653 389
Predict_Sell_price -1.0246510908942543 357
0.9958161455729662
Alert: 1497.199500799179
Execute-Time: 1.7250869274139404
Mon Nov  2 01:12:01 CST 2020
Predict_price 1.0175141512709653 389
Predict_Sell_price -1.0246510908942543 357
0.9830526128094372
Alert: 122.22815990447998
Execute-Time: 2.3622841835021973
Mon Nov  2 01:14:00 CST 2020
Predict_price 1.0175141512709653 389
Predict_Sell_price -1.0246510908942543 357
0.998368852125672
Alert: 241.03709506988525
Execute-Time: 2.101072072982788
Mon Nov  2 01:16:00 CST 2020
Predict_price 1.0175141512709653 389
Predict_Sell_price -1.0246510908942543 357
1.0092178549746715
Ready_toBuy: 1802.8262119293213
Execute-Time: 2.7881858348846436
Mon Nov  2 01:18:00 CST 2020
Predict_price 1.0175141512709653 389
Predict_Sell_price -1.0246510908942543 357
1.0187905045473182
Ready_toBuy: 120.10051012039185
Execute-Time: 2.357250213623047
Mon Nov  2 01:20:01 CST 2020
Predict_price 1.0175141512709653 389
Predict_Sell_price -1.0246510908942543 357
1.031554037310893
Ready_toBuy: 238.26927208900452
Execute-Time: 1.7846558094024658
Mon Nov  2 01:22:00 CST 2020
Predict_price 1.0175141512709653 389
Predict_Sell_price -1.0246510908942543 357
1.0219813877382005
Ready_toBuy: 357.93033599853516
Execute-Time: 1.7650361061096191
Mon Nov  2 01:24:00 CST 2020
Predict_price 1.0175141512709653 389
Predict_Sell_price -1.0246510908942543 357
1.0321922139490236
Ready_toBuy: 481.0161452293396
Execute-Time: 3.007532835006714
Mon Nov  2 01:26:00 CST 2020
Predict_price 1.0175141512709653 389
Predict_Sell_price -1.0246510908942543 357
1.0117705615273773
Ready_toBuy: 598.8704948425293
Execute-Time: 1.8317289352416992
Mon Nov  2 01:28:00 CST 2020
Predict_price 1.0175141512709653 389
Predict_Sell_price -1.0246510908942543 357
1.0117705615273773
Ready_toBuy: 719.5993251800537
Execute-Time: 1.897777795791626
Mon Nov  2 01:30:00 CST 2020
Predict_price 1.0175141512709653 389
Predict_Sell_price -1.0246510908942543 357
1.0277249774817885
Ready_toBuy: 837.5951020717621
Execute-Time: 1.5084421634674072
Mon Nov  2 01:32:00 CST 2020
Traceback (most recent call last):
  File "/Library/Frameworks/Python.framework/Versions/3.8/lib/python3.8/site-packages/urllib3/connection.py", line 156, in _new_conn
    conn = connection.create_connection(
  File "/Library/Frameworks/Python.framework/Versions/3.8/lib/python3.8/site-packages/urllib3/util/connection.py", line 61, in create_connection
    for res in socket.getaddrinfo(host, port, family, socket.SOCK_STREAM):
  File "/Library/Frameworks/Python.framework/Versions/3.8/lib/python3.8/socket.py", line 914, in getaddrinfo
    for res in _socket.getaddrinfo(host, port, family, type, proto, flags):
socket.gaierror: [Errno 8] nodename nor servname provided, or not known

During handling of the above exception, another exception occurred:

Traceback (most recent call last):
  File "/Library/Frameworks/Python.framework/Versions/3.8/lib/python3.8/site-packages/urllib3/connectionpool.py", line 665, in urlopen
    httplib_response = self._make_request(
  File "/Library/Frameworks/Python.framework/Versions/3.8/lib/python3.8/site-packages/urllib3/connectionpool.py", line 376, in _make_request
    self._validate_conn(conn)
  File "/Library/Frameworks/Python.framework/Versions/3.8/lib/python3.8/site-packages/urllib3/connectionpool.py", line 994, in _validate_conn
    conn.connect()
  File "/Library/Frameworks/Python.framework/Versions/3.8/lib/python3.8/site-packages/urllib3/connection.py", line 334, in connect
    conn = self._new_conn()
  File "/Library/Frameworks/Python.framework/Versions/3.8/lib/python3.8/site-packages/urllib3/connection.py", line 168, in _new_conn
    raise NewConnectionError(
urllib3.exceptions.NewConnectionError: <urllib3.connection.VerifiedHTTPSConnection object at 0x7fb180aaeac0>: Failed to establish a new connection: [Errno 8] nodename nor servname provided, or not known

During handling of the above exception, another exception occurred:

Traceback (most recent call last):
  File "/Library/Frameworks/Python.framework/Versions/3.8/lib/python3.8/site-packages/requests/adapters.py", line 439, in send
    resp = conn.urlopen(
  File "/Library/Frameworks/Python.framework/Versions/3.8/lib/python3.8/site-packages/urllib3/connectionpool.py", line 719, in urlopen
    retries = retries.increment(
  File "/Library/Frameworks/Python.framework/Versions/3.8/lib/python3.8/site-packages/urllib3/util/retry.py", line 436, in increment
    raise MaxRetryError(_pool, url, error or ResponseError(cause))
urllib3.exceptions.MaxRetryError: HTTPSConnectionPool(host='api.binance.com', port=443): Max retries exceeded with url: /api/v1/ping (Caused by NewConnectionError('<urllib3.connection.VerifiedHTTPSConnection object at 0x7fb180aaeac0>: Failed to establish a new connection: [Errno 8] nodename nor servname provided, or not known'))

During handling of the above exception, another exception occurred:

Traceback (most recent call last):
  File "./MACD/get_Binance.py", line 26, in <module>
    client = Client(api_key, api_secret)
  File "/Library/Frameworks/Python.framework/Versions/3.8/lib/python3.8/site-packages/binance/client.py", line 97, in __init__
    self.ping()
  File "/Library/Frameworks/Python.framework/Versions/3.8/lib/python3.8/site-packages/binance/client.py", line 378, in ping
    return self._get('ping')
  File "/Library/Frameworks/Python.framework/Versions/3.8/lib/python3.8/site-packages/binance/client.py", line 222, in _get
    return self._request_api('get', path, signed, version, **kwargs)
  File "/Library/Frameworks/Python.framework/Versions/3.8/lib/python3.8/site-packages/binance/client.py", line 191, in _request_api
    return self._request(method, uri, signed, **kwargs)
  File "/Library/Frameworks/Python.framework/Versions/3.8/lib/python3.8/site-packages/binance/client.py", line 185, in _request
    self.response = getattr(self.session, method)(uri, **kwargs)
  File "/Library/Frameworks/Python.framework/Versions/3.8/lib/python3.8/site-packages/requests/sessions.py", line 546, in get
    return self.request('GET', url, **kwargs)
  File "/Library/Frameworks/Python.framework/Versions/3.8/lib/python3.8/site-packages/requests/sessions.py", line 533, in request
    resp = self.send(prep, **send_kwargs)
  File "/Library/Frameworks/Python.framework/Versions/3.8/lib/python3.8/site-packages/requests/sessions.py", line 646, in send
    r = adapter.send(request, **kwargs)
  File "/Library/Frameworks/Python.framework/Versions/3.8/lib/python3.8/site-packages/requests/adapters.py", line 516, in send
    raise ConnectionError(e, request=request)
requests.exceptions.ConnectionError: HTTPSConnectionPool(host='api.binance.com', port=443): Max retries exceeded with url: /api/v1/ping (Caused by NewConnectionError('<urllib3.connection.VerifiedHTTPSConnection object at 0x7fb180aaeac0>: Failed to establish a new connection: [Errno 8] nodename nor servname provided, or not known'))
Traceback (most recent call last):
  File "email_send.py", line 131, in <module>
    server = smtplib.SMTP('smtp.gmail.com', 587) 
  File "/Library/Frameworks/Python.framework/Versions/3.8/lib/python3.8/smtplib.py", line 253, in __init__
    (code, msg) = self.connect(host, port)
  File "/Library/Frameworks/Python.framework/Versions/3.8/lib/python3.8/smtplib.py", line 339, in connect
    self.sock = self._get_socket(host, port, self.timeout)
  File "/Library/Frameworks/Python.framework/Versions/3.8/lib/python3.8/smtplib.py", line 308, in _get_socket
    return socket.create_connection((host, port), timeout,
  File "/Library/Frameworks/Python.framework/Versions/3.8/lib/python3.8/socket.py", line 787, in create_connection
    for res in getaddrinfo(host, port, 0, SOCK_STREAM):
  File "/Library/Frameworks/Python.framework/Versions/3.8/lib/python3.8/socket.py", line 914, in getaddrinfo
    for res in _socket.getaddrinfo(host, port, family, type, proto, flags):
socket.gaierror: [Errno 8] nodename nor servname provided, or not known
Mon Nov  2 01:34:01 CST 2020
Traceback (most recent call last):
  File "/Library/Frameworks/Python.framework/Versions/3.8/lib/python3.8/site-packages/urllib3/connection.py", line 156, in _new_conn
    conn = connection.create_connection(
  File "/Library/Frameworks/Python.framework/Versions/3.8/lib/python3.8/site-packages/urllib3/util/connection.py", line 61, in create_connection
    for res in socket.getaddrinfo(host, port, family, socket.SOCK_STREAM):
  File "/Library/Frameworks/Python.framework/Versions/3.8/lib/python3.8/socket.py", line 914, in getaddrinfo
    for res in _socket.getaddrinfo(host, port, family, type, proto, flags):
socket.gaierror: [Errno 8] nodename nor servname provided, or not known

During handling of the above exception, another exception occurred:

Traceback (most recent call last):
  File "/Library/Frameworks/Python.framework/Versions/3.8/lib/python3.8/site-packages/urllib3/connectionpool.py", line 665, in urlopen
    httplib_response = self._make_request(
  File "/Library/Frameworks/Python.framework/Versions/3.8/lib/python3.8/site-packages/urllib3/connectionpool.py", line 376, in _make_request
    self._validate_conn(conn)
  File "/Library/Frameworks/Python.framework/Versions/3.8/lib/python3.8/site-packages/urllib3/connectionpool.py", line 994, in _validate_conn
    conn.connect()
  File "/Library/Frameworks/Python.framework/Versions/3.8/lib/python3.8/site-packages/urllib3/connection.py", line 334, in connect
    conn = self._new_conn()
  File "/Library/Frameworks/Python.framework/Versions/3.8/lib/python3.8/site-packages/urllib3/connection.py", line 168, in _new_conn
    raise NewConnectionError(
urllib3.exceptions.NewConnectionError: <urllib3.connection.VerifiedHTTPSConnection object at 0x7f87072ada90>: Failed to establish a new connection: [Errno 8] nodename nor servname provided, or not known

During handling of the above exception, another exception occurred:

Traceback (most recent call last):
  File "/Library/Frameworks/Python.framework/Versions/3.8/lib/python3.8/site-packages/requests/adapters.py", line 439, in send
    resp = conn.urlopen(
  File "/Library/Frameworks/Python.framework/Versions/3.8/lib/python3.8/site-packages/urllib3/connectionpool.py", line 719, in urlopen
    retries = retries.increment(
  File "/Library/Frameworks/Python.framework/Versions/3.8/lib/python3.8/site-packages/urllib3/util/retry.py", line 436, in increment
    raise MaxRetryError(_pool, url, error or ResponseError(cause))
urllib3.exceptions.MaxRetryError: HTTPSConnectionPool(host='api.binance.com', port=443): Max retries exceeded with url: /api/v1/ping (Caused by NewConnectionError('<urllib3.connection.VerifiedHTTPSConnection object at 0x7f87072ada90>: Failed to establish a new connection: [Errno 8] nodename nor servname provided, or not known'))

During handling of the above exception, another exception occurred:

Traceback (most recent call last):
  File "./MACD/get_Binance.py", line 26, in <module>
    client = Client(api_key, api_secret)
  File "/Library/Frameworks/Python.framework/Versions/3.8/lib/python3.8/site-packages/binance/client.py", line 97, in __init__
    self.ping()
  File "/Library/Frameworks/Python.framework/Versions/3.8/lib/python3.8/site-packages/binance/client.py", line 378, in ping
    return self._get('ping')
  File "/Library/Frameworks/Python.framework/Versions/3.8/lib/python3.8/site-packages/binance/client.py", line 222, in _get
    return self._request_api('get', path, signed, version, **kwargs)
  File "/Library/Frameworks/Python.framework/Versions/3.8/lib/python3.8/site-packages/binance/client.py", line 191, in _request_api
    return self._request(method, uri, signed, **kwargs)
  File "/Library/Frameworks/Python.framework/Versions/3.8/lib/python3.8/site-packages/binance/client.py", line 185, in _request
    self.response = getattr(self.session, method)(uri, **kwargs)
  File "/Library/Frameworks/Python.framework/Versions/3.8/lib/python3.8/site-packages/requests/sessions.py", line 546, in get
    return self.request('GET', url, **kwargs)
  File "/Library/Frameworks/Python.framework/Versions/3.8/lib/python3.8/site-packages/requests/sessions.py", line 533, in request
    resp = self.send(prep, **send_kwargs)
  File "/Library/Frameworks/Python.framework/Versions/3.8/lib/python3.8/site-packages/requests/sessions.py", line 646, in send
    r = adapter.send(request, **kwargs)
  File "/Library/Frameworks/Python.framework/Versions/3.8/lib/python3.8/site-packages/requests/adapters.py", line 516, in send
    raise ConnectionError(e, request=request)
requests.exceptions.ConnectionError: HTTPSConnectionPool(host='api.binance.com', port=443): Max retries exceeded with url: /api/v1/ping (Caused by NewConnectionError('<urllib3.connection.VerifiedHTTPSConnection object at 0x7f87072ada90>: Failed to establish a new connection: [Errno 8] nodename nor servname provided, or not known'))
Traceback (most recent call last):
  File "email_send.py", line 131, in <module>
    server = smtplib.SMTP('smtp.gmail.com', 587) 
  File "/Library/Frameworks/Python.framework/Versions/3.8/lib/python3.8/smtplib.py", line 253, in __init__
    (code, msg) = self.connect(host, port)
  File "/Library/Frameworks/Python.framework/Versions/3.8/lib/python3.8/smtplib.py", line 339, in connect
    self.sock = self._get_socket(host, port, self.timeout)
  File "/Library/Frameworks/Python.framework/Versions/3.8/lib/python3.8/smtplib.py", line 308, in _get_socket
    return socket.create_connection((host, port), timeout,
  File "/Library/Frameworks/Python.framework/Versions/3.8/lib/python3.8/socket.py", line 787, in create_connection
    for res in getaddrinfo(host, port, 0, SOCK_STREAM):
  File "/Library/Frameworks/Python.framework/Versions/3.8/lib/python3.8/socket.py", line 914, in getaddrinfo
    for res in _socket.getaddrinfo(host, port, family, type, proto, flags):
socket.gaierror: [Errno 8] nodename nor servname provided, or not known
Mon Nov  2 22:09:20 CST 2020
Traceback (most recent call last):
  File "/Library/Frameworks/Python.framework/Versions/3.8/lib/python3.8/site-packages/urllib3/connection.py", line 156, in _new_conn
    conn = connection.create_connection(
  File "/Library/Frameworks/Python.framework/Versions/3.8/lib/python3.8/site-packages/urllib3/util/connection.py", line 61, in create_connection
    for res in socket.getaddrinfo(host, port, family, socket.SOCK_STREAM):
  File "/Library/Frameworks/Python.framework/Versions/3.8/lib/python3.8/socket.py", line 914, in getaddrinfo
    for res in _socket.getaddrinfo(host, port, family, type, proto, flags):
socket.gaierror: [Errno 8] nodename nor servname provided, or not known

During handling of the above exception, another exception occurred:

Traceback (most recent call last):
  File "/Library/Frameworks/Python.framework/Versions/3.8/lib/python3.8/site-packages/urllib3/connectionpool.py", line 665, in urlopen
    httplib_response = self._make_request(
  File "/Library/Frameworks/Python.framework/Versions/3.8/lib/python3.8/site-packages/urllib3/connectionpool.py", line 376, in _make_request
    self._validate_conn(conn)
  File "/Library/Frameworks/Python.framework/Versions/3.8/lib/python3.8/site-packages/urllib3/connectionpool.py", line 994, in _validate_conn
    conn.connect()
  File "/Library/Frameworks/Python.framework/Versions/3.8/lib/python3.8/site-packages/urllib3/connection.py", line 334, in connect
    conn = self._new_conn()
  File "/Library/Frameworks/Python.framework/Versions/3.8/lib/python3.8/site-packages/urllib3/connection.py", line 168, in _new_conn
    raise NewConnectionError(
urllib3.exceptions.NewConnectionError: <urllib3.connection.VerifiedHTTPSConnection object at 0x7fa44e2d6a90>: Failed to establish a new connection: [Errno 8] nodename nor servname provided, or not known

During handling of the above exception, another exception occurred:

Traceback (most recent call last):
  File "/Library/Frameworks/Python.framework/Versions/3.8/lib/python3.8/site-packages/requests/adapters.py", line 439, in send
    resp = conn.urlopen(
  File "/Library/Frameworks/Python.framework/Versions/3.8/lib/python3.8/site-packages/urllib3/connectionpool.py", line 719, in urlopen
    retries = retries.increment(
  File "/Library/Frameworks/Python.framework/Versions/3.8/lib/python3.8/site-packages/urllib3/util/retry.py", line 436, in increment
    raise MaxRetryError(_pool, url, error or ResponseError(cause))
urllib3.exceptions.MaxRetryError: HTTPSConnectionPool(host='api.binance.com', port=443): Max retries exceeded with url: /api/v1/ping (Caused by NewConnectionError('<urllib3.connection.VerifiedHTTPSConnection object at 0x7fa44e2d6a90>: Failed to establish a new connection: [Errno 8] nodename nor servname provided, or not known'))

During handling of the above exception, another exception occurred:

Traceback (most recent call last):
  File "./MACD/get_Binance.py", line 26, in <module>
    client = Client(api_key, api_secret)
  File "/Library/Frameworks/Python.framework/Versions/3.8/lib/python3.8/site-packages/binance/client.py", line 97, in __init__
    self.ping()
  File "/Library/Frameworks/Python.framework/Versions/3.8/lib/python3.8/site-packages/binance/client.py", line 378, in ping
    return self._get('ping')
  File "/Library/Frameworks/Python.framework/Versions/3.8/lib/python3.8/site-packages/binance/client.py", line 222, in _get
    return self._request_api('get', path, signed, version, **kwargs)
  File "/Library/Frameworks/Python.framework/Versions/3.8/lib/python3.8/site-packages/binance/client.py", line 191, in _request_api
    return self._request(method, uri, signed, **kwargs)
  File "/Library/Frameworks/Python.framework/Versions/3.8/lib/python3.8/site-packages/binance/client.py", line 185, in _request
    self.response = getattr(self.session, method)(uri, **kwargs)
  File "/Library/Frameworks/Python.framework/Versions/3.8/lib/python3.8/site-packages/requests/sessions.py", line 546, in get
    return self.request('GET', url, **kwargs)
  File "/Library/Frameworks/Python.framework/Versions/3.8/lib/python3.8/site-packages/requests/sessions.py", line 533, in request
    resp = self.send(prep, **send_kwargs)
  File "/Library/Frameworks/Python.framework/Versions/3.8/lib/python3.8/site-packages/requests/sessions.py", line 646, in send
    r = adapter.send(request, **kwargs)
  File "/Library/Frameworks/Python.framework/Versions/3.8/lib/python3.8/site-packages/requests/adapters.py", line 516, in send
    raise ConnectionError(e, request=request)
requests.exceptions.ConnectionError: HTTPSConnectionPool(host='api.binance.com', port=443): Max retries exceeded with url: /api/v1/ping (Caused by NewConnectionError('<urllib3.connection.VerifiedHTTPSConnection object at 0x7fa44e2d6a90>: Failed to establish a new connection: [Errno 8] nodename nor servname provided, or not known'))
Traceback (most recent call last):
  File "email_send.py", line 131, in <module>
    server = smtplib.SMTP('smtp.gmail.com', 587) 
  File "/Library/Frameworks/Python.framework/Versions/3.8/lib/python3.8/smtplib.py", line 253, in __init__
    (code, msg) = self.connect(host, port)
  File "/Library/Frameworks/Python.framework/Versions/3.8/lib/python3.8/smtplib.py", line 339, in connect
    self.sock = self._get_socket(host, port, self.timeout)
  File "/Library/Frameworks/Python.framework/Versions/3.8/lib/python3.8/smtplib.py", line 308, in _get_socket
    return socket.create_connection((host, port), timeout,
  File "/Library/Frameworks/Python.framework/Versions/3.8/lib/python3.8/socket.py", line 787, in create_connection
    for res in getaddrinfo(host, port, 0, SOCK_STREAM):
  File "/Library/Frameworks/Python.framework/Versions/3.8/lib/python3.8/socket.py", line 914, in getaddrinfo
    for res in _socket.getaddrinfo(host, port, family, type, proto, flags):
socket.gaierror: [Errno 8] nodename nor servname provided, or not known
Mon Nov  2 22:10:00 CST 2020
Traceback (most recent call last):
  File "/Library/Frameworks/Python.framework/Versions/3.8/lib/python3.8/site-packages/urllib3/connection.py", line 156, in _new_conn
    conn = connection.create_connection(
  File "/Library/Frameworks/Python.framework/Versions/3.8/lib/python3.8/site-packages/urllib3/util/connection.py", line 61, in create_connection
    for res in socket.getaddrinfo(host, port, family, socket.SOCK_STREAM):
  File "/Library/Frameworks/Python.framework/Versions/3.8/lib/python3.8/socket.py", line 914, in getaddrinfo
    for res in _socket.getaddrinfo(host, port, family, type, proto, flags):
socket.gaierror: [Errno 8] nodename nor servname provided, or not known

During handling of the above exception, another exception occurred:

Traceback (most recent call last):
  File "/Library/Frameworks/Python.framework/Versions/3.8/lib/python3.8/site-packages/urllib3/connectionpool.py", line 665, in urlopen
    httplib_response = self._make_request(
  File "/Library/Frameworks/Python.framework/Versions/3.8/lib/python3.8/site-packages/urllib3/connectionpool.py", line 376, in _make_request
    self._validate_conn(conn)
  File "/Library/Frameworks/Python.framework/Versions/3.8/lib/python3.8/site-packages/urllib3/connectionpool.py", line 994, in _validate_conn
    conn.connect()
  File "/Library/Frameworks/Python.framework/Versions/3.8/lib/python3.8/site-packages/urllib3/connection.py", line 334, in connect
    conn = self._new_conn()
  File "/Library/Frameworks/Python.framework/Versions/3.8/lib/python3.8/site-packages/urllib3/connection.py", line 168, in _new_conn
    raise NewConnectionError(
urllib3.exceptions.NewConnectionError: <urllib3.connection.VerifiedHTTPSConnection object at 0x7fd31e2d9b50>: Failed to establish a new connection: [Errno 8] nodename nor servname provided, or not known

During handling of the above exception, another exception occurred:

Traceback (most recent call last):
  File "/Library/Frameworks/Python.framework/Versions/3.8/lib/python3.8/site-packages/requests/adapters.py", line 439, in send
    resp = conn.urlopen(
  File "/Library/Frameworks/Python.framework/Versions/3.8/lib/python3.8/site-packages/urllib3/connectionpool.py", line 719, in urlopen
    retries = retries.increment(
  File "/Library/Frameworks/Python.framework/Versions/3.8/lib/python3.8/site-packages/urllib3/util/retry.py", line 436, in increment
    raise MaxRetryError(_pool, url, error or ResponseError(cause))
urllib3.exceptions.MaxRetryError: HTTPSConnectionPool(host='api.binance.com', port=443): Max retries exceeded with url: /api/v1/ping (Caused by NewConnectionError('<urllib3.connection.VerifiedHTTPSConnection object at 0x7fd31e2d9b50>: Failed to establish a new connection: [Errno 8] nodename nor servname provided, or not known'))

During handling of the above exception, another exception occurred:

Traceback (most recent call last):
  File "./MACD/get_Binance.py", line 26, in <module>
    client = Client(api_key, api_secret)
  File "/Library/Frameworks/Python.framework/Versions/3.8/lib/python3.8/site-packages/binance/client.py", line 97, in __init__
    self.ping()
  File "/Library/Frameworks/Python.framework/Versions/3.8/lib/python3.8/site-packages/binance/client.py", line 378, in ping
    return self._get('ping')
  File "/Library/Frameworks/Python.framework/Versions/3.8/lib/python3.8/site-packages/binance/client.py", line 222, in _get
    return self._request_api('get', path, signed, version, **kwargs)
  File "/Library/Frameworks/Python.framework/Versions/3.8/lib/python3.8/site-packages/binance/client.py", line 191, in _request_api
    return self._request(method, uri, signed, **kwargs)
  File "/Library/Frameworks/Python.framework/Versions/3.8/lib/python3.8/site-packages/binance/client.py", line 185, in _request
    self.response = getattr(self.session, method)(uri, **kwargs)
  File "/Library/Frameworks/Python.framework/Versions/3.8/lib/python3.8/site-packages/requests/sessions.py", line 546, in get
    return self.request('GET', url, **kwargs)
  File "/Library/Frameworks/Python.framework/Versions/3.8/lib/python3.8/site-packages/requests/sessions.py", line 533, in request
    resp = self.send(prep, **send_kwargs)
  File "/Library/Frameworks/Python.framework/Versions/3.8/lib/python3.8/site-packages/requests/sessions.py", line 646, in send
    r = adapter.send(request, **kwargs)
  File "/Library/Frameworks/Python.framework/Versions/3.8/lib/python3.8/site-packages/requests/adapters.py", line 516, in send
    raise ConnectionError(e, request=request)
requests.exceptions.ConnectionError: HTTPSConnectionPool(host='api.binance.com', port=443): Max retries exceeded with url: /api/v1/ping (Caused by NewConnectionError('<urllib3.connection.VerifiedHTTPSConnection object at 0x7fd31e2d9b50>: Failed to establish a new connection: [Errno 8] nodename nor servname provided, or not known'))
Traceback (most recent call last):
  File "email_send.py", line 131, in <module>
    server = smtplib.SMTP('smtp.gmail.com', 587) 
  File "/Library/Frameworks/Python.framework/Versions/3.8/lib/python3.8/smtplib.py", line 253, in __init__
    (code, msg) = self.connect(host, port)
  File "/Library/Frameworks/Python.framework/Versions/3.8/lib/python3.8/smtplib.py", line 339, in connect
    self.sock = self._get_socket(host, port, self.timeout)
  File "/Library/Frameworks/Python.framework/Versions/3.8/lib/python3.8/smtplib.py", line 308, in _get_socket
    return socket.create_connection((host, port), timeout,
  File "/Library/Frameworks/Python.framework/Versions/3.8/lib/python3.8/socket.py", line 787, in create_connection
    for res in getaddrinfo(host, port, 0, SOCK_STREAM):
  File "/Library/Frameworks/Python.framework/Versions/3.8/lib/python3.8/socket.py", line 914, in getaddrinfo
    for res in _socket.getaddrinfo(host, port, family, type, proto, flags):
socket.gaierror: [Errno 8] nodename nor servname provided, or not known
Mon Nov  2 22:12:00 CST 2020
Predict_price 1.0596585531930025 394
Predict_Sell_price -1.0463243527899528 361
0.3314990090334497
Execute-Time: 1.6028800010681152
Mon Nov  2 22:14:00 CST 2020
Predict_price 1.0596585531930025 394
Predict_Sell_price -1.0463243527899528 361
0.3059719435063464
Execute-Time: 2.5516018867492676
Mon Nov  2 22:16:00 CST 2020
Predict_price 1.0596585531930025 394
Predict_Sell_price -1.0463243527899528 361
0.3034192369536406
Execute-Time: 1.608891248703003
Mon Nov  2 22:18:00 CST 2020
Predict_price 1.0596585531930025 394
Predict_Sell_price -1.0463243527899528 361
0.32001182954627366
Execute-Time: 1.6806120872497559
Mon Nov  2 22:20:00 CST 2020
Predict_price 1.0596585531930025 394
Predict_Sell_price -1.0463243527899528 361
0.2912938808282881
Execute-Time: 1.7194631099700928
Mon Nov  2 22:22:00 CST 2020
Predict_price 1.0596585531930025 394
Predict_Sell_price -1.0463243527899528 361
0.3193736529080972
Execute-Time: 3.5088350772857666
Mon Nov  2 22:24:00 CST 2020
Predict_price 1.0596585531930025 394
Predict_Sell_price -1.0463243527899528 361
0.3423480118824493
Execute-Time: 1.5293428897857666
Mon Nov  2 22:26:00 CST 2020
Predict_price 1.0596585531930025 394
Predict_Sell_price -1.0463243527899528 361
0.35447336800780177
Execute-Time: 1.4094769954681396
Mon Nov  2 22:28:00 CST 2020
Predict_price 1.0596585531930025 394
Predict_Sell_price -1.0463243527899528 361
0.3531970147314489
Execute-Time: 1.404155969619751
Mon Nov  2 22:30:00 CST 2020
Predict_price 1.0596585531930025 394
Predict_Sell_price -1.0463243527899528 361
0.3780859036203303
Execute-Time: 1.520369291305542
Mon Nov  2 22:32:00 CST 2020
Predict_price 1.0596585531930025 394
Predict_Sell_price -1.0463243527899528 361
0.36532237085680136
Execute-Time: 1.5500233173370361
Mon Nov  2 22:34:00 CST 2020
Predict_price 1.0596585531930025 394
Predict_Sell_price -1.0463243527899528 361
0.42148191501632865
Execute-Time: 1.6795198917388916
Mon Nov  2 22:36:00 CST 2020
Predict_price 1.0596585531930025 394
Predict_Sell_price -1.0463243527899528 361
0.43743633097078527
Execute-Time: 1.753403902053833
Mon Nov  2 22:38:01 CST 2020
Predict_price 1.0596585531930025 394
Predict_Sell_price -1.0463243527899528 361
0.45339074692519643
Execute-Time: 1.5162341594696045
Mon Nov  2 22:40:00 CST 2020
Predict_price 1.0596585531930025 394
Predict_Sell_price -1.0463243527899528 361
0.5140175275519588
Alert: 77400.13520812988
Execute-Time: 1.57440185546875
Mon Nov  2 22:42:00 CST 2020
Predict_price 1.0596585531930025 394
Predict_Sell_price -1.0463243527899528 361
0.5069975845319725
Alert: 120.78555083274841
Execute-Time: 1.7973980903625488
Mon Nov  2 22:44:00 CST 2020
Predict_price 1.0596585531930025 394
Predict_Sell_price -1.0463243527899528 361
0.5012539947884299
Alert: 240.82160592079163
Execute-Time: 1.7544910907745361
Mon Nov  2 22:46:00 CST 2020
Predict_price 1.0596585531930025 394
Predict_Sell_price -1.0463243527899528 361
0.52997194350637
Alert: 360.5531237125397
Execute-Time: 1.7586021423339844
Mon Nov  2 22:48:00 CST 2020
Predict_price 1.0596585531930025 394
Predict_Sell_price -1.0463243527899528 361
0.519122940657325
Alert: 483.5399248600006
Execute-Time: 2.053845167160034
Mon Nov  2 22:50:01 CST 2020
Predict_price 1.0596585531930025 394
Predict_Sell_price -1.0463243527899528 361
0.4987012882357241
Alert: 601.0947849750519
Execute-Time: 1.8405330181121826
Mon Nov  2 22:52:00 CST 2020
Predict_price 1.0596585531930025 394
Predict_Sell_price -1.0463243527899528 361
0.499977641512077
Alert: 719.895124912262
Execute-Time: 1.6651592254638672
Mon Nov  2 22:54:00 CST 2020
Predict_price 1.0596585531930025 394
Predict_Sell_price -1.0463243527899528 361
0.5089121144465473
Alert: 842.7632730007172
Execute-Time: 2.2525901794433594
Mon Nov  2 22:56:00 CST 2020
Predict_price 1.0596585531930025 394
Predict_Sell_price -1.0463243527899528 361
0.470621516155915
Execute-Time: 1.6682791709899902
Mon Nov  2 22:58:00 CST 2020
Predict_price 1.0596585531930025 394
Predict_Sell_price -1.0463243527899528 361
0.4897668153012539
Execute-Time: 1.926455020904541
Mon Nov  2 23:00:01 CST 2020
Predict_price 1.0596585531930025 394
Predict_Sell_price -1.0463243527899528 361
0.5152938808283117
Alert: 1201.8574757575989
Execute-Time: 2.5909056663513184
Mon Nov  2 23:02:00 CST 2020
Predict_price 1.0596585531930025 394
Predict_Sell_price -1.0463243527899528 361
0.46423974977415056
Execute-Time: 1.3554880619049072
Mon Nov  2 23:04:00 CST 2020
Predict_price 1.0596585531930025 394
Predict_Sell_price -1.0463243527899528 361
0.45466710020150386
Execute-Time: 1.57468581199646
Mon Nov  2 23:06:00 CST 2020
Predict_price 1.0596585531930025 394
Predict_Sell_price -1.0463243527899528 361
0.45466710020150386
Execute-Time: 1.3034889698028564
Mon Nov  2 23:08:00 CST 2020
Predict_price 1.0596585531930025 394
Predict_Sell_price -1.0463243527899528 361
0.4342454477798576
Execute-Time: 1.5144801139831543
Mon Nov  2 23:10:00 CST 2020
Predict_price 1.0596585531930025 394
Predict_Sell_price -1.0463243527899528 361
0.4623252198596667
Execute-Time: 1.6848750114440918
Mon Nov  2 23:12:00 CST 2020
Predict_price 1.0596585531930025 394
Predict_Sell_price -1.0463243527899528 361
0.4655161030505489
Execute-Time: 1.7025060653686523
Mon Nov  2 23:14:00 CST 2020
Predict_price 1.0596585531930025 394
Predict_Sell_price -1.0463243527899528 361
0.45658163011607866
Execute-Time: 1.5381739139556885
Mon Nov  2 23:16:00 CST 2020
Predict_price 1.0596585531930025 394
Predict_Sell_price -1.0463243527899528 361
0.4623252198596667
Execute-Time: 1.479506254196167
Mon Nov  2 23:18:00 CST 2020
Predict_price 1.0596585531930025 394
Predict_Sell_price -1.0463243527899528 361
0.49614858168301834
Alert: 1077.3103051185608
Execute-Time: 1.8274221420288086
Mon Nov  2 23:20:00 CST 2020
Predict_price 1.0596585531930025 394
Predict_Sell_price -1.0463243527899528 361
0.5038067013410903
Alert: 122.38621211051941
Execute-Time: 2.160273790359497
Mon Nov  2 23:22:00 CST 2020
Predict_price 1.0596585531930025 394
Predict_Sell_price -1.0463243527899528 361
0.4750887526231956
Execute-Time: 1.8096821308135986
Mon Nov  2 23:24:00 CST 2020
Predict_price 1.0596585531930025 394
Predict_Sell_price -1.0463243527899528 361
0.47572692926137206
Execute-Time: 1.8587920665740967
Mon Nov  2 23:26:00 CST 2020
Predict_price 1.0596585531930025 394
Predict_Sell_price -1.0463243527899528 361
0.49487222840662
Alert: 480.150573015213
Execute-Time: 1.6384859085083008
Mon Nov  2 23:28:00 CST 2020
Predict_price 1.0596585531930025 394
Predict_Sell_price -1.0463243527899528 361
0.5152938808283117
Alert: 600.9503800868988
Execute-Time: 1.657804012298584
Mon Nov  2 23:30:00 CST 2020
Predict_price 1.0596585531930025 394
Predict_Sell_price -1.0463243527899528 361
0.5203992939337233
Alert: 721.3872790336609
Execute-Time: 1.8882513046264648
Mon Nov  2 23:32:00 CST 2020
Predict_price 1.0596585531930025 394
Predict_Sell_price -1.0463243527899528 361
0.4955104050448419
Alert: 841.2179718017578
Execute-Time: 1.634984016418457
Mon Nov  2 23:34:00 CST 2020
Predict_price 1.0596585531930025 394
Predict_Sell_price -1.0463243527899528 361
0.5159320574664882
Alert: 961.4799809455872
Execute-Time: 1.6862680912017822
Mon Nov  2 23:36:00 CST 2020
Predict_price 1.0596585531930025 394
Predict_Sell_price -1.0463243527899528 361
0.6174021429365887
Alert: 119.12955403327942
Execute-Time: 1.4981708526611328
Mon Nov  2 23:38:00 CST 2020
Predict_price 1.0596585531930025 394
Predict_Sell_price -1.0463243527899528 361
0.5733679549023684
Alert: 238.65278100967407
Execute-Time: 1.550750970840454
Mon Nov  2 23:40:00 CST 2020
Predict_price 1.0596585531930025 394
Predict_Sell_price -1.0463243527899528 361
0.5937896073240146
Alert: 359.62174224853516
Execute-Time: 1.5472888946533203
Mon Nov  2 23:42:01 CST 2020
Predict_price 1.0596585531930025 394
Predict_Sell_price -1.0463243527899528 361
0.5676243651587803
Alert: 477.47859621047974
Execute-Time: 1.4714796543121338
Mon Nov  2 23:44:00 CST 2020
Predict_price 1.0596585531930025 394
Predict_Sell_price -1.0463243527899528 361
0.5931514306858837
Alert: 597.2600860595703
Execute-Time: 1.3900642395019531
Mon Nov  2 23:46:00 CST 2020
Predict_price 1.0596585531930025 394
Predict_Sell_price -1.0463243527899528 361
0.5701770717114861
Alert: 717.4138371944427
Execute-Time: 1.5296199321746826
Mon Nov  2 23:48:01 CST 2020
Predict_price 1.0596585531930025 394
Predict_Sell_price -1.0463243527899528 361
0.5491172426516634
Alert: 837.2299470901489
Execute-Time: 1.3860821723937988
Mon Nov  2 23:50:00 CST 2020
Predict_price 1.0596585531930025 394
Predict_Sell_price -1.0463243527899528 361
0.5408209463553696
Alert: 959.3273060321808
Execute-Time: 1.567481279373169
Mon Nov  2 23:52:00 CST 2020
Predict_price 1.0596585531930025 394
Predict_Sell_price -1.0463243527899528 361
0.5165702341046646
Alert: 119.37086582183838
Execute-Time: 1.5288138389587402
Mon Nov  2 23:54:01 CST 2020
Predict_price 1.0596585531930025 394
Predict_Sell_price -1.0463243527899528 361
0.5344391799736051
Alert: 237.80770111083984
Execute-Time: 1.3166582584381104
Mon Nov  2 23:56:00 CST 2020
Predict_price 1.0596585531930025 394
Predict_Sell_price -1.0463243527899528 361
0.5574135389479572
Alert: 357.5283410549164
Execute-Time: 1.4131100177764893
Mon Nov  2 23:58:01 CST 2020
Predict_price 1.0596585531930025 394
Predict_Sell_price -1.0463243527899528 361
0.5178465873810175
Alert: 479.8479778766632
Execute-Time: 1.6321439743041992
Tue Nov  3 00:00:00 CST 2020
Predict_price 1.0503488563321746 400
Predict_Sell_price -1.0556340496506897 367
0.08861666259999706
Execute-Time: 1.5552129745483398
Tue Nov  3 00:02:00 CST 2020
Predict_price 1.0503488563321746 400
Predict_Sell_price -1.0556340496506897 367
0.06372777371111565
Execute-Time: 1.6234028339385986
Tue Nov  3 00:04:00 CST 2020
Predict_price 1.0503488563321746 400
Predict_Sell_price -1.0556340496506897 367
0.15753973952309874
Execute-Time: 1.6445510387420654
Tue Nov  3 00:06:00 CST 2020
Predict_price 1.0503488563321746 400
Predict_Sell_price -1.0556340496506897 367
0.10265654863992435
Execute-Time: 1.4580118656158447
Tue Nov  3 00:08:01 CST 2020
Predict_price 1.0503488563321746 400
Predict_Sell_price -1.0556340496506897 367
0.07649130647464458
Execute-Time: 1.4843900203704834
Tue Nov  3 00:10:00 CST 2020
Predict_price 1.0503488563321746 400
Predict_Sell_price -1.0556340496506897 367
0.09755113553446731
Execute-Time: 1.6555309295654297
Tue Nov  3 00:12:00 CST 2020
Predict_price 1.0503488563321746 400
Predict_Sell_price -1.0556340496506897 367
0.11095284493621815
Execute-Time: 1.5357959270477295
Tue Nov  3 00:14:00 CST 2020
Predict_price 1.0503488563321746 400
Predict_Sell_price -1.0556340496506897 367
0.11605825804158426
Execute-Time: 1.4098429679870605
Tue Nov  3 00:16:00 CST 2020
Predict_price 1.0503488563321746 400
Predict_Sell_price -1.0556340496506897 367
0.11350555148887848
Execute-Time: 1.4827959537506104
Tue Nov  3 00:18:01 CST 2020
Predict_price 1.0503488563321746 400
Predict_Sell_price -1.0556340496506897 367
0.14796708995045205
Execute-Time: 1.6332459449768066
Tue Nov  3 00:20:00 CST 2020
Predict_price 1.0503488563321746 400
Predict_Sell_price -1.0556340496506897 367
0.1294599674433351
Execute-Time: 1.5464656352996826
Tue Nov  3 00:22:00 CST 2020
Predict_price 1.0503488563321746 400
Predict_Sell_price -1.0556340496506897 367
0.09436025234358508
Execute-Time: 1.5806670188903809
Tue Nov  3 00:24:00 CST 2020
Predict_price 1.0503488563321746 400
Predict_Sell_price -1.0556340496506897 367
0.10457107855440823
Execute-Time: 1.5305640697479248
Tue Nov  3 00:26:01 CST 2020
Predict_price 1.0503488563321746 400
Predict_Sell_price -1.0556340496506897 367
0.1020183720017479
Execute-Time: 1.5693330764770508
Tue Nov  3 00:28:00 CST 2020
Predict_price 1.0503488563321746 400
Predict_Sell_price -1.0556340496506897 367
0.09627478225815989
Execute-Time: 1.3772430419921875
Tue Nov  3 00:30:00 CST 2020
Predict_price 1.0503488563321746 400
Predict_Sell_price -1.0556340496506897 367
0.0905311925145264
Execute-Time: 1.6198530197143555
Tue Nov  3 00:32:00 CST 2020
Predict_price 1.0503488563321746 400
Predict_Sell_price -1.0556340496506897 367
0.10648560846893756
Execute-Time: 1.5613799095153809
Tue Nov  3 00:34:00 CST 2020
Predict_price 1.0503488563321746 400
Predict_Sell_price -1.0556340496506897 367
0.08032036630370326
Execute-Time: 1.4909851551055908
Tue Nov  3 00:36:00 CST 2020
Predict_price 1.0503488563321746 400
Predict_Sell_price -1.0556340496506897 367
0.06053689052023342
Execute-Time: 1.65867280960083
Tue Nov  3 00:38:00 CST 2020
Predict_price 1.0503488563321746 400
Predict_Sell_price -1.0556340496506897 367
0.06755683354017433
Execute-Time: 1.3951332569122314
Tue Nov  3 00:40:00 CST 2020
Predict_price 1.0503488563321746 400
Predict_Sell_price -1.0556340496506897 367
0.08606395604729128
Execute-Time: 1.3077239990234375
Tue Nov  3 00:42:00 CST 2020
Predict_price 1.0503488563321746 400
Predict_Sell_price -1.0556340496506897 367
0.08670213268551319
Execute-Time: 1.3498120307922363
Tue Nov  3 00:44:00 CST 2020
Predict_price 1.0503488563321746 400
Predict_Sell_price -1.0556340496506897 367
0.1001038420871731
Execute-Time: 1.280324935913086
Tue Nov  3 00:46:00 CST 2020
Predict_price 1.0503488563321746 400
Predict_Sell_price -1.0556340496506897 367
0.08351124949463096
Execute-Time: 1.3114330768585205
Tue Nov  3 00:48:01 CST 2020
Predict_price 1.0503488563321746 400
Predict_Sell_price -1.0556340496506897 367
0.09563660561998344
Execute-Time: 1.2829408645629883
Tue Nov  3 00:50:00 CST 2020
Predict_price 1.0503488563321746 400
Predict_Sell_price -1.0556340496506897 367
0.1390326170159818
Execute-Time: 1.3588261604309082
Tue Nov  3 00:52:01 CST 2020
Predict_price 1.0503488563321746 400
Predict_Sell_price -1.0556340496506897 367
0.11350555148887848
Execute-Time: 1.400888204574585
Tue Nov  3 00:54:00 CST 2020
Predict_price 1.0503488563321746 400
Predict_Sell_price -1.0556340496506897 367
0.08734030932368964
Execute-Time: 1.401249885559082
Tue Nov  3 00:56:00 CST 2020
Predict_price 1.0503488563321746 400
Predict_Sell_price -1.0556340496506897 367
0.09627478225815989
Execute-Time: 1.6500020027160645
Tue Nov  3 00:58:00 CST 2020
Predict_price 1.0503488563321746 400
Predict_Sell_price -1.0556340496506897 367
0.08861666259999706
Execute-Time: 1.37418794631958
Tue Nov  3 01:00:00 CST 2020
Predict_price 1.0503488563321746 400
Predict_Sell_price -1.0556340496506897 367
0.1543488563322165
Execute-Time: 1.563019037246704
Tue Nov  3 01:02:00 CST 2020
Predict_price 1.0503488563321746 400
Predict_Sell_price -1.0556340496506897 367
0.12754543752880576
Execute-Time: 1.5622789859771729
Tue Nov  3 01:04:00 CST 2020
Predict_price 1.0503488563321746 400
Predict_Sell_price -1.0556340496506897 367
0.10903831502168881
Execute-Time: 1.5310819149017334
Tue Nov  3 01:06:00 CST 2020
Predict_price 1.0503488563321746 400
Predict_Sell_price -1.0556340496506897 367
0.09627478225815989
Execute-Time: 1.5905160903930664
Tue Nov  3 01:08:00 CST 2020
Predict_price 1.0503488563321746 400
Predict_Sell_price -1.0556340496506897 367
0.11605825804158426
Execute-Time: 1.8296337127685547
Tue Nov  3 01:10:00 CST 2020
Predict_price 1.0503488563321746 400
Predict_Sell_price -1.0556340496506897 367
0.0905311925145264
Execute-Time: 1.8104619979858398
Tue Nov  3 01:12:01 CST 2020
Predict_price 1.0503488563321746 400
Predict_Sell_price -1.0556340496506897 367
0.10520925519263014
Execute-Time: 1.7398490905761719
Tue Nov  3 01:14:00 CST 2020
Predict_price 1.0503488563321746 400
Predict_Sell_price -1.0556340496506897 367
0.10776196174533592
Execute-Time: 2.5338640213012695
Tue Nov  3 01:16:00 CST 2020
Predict_price 1.0503488563321746 400
Predict_Sell_price -1.0556340496506897 367
0.1639215059048632
Execute-Time: 1.7437360286712646
Tue Nov  3 01:18:00 CST 2020
Predict_price 1.0503488563321746 400
Predict_Sell_price -1.0556340496506897 367
0.15753973952309874
Execute-Time: 1.7032039165496826
Tue Nov  3 01:20:00 CST 2020
Predict_price 1.0503488563321746 400
Predict_Sell_price -1.0556340496506897 367
0.16455968254303965
Execute-Time: 1.5558719635009766
Tue Nov  3 17:06:00 CST 2020
Traceback (most recent call last):
  File "/Library/Frameworks/Python.framework/Versions/3.8/lib/python3.8/site-packages/urllib3/connection.py", line 156, in _new_conn
    conn = connection.create_connection(
  File "/Library/Frameworks/Python.framework/Versions/3.8/lib/python3.8/site-packages/urllib3/util/connection.py", line 61, in create_connection
    for res in socket.getaddrinfo(host, port, family, socket.SOCK_STREAM):
  File "/Library/Frameworks/Python.framework/Versions/3.8/lib/python3.8/socket.py", line 914, in getaddrinfo
    for res in _socket.getaddrinfo(host, port, family, type, proto, flags):
socket.gaierror: [Errno 8] nodename nor servname provided, or not known

During handling of the above exception, another exception occurred:

Traceback (most recent call last):
  File "/Library/Frameworks/Python.framework/Versions/3.8/lib/python3.8/site-packages/urllib3/connectionpool.py", line 665, in urlopen
    httplib_response = self._make_request(
  File "/Library/Frameworks/Python.framework/Versions/3.8/lib/python3.8/site-packages/urllib3/connectionpool.py", line 376, in _make_request
    self._validate_conn(conn)
  File "/Library/Frameworks/Python.framework/Versions/3.8/lib/python3.8/site-packages/urllib3/connectionpool.py", line 994, in _validate_conn
    conn.connect()
  File "/Library/Frameworks/Python.framework/Versions/3.8/lib/python3.8/site-packages/urllib3/connection.py", line 334, in connect
    conn = self._new_conn()
  File "/Library/Frameworks/Python.framework/Versions/3.8/lib/python3.8/site-packages/urllib3/connection.py", line 168, in _new_conn
    raise NewConnectionError(
urllib3.exceptions.NewConnectionError: <urllib3.connection.VerifiedHTTPSConnection object at 0x7f8f04aafb20>: Failed to establish a new connection: [Errno 8] nodename nor servname provided, or not known

During handling of the above exception, another exception occurred:

Traceback (most recent call last):
  File "/Library/Frameworks/Python.framework/Versions/3.8/lib/python3.8/site-packages/requests/adapters.py", line 439, in send
    resp = conn.urlopen(
  File "/Library/Frameworks/Python.framework/Versions/3.8/lib/python3.8/site-packages/urllib3/connectionpool.py", line 719, in urlopen
    retries = retries.increment(
  File "/Library/Frameworks/Python.framework/Versions/3.8/lib/python3.8/site-packages/urllib3/util/retry.py", line 436, in increment
    raise MaxRetryError(_pool, url, error or ResponseError(cause))
urllib3.exceptions.MaxRetryError: HTTPSConnectionPool(host='api.binance.com', port=443): Max retries exceeded with url: /api/v1/ping (Caused by NewConnectionError('<urllib3.connection.VerifiedHTTPSConnection object at 0x7f8f04aafb20>: Failed to establish a new connection: [Errno 8] nodename nor servname provided, or not known'))

During handling of the above exception, another exception occurred:

Traceback (most recent call last):
  File "./MACD/get_Binance.py", line 26, in <module>
    client = Client(api_key, api_secret)
  File "/Library/Frameworks/Python.framework/Versions/3.8/lib/python3.8/site-packages/binance/client.py", line 97, in __init__
    self.ping()
  File "/Library/Frameworks/Python.framework/Versions/3.8/lib/python3.8/site-packages/binance/client.py", line 378, in ping
    return self._get('ping')
  File "/Library/Frameworks/Python.framework/Versions/3.8/lib/python3.8/site-packages/binance/client.py", line 222, in _get
    return self._request_api('get', path, signed, version, **kwargs)
  File "/Library/Frameworks/Python.framework/Versions/3.8/lib/python3.8/site-packages/binance/client.py", line 191, in _request_api
    return self._request(method, uri, signed, **kwargs)
  File "/Library/Frameworks/Python.framework/Versions/3.8/lib/python3.8/site-packages/binance/client.py", line 185, in _request
    self.response = getattr(self.session, method)(uri, **kwargs)
  File "/Library/Frameworks/Python.framework/Versions/3.8/lib/python3.8/site-packages/requests/sessions.py", line 546, in get
    return self.request('GET', url, **kwargs)
  File "/Library/Frameworks/Python.framework/Versions/3.8/lib/python3.8/site-packages/requests/sessions.py", line 533, in request
    resp = self.send(prep, **send_kwargs)
  File "/Library/Frameworks/Python.framework/Versions/3.8/lib/python3.8/site-packages/requests/sessions.py", line 646, in send
    r = adapter.send(request, **kwargs)
  File "/Library/Frameworks/Python.framework/Versions/3.8/lib/python3.8/site-packages/requests/adapters.py", line 516, in send
    raise ConnectionError(e, request=request)
requests.exceptions.ConnectionError: HTTPSConnectionPool(host='api.binance.com', port=443): Max retries exceeded with url: /api/v1/ping (Caused by NewConnectionError('<urllib3.connection.VerifiedHTTPSConnection object at 0x7f8f04aafb20>: Failed to establish a new connection: [Errno 8] nodename nor servname provided, or not known'))
Traceback (most recent call last):
  File "email_send.py", line 131, in <module>
    server = smtplib.SMTP('smtp.gmail.com', 587) 
  File "/Library/Frameworks/Python.framework/Versions/3.8/lib/python3.8/smtplib.py", line 253, in __init__
    (code, msg) = self.connect(host, port)
  File "/Library/Frameworks/Python.framework/Versions/3.8/lib/python3.8/smtplib.py", line 339, in connect
    self.sock = self._get_socket(host, port, self.timeout)
  File "/Library/Frameworks/Python.framework/Versions/3.8/lib/python3.8/smtplib.py", line 308, in _get_socket
    return socket.create_connection((host, port), timeout,
  File "/Library/Frameworks/Python.framework/Versions/3.8/lib/python3.8/socket.py", line 787, in create_connection
    for res in getaddrinfo(host, port, 0, SOCK_STREAM):
  File "/Library/Frameworks/Python.framework/Versions/3.8/lib/python3.8/socket.py", line 914, in getaddrinfo
    for res in _socket.getaddrinfo(host, port, family, type, proto, flags):
socket.gaierror: [Errno 8] nodename nor servname provided, or not known
Tue Nov  3 22:16:00 CST 2020
Traceback (most recent call last):
  File "/Library/Frameworks/Python.framework/Versions/3.8/lib/python3.8/site-packages/urllib3/connection.py", line 156, in _new_conn
    conn = connection.create_connection(
  File "/Library/Frameworks/Python.framework/Versions/3.8/lib/python3.8/site-packages/urllib3/util/connection.py", line 61, in create_connection
    for res in socket.getaddrinfo(host, port, family, socket.SOCK_STREAM):
  File "/Library/Frameworks/Python.framework/Versions/3.8/lib/python3.8/socket.py", line 914, in getaddrinfo
    for res in _socket.getaddrinfo(host, port, family, type, proto, flags):
socket.gaierror: [Errno 8] nodename nor servname provided, or not known

During handling of the above exception, another exception occurred:

Traceback (most recent call last):
  File "/Library/Frameworks/Python.framework/Versions/3.8/lib/python3.8/site-packages/urllib3/connectionpool.py", line 665, in urlopen
    httplib_response = self._make_request(
  File "/Library/Frameworks/Python.framework/Versions/3.8/lib/python3.8/site-packages/urllib3/connectionpool.py", line 376, in _make_request
    self._validate_conn(conn)
  File "/Library/Frameworks/Python.framework/Versions/3.8/lib/python3.8/site-packages/urllib3/connectionpool.py", line 994, in _validate_conn
    conn.connect()
  File "/Library/Frameworks/Python.framework/Versions/3.8/lib/python3.8/site-packages/urllib3/connection.py", line 334, in connect
    conn = self._new_conn()
  File "/Library/Frameworks/Python.framework/Versions/3.8/lib/python3.8/site-packages/urllib3/connection.py", line 168, in _new_conn
    raise NewConnectionError(
urllib3.exceptions.NewConnectionError: <urllib3.connection.VerifiedHTTPSConnection object at 0x7fd3af2adac0>: Failed to establish a new connection: [Errno 8] nodename nor servname provided, or not known

During handling of the above exception, another exception occurred:

Traceback (most recent call last):
  File "/Library/Frameworks/Python.framework/Versions/3.8/lib/python3.8/site-packages/requests/adapters.py", line 439, in send
    resp = conn.urlopen(
  File "/Library/Frameworks/Python.framework/Versions/3.8/lib/python3.8/site-packages/urllib3/connectionpool.py", line 719, in urlopen
    retries = retries.increment(
  File "/Library/Frameworks/Python.framework/Versions/3.8/lib/python3.8/site-packages/urllib3/util/retry.py", line 436, in increment
    raise MaxRetryError(_pool, url, error or ResponseError(cause))
urllib3.exceptions.MaxRetryError: HTTPSConnectionPool(host='api.binance.com', port=443): Max retries exceeded with url: /api/v1/ping (Caused by NewConnectionError('<urllib3.connection.VerifiedHTTPSConnection object at 0x7fd3af2adac0>: Failed to establish a new connection: [Errno 8] nodename nor servname provided, or not known'))

During handling of the above exception, another exception occurred:

Traceback (most recent call last):
  File "./MACD/get_Binance.py", line 26, in <module>
    client = Client(api_key, api_secret)
  File "/Library/Frameworks/Python.framework/Versions/3.8/lib/python3.8/site-packages/binance/client.py", line 97, in __init__
    self.ping()
  File "/Library/Frameworks/Python.framework/Versions/3.8/lib/python3.8/site-packages/binance/client.py", line 378, in ping
    return self._get('ping')
  File "/Library/Frameworks/Python.framework/Versions/3.8/lib/python3.8/site-packages/binance/client.py", line 222, in _get
    return self._request_api('get', path, signed, version, **kwargs)
  File "/Library/Frameworks/Python.framework/Versions/3.8/lib/python3.8/site-packages/binance/client.py", line 191, in _request_api
    return self._request(method, uri, signed, **kwargs)
  File "/Library/Frameworks/Python.framework/Versions/3.8/lib/python3.8/site-packages/binance/client.py", line 185, in _request
    self.response = getattr(self.session, method)(uri, **kwargs)
  File "/Library/Frameworks/Python.framework/Versions/3.8/lib/python3.8/site-packages/requests/sessions.py", line 546, in get
    return self.request('GET', url, **kwargs)
  File "/Library/Frameworks/Python.framework/Versions/3.8/lib/python3.8/site-packages/requests/sessions.py", line 533, in request
    resp = self.send(prep, **send_kwargs)
  File "/Library/Frameworks/Python.framework/Versions/3.8/lib/python3.8/site-packages/requests/sessions.py", line 646, in send
    r = adapter.send(request, **kwargs)
  File "/Library/Frameworks/Python.framework/Versions/3.8/lib/python3.8/site-packages/requests/adapters.py", line 516, in send
    raise ConnectionError(e, request=request)
requests.exceptions.ConnectionError: HTTPSConnectionPool(host='api.binance.com', port=443): Max retries exceeded with url: /api/v1/ping (Caused by NewConnectionError('<urllib3.connection.VerifiedHTTPSConnection object at 0x7fd3af2adac0>: Failed to establish a new connection: [Errno 8] nodename nor servname provided, or not known'))
Traceback (most recent call last):
  File "email_send.py", line 131, in <module>
    server = smtplib.SMTP('smtp.gmail.com', 587) 
  File "/Library/Frameworks/Python.framework/Versions/3.8/lib/python3.8/smtplib.py", line 253, in __init__
    (code, msg) = self.connect(host, port)
  File "/Library/Frameworks/Python.framework/Versions/3.8/lib/python3.8/smtplib.py", line 339, in connect
    self.sock = self._get_socket(host, port, self.timeout)
  File "/Library/Frameworks/Python.framework/Versions/3.8/lib/python3.8/smtplib.py", line 308, in _get_socket
    return socket.create_connection((host, port), timeout,
  File "/Library/Frameworks/Python.framework/Versions/3.8/lib/python3.8/socket.py", line 787, in create_connection
    for res in getaddrinfo(host, port, 0, SOCK_STREAM):
  File "/Library/Frameworks/Python.framework/Versions/3.8/lib/python3.8/socket.py", line 914, in getaddrinfo
    for res in _socket.getaddrinfo(host, port, family, type, proto, flags):
socket.gaierror: [Errno 8] nodename nor servname provided, or not known
Tue Nov  3 23:06:00 CST 2020
Predict_price 1.0048652524000363 413
Predict_Sell_price -1.0372999897652289 381
-0.8917957162609536
Alert: 83772.43085694313
Execute-Time: 4.576171159744263
Tue Nov  3 23:08:00 CST 2020
Predict_price 1.0048652524000363 413
Predict_Sell_price -1.0372999897652289 381
-0.8732885937538366
Alert: 110.16007709503174
Execute-Time: 2.029839038848877
Tue Nov  3 23:10:00 CST 2020
Predict_price 1.0048652524000363 413
Predict_Sell_price -1.0372999897652289 381
-0.9083883088534956
Alert: 229.30478405952454
Execute-Time: 1.9679229259490967
Tue Nov  3 23:12:00 CST 2020
Predict_price 1.0048652524000363 413
Predict_Sell_price -1.0372999897652289 381
-0.9160464285116585
Alert: 348.4184823036194
Execute-Time: 1.643404245376587
Tue Nov  3 23:14:00 CST 2020
Traceback (most recent call last):
  File "/Library/Frameworks/Python.framework/Versions/3.8/lib/python3.8/site-packages/urllib3/connection.py", line 156, in _new_conn
    conn = connection.create_connection(
  File "/Library/Frameworks/Python.framework/Versions/3.8/lib/python3.8/site-packages/urllib3/util/connection.py", line 61, in create_connection
    for res in socket.getaddrinfo(host, port, family, socket.SOCK_STREAM):
  File "/Library/Frameworks/Python.framework/Versions/3.8/lib/python3.8/socket.py", line 914, in getaddrinfo
    for res in _socket.getaddrinfo(host, port, family, type, proto, flags):
socket.gaierror: [Errno 8] nodename nor servname provided, or not known

During handling of the above exception, another exception occurred:

Traceback (most recent call last):
  File "/Library/Frameworks/Python.framework/Versions/3.8/lib/python3.8/site-packages/urllib3/connectionpool.py", line 665, in urlopen
    httplib_response = self._make_request(
  File "/Library/Frameworks/Python.framework/Versions/3.8/lib/python3.8/site-packages/urllib3/connectionpool.py", line 376, in _make_request
    self._validate_conn(conn)
  File "/Library/Frameworks/Python.framework/Versions/3.8/lib/python3.8/site-packages/urllib3/connectionpool.py", line 994, in _validate_conn
    conn.connect()
  File "/Library/Frameworks/Python.framework/Versions/3.8/lib/python3.8/site-packages/urllib3/connection.py", line 334, in connect
    conn = self._new_conn()
  File "/Library/Frameworks/Python.framework/Versions/3.8/lib/python3.8/site-packages/urllib3/connection.py", line 168, in _new_conn
    raise NewConnectionError(
urllib3.exceptions.NewConnectionError: <urllib3.connection.VerifiedHTTPSConnection object at 0x7fc397ad8c10>: Failed to establish a new connection: [Errno 8] nodename nor servname provided, or not known

During handling of the above exception, another exception occurred:

Traceback (most recent call last):
  File "/Library/Frameworks/Python.framework/Versions/3.8/lib/python3.8/site-packages/requests/adapters.py", line 439, in send
    resp = conn.urlopen(
  File "/Library/Frameworks/Python.framework/Versions/3.8/lib/python3.8/site-packages/urllib3/connectionpool.py", line 719, in urlopen
    retries = retries.increment(
  File "/Library/Frameworks/Python.framework/Versions/3.8/lib/python3.8/site-packages/urllib3/util/retry.py", line 436, in increment
    raise MaxRetryError(_pool, url, error or ResponseError(cause))
urllib3.exceptions.MaxRetryError: HTTPSConnectionPool(host='api.binance.com', port=443): Max retries exceeded with url: /api/v1/ping (Caused by NewConnectionError('<urllib3.connection.VerifiedHTTPSConnection object at 0x7fc397ad8c10>: Failed to establish a new connection: [Errno 8] nodename nor servname provided, or not known'))

During handling of the above exception, another exception occurred:

Traceback (most recent call last):
  File "./MACD/get_Binance.py", line 26, in <module>
    client = Client(api_key, api_secret)
  File "/Library/Frameworks/Python.framework/Versions/3.8/lib/python3.8/site-packages/binance/client.py", line 97, in __init__
    self.ping()
  File "/Library/Frameworks/Python.framework/Versions/3.8/lib/python3.8/site-packages/binance/client.py", line 378, in ping
    return self._get('ping')
  File "/Library/Frameworks/Python.framework/Versions/3.8/lib/python3.8/site-packages/binance/client.py", line 222, in _get
    return self._request_api('get', path, signed, version, **kwargs)
  File "/Library/Frameworks/Python.framework/Versions/3.8/lib/python3.8/site-packages/binance/client.py", line 191, in _request_api
    return self._request(method, uri, signed, **kwargs)
  File "/Library/Frameworks/Python.framework/Versions/3.8/lib/python3.8/site-packages/binance/client.py", line 185, in _request
    self.response = getattr(self.session, method)(uri, **kwargs)
  File "/Library/Frameworks/Python.framework/Versions/3.8/lib/python3.8/site-packages/requests/sessions.py", line 546, in get
    return self.request('GET', url, **kwargs)
  File "/Library/Frameworks/Python.framework/Versions/3.8/lib/python3.8/site-packages/requests/sessions.py", line 533, in request
    resp = self.send(prep, **send_kwargs)
  File "/Library/Frameworks/Python.framework/Versions/3.8/lib/python3.8/site-packages/requests/sessions.py", line 646, in send
    r = adapter.send(request, **kwargs)
  File "/Library/Frameworks/Python.framework/Versions/3.8/lib/python3.8/site-packages/requests/adapters.py", line 516, in send
    raise ConnectionError(e, request=request)
requests.exceptions.ConnectionError: HTTPSConnectionPool(host='api.binance.com', port=443): Max retries exceeded with url: /api/v1/ping (Caused by NewConnectionError('<urllib3.connection.VerifiedHTTPSConnection object at 0x7fc397ad8c10>: Failed to establish a new connection: [Errno 8] nodename nor servname provided, or not known'))
Traceback (most recent call last):
  File "email_send.py", line 131, in <module>
    server = smtplib.SMTP('smtp.gmail.com', 587) 
  File "/Library/Frameworks/Python.framework/Versions/3.8/lib/python3.8/smtplib.py", line 253, in __init__
    (code, msg) = self.connect(host, port)
  File "/Library/Frameworks/Python.framework/Versions/3.8/lib/python3.8/smtplib.py", line 339, in connect
    self.sock = self._get_socket(host, port, self.timeout)
  File "/Library/Frameworks/Python.framework/Versions/3.8/lib/python3.8/smtplib.py", line 308, in _get_socket
    return socket.create_connection((host, port), timeout,
  File "/Library/Frameworks/Python.framework/Versions/3.8/lib/python3.8/socket.py", line 787, in create_connection
    for res in getaddrinfo(host, port, 0, SOCK_STREAM):
  File "/Library/Frameworks/Python.framework/Versions/3.8/lib/python3.8/socket.py", line 914, in getaddrinfo
    for res in _socket.getaddrinfo(host, port, family, type, proto, flags):
socket.gaierror: [Errno 8] nodename nor servname provided, or not known
Tue Nov  3 23:16:00 CST 2020
Predict_price 1.0048652524000363 413
Predict_Sell_price -1.0372999897652289 381
-0.9020065424717312
Alert: 584.542699098587
Execute-Time: 1.3195359706878662
Tue Nov  3 23:18:00 CST 2020
Predict_price 1.0048652524000363 413
Predict_Sell_price -1.0372999897652289 381
-0.8924338928990845
Alert: 705.0833661556244
Execute-Time: 1.4346189498901367
Tue Nov  3 23:20:00 CST 2020
Predict_price 1.0048652524000363 413
Predict_Sell_price -1.0372999897652289 381
-0.8771176535828498
Alert: 826.715980052948
Execute-Time: 1.508457899093628
Tue Nov  3 23:22:00 CST 2020
Predict_price 1.0048652524000363 413
Predict_Sell_price -1.0372999897652289 381
-0.9109410154062014
Alert: 946.9537920951843
Execute-Time: 1.6164748668670654
Tue Nov  3 23:24:00 CST 2020
Predict_price 1.0048652524000363 413
Predict_Sell_price -1.0372999897652289 381
-0.9402971407623635
Alert: 119.73638606071472
Execute-Time: 1.5690598487854004
Tue Nov  3 23:26:00 CST 2020
Predict_price 1.0048652524000363 413
Predict_Sell_price -1.0372999897652289 381
-0.9122173686825998
Alert: 240.45581793785095
Execute-Time: 1.5588290691375732
Tue Nov  3 23:28:00 CST 2020
Predict_price 1.0048652524000363 413
Predict_Sell_price -1.0372999897652289 381
-0.9077501322153192
Alert: 357.99747800827026
Execute-Time: 1.4018492698669434
Tue Nov  3 23:30:00 CST 2020
Predict_price 1.0048652524000363 413
Predict_Sell_price -1.0372999897652289 381
-0.9243427248079523
Alert: 479.5794720649719
Execute-Time: 1.5697929859161377
Tue Nov  3 23:32:01 CST 2020
Predict_price 1.0048652524000363 413
Predict_Sell_price -1.0372999897652289 381
-0.909664662129894
Alert: 1817.632187128067
Execute-Time: 4.869253873825073
Tue Nov  3 23:54:00 CST 2020
Predict_price 1.0048652524000363 413
Predict_Sell_price -1.0372999897652289 381
-1.0730378815031099
Execute-Time: 2.0604360103607178
Tue Nov  3 23:56:01 CST 2020
Predict_price 1.0048652524000363 413
Predict_Sell_price -1.0372999897652289 381
-0.9887985652637734
Alert: 224.69036483764648
Execute-Time: 1.9984281063079834
Tue Nov  3 23:58:00 CST 2020
Predict_price 1.0048652524000363 413
Predict_Sell_price -1.0372999897652289 381
-1.0034766279418772
Execute-Time: 1.5763928890228271
Wed Nov  4 00:00:00 CST 2020
Predict_price 1.051038886567043 410
Predict_Sell_price -1.0549440194158213 377
-0.769040885512728
Alert: 465.6997129917145
Execute-Time: 2.1277291774749756
Wed Nov  4 00:02:00 CST 2020
Predict_price 1.051038886567043 410
Predict_Sell_price -1.0549440194158213 377
-0.8092460137178441
Alert: 583.5045638084412
Execute-Time: 1.8419859409332275
